Workbook

Sheet Məzmun tərkibi və təhlil
A1: Nazirlik | C1: Azərbaycan Respublikası Elm və Təhsil Nazirliyi | K1: I yarımil | P1: Bölmə
A2: İdarə | C2: Bakı Şəhəri üzrə Təhsil İdarəsi | R2: Azərbaycan-A, Rus-R
A3: Məktəb | C3: 99 | K3: Tarix | P3: Sinif
A4: Fənn | C4: Azərbaycan Respublikası Elm və Təhsil Nazirliyi | M4: gün | N4: ay | O4: il | R4: rəqəm | S4: indeks
A5: Summativ qiymətləndirmə tapşırıqlarının məzmun tərkibi və təhlili
A6: Variant | B6: A | K6: Variant | L6: B
A7: № | B7: Məzmun xətti | C7: Məzmun standartı | D7: Səviyyə | E7: Doğru cavab | F7: Bal | G7: Doğru (%) | H7: Yanlış (%) | I7: Cavabsız (%) | K7: № | L7: Məzmun xətti | M7: Məzmun standartı | N7: Səviyyə | O7: Doğru cavab | P7: Bal | Q7: Doğru (%) | R7: Yanlış (%) | S7: Cavabsız (%)
A8: 1 | B8: =LEFT(C8) -> 2 | C8: 2.2.3. | D8: 1 | F8: =IF(D8="","",IF(D8=1,20/COUNTIF($D$8:$D$37,"1"),IF(D8=2,30/COUNTIF($D$8:$D$37,"2"),IF(D8=3,30/COUNTIF($D$8:$D$37,"3"),IF(D8=4,20/COUNTIF($D$8:$D$37,"4")))))) -> 20 | G8: =IF('Şagirdlərin nəticələri'!AT$59="","",'Şagirdlərin nəticələri'!AT$59) | H8: =IF('Şagirdlərin nəticələri'!AT$60="","",'Şagirdlərin nəticələri'!AT$60) | I8: =IF('Şagirdlərin nəticələri'!AT$61="","",'Şagirdlərin nəticələri'!AT$61) | K8: 1 | L8: =LEFT(M8) | P8: =IF(N8="","",IF(N8=1,20/COUNTIF($N$8:$N$37,"1"),IF(N8=2,30/COUNTIF($N$8:$N$37,"2"),IF(N8=3,30/COUNTIF($N$8:$N$37,"3"),IF(N8=4,20/COUNTIF($N$8:$N$37,"4")))))) | Q8: =IF('Şagirdlərin nəticələri'!AT$62="","",'Şagirdlərin nəticələri'!AT$62) | R8: =IF('Şagirdlərin nəticələri'!AT$63="","",'Şagirdlərin nəticələri'!AT$63) | S8: =IF('Şagirdlərin nəticələri'!AT$64="","",'Şagirdlərin nəticələri'!AT$64)
A9: 2 | B9: =LEFT(C9) -> 2 | C9: 2.2.2 | F9: =IF(D9="","",IF(D9=1,20/COUNTIF($D$8:$D$37,"1"),IF(D9=2,30/COUNTIF($D$8:$D$37,"2"),IF(D9=3,30/COUNTIF($D$8:$D$37,"3"),IF(D9=4,20/COUNTIF($D$8:$D$37,"4")))))) | G9: =IF('Şagirdlərin nəticələri'!AU$59="","",'Şagirdlərin nəticələri'!AU$59) | H9: =IF('Şagirdlərin nəticələri'!AU$60="","",'Şagirdlərin nəticələri'!AU$60) | I9: =IF('Şagirdlərin nəticələri'!AU$61="","",'Şagirdlərin nəticələri'!AU$61) | K9: 2 | L9: =LEFT(M9) | P9: =IF(N9="","",IF(N9=1,20/COUNTIF($N$8:$N$37,"1"),IF(N9=2,30/COUNTIF($N$8:$N$37,"2"),IF(N9=3,30/COUNTIF($N$8:$N$37,"3"),IF(N9=4,20/COUNTIF($N$8:$N$37,"4")))))) | Q9: =IF('Şagirdlərin nəticələri'!AU$62="","",'Şagirdlərin nəticələri'!AU$62) | R9: =IF('Şagirdlərin nəticələri'!AU$63="","",'Şagirdlərin nəticələri'!AU$63) | S9: =IF('Şagirdlərin nəticələri'!AU$64="","",'Şagirdlərin nəticələri'!AU$64)
A10: 3 | B10: =LEFT(C10) | F10: =IF(D10="","",IF(D10=1,20/COUNTIF($D$8:$D$37,"1"),IF(D10=2,30/COUNTIF($D$8:$D$37,"2"),IF(D10=3,30/COUNTIF($D$8:$D$37,"3"),IF(D10=4,20/COUNTIF($D$8:$D$37,"4")))))) | G10: =IF('Şagirdlərin nəticələri'!AV$59="","",'Şagirdlərin nəticələri'!AV$59) | H10: =IF('Şagirdlərin nəticələri'!AV$60="","",'Şagirdlərin nəticələri'!AV$60) | I10: =IF('Şagirdlərin nəticələri'!AV$61="","",'Şagirdlərin nəticələri'!AV$61) | K10: 3 | L10: =LEFT(M10) | P10: =IF(N10="","",IF(N10=1,20/COUNTIF($N$8:$N$37,"1"),IF(N10=2,30/COUNTIF($N$8:$N$37,"2"),IF(N10=3,30/COUNTIF($N$8:$N$37,"3"),IF(N10=4,20/COUNTIF($N$8:$N$37,"4")))))) | Q10: =IF('Şagirdlərin nəticələri'!AV$62="","",'Şagirdlərin nəticələri'!AV$62) | R10: =IF('Şagirdlərin nəticələri'!AV$63="","",'Şagirdlərin nəticələri'!AV$63) | S10: =IF('Şagirdlərin nəticələri'!AV$64="","",'Şagirdlərin nəticələri'!AV$64)
A11: 4 | B11: =LEFT(C11) | F11: =IF(D11="","",IF(D11=1,20/COUNTIF($D$8:$D$37,"1"),IF(D11=2,30/COUNTIF($D$8:$D$37,"2"),IF(D11=3,30/COUNTIF($D$8:$D$37,"3"),IF(D11=4,20/COUNTIF($D$8:$D$37,"4")))))) | G11: =IF('Şagirdlərin nəticələri'!AW$59="","",'Şagirdlərin nəticələri'!AW$59) | H11: =IF('Şagirdlərin nəticələri'!AW$60="","",'Şagirdlərin nəticələri'!AW$60) | I11: =IF('Şagirdlərin nəticələri'!AW$61="","",'Şagirdlərin nəticələri'!AW$61) | K11: 4 | L11: =LEFT(M11) | P11: =IF(N11="","",IF(N11=1,20/COUNTIF($N$8:$N$37,"1"),IF(N11=2,30/COUNTIF($N$8:$N$37,"2"),IF(N11=3,30/COUNTIF($N$8:$N$37,"3"),IF(N11=4,20/COUNTIF($N$8:$N$37,"4")))))) | Q11: =IF('Şagirdlərin nəticələri'!AW$62="","",'Şagirdlərin nəticələri'!AW$62) | R11: =IF('Şagirdlərin nəticələri'!AW$63="","",'Şagirdlərin nəticələri'!AW$63) | S11: =IF('Şagirdlərin nəticələri'!AW$64="","",'Şagirdlərin nəticələri'!AW$64)
A12: 5 | B12: =LEFT(C12) | F12: =IF(D12="","",IF(D12=1,20/COUNTIF($D$8:$D$37,"1"),IF(D12=2,30/COUNTIF($D$8:$D$37,"2"),IF(D12=3,30/COUNTIF($D$8:$D$37,"3"),IF(D12=4,20/COUNTIF($D$8:$D$37,"4")))))) | G12: =IF('Şagirdlərin nəticələri'!AX$59="","",'Şagirdlərin nəticələri'!AX$59) | H12: =IF('Şagirdlərin nəticələri'!AX$60="","",'Şagirdlərin nəticələri'!AX$60) | I12: =IF('Şagirdlərin nəticələri'!AX$61="","",'Şagirdlərin nəticələri'!AX$61) | K12: 5 | L12: =LEFT(M12) | P12: =IF(N12="","",IF(N12=1,20/COUNTIF($N$8:$N$37,"1"),IF(N12=2,30/COUNTIF($N$8:$N$37,"2"),IF(N12=3,30/COUNTIF($N$8:$N$37,"3"),IF(N12=4,20/COUNTIF($N$8:$N$37,"4")))))) | Q12: =IF('Şagirdlərin nəticələri'!AX$62="","",'Şagirdlərin nəticələri'!AX$62) | R12: =IF('Şagirdlərin nəticələri'!AX$63="","",'Şagirdlərin nəticələri'!AX$63) | S12: =IF('Şagirdlərin nəticələri'!AX$64="","",'Şagirdlərin nəticələri'!AX$64)
A13: 6 | B13: =LEFT(C13) | F13: =IF(D13="","",IF(D13=1,20/COUNTIF($D$8:$D$37,"1"),IF(D13=2,30/COUNTIF($D$8:$D$37,"2"),IF(D13=3,30/COUNTIF($D$8:$D$37,"3"),IF(D13=4,20/COUNTIF($D$8:$D$37,"4")))))) | G13: =IF('Şagirdlərin nəticələri'!AY$59="","",'Şagirdlərin nəticələri'!AY$59) | H13: =IF('Şagirdlərin nəticələri'!AY$60="","",'Şagirdlərin nəticələri'!AY$60) | I13: =IF('Şagirdlərin nəticələri'!AY$61="","",'Şagirdlərin nəticələri'!AY$61) | K13: 6 | L13: =LEFT(M13) | P13: =IF(N13="","",IF(N13=1,20/COUNTIF($N$8:$N$37,"1"),IF(N13=2,30/COUNTIF($N$8:$N$37,"2"),IF(N13=3,30/COUNTIF($N$8:$N$37,"3"),IF(N13=4,20/COUNTIF($N$8:$N$37,"4")))))) | Q13: =IF('Şagirdlərin nəticələri'!AY$62="","",'Şagirdlərin nəticələri'!AY$62) | R13: =IF('Şagirdlərin nəticələri'!AY$63="","",'Şagirdlərin nəticələri'!AY$63) | S13: =IF('Şagirdlərin nəticələri'!AY$64="","",'Şagirdlərin nəticələri'!AY$64)
A14: 7 | B14: =LEFT(C14) | F14: =IF(D14="","",IF(D14=1,20/COUNTIF($D$8:$D$37,"1"),IF(D14=2,30/COUNTIF($D$8:$D$37,"2"),IF(D14=3,30/COUNTIF($D$8:$D$37,"3"),IF(D14=4,20/COUNTIF($D$8:$D$37,"4")))))) | G14: =IF('Şagirdlərin nəticələri'!AZ$59="","",'Şagirdlərin nəticələri'!AZ$59) | H14: =IF('Şagirdlərin nəticələri'!AZ$60="","",'Şagirdlərin nəticələri'!AZ$60) | I14: =IF('Şagirdlərin nəticələri'!AZ$61="","",'Şagirdlərin nəticələri'!AZ$61) | K14: 7 | L14: =LEFT(M14) | P14: =IF(N14="","",IF(N14=1,20/COUNTIF($N$8:$N$37,"1"),IF(N14=2,30/COUNTIF($N$8:$N$37,"2"),IF(N14=3,30/COUNTIF($N$8:$N$37,"3"),IF(N14=4,20/COUNTIF($N$8:$N$37,"4")))))) | Q14: =IF('Şagirdlərin nəticələri'!AZ$62="","",'Şagirdlərin nəticələri'!AZ$62) | R14: =IF('Şagirdlərin nəticələri'!AZ$63="","",'Şagirdlərin nəticələri'!AZ$63) | S14: =IF('Şagirdlərin nəticələri'!AZ$64="","",'Şagirdlərin nəticələri'!AZ$64)
A15: 8 | B15: =LEFT(C15) | F15: =IF(D15="","",IF(D15=1,20/COUNTIF($D$8:$D$37,"1"),IF(D15=2,30/COUNTIF($D$8:$D$37,"2"),IF(D15=3,30/COUNTIF($D$8:$D$37,"3"),IF(D15=4,20/COUNTIF($D$8:$D$37,"4")))))) | G15: =IF('Şagirdlərin nəticələri'!BA$59="","",'Şagirdlərin nəticələri'!BA$59) | H15: =IF('Şagirdlərin nəticələri'!BA$60="","",'Şagirdlərin nəticələri'!BA$60) | I15: =IF('Şagirdlərin nəticələri'!BA$61="","",'Şagirdlərin nəticələri'!BA$61) | K15: 8 | L15: =LEFT(M15) | P15: =IF(N15="","",IF(N15=1,20/COUNTIF($N$8:$N$37,"1"),IF(N15=2,30/COUNTIF($N$8:$N$37,"2"),IF(N15=3,30/COUNTIF($N$8:$N$37,"3"),IF(N15=4,20/COUNTIF($N$8:$N$37,"4")))))) | Q15: =IF('Şagirdlərin nəticələri'!BA$62="","",'Şagirdlərin nəticələri'!BA$62) | R15: =IF('Şagirdlərin nəticələri'!BA$63="","",'Şagirdlərin nəticələri'!BA$63) | S15: =IF('Şagirdlərin nəticələri'!BA$64="","",'Şagirdlərin nəticələri'!BA$64)
A16: 9 | B16: =LEFT(C16) | F16: =IF(D16="","",IF(D16=1,20/COUNTIF($D$8:$D$37,"1"),IF(D16=2,30/COUNTIF($D$8:$D$37,"2"),IF(D16=3,30/COUNTIF($D$8:$D$37,"3"),IF(D16=4,20/COUNTIF($D$8:$D$37,"4")))))) | G16: =IF('Şagirdlərin nəticələri'!BB$59="","",'Şagirdlərin nəticələri'!BB$59) | H16: =IF('Şagirdlərin nəticələri'!BB$60="","",'Şagirdlərin nəticələri'!BB$60) | I16: =IF('Şagirdlərin nəticələri'!BB$61="","",'Şagirdlərin nəticələri'!BB$61) | K16: 9 | L16: =LEFT(M16) | P16: =IF(N16="","",IF(N16=1,20/COUNTIF($N$8:$N$37,"1"),IF(N16=2,30/COUNTIF($N$8:$N$37,"2"),IF(N16=3,30/COUNTIF($N$8:$N$37,"3"),IF(N16=4,20/COUNTIF($N$8:$N$37,"4")))))) | Q16: =IF('Şagirdlərin nəticələri'!BB$62="","",'Şagirdlərin nəticələri'!BB$62) | R16: =IF('Şagirdlərin nəticələri'!BB$63="","",'Şagirdlərin nəticələri'!BB$63) | S16: =IF('Şagirdlərin nəticələri'!BB$64="","",'Şagirdlərin nəticələri'!BB$64)
A17: 10 | B17: =LEFT(C17) | F17: =IF(D17="","",IF(D17=1,20/COUNTIF($D$8:$D$37,"1"),IF(D17=2,30/COUNTIF($D$8:$D$37,"2"),IF(D17=3,30/COUNTIF($D$8:$D$37,"3"),IF(D17=4,20/COUNTIF($D$8:$D$37,"4")))))) | G17: =IF('Şagirdlərin nəticələri'!BC$59="","",'Şagirdlərin nəticələri'!BC$59) | H17: =IF('Şagirdlərin nəticələri'!BC$60="","",'Şagirdlərin nəticələri'!BC$60) | I17: =IF('Şagirdlərin nəticələri'!BC$61="","",'Şagirdlərin nəticələri'!BC$61) | K17: 10 | L17: =LEFT(M17) | P17: =IF(N17="","",IF(N17=1,20/COUNTIF($N$8:$N$37,"1"),IF(N17=2,30/COUNTIF($N$8:$N$37,"2"),IF(N17=3,30/COUNTIF($N$8:$N$37,"3"),IF(N17=4,20/COUNTIF($N$8:$N$37,"4")))))) | Q17: =IF('Şagirdlərin nəticələri'!BC$62="","",'Şagirdlərin nəticələri'!BC$62) | R17: =IF('Şagirdlərin nəticələri'!BC$63="","",'Şagirdlərin nəticələri'!BC$63) | S17: =IF('Şagirdlərin nəticələri'!BC$64="","",'Şagirdlərin nəticələri'!BC$64)
A18: 11 | B18: =LEFT(C18) | F18: =IF(D18="","",IF(D18=1,20/COUNTIF($D$8:$D$37,"1"),IF(D18=2,30/COUNTIF($D$8:$D$37,"2"),IF(D18=3,30/COUNTIF($D$8:$D$37,"3"),IF(D18=4,20/COUNTIF($D$8:$D$37,"4")))))) | G18: =IF('Şagirdlərin nəticələri'!BD$59="","",'Şagirdlərin nəticələri'!BD$59) | H18: =IF('Şagirdlərin nəticələri'!BD$60="","",'Şagirdlərin nəticələri'!BD$60) | I18: =IF('Şagirdlərin nəticələri'!BD$61="","",'Şagirdlərin nəticələri'!BD$61) | K18: 11 | L18: =LEFT(M18) | P18: =IF(N18="","",IF(N18=1,20/COUNTIF($N$8:$N$37,"1"),IF(N18=2,30/COUNTIF($N$8:$N$37,"2"),IF(N18=3,30/COUNTIF($N$8:$N$37,"3"),IF(N18=4,20/COUNTIF($N$8:$N$37,"4")))))) | Q18: =IF('Şagirdlərin nəticələri'!BD$62="","",'Şagirdlərin nəticələri'!BD$62) | R18: =IF('Şagirdlərin nəticələri'!BD$63="","",'Şagirdlərin nəticələri'!BD$63) | S18: =IF('Şagirdlərin nəticələri'!BD$64="","",'Şagirdlərin nəticələri'!BD$64)
A19: 12 | B19: =LEFT(C19) | F19: =IF(D19="","",IF(D19=1,20/COUNTIF($D$8:$D$37,"1"),IF(D19=2,30/COUNTIF($D$8:$D$37,"2"),IF(D19=3,30/COUNTIF($D$8:$D$37,"3"),IF(D19=4,20/COUNTIF($D$8:$D$37,"4")))))) | G19: =IF('Şagirdlərin nəticələri'!BE$59="","",'Şagirdlərin nəticələri'!BE$59) | H19: =IF('Şagirdlərin nəticələri'!BE$60="","",'Şagirdlərin nəticələri'!BE$60) | I19: =IF('Şagirdlərin nəticələri'!BE$61="","",'Şagirdlərin nəticələri'!BE$61) | K19: 12 | L19: =LEFT(M19) | P19: =IF(N19="","",IF(N19=1,20/COUNTIF($N$8:$N$37,"1"),IF(N19=2,30/COUNTIF($N$8:$N$37,"2"),IF(N19=3,30/COUNTIF($N$8:$N$37,"3"),IF(N19=4,20/COUNTIF($N$8:$N$37,"4")))))) | Q19: =IF('Şagirdlərin nəticələri'!BE$62="","",'Şagirdlərin nəticələri'!BE$62) | R19: =IF('Şagirdlərin nəticələri'!BE$63="","",'Şagirdlərin nəticələri'!BE$63) | S19: =IF('Şagirdlərin nəticələri'!BE$64="","",'Şagirdlərin nəticələri'!BE$64)
A20: 13 | B20: =LEFT(C20) | F20: =IF(D20="","",IF(D20=1,20/COUNTIF($D$8:$D$37,"1"),IF(D20=2,30/COUNTIF($D$8:$D$37,"2"),IF(D20=3,30/COUNTIF($D$8:$D$37,"3"),IF(D20=4,20/COUNTIF($D$8:$D$37,"4")))))) | G20: =IF('Şagirdlərin nəticələri'!BF$59="","",'Şagirdlərin nəticələri'!BF$59) | H20: =IF('Şagirdlərin nəticələri'!BF$60="","",'Şagirdlərin nəticələri'!BF$60) | I20: =IF('Şagirdlərin nəticələri'!BF$61="","",'Şagirdlərin nəticələri'!BF$61) | K20: 13 | L20: =LEFT(M20) | P20: =IF(N20="","",IF(N20=1,20/COUNTIF($N$8:$N$37,"1"),IF(N20=2,30/COUNTIF($N$8:$N$37,"2"),IF(N20=3,30/COUNTIF($N$8:$N$37,"3"),IF(N20=4,20/COUNTIF($N$8:$N$37,"4")))))) | Q20: =IF('Şagirdlərin nəticələri'!BF$62="","",'Şagirdlərin nəticələri'!BF$62) | R20: =IF('Şagirdlərin nəticələri'!BF$63="","",'Şagirdlərin nəticələri'!BF$63) | S20: =IF('Şagirdlərin nəticələri'!BF$64="","",'Şagirdlərin nəticələri'!BF$64)
A21: 14 | B21: =LEFT(C21) | F21: =IF(D21="","",IF(D21=1,20/COUNTIF($D$8:$D$37,"1"),IF(D21=2,30/COUNTIF($D$8:$D$37,"2"),IF(D21=3,30/COUNTIF($D$8:$D$37,"3"),IF(D21=4,20/COUNTIF($D$8:$D$37,"4")))))) | G21: =IF('Şagirdlərin nəticələri'!BG$59="","",'Şagirdlərin nəticələri'!BG$59) | H21: =IF('Şagirdlərin nəticələri'!BG$60="","",'Şagirdlərin nəticələri'!BG$60) | I21: =IF('Şagirdlərin nəticələri'!BG$61="","",'Şagirdlərin nəticələri'!BG$61) | K21: 14 | L21: =LEFT(M21) | P21: =IF(N21="","",IF(N21=1,20/COUNTIF($N$8:$N$37,"1"),IF(N21=2,30/COUNTIF($N$8:$N$37,"2"),IF(N21=3,30/COUNTIF($N$8:$N$37,"3"),IF(N21=4,20/COUNTIF($N$8:$N$37,"4")))))) | Q21: =IF('Şagirdlərin nəticələri'!BG$62="","",'Şagirdlərin nəticələri'!BG$62) | R21: =IF('Şagirdlərin nəticələri'!BG$63="","",'Şagirdlərin nəticələri'!BG$63) | S21: =IF('Şagirdlərin nəticələri'!BG$64="","",'Şagirdlərin nəticələri'!BG$64)
A22: 15 | B22: =LEFT(C22) | F22: =IF(D22="","",IF(D22=1,20/COUNTIF($D$8:$D$37,"1"),IF(D22=2,30/COUNTIF($D$8:$D$37,"2"),IF(D22=3,30/COUNTIF($D$8:$D$37,"3"),IF(D22=4,20/COUNTIF($D$8:$D$37,"4")))))) | G22: =IF('Şagirdlərin nəticələri'!BH$59="","",'Şagirdlərin nəticələri'!BH$59) | H22: =IF('Şagirdlərin nəticələri'!BH$60="","",'Şagirdlərin nəticələri'!BH$60) | I22: =IF('Şagirdlərin nəticələri'!BH$61="","",'Şagirdlərin nəticələri'!BH$61) | K22: 15 | L22: =LEFT(M22) | P22: =IF(N22="","",IF(N22=1,20/COUNTIF($N$8:$N$37,"1"),IF(N22=2,30/COUNTIF($N$8:$N$37,"2"),IF(N22=3,30/COUNTIF($N$8:$N$37,"3"),IF(N22=4,20/COUNTIF($N$8:$N$37,"4")))))) | Q22: =IF('Şagirdlərin nəticələri'!BH$62="","",'Şagirdlərin nəticələri'!BH$62) | R22: =IF('Şagirdlərin nəticələri'!BH$63="","",'Şagirdlərin nəticələri'!BH$63) | S22: =IF('Şagirdlərin nəticələri'!BH$64="","",'Şagirdlərin nəticələri'!BH$64)
A23: 16 | B23: =LEFT(C23) | F23: =IF(D23="","",IF(D23=1,20/COUNTIF($D$8:$D$37,"1"),IF(D23=2,30/COUNTIF($D$8:$D$37,"2"),IF(D23=3,30/COUNTIF($D$8:$D$37,"3"),IF(D23=4,20/COUNTIF($D$8:$D$37,"4")))))) | G23: =IF('Şagirdlərin nəticələri'!BI$59="","",'Şagirdlərin nəticələri'!BI$59) | H23: =IF('Şagirdlərin nəticələri'!BI$60="","",'Şagirdlərin nəticələri'!BI$60) | I23: =IF('Şagirdlərin nəticələri'!BI$61="","",'Şagirdlərin nəticələri'!BI$61) | K23: 16 | L23: =LEFT(M23) | P23: =IF(N23="","",IF(N23=1,20/COUNTIF($N$8:$N$37,"1"),IF(N23=2,30/COUNTIF($N$8:$N$37,"2"),IF(N23=3,30/COUNTIF($N$8:$N$37,"3"),IF(N23=4,20/COUNTIF($N$8:$N$37,"4")))))) | Q23: =IF('Şagirdlərin nəticələri'!BI$62="","",'Şagirdlərin nəticələri'!BI$62) | R23: =IF('Şagirdlərin nəticələri'!BI$63="","",'Şagirdlərin nəticələri'!BI$63) | S23: =IF('Şagirdlərin nəticələri'!BI$64="","",'Şagirdlərin nəticələri'!BI$64)
A24: 17 | B24: =LEFT(C24) | F24: =IF(D24="","",IF(D24=1,20/COUNTIF($D$8:$D$37,"1"),IF(D24=2,30/COUNTIF($D$8:$D$37,"2"),IF(D24=3,30/COUNTIF($D$8:$D$37,"3"),IF(D24=4,20/COUNTIF($D$8:$D$37,"4")))))) | G24: =IF('Şagirdlərin nəticələri'!BJ$59="","",'Şagirdlərin nəticələri'!BJ$59) | H24: =IF('Şagirdlərin nəticələri'!BJ$60="","",'Şagirdlərin nəticələri'!BJ$60) | I24: =IF('Şagirdlərin nəticələri'!BJ$61="","",'Şagirdlərin nəticələri'!BJ$61) | K24: 17 | L24: =LEFT(M24) | P24: =IF(N24="","",IF(N24=1,20/COUNTIF($N$8:$N$37,"1"),IF(N24=2,30/COUNTIF($N$8:$N$37,"2"),IF(N24=3,30/COUNTIF($N$8:$N$37,"3"),IF(N24=4,20/COUNTIF($N$8:$N$37,"4")))))) | Q24: =IF('Şagirdlərin nəticələri'!BJ$62="","",'Şagirdlərin nəticələri'!BJ$62) | R24: =IF('Şagirdlərin nəticələri'!BJ$63="","",'Şagirdlərin nəticələri'!BJ$63) | S24: =IF('Şagirdlərin nəticələri'!BJ$64="","",'Şagirdlərin nəticələri'!BJ$64)
A25: 18 | B25: =LEFT(C25) | F25: =IF(D25="","",IF(D25=1,20/COUNTIF($D$8:$D$37,"1"),IF(D25=2,30/COUNTIF($D$8:$D$37,"2"),IF(D25=3,30/COUNTIF($D$8:$D$37,"3"),IF(D25=4,20/COUNTIF($D$8:$D$37,"4")))))) | G25: =IF('Şagirdlərin nəticələri'!BK$59="","",'Şagirdlərin nəticələri'!BK$59) | H25: =IF('Şagirdlərin nəticələri'!BK$60="","",'Şagirdlərin nəticələri'!BK$60) | I25: =IF('Şagirdlərin nəticələri'!BK$61="","",'Şagirdlərin nəticələri'!BK$61) | K25: 18 | L25: =LEFT(M25) | P25: =IF(N25="","",IF(N25=1,20/COUNTIF($N$8:$N$37,"1"),IF(N25=2,30/COUNTIF($N$8:$N$37,"2"),IF(N25=3,30/COUNTIF($N$8:$N$37,"3"),IF(N25=4,20/COUNTIF($N$8:$N$37,"4")))))) | Q25: =IF('Şagirdlərin nəticələri'!BK$62="","",'Şagirdlərin nəticələri'!BK$62) | R25: =IF('Şagirdlərin nəticələri'!BK$63="","",'Şagirdlərin nəticələri'!BK$63) | S25: =IF('Şagirdlərin nəticələri'!BK$64="","",'Şagirdlərin nəticələri'!BK$64)
A26: 19 | B26: =LEFT(C26) | F26: =IF(D26="","",IF(D26=1,20/COUNTIF($D$8:$D$37,"1"),IF(D26=2,30/COUNTIF($D$8:$D$37,"2"),IF(D26=3,30/COUNTIF($D$8:$D$37,"3"),IF(D26=4,20/COUNTIF($D$8:$D$37,"4")))))) | G26: =IF('Şagirdlərin nəticələri'!BL$59="","",'Şagirdlərin nəticələri'!BL$59) | H26: =IF('Şagirdlərin nəticələri'!BL$60="","",'Şagirdlərin nəticələri'!BL$60) | I26: =IF('Şagirdlərin nəticələri'!BL$61="","",'Şagirdlərin nəticələri'!BL$61) | K26: 19 | L26: =LEFT(M26) | P26: =IF(N26="","",IF(N26=1,20/COUNTIF($N$8:$N$37,"1"),IF(N26=2,30/COUNTIF($N$8:$N$37,"2"),IF(N26=3,30/COUNTIF($N$8:$N$37,"3"),IF(N26=4,20/COUNTIF($N$8:$N$37,"4")))))) | Q26: =IF('Şagirdlərin nəticələri'!BL$62="","",'Şagirdlərin nəticələri'!BL$62) | R26: =IF('Şagirdlərin nəticələri'!BL$63="","",'Şagirdlərin nəticələri'!BL$63) | S26: =IF('Şagirdlərin nəticələri'!BL$64="","",'Şagirdlərin nəticələri'!BL$64)
A27: 20 | B27: =LEFT(C27) | F27: =IF(D27="","",IF(D27=1,20/COUNTIF($D$8:$D$37,"1"),IF(D27=2,30/COUNTIF($D$8:$D$37,"2"),IF(D27=3,30/COUNTIF($D$8:$D$37,"3"),IF(D27=4,20/COUNTIF($D$8:$D$37,"4")))))) | G27: =IF('Şagirdlərin nəticələri'!BM$59="","",'Şagirdlərin nəticələri'!BM$59) | H27: =IF('Şagirdlərin nəticələri'!BM$60="","",'Şagirdlərin nəticələri'!BM$60) | I27: =IF('Şagirdlərin nəticələri'!BM$61="","",'Şagirdlərin nəticələri'!BM$61) | K27: 20 | L27: =LEFT(M27) | P27: =IF(N27="","",IF(N27=1,20/COUNTIF($N$8:$N$37,"1"),IF(N27=2,30/COUNTIF($N$8:$N$37,"2"),IF(N27=3,30/COUNTIF($N$8:$N$37,"3"),IF(N27=4,20/COUNTIF($N$8:$N$37,"4")))))) | Q27: =IF('Şagirdlərin nəticələri'!BM$62="","",'Şagirdlərin nəticələri'!BM$62) | R27: =IF('Şagirdlərin nəticələri'!BM$63="","",'Şagirdlərin nəticələri'!BM$63) | S27: =IF('Şagirdlərin nəticələri'!BM$64="","",'Şagirdlərin nəticələri'!BM$64)
A28: 21 | B28: =LEFT(C28) | F28: =IF(D28="","",IF(D28=1,20/COUNTIF($D$8:$D$37,"1"),IF(D28=2,30/COUNTIF($D$8:$D$37,"2"),IF(D28=3,30/COUNTIF($D$8:$D$37,"3"),IF(D28=4,20/COUNTIF($D$8:$D$37,"4")))))) | G28: =IF('Şagirdlərin nəticələri'!BN$59="","",'Şagirdlərin nəticələri'!BN$59) | H28: =IF('Şagirdlərin nəticələri'!BN$60="","",'Şagirdlərin nəticələri'!BN$60) | I28: =IF('Şagirdlərin nəticələri'!BN$61="","",'Şagirdlərin nəticələri'!BN$61) | K28: 21 | L28: =LEFT(M28) | P28: =IF(N28="","",IF(N28=1,20/COUNTIF($N$8:$N$37,"1"),IF(N28=2,30/COUNTIF($N$8:$N$37,"2"),IF(N28=3,30/COUNTIF($N$8:$N$37,"3"),IF(N28=4,20/COUNTIF($N$8:$N$37,"4")))))) | Q28: =IF('Şagirdlərin nəticələri'!BN$62="","",'Şagirdlərin nəticələri'!BN$62) | R28: =IF('Şagirdlərin nəticələri'!BN$63="","",'Şagirdlərin nəticələri'!BN$63) | S28: =IF('Şagirdlərin nəticələri'!BN$64="","",'Şagirdlərin nəticələri'!BN$64)
A29: 22 | B29: =LEFT(C29) | F29: =IF(D29="","",IF(D29=1,20/COUNTIF($D$8:$D$37,"1"),IF(D29=2,30/COUNTIF($D$8:$D$37,"2"),IF(D29=3,30/COUNTIF($D$8:$D$37,"3"),IF(D29=4,20/COUNTIF($D$8:$D$37,"4")))))) | G29: =IF('Şagirdlərin nəticələri'!BO$59="","",'Şagirdlərin nəticələri'!BO$59) | H29: =IF('Şagirdlərin nəticələri'!BO$60="","",'Şagirdlərin nəticələri'!BO$60) | I29: =IF('Şagirdlərin nəticələri'!BO$61="","",'Şagirdlərin nəticələri'!BO$61) | K29: 22 | L29: =LEFT(M29) | P29: =IF(N29="","",IF(N29=1,20/COUNTIF($N$8:$N$37,"1"),IF(N29=2,30/COUNTIF($N$8:$N$37,"2"),IF(N29=3,30/COUNTIF($N$8:$N$37,"3"),IF(N29=4,20/COUNTIF($N$8:$N$37,"4")))))) | Q29: =IF('Şagirdlərin nəticələri'!BO$62="","",'Şagirdlərin nəticələri'!BO$62) | R29: =IF('Şagirdlərin nəticələri'!BO$63="","",'Şagirdlərin nəticələri'!BO$63) | S29: =IF('Şagirdlərin nəticələri'!BO$64="","",'Şagirdlərin nəticələri'!BO$64)
A30: 23 | B30: =LEFT(C30) | F30: =IF(D30="","",IF(D30=1,20/COUNTIF($D$8:$D$37,"1"),IF(D30=2,30/COUNTIF($D$8:$D$37,"2"),IF(D30=3,30/COUNTIF($D$8:$D$37,"3"),IF(D30=4,20/COUNTIF($D$8:$D$37,"4")))))) | G30: =IF('Şagirdlərin nəticələri'!BP$59="","",'Şagirdlərin nəticələri'!BP$59) | H30: =IF('Şagirdlərin nəticələri'!BP$60="","",'Şagirdlərin nəticələri'!BP$60) | I30: =IF('Şagirdlərin nəticələri'!BP$61="","",'Şagirdlərin nəticələri'!BP$61) | K30: 23 | L30: =LEFT(M30) | P30: =IF(N30="","",IF(N30=1,20/COUNTIF($N$8:$N$37,"1"),IF(N30=2,30/COUNTIF($N$8:$N$37,"2"),IF(N30=3,30/COUNTIF($N$8:$N$37,"3"),IF(N30=4,20/COUNTIF($N$8:$N$37,"4")))))) | Q30: =IF('Şagirdlərin nəticələri'!BP$62="","",'Şagirdlərin nəticələri'!BP$62) | R30: =IF('Şagirdlərin nəticələri'!BP$63="","",'Şagirdlərin nəticələri'!BP$63) | S30: =IF('Şagirdlərin nəticələri'!BP$64="","",'Şagirdlərin nəticələri'!BP$64)
A31: 24 | B31: =LEFT(C31) | F31: =IF(D31="","",IF(D31=1,20/COUNTIF($D$8:$D$37,"1"),IF(D31=2,30/COUNTIF($D$8:$D$37,"2"),IF(D31=3,30/COUNTIF($D$8:$D$37,"3"),IF(D31=4,20/COUNTIF($D$8:$D$37,"4")))))) | G31: =IF('Şagirdlərin nəticələri'!BQ$59="","",'Şagirdlərin nəticələri'!BQ$59) | H31: =IF('Şagirdlərin nəticələri'!BQ$60="","",'Şagirdlərin nəticələri'!BQ$60) | I31: =IF('Şagirdlərin nəticələri'!BQ$61="","",'Şagirdlərin nəticələri'!BQ$61) | K31: 24 | L31: =LEFT(M31) | P31: =IF(N31="","",IF(N31=1,20/COUNTIF($N$8:$N$37,"1"),IF(N31=2,30/COUNTIF($N$8:$N$37,"2"),IF(N31=3,30/COUNTIF($N$8:$N$37,"3"),IF(N31=4,20/COUNTIF($N$8:$N$37,"4")))))) | Q31: =IF('Şagirdlərin nəticələri'!BQ$62="","",'Şagirdlərin nəticələri'!BQ$62) | R31: =IF('Şagirdlərin nəticələri'!BQ$63="","",'Şagirdlərin nəticələri'!BQ$63) | S31: =IF('Şagirdlərin nəticələri'!BQ$64="","",'Şagirdlərin nəticələri'!BQ$64)
A32: 25 | B32: =LEFT(C32) | F32: =IF(D32="","",IF(D32=1,20/COUNTIF($D$8:$D$37,"1"),IF(D32=2,30/COUNTIF($D$8:$D$37,"2"),IF(D32=3,30/COUNTIF($D$8:$D$37,"3"),IF(D32=4,20/COUNTIF($D$8:$D$37,"4")))))) | G32: =IF('Şagirdlərin nəticələri'!BR$59="","",'Şagirdlərin nəticələri'!BR$59) | H32: =IF('Şagirdlərin nəticələri'!BR$60="","",'Şagirdlərin nəticələri'!BR$60) | I32: =IF('Şagirdlərin nəticələri'!BR$61="","",'Şagirdlərin nəticələri'!BR$61) | K32: 25 | L32: =LEFT(M32) | P32: =IF(N32="","",IF(N32=1,20/COUNTIF($N$8:$N$37,"1"),IF(N32=2,30/COUNTIF($N$8:$N$37,"2"),IF(N32=3,30/COUNTIF($N$8:$N$37,"3"),IF(N32=4,20/COUNTIF($N$8:$N$37,"4")))))) | Q32: =IF('Şagirdlərin nəticələri'!BR$62="","",'Şagirdlərin nəticələri'!BR$62) | R32: =IF('Şagirdlərin nəticələri'!BR$63="","",'Şagirdlərin nəticələri'!BR$63) | S32: =IF('Şagirdlərin nəticələri'!BR$64="","",'Şagirdlərin nəticələri'!BR$64)
A33: 26 | B33: =LEFT(C33) | F33: =IF(D33="","",IF(D33=1,20/COUNTIF($D$8:$D$37,"1"),IF(D33=2,30/COUNTIF($D$8:$D$37,"2"),IF(D33=3,30/COUNTIF($D$8:$D$37,"3"),IF(D33=4,20/COUNTIF($D$8:$D$37,"4")))))) | G33: =IF('Şagirdlərin nəticələri'!BS$59="","",'Şagirdlərin nəticələri'!BS$59) | H33: =IF('Şagirdlərin nəticələri'!BS$60="","",'Şagirdlərin nəticələri'!BS$60) | I33: =IF('Şagirdlərin nəticələri'!BS$61="","",'Şagirdlərin nəticələri'!BS$61) | K33: 26 | L33: =LEFT(M33) | P33: =IF(N33="","",IF(N33=1,20/COUNTIF($N$8:$N$37,"1"),IF(N33=2,30/COUNTIF($N$8:$N$37,"2"),IF(N33=3,30/COUNTIF($N$8:$N$37,"3"),IF(N33=4,20/COUNTIF($N$8:$N$37,"4")))))) | Q33: =IF('Şagirdlərin nəticələri'!BS$62="","",'Şagirdlərin nəticələri'!BS$62) | R33: =IF('Şagirdlərin nəticələri'!BS$63="","",'Şagirdlərin nəticələri'!BS$63) | S33: =IF('Şagirdlərin nəticələri'!BS$64="","",'Şagirdlərin nəticələri'!BS$64)
A34: 27 | B34: =LEFT(C34) | F34: =IF(D34="","",IF(D34=1,20/COUNTIF($D$8:$D$37,"1"),IF(D34=2,30/COUNTIF($D$8:$D$37,"2"),IF(D34=3,30/COUNTIF($D$8:$D$37,"3"),IF(D34=4,20/COUNTIF($D$8:$D$37,"4")))))) | G34: =IF('Şagirdlərin nəticələri'!BT$59="","",'Şagirdlərin nəticələri'!BT$59) | H34: =IF('Şagirdlərin nəticələri'!BT$60="","",'Şagirdlərin nəticələri'!BT$60) | I34: =IF('Şagirdlərin nəticələri'!BT$61="","",'Şagirdlərin nəticələri'!BT$61) | K34: 27 | L34: =LEFT(M34) | P34: =IF(N34="","",IF(N34=1,20/COUNTIF($N$8:$N$37,"1"),IF(N34=2,30/COUNTIF($N$8:$N$37,"2"),IF(N34=3,30/COUNTIF($N$8:$N$37,"3"),IF(N34=4,20/COUNTIF($N$8:$N$37,"4")))))) | Q34: =IF('Şagirdlərin nəticələri'!BT$62="","",'Şagirdlərin nəticələri'!BT$62) | R34: =IF('Şagirdlərin nəticələri'!BT$63="","",'Şagirdlərin nəticələri'!BT$63) | S34: =IF('Şagirdlərin nəticələri'!BT$64="","",'Şagirdlərin nəticələri'!BT$64)
A35: 28 | B35: =LEFT(C35) | F35: =IF(D35="","",IF(D35=1,20/COUNTIF($D$8:$D$37,"1"),IF(D35=2,30/COUNTIF($D$8:$D$37,"2"),IF(D35=3,30/COUNTIF($D$8:$D$37,"3"),IF(D35=4,20/COUNTIF($D$8:$D$37,"4")))))) | G35: =IF('Şagirdlərin nəticələri'!BU$59="","",'Şagirdlərin nəticələri'!BU$59) | H35: =IF('Şagirdlərin nəticələri'!BU$60="","",'Şagirdlərin nəticələri'!BU$60) | I35: =IF('Şagirdlərin nəticələri'!BU$61="","",'Şagirdlərin nəticələri'!BU$61) | K35: 28 | L35: =LEFT(M35) | P35: =IF(N35="","",IF(N35=1,20/COUNTIF($N$8:$N$37,"1"),IF(N35=2,30/COUNTIF($N$8:$N$37,"2"),IF(N35=3,30/COUNTIF($N$8:$N$37,"3"),IF(N35=4,20/COUNTIF($N$8:$N$37,"4")))))) | Q35: =IF('Şagirdlərin nəticələri'!BU$62="","",'Şagirdlərin nəticələri'!BU$62) | R35: =IF('Şagirdlərin nəticələri'!BU$63="","",'Şagirdlərin nəticələri'!BU$63) | S35: =IF('Şagirdlərin nəticələri'!BU$64="","",'Şagirdlərin nəticələri'!BU$64)
A36: 29 | B36: =LEFT(C36) | F36: =IF(D36="","",IF(D36=1,20/COUNTIF($D$8:$D$37,"1"),IF(D36=2,30/COUNTIF($D$8:$D$37,"2"),IF(D36=3,30/COUNTIF($D$8:$D$37,"3"),IF(D36=4,20/COUNTIF($D$8:$D$37,"4")))))) | G36: =IF('Şagirdlərin nəticələri'!BV$59="","",'Şagirdlərin nəticələri'!BV$59) | H36: =IF('Şagirdlərin nəticələri'!BV$60="","",'Şagirdlərin nəticələri'!BV$60) | I36: =IF('Şagirdlərin nəticələri'!BV$61="","",'Şagirdlərin nəticələri'!BV$61) | K36: 29 | L36: =LEFT(M36) | P36: =IF(N36="","",IF(N36=1,20/COUNTIF($N$8:$N$37,"1"),IF(N36=2,30/COUNTIF($N$8:$N$37,"2"),IF(N36=3,30/COUNTIF($N$8:$N$37,"3"),IF(N36=4,20/COUNTIF($N$8:$N$37,"4")))))) | Q36: =IF('Şagirdlərin nəticələri'!BV$62="","",'Şagirdlərin nəticələri'!BV$62) | R36: =IF('Şagirdlərin nəticələri'!BV$63="","",'Şagirdlərin nəticələri'!BV$63) | S36: =IF('Şagirdlərin nəticələri'!BV$64="","",'Şagirdlərin nəticələri'!BV$64)
A37: 30 | B37: =LEFT(C37) | F37: =IF(D37="","",IF(D37=1,20/COUNTIF($D$8:$D$37,"1"),IF(D37=2,30/COUNTIF($D$8:$D$37,"2"),IF(D37=3,30/COUNTIF($D$8:$D$37,"3"),IF(D37=4,20/COUNTIF($D$8:$D$37,"4")))))) | G37: =IF('Şagirdlərin nəticələri'!BW$59="","",'Şagirdlərin nəticələri'!BW$59) | H37: =IF('Şagirdlərin nəticələri'!BW$60="","",'Şagirdlərin nəticələri'!BW$60) | I37: =IF('Şagirdlərin nəticələri'!BW$61="","",'Şagirdlərin nəticələri'!BW$61) | K37: 30 | L37: =LEFT(M37) | P37: =IF(N37="","",IF(N37=1,20/COUNTIF($N$8:$N$37,"1"),IF(N37=2,30/COUNTIF($N$8:$N$37,"2"),IF(N37=3,30/COUNTIF($N$8:$N$37,"3"),IF(N37=4,20/COUNTIF($N$8:$N$37,"4")))))) | Q37: =IF('Şagirdlərin nəticələri'!BW$62="","",'Şagirdlərin nəticələri'!BW$62) | R37: =IF('Şagirdlərin nəticələri'!BW$63="","",'Şagirdlərin nəticələri'!BW$63) | S37: =IF('Şagirdlərin nəticələri'!BW$64="","",'Şagirdlərin nəticələri'!BW$64)
A38: Variant | B38: A | K38: Variant | L38: B
A39: Səviyyə göstəriciləri | C39: Doğru payı | D39: Tapşırıq sayı | E39: Tapşırıq faizlə | F39: Bal | G39: Doğru (%) | H39: Yanlış (%) | I39: Cavabsız (%) | K39: Səviyyə göstəriciləri | M39: Doğru payı | N39: Tapşırıq sayı | O39: Tapşırıq faizlə | P39: Bal | Q39: Doğru (%) | R39: Yanlış (%) | S39: Cavabsız (%)
A41: 1 | B41: Asan | C41: (75-100] | D41: =COUNTIF(D8:D37,"1") -> 1 | E41: =IF(D41=0,"",D41*100/(SUM(D41:D44))) -> 100 | F41: =IF(D41=0,"",AVERAGEIF(D8:D37,1,F8:F37)) -> 20 | G41: =IF(D41=0,"",AVERAGEIF(D8:D37,1,G8:G37)) -> #DIV/0! | H41: =IF(D41=0,"",AVERAGEIF(D8:D37,1,H8:H37)) -> #DIV/0! | I41: =IF(D41=0,"",AVERAGEIF(D8:D37,1,I8:I37)) -> #DIV/0! | K41: 1 | L41: Asan | M41: (75-100] | N41: =COUNTIF(N8:N37,"1") -> 0 | O41: =IF(N41=0,"",N41*100/(SUM(N41:N44))) | P41: =IF(N41=0,"",AVERAGEIF(N8:N37,1,P8:P37)) | Q41: =IF(N41=0,"",AVERAGEIF(N8:N37,1,Q8:Q37)) | R41: =IF(N41=0,"",AVERAGEIF(N8:N37,1,R8:R37)) | S41: =IF(N41=0,"",AVERAGEIF(N8:N37,1,S8:S37))
...

Sheet Şagirdlərin nəticələri
A1: Summativ qiymətləndirmə üzrə nəticələr
AR2: Variant | AS2: A | AT2: ='Məzmun tərkibi və təhlil'!$E8 -> 0 | AU2: ='Məzmun tərkibi və təhlil'!$E9 -> 0 | AV2: ='Məzmun tərkibi və təhlil'!$E10 -> 0 | AW2: ='Məzmun tərkibi və təhlil'!$E11 -> 0 | AX2: ='Məzmun tərkibi və təhlil'!$E12 -> 0 | AY2: ='Məzmun tərkibi və təhlil'!$E13 -> 0 | AZ2: ='Məzmun tərkibi və təhlil'!$E14 -> 0 | BA2: ='Məzmun tərkibi və təhlil'!$E15 -> 0 | BB2: ='Məzmun tərkibi və təhlil'!$E16 -> 0 | BC2: ='Məzmun tərkibi və təhlil'!$E17 -> 0 | BD2: ='Məzmun tərkibi və təhlil'!$E18 -> 0 | BE2: ='Məzmun tərkibi və təhlil'!$E19 -> 0 | BF2: ='Məzmun tərkibi və təhlil'!$E20 -> 0 | BG2: ='Məzmun tərkibi və təhlil'!$E21 -> 0 | BH2: ='Məzmun tərkibi və təhlil'!$E22 -> 0 | BI2: ='Məzmun tərkibi və təhlil'!$E23 -> 0 | BJ2: ='Məzmun tərkibi və təhlil'!$E24 -> 0 | BK2: ='Məzmun tərkibi və təhlil'!$E25 -> 0 | BL2: ='Məzmun tərkibi və təhlil'!$E26 -> 0 | BM2: ='Məzmun tərkibi və təhlil'!$E27 -> 0 | BN2: ='Məzmun tərkibi və təhlil'!$E28 -> 0 | BO2: ='Məzmun tərkibi və təhlil'!$E29 -> 0 | BP2: ='Məzmun tərkibi və təhlil'!$E30 -> 0 | BQ2: ='Məzmun tərkibi və təhlil'!$E31 -> 0 | BR2: ='Məzmun tərkibi və təhlil'!$E32 -> 0 | BS2: ='Məzmun tərkibi və təhlil'!$E33 -> 0 | BT2: ='Məzmun tərkibi və təhlil'!$E34 -> 0 | BU2: ='Məzmun tərkibi və təhlil'!$E35 -> 0 | BV2: ='Məzmun tərkibi və təhlil'!$E36 -> 0 | BW2: ='Məzmun tərkibi və təhlil'!$E37 -> 0
AR3: Variant | AS3: A | AT3: ='Məzmun tərkibi və təhlil'!$F8 -> 20 | AU3: ='Məzmun tərkibi və təhlil'!$F9 | AV3: ='Məzmun tərkibi və təhlil'!$F10 | AW3: ='Məzmun tərkibi və təhlil'!$F11 | AX3: ='Məzmun tərkibi və təhlil'!$F12 | AY3: ='Məzmun tərkibi və təhlil'!$F13 | AZ3: ='Məzmun tərkibi və təhlil'!$F14 | BA3: ='Məzmun tərkibi və təhlil'!$F15 | BB3: ='Məzmun tərkibi və təhlil'!$F16 | BC3: ='Məzmun tərkibi və təhlil'!$F17 | BD3: ='Məzmun tərkibi və təhlil'!$F18 | BE3: ='Məzmun tərkibi və təhlil'!$F19 | BF3: ='Məzmun tərkibi və təhlil'!$F20 | BG3: ='Məzmun tərkibi və təhlil'!$F21 | BH3: ='Məzmun tərkibi və təhlil'!$F22 | BI3: ='Məzmun tərkibi və təhlil'!$F23 | BJ3: ='Məzmun tərkibi və təhlil'!$F24 | BK3: ='Məzmun tərkibi və təhlil'!$F25 | BL3: ='Məzmun tərkibi və təhlil'!$F26 | BM3: ='Məzmun tərkibi və təhlil'!$F27 | BN3: ='Məzmun tərkibi və təhlil'!$F28 | BO3: ='Məzmun tərkibi və təhlil'!$F29 | BP3: ='Məzmun tərkibi və təhlil'!$F30 | BQ3: ='Məzmun tərkibi və təhlil'!$F31 | BR3: ='Məzmun tərkibi və təhlil'!$F32 | BS3: ='Məzmun tərkibi və təhlil'!$F33 | BT3: ='Məzmun tərkibi və təhlil'!$F34 | BU3: ='Məzmun tərkibi və təhlil'!$F35 | BV3: ='Məzmun tərkibi və təhlil'!$F36 | BW3: ='Məzmun tərkibi və təhlil'!$F37
AR4: Variant | AS4: B | AT4: ='Məzmun tərkibi və təhlil'!$O8 -> 0 | AU4: ='Məzmun tərkibi və təhlil'!$O9 -> 0 | AV4: ='Məzmun tərkibi və təhlil'!$O10 -> 0 | AW4: ='Məzmun tərkibi və təhlil'!$O11 -> 0 | AX4: ='Məzmun tərkibi və təhlil'!$O12 -> 0 | AY4: ='Məzmun tərkibi və təhlil'!$O13 -> 0 | AZ4: ='Məzmun tərkibi və təhlil'!$O14 -> 0 | BA4: ='Məzmun tərkibi və təhlil'!$O15 -> 0 | BB4: ='Məzmun tərkibi və təhlil'!$O16 -> 0 | BC4: ='Məzmun tərkibi və təhlil'!$O17 -> 0 | BD4: ='Məzmun tərkibi və təhlil'!$O18 -> 0 | BE4: ='Məzmun tərkibi və təhlil'!$O19 -> 0 | BF4: ='Məzmun tərkibi və təhlil'!$O20 -> 0 | BG4: ='Məzmun tərkibi və təhlil'!$O21 -> 0 | BH4: ='Məzmun tərkibi və təhlil'!$O22 -> 0 | BI4: ='Məzmun tərkibi və təhlil'!$O23 -> 0 | BJ4: ='Məzmun tərkibi və təhlil'!$O24 -> 0 | BK4: ='Məzmun tərkibi və təhlil'!$O25 -> 0 | BL4: ='Məzmun tərkibi və təhlil'!$O26 -> 0 | BM4: ='Məzmun tərkibi və təhlil'!$O27 -> 0 | BN4: ='Məzmun tərkibi və təhlil'!$O28 -> 0 | BO4: ='Məzmun tərkibi və təhlil'!$O29 -> 0 | BP4: ='Məzmun tərkibi və təhlil'!$O30 -> 0 | BQ4: ='Məzmun tərkibi və təhlil'!$O31 -> 0 | BR4: ='Məzmun tərkibi və təhlil'!$O32 -> 0 | BS4: ='Məzmun tərkibi və təhlil'!$O33 -> 0 | BT4: ='Məzmun tərkibi və təhlil'!$O34 -> 0 | BU4: ='Məzmun tərkibi və təhlil'!$O35 -> 0 | BV4: ='Məzmun tərkibi və təhlil'!$O36 -> 0 | BW4: ='Məzmun tərkibi və təhlil'!$O37 -> 0
AR5: Variant | AS5: B | AT5: ='Məzmun tərkibi və təhlil'!$P8 | AU5: ='Məzmun tərkibi və təhlil'!$P9 | AV5: ='Məzmun tərkibi və təhlil'!$P10 | AW5: ='Məzmun tərkibi və təhlil'!$P11 | AX5: ='Məzmun tərkibi və təhlil'!$P12 | AY5: ='Məzmun tərkibi və təhlil'!$P13 | AZ5: ='Məzmun tərkibi və təhlil'!$P14 | BA5: ='Məzmun tərkibi və təhlil'!$P15 | BB5: ='Məzmun tərkibi və təhlil'!$P16 | BC5: ='Məzmun tərkibi və təhlil'!$P17 | BD5: ='Məzmun tərkibi və təhlil'!$P18 | BE5: ='Məzmun tərkibi və təhlil'!$P19 | BF5: ='Məzmun tərkibi və təhlil'!$P20 | BG5: ='Məzmun tərkibi və təhlil'!$P21 | BH5: ='Məzmun tərkibi və təhlil'!$P22 | BI5: ='Məzmun tərkibi və təhlil'!$P23 | BJ5: ='Məzmun tərkibi və təhlil'!$P24 | BK5: ='Məzmun tərkibi və təhlil'!$P25 | BL5: ='Məzmun tərkibi və təhlil'!$P26 | BM5: ='Məzmun tərkibi və təhlil'!$P27 | BN5: ='Məzmun tərkibi və təhlil'!$P28 | BO5: ='Məzmun tərkibi və təhlil'!$P29 | BP5: ='Məzmun tərkibi və təhlil'!$P30 | BQ5: ='Məzmun tərkibi və təhlil'!$P31 | BR5: ='Məzmun tərkibi və təhlil'!$P32 | BS5: ='Məzmun tərkibi və təhlil'!$P33 | BT5: ='Məzmun tərkibi və təhlil'!$P34 | BU5: ='Məzmun tərkibi və təhlil'!$P35 | BV5: ='Məzmun tərkibi və təhlil'!$P36 | BW5: ='Məzmun tərkibi və təhlil'!$P37
A6: № | B6: =IF('Məzmun tərkibi və təhlil'!R3="","",'Məzmun tərkibi və təhlil'!R3) | C6: =IF('Məzmun tərkibi və təhlil'!S3="","",'Məzmun tərkibi və təhlil'!S3) | D6: =IF('Məzmun tərkibi və təhlil'!R1="","",'Məzmun tərkibi və təhlil'!R1) | E6: =IF('Məzmun tərkibi və təhlil'!C4="","",'Məzmun tərkibi və təhlil'!C4) -> Azərbaycan Respublikası Elm və Təhsil Nazirliyi | F6: Şagird | I6: Cins | J6: Variant | K6: Tapşırıqlar | AP6: Şagird | AT6: Tapşırıqlar | BX6: Bal | BY6: Qiymət
B7: Sinif | C7: İndeks | D7: Bölmə | E7: Fənn | F7: Soyad | G7: Ad | H7: Ata adı | K7: 1 | L7: 2 | M7: 3 | N7: 4 | O7: 5 | P7: 6 | Q7: 7 | R7: 8 | S7: 9 | T7: 10 | U7: 11 | V7: 12 | W7: 13 | X7: 14 | Y7: 15 | Z7: 16 | AA7: 17 | AB7: 18 | AC7: 19 | AD7: 20 | AE7: 21 | AF7: 22 | AG7: 23 | AH7: 24 | AI7: 25 | AJ7: 26 | AK7: 27 | AL7: 28 | AM7: 29 | AN7: 30 | AP7: Soyad | AQ7: Ad | AR7: Ata adı | AS7: Variant | AT7: 1 | AU7: 2 | AV7: 3 | AW7: 4 | AX7: 5 | AY7: 6 | AZ7: 7 | BA7: 8 | BB7: 9 | BC7: 10 | BD7: 11 | BE7: 12 | BF7: 13 | BG7: 14 | BH7: 15 | BI7: 16 | BJ7: 17 | BK7: 18 | BL7: 19 | BM7: 20 | BN7: 21 | BO7: 22 | BP7: 23 | BQ7: 24 | BR7: 25 | BS7: 26 | BT7: 27 | BU7: 28 | BV7: 29 | BW7: 30
A8: =IF(F8="","",K7) | B8: =IF(F8="","",$B$6) | C8: =IF(F8="","",$C$6) | D8: =IF(F8="","",$D$6) | E8: =IF(F8="","",$E$6) | K8: A | L8: B | AP8: =IF(F8="","",F8) | AQ8: =IF(G8="","",G8) | AR8: =IF(H8="","",H8) | AS8: =IF(J8="","",J8) | AT8: =IF(K8="","",IF($AS8="A",IF(K8=AT$2,AT$3,IF(K8<3.9999,AT$3*K8/4,0)),IF(K8=AT$4,AT$5,IF(K8<3.9999,AT$5*K8/4,0)))) -> 0 | AU8: =IF(L8="","",IF($AS8="A",IF(L8=AU$2,AU$3,IF(L8<3.9999,AU$3*L8/4,0)),IF(L8=AU$4,AU$5,IF(L8<3.9999,AU$5*L8/4,0)))) -> 0 | AV8: =IF(M8="","",IF($AS8="A",IF(M8=AV$2,AV$3,IF(M8<3.9999,AV$3*M8/4,0)),IF(M8=AV$4,AV$5,IF(M8<3.9999,AV$5*M8/4,0)))) | AW8: =IF(N8="","",IF($AS8="A",IF(N8=AW$2,AW$3,IF(N8<3.9999,AW$3*N8/4,0)),IF(N8=AW$4,AW$5,IF(N8<3.9999,AW$5*N8/4,0)))) | AX8: =IF(O8="","",IF($AS8="A",IF(O8=AX$2,AX$3,IF(O8<3.9999,AX$3*O8/4,0)),IF(O8=AX$4,AX$5,IF(O8<3.9999,AX$5*O8/4,0)))) | AY8: =IF(P8="","",IF($AS8="A",IF(P8=AY$2,AY$3,IF(P8<3.9999,AY$3*P8/4,0)),IF(P8=AY$4,AY$5,IF(P8<3.9999,AY$5*P8/4,0)))) | AZ8: =IF(Q8="","",IF($AS8="A",IF(Q8=AZ$2,AZ$3,IF(Q8<3.9999,AZ$3*Q8/4,0)),IF(Q8=AZ$4,AZ$5,IF(Q8<3.9999,AZ$5*Q8/4,0)))) | BA8: =IF(R8="","",IF($AS8="A",IF(R8=BA$2,BA$3,IF(R8<3.9999,BA$3*R8/4,0)),IF(R8=BA$4,BA$5,IF(R8<3.9999,BA$5*R8/4,0)))) | ... BW8: =IF(AN8="","",IF($AS8="A",IF(AN8=BW$2,BW$3,IF(AN8<3.9999,BW$3*AN8/4,0)),IF(AN8=BW$4,BW$5,IF(AN8<3.9999,BW$5*AN8/4,0)))) | BX8: =IF(AS8="","",SUM(AT8:BW8)) | BY8: =IF(BX8<=30,2,IF(BX8<=60,3,IF(BX8<=80,4,IF(BX8<=100,5,""))))
A9: =IF(F9="","",A8+1) | B9: =IF(F9="","",$B$6) | C9: =IF(F9="","",$C$6) | D9: =IF(F9="","",$D$6) | E9: =IF(F9="","",$E$6) | AP9: =IF(F9="","",F9) | AQ9: =IF(G9="","",G9) | AR9: =IF(H9="","",H9) | AS9: =IF(J9="","",J9) | AT9: =IF(K9="","",IF($AS9="A",IF(K9=AT$2,AT$3,IF(K9<3.9999,AT$3*K9/4,0)),IF(K9=AT$4,AT$5,IF(K9<3.9999,AT$5*K9/4,0)))) | AU9: =IF(L9="","",IF($AS9="A",IF(L9=AU$2,AU$3,IF(L9<3.9999,AU$3*L9/4,0)),IF(L9=AU$4,AU$5,IF(L9<3.9999,AU$5*L9/4,0)))) | AV9: =IF(M9="","",IF($AS9="A",IF(M9=AV$2,AV$3,IF(M9<3.9999,AV$3*M9/4,0)),IF(M9=AV$4,AV$5,IF(M9<3.9999,AV$5*M9/4,0)))) | AW9: =IF(N9="","",IF($AS9="A",IF(N9=AW$2,AW$3,IF(N9<3.9999,AW$3*N9/4,0)),IF(N9=AW$4,AW$5,IF(N9<3.9999,AW$5*N9/4,0)))) | AX9: =IF(O9="","",IF($AS9="A",IF(O9=AX$2,AX$3,IF(O9<3.9999,AX$3*O9/4,0)),IF(O9=AX$4,AX$5,IF(O9<3.9999,AX$5*O9/4,0)))) | AY9: =IF(P9="","",IF($AS9="A",IF(P9=AY$2,AY$3,IF(P9<3.9999,AY$3*P9/4,0)),IF(P9=AY$4,AY$5,IF(P9<3.9999,AY$5*P9/4,0)))) | AZ9: =IF(Q9="","",IF($AS9="A",IF(Q9=AZ$2,AZ$3,IF(Q9<3.9999,AZ$3*Q9/4,0)),IF(Q9=AZ$4,AZ$5,IF(Q9<3.9999,AZ$5*Q9/4,0)))) | BA9: =IF(R9="","",IF($AS9="A",IF(R9=BA$2,BA$3,IF(R9<3.9999,BA$3*R9/4,0)),IF(R9=BA$4,BA$5,IF(R9<3.9999,BA$5*R9/4,0)))) | ... BW9: =IF(AN9="","",IF($AS9="A",IF(AN9=BW$2,BW$3,IF(AN9<3.9999,BW$3*AN9/4,0)),IF(AN9=BW$4,BW$5,IF(AN9<3.9999,BW$5*AN9/4,0)))) | BX9: =IF(AS9="","",SUM(AT9:BW9)) | BY9: =IF(BX9<=30,2,IF(BX9<=60,3,IF(BX9<=80,4,IF(BX9<=100,5,""))))
A10: =IF(F10="","",A9+1) | B10: =IF(F10="","",$B$6) | C10: =IF(F10="","",$C$6) | D10: =IF(F10="","",$D$6) | E10: =IF(F10="","",$E$6) | AP10: =IF(F10="","",F10) | AQ10: =IF(G10="","",G10) | AR10: =IF(H10="","",H10) | AS10: =IF(J10="","",J10) | AT10: =IF(K10="","",IF($AS10="A",IF(K10=AT$2,AT$3,IF(K10<3.9999,AT$3*K10/4,0)),IF(K10=AT$4,AT$5,IF(K10<3.9999,AT$5*K10/4,0)))) | AU10: =IF(L10="","",IF($AS10="A",IF(L10=AU$2,AU$3,IF(L10<3.9999,AU$3*L10/4,0)),IF(L10=AU$4,AU$5,IF(L10<3.9999,AU$5*L10/4,0)))) | AV10: =IF(M10="","",IF($AS10="A",IF(M10=AV$2,AV$3,IF(M10<3.9999,AV$3*M10/4,0)),IF(M10=AV$4,AV$5,IF(M10<3.9999,AV$5*M10/4,0)))) | AW10: =IF(N10="","",IF($AS10="A",IF(N10=AW$2,AW$3,IF(N10<3.9999,AW$3*N10/4,0)),IF(N10=AW$4,AW$5,IF(N10<3.9999,AW$5*N10/4,0)))) | AX10: =IF(O10="","",IF($AS10="A",IF(O10=AX$2,AX$3,IF(O10<3.9999,AX$3*O10/4,0)),IF(O10=AX$4,AX$5,IF(O10<3.9999,AX$5*O10/4,0)))) | AY10: =IF(P10="","",IF($AS10="A",IF(P10=AY$2,AY$3,IF(P10<3.9999,AY$3*P10/4,0)),IF(P10=AY$4,AY$5,IF(P10<3.9999,AY$5*P10/4,0)))) | AZ10: =IF(Q10="","",IF($AS10="A",IF(Q10=AZ$2,AZ$3,IF(Q10<3.9999,AZ$3*Q10/4,0)),IF(Q10=AZ$4,AZ$5,IF(Q10<3.9999,AZ$5*Q10/4,0)))) | BA10: =IF(R10="","",IF($AS10="A",IF(R10=BA$2,BA$3,IF(R10<3.9999,BA$3*R10/4,0)),IF(R10=BA$4,BA$5,IF(R10<3.9999,BA$5*R10/4,0)))) | ... BW10: =IF(AN10="","",IF($AS10="A",IF(AN10=BW$2,BW$3,IF(AN10<3.9999,BW$3*AN10/4,0)),IF(AN10=BW$4,BW$5,IF(AN10<3.9999,BW$5*AN10/4,0)))) | BX10: =IF(AS10="","",SUM(AT10:BW10)) | BY10: =IF(BX10<=30,2,IF(BX10<=60,3,IF(BX10<=80,4,IF(BX10<=100,5,""))))
A11: =IF(F11="","",A10+1) | B11: =IF(F11="","",$B$6) | C11: =IF(F11="","",$C$6) | D11: =IF(F11="","",$D$6) | E11: =IF(F11="","",$E$6) | AP11: =IF(F11="","",F11) | AQ11: =IF(G11="","",G11) | AR11: =IF(H11="","",H11) | AS11: =IF(J11="","",J11) | AT11: =IF(K11="","",IF($AS11="A",IF(K11=AT$2,AT$3,IF(K11<3.9999,AT$3*K11/4,0)),IF(K11=AT$4,AT$5,IF(K11<3.9999,AT$5*K11/4,0)))) | AU11: =IF(L11="","",IF($AS11="A",IF(L11=AU$2,AU$3,IF(L11<3.9999,AU$3*L11/4,0)),IF(L11=AU$4,AU$5,IF(L11<3.9999,AU$5*L11/4,0)))) | AV11: =IF(M11="","",IF($AS11="A",IF(M11=AV$2,AV$3,IF(M11<3.9999,AV$3*M11/4,0)),IF(M11=AV$4,AV$5,IF(M11<3.9999,AV$5*M11/4,0)))) | AW11: =IF(N11="","",IF($AS11="A",IF(N11=AW$2,AW$3,IF(N11<3.9999,AW$3*N11/4,0)),IF(N11=AW$4,AW$5,IF(N11<3.9999,AW$5*N11/4,0)))) | AX11: =IF(O11="","",IF($AS11="A",IF(O11=AX$2,AX$3,IF(O11<3.9999,AX$3*O11/4,0)),IF(O11=AX$4,AX$5,IF(O11<3.9999,AX$5*O11/4,0)))) | AY11: =IF(P11="","",IF($AS11="A",IF(P11=AY$2,AY$3,IF(P11<3.9999,AY$3*P11/4,0)),IF(P11=AY$4,AY$5,IF(P11<3.9999,AY$5*P11/4,0)))) | AZ11: =IF(Q11="","",IF($AS11="A",IF(Q11=AZ$2,AZ$3,IF(Q11<3.9999,AZ$3*Q11/4,0)),IF(Q11=AZ$4,AZ$5,IF(Q11<3.9999,AZ$5*Q11/4,0)))) | BA11: =IF(R11="","",IF($AS11="A",IF(R11=BA$2,BA$3,IF(R11<3.9999,BA$3*R11/4,0)),IF(R11=BA$4,BA$5,IF(R11<3.9999,BA$5*R11/4,0)))) | ... BW11: =IF(AN11="","",IF($AS11="A",IF(AN11=BW$2,BW$3,IF(AN11<3.9999,BW$3*AN11/4,0)),IF(AN11=BW$4,BW$5,IF(AN11<3.9999,BW$5*AN11/4,0)))) | BX11: =IF(AS11="","",SUM(AT11:BW11)) | BY11: =IF(BX11<=30,2,IF(BX11<=60,3,IF(BX11<=80,4,IF(BX11<=100,5,""))))
A12: =IF(F12="","",A11+1) | B12: =IF(F12="","",$B$6) | C12: =IF(F12="","",$C$6) | D12: =IF(F12="","",$D$6) | E12: =IF(F12="","",$E$6) | AP12: =IF(F12="","",F12) | AQ12: =IF(G12="","",G12) | AR12: =IF(H12="","",H12) | AS12: =IF(J12="","",J12) | AT12: =IF(K12="","",IF($AS12="A",IF(K12=AT$2,AT$3,IF(K12<3.9999,AT$3*K12/4,0)),IF(K12=AT$4,AT$5,IF(K12<3.9999,AT$5*K12/4,0)))) | AU12: =IF(L12="","",IF($AS12="A",IF(L12=AU$2,AU$3,IF(L12<3.9999,AU$3*L12/4,0)),IF(L12=AU$4,AU$5,IF(L12<3.9999,AU$5*L12/4,0)))) | AV12: =IF(M12="","",IF($AS12="A",IF(M12=AV$2,AV$3,IF(M12<3.9999,AV$3*M12/4,0)),IF(M12=AV$4,AV$5,IF(M12<3.9999,AV$5*M12/4,0)))) | AW12: =IF(N12="","",IF($AS12="A",IF(N12=AW$2,AW$3,IF(N12<3.9999,AW$3*N12/4,0)),IF(N12=AW$4,AW$5,IF(N12<3.9999,AW$5*N12/4,0)))) | AX12: =IF(O12="","",IF($AS12="A",IF(O12=AX$2,AX$3,IF(O12<3.9999,AX$3*O12/4,0)),IF(O12=AX$4,AX$5,IF(O12<3.9999,AX$5*O12/4,0)))) | AY12: =IF(P12="","",IF($AS12="A",IF(P12=AY$2,AY$3,IF(P12<3.9999,AY$3*P12/4,0)),IF(P12=AY$4,AY$5,IF(P12<3.9999,AY$5*P12/4,0)))) | AZ12: =IF(Q12="","",IF($AS12="A",IF(Q12=AZ$2,AZ$3,IF(Q12<3.9999,AZ$3*Q12/4,0)),IF(Q12=AZ$4,AZ$5,IF(Q12<3.9999,AZ$5*Q12/4,0)))) | BA12: =IF(R12="","",IF($AS12="A",IF(R12=BA$2,BA$3,IF(R12<3.9999,BA$3*R12/4,0)),IF(R12=BA$4,BA$5,IF(R12<3.9999,BA$5*R12/4,0)))) | ... BW12: =IF(AN12="","",IF($AS12="A",IF(AN12=BW$2,BW$3,IF(AN12<3.9999,BW$3*AN12/4,0)),IF(AN12=BW$4,BW$5,IF(AN12<3.9999,BW$5*AN12/4,0)))) | BX12: =IF(AS12="","",SUM(AT12:BW12)) | BY12: =IF(BX12<=30,2,IF(BX12<=60,3,IF(BX12<=80,4,IF(BX12<=100,5,""))))
A13: =IF(F13="","",A12+1) | B13: =IF(F13="","",$B$6) | C13: =IF(F13="","",$C$6) | D13: =IF(F13="","",$D$6) | E13: =IF(F13="","",$E$6) | AP13: =IF(F13="","",F13) | AQ13: =IF(G13="","",G13) | AR13: =IF(H13="","",H13) | AS13: =IF(J13="","",J13) | AT13: =IF(K13="","",IF($AS13="A",IF(K13=AT$2,AT$3,IF(K13<3.9999,AT$3*K13/4,0)),IF(K13=AT$4,AT$5,IF(K13<3.9999,AT$5*K13/4,0)))) | AU13: =IF(L13="","",IF($AS13="A",IF(L13=AU$2,AU$3,IF(L13<3.9999,AU$3*L13/4,0)),IF(L13=AU$4,AU$5,IF(L13<3.9999,AU$5*L13/4,0)))) | AV13: =IF(M13="","",IF($AS13="A",IF(M13=AV$2,AV$3,IF(M13<3.9999,AV$3*M13/4,0)),IF(M13=AV$4,AV$5,IF(M13<3.9999,AV$5*M13/4,0)))) | AW13: =IF(N13="","",IF($AS13="A",IF(N13=AW$2,AW$3,IF(N13<3.9999,AW$3*N13/4,0)),IF(N13=AW$4,AW$5,IF(N13<3.9999,AW$5*N13/4,0)))) | AX13: =IF(O13="","",IF($AS13="A",IF(O13=AX$2,AX$3,IF(O13<3.9999,AX$3*O13/4,0)),IF(O13=AX$4,AX$5,IF(O13<3.9999,AX$5*O13/4,0)))) | AY13: =IF(P13="","",IF($AS13="A",IF(P13=AY$2,AY$3,IF(P13<3.9999,AY$3*P13/4,0)),IF(P13=AY$4,AY$5,IF(P13<3.9999,AY$5*P13/4,0)))) | AZ13: =IF(Q13="","",IF($AS13="A",IF(Q13=AZ$2,AZ$3,IF(Q13<3.9999,AZ$3*Q13/4,0)),IF(Q13=AZ$4,AZ$5,IF(Q13<3.9999,AZ$5*Q13/4,0)))) | BA13: =IF(R13="","",IF($AS13="A",IF(R13=BA$2,BA$3,IF(R13<3.9999,BA$3*R13/4,0)),IF(R13=BA$4,BA$5,IF(R13<3.9999,BA$5*R13/4,0)))) | ... BW13: =IF(AN13="","",IF($AS13="A",IF(AN13=BW$2,BW$3,IF(AN13<3.9999,BW$3*AN13/4,0)),IF(AN13=BW$4,BW$5,IF(AN13<3.9999,BW$5*AN13/4,0)))) | BX13: =IF(AS13="","",SUM(AT13:BW13)) | BY13: =IF(BX13<=30,2,IF(BX13<=60,3,IF(BX13<=80,4,IF(BX13<=100,5,""))))
A14: =IF(F14="","",A13+1) | B14: =IF(F14="","",$B$6) | C14: =IF(F14="","",$C$6) | D14: =IF(F14="","",$D$6) | E14: =IF(F14="","",$E$6) | AP14: =IF(F14="","",F14) | AQ14: =IF(G14="","",G14) | AR14: =IF(H14="","",H14) | AS14: =IF(J14="","",J14) | AT14: =IF(K14="","",IF($AS14="A",IF(K14=AT$2,AT$3,IF(K14<3.9999,AT$3*K14/4,0)),IF(K14=AT$4,AT$5,IF(K14<3.9999,AT$5*K14/4,0)))) | AU14: =IF(L14="","",IF($AS14="A",IF(L14=AU$2,AU$3,IF(L14<3.9999,AU$3*L14/4,0)),IF(L14=AU$4,AU$5,IF(L14<3.9999,AU$5*L14/4,0)))) | AV14: =IF(M14="","",IF($AS14="A",IF(M14=AV$2,AV$3,IF(M14<3.9999,AV$3*M14/4,0)),IF(M14=AV$4,AV$5,IF(M14<3.9999,AV$5*M14/4,0)))) | AW14: =IF(N14="","",IF($AS14="A",IF(N14=AW$2,AW$3,IF(N14<3.9999,AW$3*N14/4,0)),IF(N14=AW$4,AW$5,IF(N14<3.9999,AW$5*N14/4,0)))) | AX14: =IF(O14="","",IF($AS14="A",IF(O14=AX$2,AX$3,IF(O14<3.9999,AX$3*O14/4,0)),IF(O14=AX$4,AX$5,IF(O14<3.9999,AX$5*O14/4,0)))) | AY14: =IF(P14="","",IF($AS14="A",IF(P14=AY$2,AY$3,IF(P14<3.9999,AY$3*P14/4,0)),IF(P14=AY$4,AY$5,IF(P14<3.9999,AY$5*P14/4,0)))) | AZ14: =IF(Q14="","",IF($AS14="A",IF(Q14=AZ$2,AZ$3,IF(Q14<3.9999,AZ$3*Q14/4,0)),IF(Q14=AZ$4,AZ$5,IF(Q14<3.9999,AZ$5*Q14/4,0)))) | BA14: =IF(R14="","",IF($AS14="A",IF(R14=BA$2,BA$3,IF(R14<3.9999,BA$3*R14/4,0)),IF(R14=BA$4,BA$5,IF(R14<3.9999,BA$5*R14/4,0)))) | ... BW14: =IF(AN14="","",IF($AS14="A",IF(AN14=BW$2,BW$3,IF(AN14<3.9999,BW$3*AN14/4,0)),IF(AN14=BW$4,BW$5,IF(AN14<3.9999,BW$5*AN14/4,0)))) | BX14: =IF(AS14="","",SUM(AT14:BW14)) | BY14: =IF(BX14<=30,2,IF(BX14<=60,3,IF(BX14<=80,4,IF(BX14<=100,5,""))))
A15: =IF(F15="","",A14+1) | B15: =IF(F15="","",$B$6) | C15: =IF(F15="","",$C$6) | D15: =IF(F15="","",$D$6) | E15: =IF(F15="","",$E$6) | AP15: =IF(F15="","",F15) | AQ15: =IF(G15="","",G15) | AR15: =IF(H15="","",H15) | AS15: =IF(J15="","",J15) | AT15: =IF(K15="","",IF($AS15="A",IF(K15=AT$2,AT$3,IF(K15<3.9999,AT$3*K15/4,0)),IF(K15=AT$4,AT$5,IF(K15<3.9999,AT$5*K15/4,0)))) | AU15: =IF(L15="","",IF($AS15="A",IF(L15=AU$2,AU$3,IF(L15<3.9999,AU$3*L15/4,0)),IF(L15=AU$4,AU$5,IF(L15<3.9999,AU$5*L15/4,0)))) | AV15: =IF(M15="","",IF($AS15="A",IF(M15=AV$2,AV$3,IF(M15<3.9999,AV$3*M15/4,0)),IF(M15=AV$4,AV$5,IF(M15<3.9999,AV$5*M15/4,0)))) | AW15: =IF(N15="","",IF($AS15="A",IF(N15=AW$2,AW$3,IF(N15<3.9999,AW$3*N15/4,0)),IF(N15=AW$4,AW$5,IF(N15<3.9999,AW$5*N15/4,0)))) | AX15: =IF(O15="","",IF($AS15="A",IF(O15=AX$2,AX$3,IF(O15<3.9999,AX$3*O15/4,0)),IF(O15=AX$4,AX$5,IF(O15<3.9999,AX$5*O15/4,0)))) | AY15: =IF(P15="","",IF($AS15="A",IF(P15=AY$2,AY$3,IF(P15<3.9999,AY$3*P15/4,0)),IF(P15=AY$4,AY$5,IF(P15<3.9999,AY$5*P15/4,0)))) | AZ15: =IF(Q15="","",IF($AS15="A",IF(Q15=AZ$2,AZ$3,IF(Q15<3.9999,AZ$3*Q15/4,0)),IF(Q15=AZ$4,AZ$5,IF(Q15<3.9999,AZ$5*Q15/4,0)))) | BA15: =IF(R15="","",IF($AS15="A",IF(R15=BA$2,BA$3,IF(R15<3.9999,BA$3*R15/4,0)),IF(R15=BA$4,BA$5,IF(R15<3.9999,BA$5*R15/4,0)))) | ... BW15: =IF(AN15="","",IF($AS15="A",IF(AN15=BW$2,BW$3,IF(AN15<3.9999,BW$3*AN15/4,0)),IF(AN15=BW$4,BW$5,IF(AN15<3.9999,BW$5*AN15/4,0)))) | BX15: =IF(AS15="","",SUM(AT15:BW15)) | BY15: =IF(BX15<=30,2,IF(BX15<=60,3,IF(BX15<=80,4,IF(BX15<=100,5,""))))
A16: =IF(F16="","",A15+1) | B16: =IF(F16="","",$B$6) | C16: =IF(F16="","",$C$6) | D16: =IF(F16="","",$D$6) | E16: =IF(F16="","",$E$6) | AP16: =IF(F16="","",F16) | AQ16: =IF(G16="","",G16) | AR16: =IF(H16="","",H16) | AS16: =IF(J16="","",J16) | AT16: =IF(K16="","",IF($AS16="A",IF(K16=AT$2,AT$3,IF(K16<3.9999,AT$3*K16/4,0)),IF(K16=AT$4,AT$5,IF(K16<3.9999,AT$5*K16/4,0)))) | AU16: =IF(L16="","",IF($AS16="A",IF(L16=AU$2,AU$3,IF(L16<3.9999,AU$3*L16/4,0)),IF(L16=AU$4,AU$5,IF(L16<3.9999,AU$5*L16/4,0)))) | AV16: =IF(M16="","",IF($AS16="A",IF(M16=AV$2,AV$3,IF(M16<3.9999,AV$3*M16/4,0)),IF(M16=AV$4,AV$5,IF(M16<3.9999,AV$5*M16/4,0)))) | AW16: =IF(N16="","",IF($AS16="A",IF(N16=AW$2,AW$3,IF(N16<3.9999,AW$3*N16/4,0)),IF(N16=AW$4,AW$5,IF(N16<3.9999,AW$5*N16/4,0)))) | AX16: =IF(O16="","",IF($AS16="A",IF(O16=AX$2,AX$3,IF(O16<3.9999,AX$3*O16/4,0)),IF(O16=AX$4,AX$5,IF(O16<3.9999,AX$5*O16/4,0)))) | AY16: =IF(P16="","",IF($AS16="A",IF(P16=AY$2,AY$3,IF(P16<3.9999,AY$3*P16/4,0)),IF(P16=AY$4,AY$5,IF(P16<3.9999,AY$5*P16/4,0)))) | AZ16: =IF(Q16="","",IF($AS16="A",IF(Q16=AZ$2,AZ$3,IF(Q16<3.9999,AZ$3*Q16/4,0)),IF(Q16=AZ$4,AZ$5,IF(Q16<3.9999,AZ$5*Q16/4,0)))) | BA16: =IF(R16="","",IF($AS16="A",IF(R16=BA$2,BA$3,IF(R16<3.9999,BA$3*R16/4,0)),IF(R16=BA$4,BA$5,IF(R16<3.9999,BA$5*R16/4,0)))) | ... BW16: =IF(AN16="","",IF($AS16="A",IF(AN16=BW$2,BW$3,IF(AN16<3.9999,BW$3*AN16/4,0)),IF(AN16=BW$4,BW$5,IF(AN16<3.9999,BW$5*AN16/4,0)))) | BX16: =IF(AS16="","",SUM(AT16:BW16)) | BY16: =IF(BX16<=30,2,IF(BX16<=60,3,IF(BX16<=80,4,IF(BX16<=100,5,""))))
A17: =IF(F17="","",A16+1) | B17: =IF(F17="","",$B$6) | C17: =IF(F17="","",$C$6) | D17: =IF(F17="","",$D$6) | E17: =IF(F17="","",$E$6) | AP17: =IF(F17="","",F17) | AQ17: =IF(G17="","",G17) | AR17: =IF(H17="","",H17) | AS17: =IF(J17="","",J17) | AT17: =IF(K17="","",IF($AS17="A",IF(K17=AT$2,AT$3,IF(K17<3.9999,AT$3*K17/4,0)),IF(K17=AT$4,AT$5,IF(K17<3.9999,AT$5*K17/4,0)))) | AU17: =IF(L17="","",IF($AS17="A",IF(L17=AU$2,AU$3,IF(L17<3.9999,AU$3*L17/4,0)),IF(L17=AU$4,AU$5,IF(L17<3.9999,AU$5*L17/4,0)))) | AV17: =IF(M17="","",IF($AS17="A",IF(M17=AV$2,AV$3,IF(M17<3.9999,AV$3*M17/4,0)),IF(M17=AV$4,AV$5,IF(M17<3.9999,AV$5*M17/4,0)))) | AW17: =IF(N17="","",IF($AS17="A",IF(N17=AW$2,AW$3,IF(N17<3.9999,AW$3*N17/4,0)),IF(N17=AW$4,AW$5,IF(N17<3.9999,AW$5*N17/4,0)))) | AX17: =IF(O17="","",IF($AS17="A",IF(O17=AX$2,AX$3,IF(O17<3.9999,AX$3*O17/4,0)),IF(O17=AX$4,AX$5,IF(O17<3.9999,AX$5*O17/4,0)))) | AY17: =IF(P17="","",IF($AS17="A",IF(P17=AY$2,AY$3,IF(P17<3.9999,AY$3*P17/4,0)),IF(P17=AY$4,AY$5,IF(P17<3.9999,AY$5*P17/4,0)))) | AZ17: =IF(Q17="","",IF($AS17="A",IF(Q17=AZ$2,AZ$3,IF(Q17<3.9999,AZ$3*Q17/4,0)),IF(Q17=AZ$4,AZ$5,IF(Q17<3.9999,AZ$5*Q17/4,0)))) | BA17: =IF(R17="","",IF($AS17="A",IF(R17=BA$2,BA$3,IF(R17<3.9999,BA$3*R17/4,0)),IF(R17=BA$4,BA$5,IF(R17<3.9999,BA$5*R17/4,0)))) | ... BW17: =IF(AN17="","",IF($AS17="A",IF(AN17=BW$2,BW$3,IF(AN17<3.9999,BW$3*AN17/4,0)),IF(AN17=BW$4,BW$5,IF(AN17<3.9999,BW$5*AN17/4,0)))) | BX17: =IF(AS17="","",SUM(AT17:BW17)) | BY17: =IF(BX17<=30,2,IF(BX17<=60,3,IF(BX17<=80,4,IF(BX17<=100,5,""))))
A18: =IF(F18="","",A17+1) | B18: =IF(F18="","",$B$6) | C18: =IF(F18="","",$C$6) | D18: =IF(F18="","",$D$6) | E18: =IF(F18="","",$E$6) | AP18: =IF(F18="","",F18) | AQ18: =IF(G18="","",G18) | AR18: =IF(H18="","",H18) | AS18: =IF(J18="","",J18) | AT18: =IF(K18="","",IF($AS18="A",IF(K18=AT$2,AT$3,IF(K18<3.9999,AT$3*K18/4,0)),IF(K18=AT$4,AT$5,IF(K18<3.9999,AT$5*K18/4,0)))) | AU18: =IF(L18="","",IF($AS18="A",IF(L18=AU$2,AU$3,IF(L18<3.9999,AU$3*L18/4,0)),IF(L18=AU$4,AU$5,IF(L18<3.9999,AU$5*L18/4,0)))) | AV18: =IF(M18="","",IF($AS18="A",IF(M18=AV$2,AV$3,IF(M18<3.9999,AV$3*M18/4,0)),IF(M18=AV$4,AV$5,IF(M18<3.9999,AV$5*M18/4,0)))) | AW18: =IF(N18="","",IF($AS18="A",IF(N18=AW$2,AW$3,IF(N18<3.9999,AW$3*N18/4,0)),IF(N18=AW$4,AW$5,IF(N18<3.9999,AW$5*N18/4,0)))) | AX18: =IF(O18="","",IF($AS18="A",IF(O18=AX$2,AX$3,IF(O18<3.9999,AX$3*O18/4,0)),IF(O18=AX$4,AX$5,IF(O18<3.9999,AX$5*O18/4,0)))) | AY18: =IF(P18="","",IF($AS18="A",IF(P18=AY$2,AY$3,IF(P18<3.9999,AY$3*P18/4,0)),IF(P18=AY$4,AY$5,IF(P18<3.9999,AY$5*P18/4,0)))) | AZ18: =IF(Q18="","",IF($AS18="A",IF(Q18=AZ$2,AZ$3,IF(Q18<3.9999,AZ$3*Q18/4,0)),IF(Q18=AZ$4,AZ$5,IF(Q18<3.9999,AZ$5*Q18/4,0)))) | BA18: =IF(R18="","",IF($AS18="A",IF(R18=BA$2,BA$3,IF(R18<3.9999,BA$3*R18/4,0)),IF(R18=BA$4,BA$5,IF(R18<3.9999,BA$5*R18/4,0)))) | ... BW18: =IF(AN18="","",IF($AS18="A",IF(AN18=BW$2,BW$3,IF(AN18<3.9999,BW$3*AN18/4,0)),IF(AN18=BW$4,BW$5,IF(AN18<3.9999,BW$5*AN18/4,0)))) | BX18: =IF(AS18="","",SUM(AT18:BW18)) | BY18: =IF(BX18<=30,2,IF(BX18<=60,3,IF(BX18<=80,4,IF(BX18<=100,5,""))))
A19: =IF(F19="","",A18+1) | B19: =IF(F19="","",$B$6) | C19: =IF(F19="","",$C$6) | D19: =IF(F19="","",$D$6) | E19: =IF(F19="","",$E$6) | AP19: =IF(F19="","",F19) | AQ19: =IF(G19="","",G19) | AR19: =IF(H19="","",H19) | AS19: =IF(J19="","",J19) | AT19: =IF(K19="","",IF($AS19="A",IF(K19=AT$2,AT$3,IF(K19<3.9999,AT$3*K19/4,0)),IF(K19=AT$4,AT$5,IF(K19<3.9999,AT$5*K19/4,0)))) | AU19: =IF(L19="","",IF($AS19="A",IF(L19=AU$2,AU$3,IF(L19<3.9999,AU$3*L19/4,0)),IF(L19=AU$4,AU$5,IF(L19<3.9999,AU$5*L19/4,0)))) | AV19: =IF(M19="","",IF($AS19="A",IF(M19=AV$2,AV$3,IF(M19<3.9999,AV$3*M19/4,0)),IF(M19=AV$4,AV$5,IF(M19<3.9999,AV$5*M19/4,0)))) | AW19: =IF(N19="","",IF($AS19="A",IF(N19=AW$2,AW$3,IF(N19<3.9999,AW$3*N19/4,0)),IF(N19=AW$4,AW$5,IF(N19<3.9999,AW$5*N19/4,0)))) | AX19: =IF(O19="","",IF($AS19="A",IF(O19=AX$2,AX$3,IF(O19<3.9999,AX$3*O19/4,0)),IF(O19=AX$4,AX$5,IF(O19<3.9999,AX$5*O19/4,0)))) | AY19: =IF(P19="","",IF($AS19="A",IF(P19=AY$2,AY$3,IF(P19<3.9999,AY$3*P19/4,0)),IF(P19=AY$4,AY$5,IF(P19<3.9999,AY$5*P19/4,0)))) | AZ19: =IF(Q19="","",IF($AS19="A",IF(Q19=AZ$2,AZ$3,IF(Q19<3.9999,AZ$3*Q19/4,0)),IF(Q19=AZ$4,AZ$5,IF(Q19<3.9999,AZ$5*Q19/4,0)))) | BA19: =IF(R19="","",IF($AS19="A",IF(R19=BA$2,BA$3,IF(R19<3.9999,BA$3*R19/4,0)),IF(R19=BA$4,BA$5,IF(R19<3.9999,BA$5*R19/4,0)))) | ... BW19: =IF(AN19="","",IF($AS19="A",IF(AN19=BW$2,BW$3,IF(AN19<3.9999,BW$3*AN19/4,0)),IF(AN19=BW$4,BW$5,IF(AN19<3.9999,BW$5*AN19/4,0)))) | BX19: =IF(AS19="","",SUM(AT19:BW19)) | BY19: =IF(BX19<=30,2,IF(BX19<=60,3,IF(BX19<=80,4,IF(BX19<=100,5,""))))
A20: =IF(F20="","",A19+1) | B20: =IF(F20="","",$B$6) | C20: =IF(F20="","",$C$6) | D20: =IF(F20="","",$D$6) | E20: =IF(F20="","",$E$6) | AP20: =IF(F20="","",F20) | AQ20: =IF(G20="","",G20) | AR20: =IF(H20="","",H20) | AS20: =IF(J20="","",J20) | AT20: =IF(K20="","",IF($AS20="A",IF(K20=AT$2,AT$3,IF(K20<3.9999,AT$3*K20/4,0)),IF(K20=AT$4,AT$5,IF(K20<3.9999,AT$5*K20/4,0)))) | AU20: =IF(L20="","",IF($AS20="A",IF(L20=AU$2,AU$3,IF(L20<3.9999,AU$3*L20/4,0)),IF(L20=AU$4,AU$5,IF(L20<3.9999,AU$5*L20/4,0)))) | AV20: =IF(M20="","",IF($AS20="A",IF(M20=AV$2,AV$3,IF(M20<3.9999,AV$3*M20/4,0)),IF(M20=AV$4,AV$5,IF(M20<3.9999,AV$5*M20/4,0)))) | AW20: =IF(N20="","",IF($AS20="A",IF(N20=AW$2,AW$3,IF(N20<3.9999,AW$3*N20/4,0)),IF(N20=AW$4,AW$5,IF(N20<3.9999,AW$5*N20/4,0)))) | AX20: =IF(O20="","",IF($AS20="A",IF(O20=AX$2,AX$3,IF(O20<3.9999,AX$3*O20/4,0)),IF(O20=AX$4,AX$5,IF(O20<3.9999,AX$5*O20/4,0)))) | AY20: =IF(P20="","",IF($AS20="A",IF(P20=AY$2,AY$3,IF(P20<3.9999,AY$3*P20/4,0)),IF(P20=AY$4,AY$5,IF(P20<3.9999,AY$5*P20/4,0)))) | AZ20: =IF(Q20="","",IF($AS20="A",IF(Q20=AZ$2,AZ$3,IF(Q20<3.9999,AZ$3*Q20/4,0)),IF(Q20=AZ$4,AZ$5,IF(Q20<3.9999,AZ$5*Q20/4,0)))) | BA20: =IF(R20="","",IF($AS20="A",IF(R20=BA$2,BA$3,IF(R20<3.9999,BA$3*R20/4,0)),IF(R20=BA$4,BA$5,IF(R20<3.9999,BA$5*R20/4,0)))) | ... BW20: =IF(AN20="","",IF($AS20="A",IF(AN20=BW$2,BW$3,IF(AN20<3.9999,BW$3*AN20/4,0)),IF(AN20=BW$4,BW$5,IF(AN20<3.9999,BW$5*AN20/4,0)))) | BX20: =IF(AS20="","",SUM(AT20:BW20)) | BY20: =IF(BX20<=30,2,IF(BX20<=60,3,IF(BX20<=80,4,IF(BX20<=100,5,""))))
... A57: =IF(F57="","",A56+1) | B57: =IF(F57="","",$B$6) | C57: =IF(F57="","",$C$6) | D57: =IF(F57="","",$D$6) | E57: =IF(F57="","",$E$6) | AP57: =IF(F57="","",F57) | AQ57: =IF(G57="","",G57) | AR57: =IF(H57="","",H57) | AS57: =IF(J57="","",J57) | AT57: =IF(K57="","",IF($AS57="A",IF(K57=AT$2,AT$3,IF(K57<3.9999,AT$3*K57/4,0)),IF(K57=AT$4,AT$5,IF(K57<3.9999,AT$5*K57/4,0)))) | AU57: =IF(L57="","",IF($AS57="A",IF(L57=AU$2,AU$3,IF(L57<3.9999,AU$3*L57/4,0)),IF(L57=AU$4,AU$5,IF(L57<3.9999,AU$5*L57/4,0)))) | AV57: =IF(M57="","",IF($AS57="A",IF(M57=AV$2,AV$3,IF(M57<3.9999,AV$3*M57/4,0)),IF(M57=AV$4,AV$5,IF(M57<3.9999,AV$5*M57/4,0)))) | AW57: =IF(N57="","",IF($AS57="A",IF(N57=AW$2,AW$3,IF(N57<3.9999,AW$3*N57/4,0)),IF(N57=AW$4,AW$5,IF(N57<3.9999,AW$5*N57/4,0)))) | AX57: =IF(O57="","",IF($AS57="A",IF(O57=AX$2,AX$3,IF(O57<3.9999,AX$3*O57/4,0)),IF(O57=AX$4,AX$5,IF(O57<3.9999,AX$5*O57/4,0)))) | AY57: =IF(P57="","",IF($AS57="A",IF(P57=AY$2,AY$3,IF(P57<3.9999,AY$3*P57/4,0)),IF(P57=AY$4,AY$5,IF(P57<3.9999,AY$5*P57/4,0)))) | AZ57: =IF(Q57="","",IF($AS57="A",IF(Q57=AZ$2,AZ$3,IF(Q57<3.9999,AZ$3*Q57/4,0)),IF(Q57=AZ$4,AZ$5,IF(Q57<3.9999,AZ$5*Q57/4,0)))) | BA57: =IF(R57="","",IF($AS57="A",IF(R57=BA$2,BA$3,IF(R57<3.9999,BA$3*R57/4,0)),IF(R57=BA$4,BA$5,IF(R57<3.9999,BA$5*R57/4,0)))) | ... BW57: =IF(AN57="","",IF($AS57="A",IF(AN57=BW$2,BW$3,IF(AN57<3.9999,BW$3*AN57/4,0)),IF(AN57=BW$4,BW$5,IF(AN57<3.9999,BW$5*AN57/4,0)))) | BX57: =IF(AS57="","",SUM(AT57:BW57)) | BY57: =IF(BX57<=30,2,IF(BX57<=60,3,IF(BX57<=80,4,IF(BX57<=100,5,""))))
AR59: A variantı | AS59: Doğru | AT59: =IF(AT2=0,"",(COUNTIFS($AS$8:$AS$57,"A",AT8:AT57,">0")*100/COUNTIF($AS$8:$AS$57,"A"))) | AU59: =IF(AU2=0,"",(COUNTIFS($AS$8:$AS$57,"A",AU8:AU57,">0")*100/COUNTIF($AS$8:$AS$57,"A"))) | AV59: =IF(AV2=0,"",(COUNTIFS($AS$8:$AS$57,"A",AV8:AV57,">0")*100/COUNTIF($AS$8:$AS$57,"A"))) | AW59: =IF(AW2=0,"",(COUNTIFS($AS$8:$AS$57,"A",AW8:AW57,">0")*100/COUNTIF($AS$8:$AS$57,"A"))) | AX59: =IF(AX2=0,"",(COUNTIFS($AS$8:$AS$57,"A",AX8:AX57,">0")*100/COUNTIF($AS$8:$AS$57,"A"))) | AY59: =IF(AY2=0,"",(COUNTIFS($AS$8:$AS$57,"A",AY8:AY57,">0")*100/COUNTIF($AS$8:$AS$57,"A"))) | AZ59: =IF(AZ2=0,"",(COUNTIFS($AS$8:$AS$57,"A",AZ8:AZ57,">0")*100/COUNTIF($AS$8:$AS$57,"A"))) | BA59: =IF(BA2=0,"",(COUNTIFS($AS$8:$AS$57,"A",BA8:BA57,">0")*100/COUNTIF($AS$8:$AS$57,"A"))) | ... BW59: =IF(BW2=0,"",(COUNTIFS($AS$8:$AS$57,"A",BW8:BW57,">0")*100/COUNTIF($AS$8:$AS$57,"A")))
AS60: Yanlış | AT60: =IF(AT2=0,"",(COUNTIFS($AS$8:$AS$57,"A",AT8:AT57,"=0")*100/COUNTIF($AS$8:$AS$57,"A"))) | AU60: =IF(AU2=0,"",(COUNTIFS($AS$8:$AS$57,"A",AU8:AU57,"=0")*100/COUNTIF($AS$8:$AS$57,"A"))) | AV60: =IF(AV2=0,"",(COUNTIFS($AS$8:$AS$57,"A",AV8:AV57,"=0")*100/COUNTIF($AS$8:$AS$57,"A"))) | AW60: =IF(AW2=0,"",(COUNTIFS($AS$8:$AS$57,"A",AW8:AW57,"=0")*100/COUNTIF($AS$8:$AS$57,"A"))) | AX60: =IF(AX2=0,"",(COUNTIFS($AS$8:$AS$57,"A",AX8:AX57,"=0")*100/COUNTIF($AS$8:$AS$57,"A"))) | AY60: =IF(AY2=0,"",(COUNTIFS($AS$8:$AS$57,"A",AY8:AY57,"=0")*100/COUNTIF($AS$8:$AS$57,"A"))) | AZ60: =IF(AZ2=0,"",(COUNTIFS($AS$8:$AS$57,"A",AZ8:AZ57,"=0")*100/COUNTIF($AS$8:$AS$57,"A"))) | BA60: =IF(BA2=0,"",(COUNTIFS($AS$8:$AS$57,"A",BA8:BA57,"=0")*100/COUNTIF($AS$8:$AS$57,"A"))) | ... BW60: =IF(BW2=0,"",(COUNTIFS($AS$8:$AS$57,"A",BW8:BW57,"=0")*100/COUNTIF($AS$8:$AS$57,"A")))
AS61: Cavabsız | AT61: =IF(AT2=0,"",(COUNTIFS($AS$8:$AS$57,"A",AT8:AT57,"")*100/COUNTIF($AS$8:$AS$57,"A"))) | AU61: =IF(AU2=0,"",(COUNTIFS($AS$8:$AS$57,"A",AU8:AU57,"")*100/COUNTIF($AS$8:$AS$57,"A"))) | AV61: =IF(AV2=0,"",(COUNTIFS($AS$8:$AS$57,"A",AV8:AV57,"")*100/COUNTIF($AS$8:$AS$57,"A"))) | AW61: =IF(AW2=0,"",(COUNTIFS($AS$8:$AS$57,"A",AW8:AW57,"")*100/COUNTIF($AS$8:$AS$57,"A"))) | AX61: =IF(AX2=0,"",(COUNTIFS($AS$8:$AS$57,"A",AX8:AX57,"")*100/COUNTIF($AS$8:$AS$57,"A"))) | AY61: =IF(AY2=0,"",(COUNTIFS($AS$8:$AS$57,"A",AY8:AY57,"")*100/COUNTIF($AS$8:$AS$57,"A"))) | AZ61: =IF(AZ2=0,"",(COUNTIFS($AS$8:$AS$57,"A",AZ8:AZ57,"")*100/COUNTIF($AS$8:$AS$57,"A"))) | BA61: =IF(BA2=0,"",(COUNTIFS($AS$8:$AS$57,"A",BA8:BA57,"")*100/COUNTIF($AS$8:$AS$57,"A"))) | ... BW61: =IF(BW2=0,"",(COUNTIFS($AS$8:$AS$57,"A",BW8:BW57,"")*100/COUNTIF($AS$8:$AS$57,"A")))
AR62: B variantı | AS62: Doğru | AT62: =IF(AT4=0,"",(COUNTIFS($AS$8:$AS$57,"B",AT8:AT57,">0")*100/COUNTIF($AS$8:$AS$57,"B"))) | AU62: =IF(AU4=0,"",(COUNTIFS($AS$8:$AS$57,"B",AU8:AU57,">0")*100/COUNTIF($AS$8:$AS$57,"B"))) | AV62: =IF(AV4=0,"",(COUNTIFS($AS$8:$AS$57,"B",AV8:AV57,">0")*100/COUNTIF($AS$8:$AS$57,"B"))) | AW62: =IF(AW4=0,"",(COUNTIFS($AS$8:$AS$57,"B",AW8:AW57,">0")*100/COUNTIF($AS$8:$AS$57,"B"))) | AX62: =IF(AX4=0,"",(COUNTIFS($AS$8:$AS$57,"B",AX8:AX57,">0")*100/COUNTIF($AS$8:$AS$57,"B"))) | AY62: =IF(AY4=0,"",(COUNTIFS($AS$8:$AS$57,"B",AY8:AY57,">0")*100/COUNTIF($AS$8:$AS$57,"B"))) | AZ62: =IF(AZ4=0,"",(COUNTIFS($AS$8:$AS$57,"B",AZ8:AZ57,">0")*100/COUNTIF($AS$8:$AS$57,"B"))) | BA62: =IF(BA4=0,"",(COUNTIFS($AS$8:$AS$57,"B",BA8:BA57,">0")*100/COUNTIF($AS$8:$AS$57,"B"))) | ... BW62: =IF(BW4=0,"",(COUNTIFS($AS$8:$AS$57,"B",BW8:BW57,">0")*100/COUNTIF($AS$8:$AS$57,"B")))
AS63: Yanlış | AT63: =IF(AT4=0,"",(COUNTIFS($AS$8:$AS$57,"B",AT8:AT57,"=0")*100/COUNTIF($AS$8:$AS$57,"B"))) | AU63: =IF(AU4=0,"",(COUNTIFS($AS$8:$AS$57,"B",AU8:AU57,"=0")*100/COUNTIF($AS$8:$AS$57,"B"))) | AV63: =IF(AV4=0,"",(COUNTIFS($AS$8:$AS$57,"B",AV8:AV57,"=0")*100/COUNTIF($AS$8:$AS$57,"B"))) | AW63: =IF(AW4=0,"",(COUNTIFS($AS$8:$AS$57,"B",AW8:AW57,"=0")*100/COUNTIF($AS$8:$AS$57,"B"))) | AX63: =IF(AX4=0,"",(COUNTIFS($AS$8:$AS$57,"B",AX8:AX57,"=0")*100/COUNTIF($AS$8:$AS$57,"B"))) | AY63: =IF(AY4=0,"",(COUNTIFS($AS$8:$AS$57,"B",AY8:AY57,"=0")*100/COUNTIF($AS$8:$AS$57,"B"))) | AZ63: =IF(AZ4=0,"",(COUNTIFS($AS$8:$AS$57,"B",AZ8:AZ57,"=0")*100/COUNTIF($AS$8:$AS$57,"B"))) | BA63: =IF(BA4=0,"",(COUNTIFS($AS$8:$AS$57,"B",BA8:BA57,"=0")*100/COUNTIF($AS$8:$AS$57,"B"))) | ... BW63: =IF(BW4=0,"",(COUNTIFS($AS$8:$AS$57,"B",BW8:BW57,"=0")*100/COUNTIF($AS$8:$AS$57,"B")))
