Workbook

Sheet Şagirdlər
B1: Şagirdlər haqqında məlumat
B2: Sinif | D2: 8 | E2: İndeks | F2: e | G2: Bölmə | I2: Azərbaycan | K2: Sinif rəhbəri (soyadı, adı və atasının adı) | N2: Məhərrəmova Cəmilə Kərəm
B3: № | C3: UTİS kod | D3: Şagird | G3: Cinsi | H3: Doğum tarixi | K3: Telefon nömrələri | N3: Ünvan
D4: soyadı | E4: adı | F4: ata adı | H4: Gün | I4: Ay | J4: İl | K4: Şagirdin mobil telefon nömrəsi | L4: Valideynin mobil telefon nömrəsi | M4: Ev telefonunun nömrəsi
B5: 1 | C5: 1356498 | D5: Atayev | E5: Ayxan | F5: Zöhrab | G5: k | H5: 19 | I5: 9 | J5: 2007 | K5: 050-436-14-61 | L5: 050-422-39-90 | N5: Binəqədi rayonu M.Ə.Rəsulzadə qəs. Əli Məmmədov küçəsi
B6: 2 | C6: 1356404 | D6: Bayramlı | E6: Məhəmməd | F6: Rafiq | G6: k | H6: 22 | I6: 7 | J6: 2008 | K6: 070-532-09-33 | L6: 050-470-55-81 | M6: 412-23-03 | N6: Binəqədi rayonu 1-ci mədən 43-cü korpus
B7: 3 | C7: 1356298 | D7: Əhmədov | E7: Məhəmməd | F7: Şahin | G7: k | H7: 2 | I7: 2 | J7: 2008 | L7: 077-422-75-13 | M7: 412-50-38 | N7: Bakı şəh.,Binəqədi ray.,M.Ə.Rəsulzadə qəs.,Fəxrəddin Şahbazov küç., ev46
B8: 4 | C8: 1356179 | D8: Əhmədova | E8: Məleykə | F8: Şahin | G8: q | H8: 17 | I8: 2 | J8: 2007 | K8: 055-633-35-72 | M8: 412-50-38 | N8: Bakı şəh.,Binəqədi ray.,M.Ə.Rəsulzadə qəs.,Fəxrəddin Şahbazov küç., ev46
B9: 5 | C9: 1253147 | D9: Əsədov | E9: İlhan | F9: Şükür | G9: k | H9: 9 | I9: 3 | J9: 2008 | L9: 050-370-30-41 | M9: 412-67-42 | N9: Binəqədi rayonu M.Ə.Rəsulzadə qəs.Ağa Neymətulla küç. 6.9
B10: 6 | C10: 1031550 | D10: Hacızadə | E10: Nurcan | F10: Üzeyir | G10: q | H10: 11 | I10: 3 | J10: 2008 | K10: 050-885-88-47 | M10: 412-00-62 | N10: Binəqədi ray.,Rəsulzadə qəs.,Zahid Qənbərov küç.,ev1 mənzil 7
B11: 7 | C11: 1357286 | D11: Həsənov | E11: Mansur | F11: Elnur | G11: k | H11: 23 | I11: 10 | J11: 2007 | K11: 070-566-42-66 | L11: 070-804-00-10 | M11: 412-74-77 | N11: Binəqədi ray.,Mədən 1 korpus 43 ev 668
B12: 8 | C12: 2428416 | D12: Hüseynli | E12: Hüseyn | F12: Vahid | G12: k | H12: 26 | I12: 12 | J12: 2007 | L12: 050-536-33-24 | N12: Binəqədi ray.,Zəngəzur küçəsi
B13: 9 | C13: 1356063 | D13: Hüseynova | E13: Şəhanə | F13: Teymur | G13: q | H13: 25 | I13: 8 | J13: 2008 | L13: 070-510-77-06 | N13: Binəqədi ray., Baksol
B14: 10 | C14: 1355916 | D14: Xəlilzadə | E14: Fatimə | F14: Əziz | G14: q | H14: 27 | I14: 11 | J14: 2006 | K14: 077-734-00-49 | N14: Novxanı kəndi,yeni tikililər
B15: 11 | C15: 1355576 | D15: İsayeva | E15: Rəbiyə | F15: Şəhavat | G15: q | H15: 29 | I15: 9 | J15: 2007 | K15: 077-331-39-05 | M15: 412-37-39 | N15: Bakı şəh.,Binəqədi ray.,Rəsulzadə qəs., 8 mart küç.,ev8
B16: 12 | C16: 1674572 | D16: Qasımov | E16: Şamil | F16: Ramin | G16: k | H16: 14 | I16: 6 | J16: 2006 | K16: 050-688-14-40 | N16: Binəqədi rayonu M.Ə.Rəsulzadə qəs. F.Şahbazov küç. Ev 61
B17: 13 | C17: 2002217 | D17: Qocayeva | E17: Fatimə | F17: Qüdrət | G17: q | H17: 16 | I17: 6 | J17: 2008 | L17: 055-977-78-92 | N17: Binəqədi rayonu M,Ə.Rəsulzadə qəs. Bina 197 ev 15
B18: 14 | C18: 1356289 | D18: Mehdiyev | E18: Mərhəmət | F18: Elsevər | G18: k | H18: 4 | I18: 11 | J18: 2006 | K18: 070-390-26-42 | M18: 412-46-99 | N18: Binəqədi ray.,Rəsulzadə qəs.,Həmidə xanım Məmmədquluzadə ev22
B19: 15 | C19: 1354929 | D19: Musayeva | E19: Selcan | F19: Emil | G19: q | H19: 16 | I19: 5 | J19: 2008 | K19: 050-514-70-43 | L19: 055-883-06-35 | N19: Binəqədi rayonu Baksol 15
B20: 16 | C20: 1829373 | D20: Nəsirov | E20: Əli | F20: Azər | G20: k | H20: 3 | I20: 8 | J20: 2008 | K20: 077-621-5702 | N20: Nərimanov ray.,Ziya Bünyadov prospekti PY-UA 38 10
B21: 17 | C21: 1350788 | D21: Sarı | E21: Xəlil | F21: Ruslan | G21: k | H21: 22 | I21: 7 | J21: 2008 | L21: 055-656-52-07 | M21: 412-05-09 | N21: Binəqədi rayonu M.Ə.Rəsulzadə qəs. Həmidə Məmmədquluzadə küç. Ev 8
B22: 18 | C22: 1350643 | D22: Şirinov | E22: Elxan | F22: Samir | G22: k | H22: 19 | I22: 3 | J22: 2008 | K22: 050-827-52-02 | L22: 050-530-49-49 | N22: Binəqədi şosesi ev 53
B23: 19 | C23: 2188973 | D23: Ağayev | E23: Nahid | F23: Vahid | G23: k | H23: 15 | I23: 2 | J23: 2008 | K23: 050-575-99-83 | L23: 077-510-94-62 | N23: Binəqədi rayonu M.Ə.Rəsulzadə qəs.
B24: 20 | C24: 1402855 | D24: Məmmədov | E24: Raul | F24: Vügar | G24: k | H24: 9 | I24: 4 | J24: 2008 | M24: 412-65-69 | N24: Binəqədi rayonu M.Ə.Rəsulzadə qəs. Z Qəmbərov küş.
B25: 21
B26: 22
B27: 23
B28: 24
B29: 25
B30: 26
B31: 27
B32: 28
B33: 29
B34: 30
B35: 31
B36: 32
... B54: 50

Sheet Müəllimlər
B1: Müəllimlər haqqında məlumat
B2: Fənlərin kodu | C2: Fənn | D2: Müəllimin soyadı, adı və atasının adı | E2: İllik dərs saatı | F2: UTİS kod | G2: Telefon nömrələri | I2: Mail adresi | J2: Fənn olimpiadaları | O2: Fənn müsabiqələri | T2: Təqdimat müsabiqələri | Y2: Məntiq olimpiadası | AD2: STEAM yarışları | AI2: Digər milli və beynəlxalq olimpiada, yarış və müsabiqələr
G3: Mobil telefon nömrəsi | H3: Ev telefonunun nömrəsi | J3: Final turun qalibləri | K3: I yer | L3: II yer | M3: III yer | N3: Həvəsləndirici | O3: Final turun qalibləri | P3: I yer | Q3: II yer | R3: III yer | S3: Həvəsləndirici | T3: Final turun qalibləri | U3: I yer | V3: II yer | W3: III yer | X3: Həvəsləndirici | Y3: Final turun qalibləri | Z3: I yer | AA3: II yer | AB3: III yer | AC3: Həvəsləndirici | AD3: Final turun qalibləri | AE3: I yer | AF3: II yer | AG3: III yer | AH3: Həvəsləndirici | AI3: Final turun qalibləri | AJ3: I yer | AK3: II yer | AL3: III yer | AM3: Həvəsləndirici
B4: 101 | C4: Tədris dili | D4: Səfərova Elnarə Yəhya | E4: 102 | F4: 1211755 | G4: 050-730-25-95 | H4: 412-54-97 | I4: ifosrasul@gmail.com
B5: 102 | C5: Ədəbiyyat | D5: Səfərova Elnarə Yəhya | E5: 68 | F5: 1211755 | G5: 050-730-25-95 | H5: 412-54-97 | I5: ifosrasul@gmail.com
B6: 103 | C6: Dövlət dili
B7: 104 | C7: Xarici dil | D7: Abbasova Maral Nadir, Əbülfətova Vəfa Nəriman | E7: 102 | F7: 1238796, 1238986 | G7: 055-560-60-44, 055-661-63-58 | H7: 412-51-97, 412-50-64 | I7: maralabbasova62@gmail.com ,
B8: 105 | C8: İkinci xarici dil | D8: Ələkbərova Tamila Səməd, Həsənova Kəmalə Faiq | E8: 34.34 | F8: 1274639, 1275210 | G8: 055-780-88-82, 050-369-85-55 | H8: 526-34-69, 431-86-89 | I8: elekbarovatamella@gmail.com, kamala-hesenova@mail.ru
B9: 106 | C9: Riyaziyyat | D9: Məhərrəmova Cəmilə Kərəm | E9: 170 | F9: 1194467 | G9: 051-701-17-75 | H9: 412-20-53 | I9: m-cemile@yahoo.com
B10: 107 | C10: İnformatika | D10: Həmidova Yazgül Bayram | E10: 34 | F10: 1791830 | G10: 055-636-90-64 | H10: 412-39-69 | I10: yaz.gul.15@mail.ru
B11: 108 | C11: Azərbaycan tarixi | D11: Bayramova Tahirə Müslüm | E11: 34 | F11: 1093316 | G11: 050-418-21-71 | H11: 411-69-47 | I11: turqutbayramov@gmail.com
B12: 109 | C12: Ümumi tarix | D12: Bayramova Tahirə Müslüm | E12: 34 | F12: 1093316 | G12: 050-418-21-71 | H12: 411-69-47 | I12: turqutbayramov@gmail.com
B13: 110 | C13: Fizika | D13: Süleymanava Nərminə Əlövsət | E13: 68 | F13: 1619437 | G13: 055-561-41-89 | I13: nerminemeherremova@gmail.com
B14: 111 | C14: Kimya | D14: Hüseynova Rəna Qədir | E14: 34 | F14: 1069207 | G14: 050-729-24-45 | H14: 412-38-82 | I14: huseynovar89@gmail.com
B15: 112 | C15: Biologiya | D15: Həmidova Məlahət Mənsub | E15: 68 | F15: 1069818 | G15: 050-484-63-48 | H15: 411-39-39 | I15: hemidovamelahet19@gmail.com
B16: 113 | C16: Coğrafiya | D16: Məmmədova Sevil Zahid | E16: 68 | F16: 1092959 | G16: 055-412-12-06 | H16: 412-12-06 | I16: sevilgeograph@gmail.com
B17: 114 | C17: Həyat bilgisi | D17: Həmidova Məlahət Mənsub | E17: 34 | F17: 1069818 | G17: 050-484-63-48 | H17: 411-39-39 | I17: hemidovamelahet19@gmail.com
B18: 115 | C18: Texnologiya | D18: Atakişiyeva Səadət Hüseyin, Məmmədova Rübabə Rəsul | E18: 34.34 | F18: 1783910, 1785387 | G18: 070-639-85-53, 055-386-01-51 | H18: 412-04-92, 412-59-41 | I18: atakishiyevbhruz@gmail.com mmmdovarubab855@gmail.com
B19: 116 | C19: Fiziki tərbiyə | D19: Xəlilova Bahar Xəlil, İsgəndərova İrina Qasım | E19: 68.68 | F19: 1342574, 1341920 | G19: 051-818-61-17, 055-439-73-58 | H19: 412-18-76, ------- | I19: bahar889999@gmail.com, isgenderovaira@gmail.com
B20: 117 | C20: Musiqi | D20: Həşimova Fəridə Həşim | E20: 34 | F20: 1787014 | G20: 055-836-67-62 | I20: farida.hewimova@gmail.com
B21: 118 | C21: Təsviri incəsənət | D21: Quliyeva Təranə Xanlar | E21: 34 | F21: 1784642 | G21: 050-745-26-08 | I21: 7262313@gmail.com
B22: 119 | C22: Çağırışaqədərki hazırlıq
B23: 120 | C23: Əlavə

Sheet Tədris dili
B1: Fənn üzrə nailiyyətlər cədvəli
B2: Sinif | C2: =Şagirdlər!D2 -> 8 | D2: İndeks | E2: =Şagirdlər!F2 -> e | F2: Bölmə | H2: =Şagirdlər!I2 -> Azərbaycan | K2: Fənn | N2: =Müəllimlər!C4 -> Tədris dili | S2: Fənn müəllimi (soyadı, adı və atasının adı) | AB2: =Müəllimlər!D4 -> Səfərova Elnarə Yəhya | AL2: İllik dərs saatı | AP2: =Müəllimlər!E4 -> 102
B3: UTİS kod | C3: Şagird | F3: Cinsi | G3: Doğum tarixi | J3: İştirak edilməyən dərslərin sayı | K3: Öİ | L3: I yarımil üzrə nailiyyətlər | Y3: II yarımil üzrə nailiyyətlər | AL3: İllik nailiyyətlər
L4: D | M4: Summativ qiymətləndirmələr | V4: Monitorinq | Y4: D | Z4: Summativ qiymətləndirmələr | AI4: Monitorinq | AL4: İllik
C5: soyadı | D5: adı | E5: ata adı | G5: Gün | H5: Ay | I5: İl | K5: Ötən tədris ili üzrə illik nəticə | L5: Diaqnostik-1 | M5: KSQ | N5: KSQ | O5: KSQ | P5: KSQ | Q5: KSQ | R5: KSQ | S5: KSQ orta | T5: BSQ | U5: I yarımil | V5: Monitorinq-1 | W5: Monitorinq-2 | X5: Monitorinq orta | Y5: Diaqnostik-2 | Z5: KSQ | AA5: KSQ | AB5: KSQ | AC5: KSQ | AD5: KSQ | AE5: KSQ | AF5: KSQ orta | AG5: BSQ | AH5: II yarımil | AI5: Monitorinq-3 | AJ5: Monitorinq-4 | AK5: Monitorinq orta | AL5: "Diaqnostik" orta illik | AM5: "Monitorinq" orta illik | AN5: "KSQ orta" orta illik | AO5: "BSQ" orta illik | AP5: İllik | AQ5: Buraxılış imtahanı nəticəsi
B6: =IF(Şagirdlər!C5="","",Şagirdlər!C5) -> 1356498 | C6: =IF(Şagirdlər!D5="","",Şagirdlər!D5) -> Atayev | D6: =IF(Şagirdlər!E5="","",Şagirdlər!E5) -> Ayxan | E6: =IF(Şagirdlər!F5="","",Şagirdlər!F5) -> Zöhrab | F6: =IF(Şagirdlər!G5="","",Şagirdlər!G5) -> k | G6: =IF(Şagirdlər!H5="","",Şagirdlər!H5) -> 19 | H6: =IF(Şagirdlər!I5="","",Şagirdlər!I5) -> 9 | I6: =IF(Şagirdlər!J5="","",Şagirdlər!J5) -> 2007 | K6: 48 | M6: 60 | N6: 50 | O6: 45 | S6: =IFERROR(AVERAGE(M6:R6),"") -> 51.666667 | T6: 35 | U6: =IF(T6="",S6,IF(S6="",T6,S6*40/100+T6*60/100)) -> 41.666667 | X6: =IFERROR(AVERAGE(V6:W6),"") | AF6: =IFERROR(AVERAGE(Z6:AE6),"") | AH6: =IF(AG6="",AF6,IF(AF6="",AG6,AF6*40/100+AG6*60/100)) | AK6: =IFERROR(AVERAGE(AI6:AJ6),"") | AL6: =IFERROR(AVERAGE(L6,Y6),"") | AM6: =IFERROR(AVERAGE(X6,AK6),"") | AN6: =IFERROR(AVERAGE(S6,AF6),"") -> 51.666667 | AO6: =IFERROR(AVERAGE(T6,AG6),"") -> 35 | AP6: =IF(AO6="",AN6,IF(AN6="",AO6,AN6*40/100+AO6*60/100)) -> 41.666667
B7: =IF(Şagirdlər!C6="","",Şagirdlər!C6) -> 1356404 | C7: =IF(Şagirdlər!D6="","",Şagirdlər!D6) -> Bayramlı | D7: =IF(Şagirdlər!E6="","",Şagirdlər!E6) -> Məhəmməd | E7: =IF(Şagirdlər!F6="","",Şagirdlər!F6) -> Rafiq | F7: =IF(Şagirdlər!G6="","",Şagirdlər!G6) -> k | G7: =IF(Şagirdlər!H6="","",Şagirdlər!H6) -> 22 | H7: =IF(Şagirdlər!I6="","",Şagirdlər!I6) -> 7 | I7: =IF(Şagirdlər!J6="","",Şagirdlər!J6) -> 2008 | K7: 53 | M7: 55 | N7: 50 | O7: 40 | S7: =IFERROR(AVERAGE(M7:R7),"") -> 48.333333 | T7: 39 | U7: =IF(T7="",S7,IF(S7="",T7,S7*40/100+T7*60/100)) -> 42.733333 | X7: =IFERROR(AVERAGE(V7:W7),"") | AF7: =IFERROR(AVERAGE(Z7:AE7),"") | AH7: =IF(AG7="",AF7,IF(AF7="",AG7,AF7*40/100+AG7*60/100)) | AK7: =IFERROR(AVERAGE(AI7:AJ7),"") | AL7: =IFERROR(AVERAGE(L7,Y7),"") | AM7: =IFERROR(AVERAGE(X7,AK7),"") | AN7: =IFERROR(AVERAGE(S7,AF7),"") -> 48.333333 | AO7: =IFERROR(AVERAGE(T7,AG7),"") -> 39 | AP7: =IF(AO7="",AN7,IF(AN7="",AO7,AN7*40/100+AO7*60/100)) -> 42.733333
B8: =IF(Şagirdlər!C7="","",Şagirdlər!C7) -> 1356298 | C8: =IF(Şagirdlər!D7="","",Şagirdlər!D7) -> Əhmədov | D8: =IF(Şagirdlər!E7="","",Şagirdlər!E7) -> Məhəmməd | E8: =IF(Şagirdlər!F7="","",Şagirdlər!F7) -> Şahin | F8: =IF(Şagirdlər!G7="","",Şagirdlər!G7) -> k | G8: =IF(Şagirdlər!H7="","",Şagirdlər!H7) -> 2 | H8: =IF(Şagirdlər!I7="","",Şagirdlər!I7) -> 2 | I8: =IF(Şagirdlər!J7="","",Şagirdlər!J7) -> 2008 | K8: 58 | M8: 50 | N8: 60 | O8: 55 | S8: =IFERROR(AVERAGE(M8:R8),"") -> 55 | T8: 41 | U8: =IF(T8="",S8,IF(S8="",T8,S8*40/100+T8*60/100)) -> 46.6 | X8: =IFERROR(AVERAGE(V8:W8),"") | AF8: =IFERROR(AVERAGE(Z8:AE8),"") | AH8: =IF(AG8="",AF8,IF(AF8="",AG8,AF8*40/100+AG8*60/100)) | AK8: =IFERROR(AVERAGE(AI8:AJ8),"") | AL8: =IFERROR(AVERAGE(L8,Y8),"") | AM8: =IFERROR(AVERAGE(X8,AK8),"") | AN8: =IFERROR(AVERAGE(S8,AF8),"") -> 55 | AO8: =IFERROR(AVERAGE(T8,AG8),"") -> 41 | AP8: =IF(AO8="",AN8,IF(AN8="",AO8,AN8*40/100+AO8*60/100)) -> 46.6
B9: =IF(Şagirdlər!C8="","",Şagirdlər!C8) -> 1356179 | C9: =IF(Şagirdlər!D8="","",Şagirdlər!D8) -> Əhmədova | D9: =IF(Şagirdlər!E8="","",Şagirdlər!E8) -> Məleykə | E9: =IF(Şagirdlər!F8="","",Şagirdlər!F8) -> Şahin | F9: =IF(Şagirdlər!G8="","",Şagirdlər!G8) -> q | G9: =IF(Şagirdlər!H8="","",Şagirdlər!H8) -> 17 | H9: =IF(Şagirdlər!I8="","",Şagirdlər!I8) -> 2 | I9: =IF(Şagirdlər!J8="","",Şagirdlər!J8) -> 2007 | K9: 73 | M9: 60 | N9: 60 | O9: 60 | S9: =IFERROR(AVERAGE(M9:R9),"") -> 60 | T9: 55 | U9: =IF(T9="",S9,IF(S9="",T9,S9*40/100+T9*60/100)) -> 57 | X9: =IFERROR(AVERAGE(V9:W9),"") | AF9: =IFERROR(AVERAGE(Z9:AE9),"") | AH9: =IF(AG9="",AF9,IF(AF9="",AG9,AF9*40/100+AG9*60/100)) | AK9: =IFERROR(AVERAGE(AI9:AJ9),"") | AL9: =IFERROR(AVERAGE(L9,Y9),"") | AM9: =IFERROR(AVERAGE(X9,AK9),"") | AN9: =IFERROR(AVERAGE(S9,AF9),"") -> 60 | AO9: =IFERROR(AVERAGE(T9,AG9),"") -> 55 | AP9: =IF(AO9="",AN9,IF(AN9="",AO9,AN9*40/100+AO9*60/100)) -> 57
B10: =IF(Şagirdlər!C9="","",Şagirdlər!C9) -> 1253147 | C10: =IF(Şagirdlər!D9="","",Şagirdlər!D9) -> Əsədov | D10: =IF(Şagirdlər!E9="","",Şagirdlər!E9) -> İlhan | E10: =IF(Şagirdlər!F9="","",Şagirdlər!F9) -> Şükür | F10: =IF(Şagirdlər!G9="","",Şagirdlər!G9) -> k | G10: =IF(Şagirdlər!H9="","",Şagirdlər!H9) -> 9 | H10: =IF(Şagirdlər!I9="","",Şagirdlər!I9) -> 3 | I10: =IF(Şagirdlər!J9="","",Şagirdlər!J9) -> 2008 | K10: 48 | M10: 80 | N10: 55 | O10: 60 | S10: =IFERROR(AVERAGE(M10:R10),"") -> 65 | T10: 64 | U10: =IF(T10="",S10,IF(S10="",T10,S10*40/100+T10*60/100)) -> 64.4 | X10: =IFERROR(AVERAGE(V10:W10),"") | AF10: =IFERROR(AVERAGE(Z10:AE10),"") | AH10: =IF(AG10="",AF10,IF(AF10="",AG10,AF10*40/100+AG10*60/100)) | AK10: =IFERROR(AVERAGE(AI10:AJ10),"") | AL10: =IFERROR(AVERAGE(L10,Y10),"") | AM10: =IFERROR(AVERAGE(X10,AK10),"") | AN10: =IFERROR(AVERAGE(S10,AF10),"") -> 65 | AO10: =IFERROR(AVERAGE(T10,AG10),"") -> 64 | AP10: =IF(AO10="",AN10,IF(AN10="",AO10,AN10*40/100+AO10*60/100)) -> 64.4
B11: =IF(Şagirdlər!C10="","",Şagirdlər!C10) -> 1031550 | C11: =IF(Şagirdlər!D10="","",Şagirdlər!D10) -> Hacızadə | D11: =IF(Şagirdlər!E10="","",Şagirdlər!E10) -> Nurcan | E11: =IF(Şagirdlər!F10="","",Şagirdlər!F10) -> Üzeyir | F11: =IF(Şagirdlər!G10="","",Şagirdlər!G10) -> q | G11: =IF(Şagirdlər!H10="","",Şagirdlər!H10) -> 11 | H11: =IF(Şagirdlər!I10="","",Şagirdlər!I10) -> 3 | I11: =IF(Şagirdlər!J10="","",Şagirdlər!J10) -> 2008 | K11: 100 | M11: 85 | N11: 90 | O11: 95 | S11: =IFERROR(AVERAGE(M11:R11),"") -> 90 | T11: 94 | U11: =IF(T11="",S11,IF(S11="",T11,S11*40/100+T11*60/100)) -> 92.4 | X11: =IFERROR(AVERAGE(V11:W11),"") | AF11: =IFERROR(AVERAGE(Z11:AE11),"") | AH11: =IF(AG11="",AF11,IF(AF11="",AG11,AF11*40/100+AG11*60/100)) | AK11: =IFERROR(AVERAGE(AI11:AJ11),"") | AL11: =IFERROR(AVERAGE(L11,Y11),"") | AM11: =IFERROR(AVERAGE(X11,AK11),"") | AN11: =IFERROR(AVERAGE(S11,AF11),"") -> 90 | AO11: =IFERROR(AVERAGE(T11,AG11),"") -> 94 | AP11: =IF(AO11="",AN11,IF(AN11="",AO11,AN11*40/100+AO11*60/100)) -> 92.4
B12: =IF(Şagirdlər!C11="","",Şagirdlər!C11) -> 1357286 | C12: =IF(Şagirdlər!D11="","",Şagirdlər!D11) -> Həsənov | D12: =IF(Şagirdlər!E11="","",Şagirdlər!E11) -> Mansur | E12: =IF(Şagirdlər!F11="","",Şagirdlər!F11) -> Elnur | F12: =IF(Şagirdlər!G11="","",Şagirdlər!G11) -> k | G12: =IF(Şagirdlər!H11="","",Şagirdlər!H11) -> 23 | H12: =IF(Şagirdlər!I11="","",Şagirdlər!I11) -> 10 | I12: =IF(Şagirdlər!J11="","",Şagirdlər!J11) -> 2007 | K12: 68 | M12: 75 | N12: 70 | O12: 65 | S12: =IFERROR(AVERAGE(M12:R12),"") -> 70 | T12: 64 | U12: =IF(T12="",S12,IF(S12="",T12,S12*40/100+T12*60/100)) -> 66.4 | X12: =IFERROR(AVERAGE(V12:W12),"") | AF12: =IFERROR(AVERAGE(Z12:AE12),"") | AH12: =IF(AG12="",AF12,IF(AF12="",AG12,AF12*40/100+AG12*60/100)) | AK12: =IFERROR(AVERAGE(AI12:AJ12),"") | AL12: =IFERROR(AVERAGE(L12,Y12),"") | AM12: =IFERROR(AVERAGE(X12,AK12),"") | AN12: =IFERROR(AVERAGE(S12,AF12),"") -> 70 | AO12: =IFERROR(AVERAGE(T12,AG12),"") -> 64 | AP12: =IF(AO12="",AN12,IF(AN12="",AO12,AN12*40/100+AO12*60/100)) -> 66.4
B13: =IF(Şagirdlər!C12="","",Şagirdlər!C12) -> 2428416 | C13: =IF(Şagirdlər!D12="","",Şagirdlər!D12) -> Hüseynli | D13: =IF(Şagirdlər!E12="","",Şagirdlər!E12) -> Hüseyn | E13: =IF(Şagirdlər!F12="","",Şagirdlər!F12) -> Vahid | F13: =IF(Şagirdlər!G12="","",Şagirdlər!G12) -> k | G13: =IF(Şagirdlər!H12="","",Şagirdlər!H12) -> 26 | H13: =IF(Şagirdlər!I12="","",Şagirdlər!I12) -> 12 | I13: =IF(Şagirdlər!J12="","",Şagirdlər!J12) -> 2007 | K13: 40 | M13: 40 | N13: 35 | O13: 35 | S13: =IFERROR(AVERAGE(M13:R13),"") -> 36.666667 | T13: 32 | U13: =IF(T13="",S13,IF(S13="",T13,S13*40/100+T13*60/100)) -> 33.866667 | X13: =IFERROR(AVERAGE(V13:W13),"") | AF13: =IFERROR(AVERAGE(Z13:AE13),"") | AH13: =IF(AG13="",AF13,IF(AF13="",AG13,AF13*40/100+AG13*60/100)) | AK13: =IFERROR(AVERAGE(AI13:AJ13),"") | AL13: =IFERROR(AVERAGE(L13,Y13),"") | AM13: =IFERROR(AVERAGE(X13,AK13),"") | AN13: =IFERROR(AVERAGE(S13,AF13),"") -> 36.666667 | AO13: =IFERROR(AVERAGE(T13,AG13),"") -> 32 | AP13: =IF(AO13="",AN13,IF(AN13="",AO13,AN13*40/100+AO13*60/100)) -> 33.866667
B14: =IF(Şagirdlər!C13="","",Şagirdlər!C13) -> 1356063 | C14: =IF(Şagirdlər!D13="","",Şagirdlər!D13) -> Hüseynova | D14: =IF(Şagirdlər!E13="","",Şagirdlər!E13) -> Şəhanə | E14: =IF(Şagirdlər!F13="","",Şagirdlər!F13) -> Teymur | F14: =IF(Şagirdlər!G13="","",Şagirdlər!G13) -> q | G14: =IF(Şagirdlər!H13="","",Şagirdlər!H13) -> 25 | H14: =IF(Şagirdlər!I13="","",Şagirdlər!I13) -> 8 | I14: =IF(Şagirdlər!J13="","",Şagirdlər!J13) -> 2008 | K14: 70 | M14: 80 | N14: 80 | O14: 75 | S14: =IFERROR(AVERAGE(M14:R14),"") -> 78.333333 | T14: 65 | U14: =IF(T14="",S14,IF(S14="",T14,S14*40/100+T14*60/100)) -> 70.333333 | X14: =IFERROR(AVERAGE(V14:W14),"") | AF14: =IFERROR(AVERAGE(Z14:AE14),"") | AH14: =IF(AG14="",AF14,IF(AF14="",AG14,AF14*40/100+AG14*60/100)) | AK14: =IFERROR(AVERAGE(AI14:AJ14),"") | AL14: =IFERROR(AVERAGE(L14,Y14),"") | AM14: =IFERROR(AVERAGE(X14,AK14),"") | AN14: =IFERROR(AVERAGE(S14,AF14),"") -> 78.333333 | AO14: =IFERROR(AVERAGE(T14,AG14),"") -> 65 | AP14: =IF(AO14="",AN14,IF(AN14="",AO14,AN14*40/100+AO14*60/100)) -> 70.333333
B15: =IF(Şagirdlər!C14="","",Şagirdlər!C14) -> 1355916 | C15: =IF(Şagirdlər!D14="","",Şagirdlər!D14) -> Xəlilzadə | D15: =IF(Şagirdlər!E14="","",Şagirdlər!E14) -> Fatimə | E15: =IF(Şagirdlər!F14="","",Şagirdlər!F14) -> Əziz | F15: =IF(Şagirdlər!G14="","",Şagirdlər!G14) -> q | G15: =IF(Şagirdlər!H14="","",Şagirdlər!H14) -> 27 | H15: =IF(Şagirdlər!I14="","",Şagirdlər!I14) -> 11 | I15: =IF(Şagirdlər!J14="","",Şagirdlər!J14) -> 2006 | K15: 68 | M15: 80 | N15: 80 | O15: 70 | S15: =IFERROR(AVERAGE(M15:R15),"") -> 76.666667 | T15: 64 | U15: =IF(T15="",S15,IF(S15="",T15,S15*40/100+T15*60/100)) -> 69.066667 | X15: =IFERROR(AVERAGE(V15:W15),"") | AF15: =IFERROR(AVERAGE(Z15:AE15),"") | AH15: =IF(AG15="",AF15,IF(AF15="",AG15,AF15*40/100+AG15*60/100)) | AK15: =IFERROR(AVERAGE(AI15:AJ15),"") | AL15: =IFERROR(AVERAGE(L15,Y15),"") | AM15: =IFERROR(AVERAGE(X15,AK15),"") | AN15: =IFERROR(AVERAGE(S15,AF15),"") -> 76.666667 | AO15: =IFERROR(AVERAGE(T15,AG15),"") -> 64 | AP15: =IF(AO15="",AN15,IF(AN15="",AO15,AN15*40/100+AO15*60/100)) -> 69.066667
B16: =IF(Şagirdlər!C15="","",Şagirdlər!C15) -> 1355576 | C16: =IF(Şagirdlər!D15="","",Şagirdlər!D15) -> İsayeva | D16: =IF(Şagirdlər!E15="","",Şagirdlər!E15) -> Rəbiyə | E16: =IF(Şagirdlər!F15="","",Şagirdlər!F15) -> Şəhavat | F16: =IF(Şagirdlər!G15="","",Şagirdlər!G15) -> q | G16: =IF(Şagirdlər!H15="","",Şagirdlər!H15) -> 29 | H16: =IF(Şagirdlər!I15="","",Şagirdlər!I15) -> 9 | I16: =IF(Şagirdlər!J15="","",Şagirdlər!J15) -> 2007 | K16: 56 | M16: 65 | N16: 60 | O16: 65 | S16: =IFERROR(AVERAGE(M16:R16),"") -> 63.333333 | T16: 64 | U16: =IF(T16="",S16,IF(S16="",T16,S16*40/100+T16*60/100)) -> 63.733333 | X16: =IFERROR(AVERAGE(V16:W16),"") | AF16: =IFERROR(AVERAGE(Z16:AE16),"") | AH16: =IF(AG16="",AF16,IF(AF16="",AG16,AF16*40/100+AG16*60/100)) | AK16: =IFERROR(AVERAGE(AI16:AJ16),"") | AL16: =IFERROR(AVERAGE(L16,Y16),"") | AM16: =IFERROR(AVERAGE(X16,AK16),"") | AN16: =IFERROR(AVERAGE(S16,AF16),"") -> 63.333333 | AO16: =IFERROR(AVERAGE(T16,AG16),"") -> 64 | AP16: =IF(AO16="",AN16,IF(AN16="",AO16,AN16*40/100+AO16*60/100)) -> 63.733333
B17: =IF(Şagirdlər!C16="","",Şagirdlər!C16) -> 1674572 | C17: =IF(Şagirdlər!D16="","",Şagirdlər!D16) -> Qasımov | D17: =IF(Şagirdlər!E16="","",Şagirdlər!E16) -> Şamil | E17: =IF(Şagirdlər!F16="","",Şagirdlər!F16) -> Ramin | F17: =IF(Şagirdlər!G16="","",Şagirdlər!G16) -> k | G17: =IF(Şagirdlər!H16="","",Şagirdlər!H16) -> 14 | H17: =IF(Şagirdlər!I16="","",Şagirdlər!I16) -> 6 | I17: =IF(Şagirdlər!J16="","",Şagirdlər!J16) -> 2006 | K17: 40 | M17: 35 | N17: 35 | O17: 35 | S17: =IFERROR(AVERAGE(M17:R17),"") -> 35 | T17: 34 | U17: =IF(T17="",S17,IF(S17="",T17,S17*40/100+T17*60/100)) -> 34.4 | X17: =IFERROR(AVERAGE(V17:W17),"") | AF17: =IFERROR(AVERAGE(Z17:AE17),"") | AH17: =IF(AG17="",AF17,IF(AF17="",AG17,AF17*40/100+AG17*60/100)) | AK17: =IFERROR(AVERAGE(AI17:AJ17),"") | AL17: =IFERROR(AVERAGE(L17,Y17),"") | AM17: =IFERROR(AVERAGE(X17,AK17),"") | AN17: =IFERROR(AVERAGE(S17,AF17),"") -> 35 | AO17: =IFERROR(AVERAGE(T17,AG17),"") -> 34 | AP17: =IF(AO17="",AN17,IF(AN17="",AO17,AN17*40/100+AO17*60/100)) -> 34.4
... B23: =IF(Şagirdlər!C22="","",Şagirdlər!C22) -> 1350643 | C23: =IF(Şagirdlər!D22="","",Şagirdlər!D22) -> Şirinov | D23: =IF(Şagirdlər!E22="","",Şagirdlər!E22) -> Elxan | E23: =IF(Şagirdlər!F22="","",Şagirdlər!F22) -> Samir | F23: =IF(Şagirdlər!G22="","",Şagirdlər!G22) -> k | G23: =IF(Şagirdlər!H22="","",Şagirdlər!H22) -> 19 | H23: =IF(Şagirdlər!I22="","",Şagirdlər!I22) -> 3 | I23: =IF(Şagirdlər!J22="","",Şagirdlər!J22) -> 2008 | K23: 38 | M23: 35 | N23: 43 | O23: 40 | S23: =IFERROR(AVERAGE(M23:R23),"") -> 39.333333 | T23: 43 | U23: =IF(T23="",S23,IF(S23="",T23,S23*40/100+T23*60/100)) -> 41.533333 | X23: =IFERROR(AVERAGE(V23:W23),"") | AF23: =IFERROR(AVERAGE(Z23:AE23),"") | AH23: =IF(AG23="",AF23,IF(AF23="",AG23,AF23*40/100+AG23*60/100)) | AK23: =IFERROR(AVERAGE(AI23:AJ23),"") | AL23: =IFERROR(AVERAGE(L23,Y23),"") | AM23: =IFERROR(AVERAGE(X23,AK23),"") | AN23: =IFERROR(AVERAGE(S23,AF23),"") -> 39.333333 | AO23: =IFERROR(AVERAGE(T23,AG23),"") -> 43 | AP23: =IF(AO23="",AN23,IF(AN23="",AO23,AN23*40/100+AO23*60/100)) -> 41.533333
B24: =IF(Şagirdlər!C23="","",Şagirdlər!C23) -> 2188973 | C24: =IF(Şagirdlər!D23="","",Şagirdlər!D23) -> Ağayev | D24: =IF(Şagirdlər!E23="","",Şagirdlər!E23) -> Nahid | E24: =IF(Şagirdlər!F23="","",Şagirdlər!F23) -> Vahid | F24: =IF(Şagirdlər!G23="","",Şagirdlər!G23) -> k | G24: =IF(Şagirdlər!H23="","",Şagirdlər!H23) -> 15 | H24: =IF(Şagirdlər!I23="","",Şagirdlər!I23) -> 2 | I24: =IF(Şagirdlər!J23="","",Şagirdlər!J23) -> 2008 | K24: 70 | N24: 55 | O24: 50 | S24: =IFERROR(AVERAGE(M24:R24),"") -> 52.5 | T24: 50 | U24: =IF(T24="",S24,IF(S24="",T24,S24*40/100+T24*60/100)) -> 51 | X24: =IFERROR(AVERAGE(V24:W24),"") | AF24: =IFERROR(AVERAGE(Z24:AE24),"") | AH24: =IF(AG24="",AF24,IF(AF24="",AG24,AF24*40/100+AG24*60/100)) | AK24: =IFERROR(AVERAGE(AI24:AJ24),"") | AL24: =IFERROR(AVERAGE(L24,Y24),"") | AM24: =IFERROR(AVERAGE(X24,AK24),"") | AN24: =IFERROR(AVERAGE(S24,AF24),"") -> 52.5 | AO24: =IFERROR(AVERAGE(T24,AG24),"") -> 50 | AP24: =IF(AO24="",AN24,IF(AN24="",AO24,AN24*40/100+AO24*60/100)) -> 51
B25: =IF(Şagirdlər!C24="","",Şagirdlər!C24) -> 1402855 | C25: =IF(Şagirdlər!D24="","",Şagirdlər!D24) -> Məmmədov | D25: =IF(Şagirdlər!E24="","",Şagirdlər!E24) -> Raul | E25: =IF(Şagirdlər!F24="","",Şagirdlər!F24) -> Vügar | F25: =IF(Şagirdlər!G24="","",Şagirdlər!G24) -> k | G25: =IF(Şagirdlər!H24="","",Şagirdlər!H24) -> 9 | H25: =IF(Şagirdlər!I24="","",Şagirdlər!I24) -> 4 | I25: =IF(Şagirdlər!J24="","",Şagirdlər!J24) -> 2008 | K25: 78 | M25: 70 | N25: 75 | O25: 62 | S25: =IFERROR(AVERAGE(M25:R25),"") -> 69 | T25: 63 | U25: =IF(T25="",S25,IF(S25="",T25,S25*40/100+T25*60/100)) -> 65.4 | X25: =IFERROR(AVERAGE(V25:W25),"") | AF25: =IFERROR(AVERAGE(Z25:AE25),"") | AH25: =IF(AG25="",AF25,IF(AF25="",AG25,AF25*40/100+AG25*60/100)) | AK25: =IFERROR(AVERAGE(AI25:AJ25),"") | AL25: =IFERROR(AVERAGE(L25,Y25),"") | AM25: =IFERROR(AVERAGE(X25,AK25),"") | AN25: =IFERROR(AVERAGE(S25,AF25),"") -> 69 | AO25: =IFERROR(AVERAGE(T25,AG25),"") -> 63 | AP25: =IF(AO25="",AN25,IF(AN25="",AO25,AN25*40/100+AO25*60/100)) -> 65.4
B26: =IF(Şagirdlər!C25="","",Şagirdlər!C25) | C26: =IF(Şagirdlər!D25="","",Şagirdlər!D25) | D26: =IF(Şagirdlər!E25="","",Şagirdlər!E25) | E26: =IF(Şagirdlər!F25="","",Şagirdlər!F25) | F26: =IF(Şagirdlər!G25="","",Şagirdlər!G25) | G26: =IF(Şagirdlər!H25="","",Şagirdlər!H25) | H26: =IF(Şagirdlər!I25="","",Şagirdlər!I25) | I26: =IF(Şagirdlər!J25="","",Şagirdlər!J25) | S26: =IFERROR(AVERAGE(M26:R26),"") | U26: =IF(T26="",S26,IF(S26="",T26,S26*40/100+T26*60/100)) | X26: =IFERROR(AVERAGE(V26:W26),"") | AF26: =IFERROR(AVERAGE(Z26:AE26),"") | AH26: =IF(AG26="",AF26,IF(AF26="",AG26,AF26*40/100+AG26*60/100)) | AK26: =IFERROR(AVERAGE(AI26:AJ26),"") | AL26: =IFERROR(AVERAGE(L26,Y26),"") | AM26: =IFERROR(AVERAGE(X26,AK26),"") | AN26: =IFERROR(AVERAGE(S26,AF26),"") | AO26: =IFERROR(AVERAGE(T26,AG26),"") | AP26: =IF(AO26="",AN26,IF(AN26="",AO26,AN26*40/100+AO26*60/100))
B27: =IF(Şagirdlər!C26="","",Şagirdlər!C26) | C27: =IF(Şagirdlər!D26="","",Şagirdlər!D26) | D27: =IF(Şagirdlər!E26="","",Şagirdlər!E26) | E27: =IF(Şagirdlər!F26="","",Şagirdlər!F26) | F27: =IF(Şagirdlər!G26="","",Şagirdlər!G26) | G27: =IF(Şagirdlər!H26="","",Şagirdlər!H26) | H27: =IF(Şagirdlər!I26="","",Şagirdlər!I26) | I27: =IF(Şagirdlər!J26="","",Şagirdlər!J26) | S27: =IFERROR(AVERAGE(M27:R27),"") | U27: =IF(T27="",S27,IF(S27="",T27,S27*40/100+T27*60/100)) | X27: =IFERROR(AVERAGE(V27:W27),"") | AF27: =IFERROR(AVERAGE(Z27:AE27),"") | AH27: =IF(AG27="",AF27,IF(AF27="",AG27,AF27*40/100+AG27*60/100)) | AK27: =IFERROR(AVERAGE(AI27:AJ27),"") | AL27: =IFERROR(AVERAGE(L27,Y27),"") | AM27: =IFERROR(AVERAGE(X27,AK27),"") | AN27: =IFERROR(AVERAGE(S27,AF27),"") | AO27: =IFERROR(AVERAGE(T27,AG27),"") | AP27: =IF(AO27="",AN27,IF(AN27="",AO27,AN27*40/100+AO27*60/100))
B28: =IF(Şagirdlər!C27="","",Şagirdlər!C27) | C28: =IF(Şagirdlər!D27="","",Şagirdlər!D27) | D28: =IF(Şagirdlər!E27="","",Şagirdlər!E27) | E28: =IF(Şagirdlər!F27="","",Şagirdlər!F27) | F28: =IF(Şagirdlər!G27="","",Şagirdlər!G27) | G28: =IF(Şagirdlər!H27="","",Şagirdlər!H27) | H28: =IF(Şagirdlər!I27="","",Şagirdlər!I27) | I28: =IF(Şagirdlər!J27="","",Şagirdlər!J27) | S28: =IFERROR(AVERAGE(M28:R28),"") | U28: =IF(T28="",S28,IF(S28="",T28,S28*40/100+T28*60/100)) | X28: =IFERROR(AVERAGE(V28:W28),"") | AF28: =IFERROR(AVERAGE(Z28:AE28),"") | AH28: =IF(AG28="",AF28,IF(AF28="",AG28,AF28*40/100+AG28*60/100)) | AK28: =IFERROR(AVERAGE(AI28:AJ28),"") | AL28: =IFERROR(AVERAGE(L28,Y28),"") | AM28: =IFERROR(AVERAGE(X28,AK28),"") | AN28: =IFERROR(AVERAGE(S28,AF28),"") | AO28: =IFERROR(AVERAGE(T28,AG28),"") | AP28: =IF(AO28="",AN28,IF(AN28="",AO28,AN28*40/100+AO28*60/100))
B29: =IF(Şagirdlər!C28="","",Şagirdlər!C28) | C29: =IF(Şagirdlər!D28="","",Şagirdlər!D28) | D29: =IF(Şagirdlər!E28="","",Şagirdlər!E28) | E29: =IF(Şagirdlər!F28="","",Şagirdlər!F28) | F29: =IF(Şagirdlər!G28="","",Şagirdlər!G28) | G29: =IF(Şagirdlər!H28="","",Şagirdlər!H28) | H29: =IF(Şagirdlər!I28="","",Şagirdlər!I28) | I29: =IF(Şagirdlər!J28="","",Şagirdlər!J28) | S29: =IFERROR(AVERAGE(M29:R29),"") | U29: =IF(T29="",S29,IF(S29="",T29,S29*40/100+T29*60/100)) | X29: =IFERROR(AVERAGE(V29:W29),"") | AF29: =IFERROR(AVERAGE(Z29:AE29),"") | AH29: =IF(AG29="",AF29,IF(AF29="",AG29,AF29*40/100+AG29*60/100)) | AK29: =IFERROR(AVERAGE(AI29:AJ29),"") | AL29: =IFERROR(AVERAGE(L29,Y29),"") | AM29: =IFERROR(AVERAGE(X29,AK29),"") | AN29: =IFERROR(AVERAGE(S29,AF29),"") | AO29: =IFERROR(AVERAGE(T29,AG29),"") | AP29: =IF(AO29="",AN29,IF(AN29="",AO29,AN29*40/100+AO29*60/100))
B30: =IF(Şagirdlər!C29="","",Şagirdlər!C29) | C30: =IF(Şagirdlər!D29="","",Şagirdlər!D29) | D30: =IF(Şagirdlər!E29="","",Şagirdlər!E29) | E30: =IF(Şagirdlər!F29="","",Şagirdlər!F29) | F30: =IF(Şagirdlər!G29="","",Şagirdlər!G29) | G30: =IF(Şagirdlər!H29="","",Şagirdlər!H29) | H30: =IF(Şagirdlər!I29="","",Şagirdlər!I29) | I30: =IF(Şagirdlər!J29="","",Şagirdlər!J29) | S30: =IFERROR(AVERAGE(M30:R30),"") | U30: =IF(T30="",S30,IF(S30="",T30,S30*40/100+T30*60/100)) | X30: =IFERROR(AVERAGE(V30:W30),"") | AF30: =IFERROR(AVERAGE(Z30:AE30),"") | AH30: =IF(AG30="",AF30,IF(AF30="",AG30,AF30*40/100+AG30*60/100)) | AK30: =IFERROR(AVERAGE(AI30:AJ30),"") | AL30: =IFERROR(AVERAGE(L30,Y30),"") | AM30: =IFERROR(AVERAGE(X30,AK30),"") | AN30: =IFERROR(AVERAGE(S30,AF30),"") | AO30: =IFERROR(AVERAGE(T30,AG30),"") | AP30: =IF(AO30="",AN30,IF(AN30="",AO30,AN30*40/100+AO30*60/100))
B31: =IF(Şagirdlər!C30="","",Şagirdlər!C30) | C31: =IF(Şagirdlər!D30="","",Şagirdlər!D30) | D31: =IF(Şagirdlər!E30="","",Şagirdlər!E30) | E31: =IF(Şagirdlər!F30="","",Şagirdlər!F30) | F31: =IF(Şagirdlər!G30="","",Şagirdlər!G30) | G31: =IF(Şagirdlər!H30="","",Şagirdlər!H30) | H31: =IF(Şagirdlər!I30="","",Şagirdlər!I30) | I31: =IF(Şagirdlər!J30="","",Şagirdlər!J30) | S31: =IFERROR(AVERAGE(M31:R31),"") | U31: =IF(T31="",S31,IF(S31="",T31,S31*40/100+T31*60/100)) | X31: =IFERROR(AVERAGE(V31:W31),"") | AF31: =IFERROR(AVERAGE(Z31:AE31),"") | AH31: =IF(AG31="",AF31,IF(AF31="",AG31,AF31*40/100+AG31*60/100)) | AK31: =IFERROR(AVERAGE(AI31:AJ31),"") | AL31: =IFERROR(AVERAGE(L31,Y31),"") | AM31: =IFERROR(AVERAGE(X31,AK31),"") | AN31: =IFERROR(AVERAGE(S31,AF31),"") | AO31: =IFERROR(AVERAGE(T31,AG31),"") | AP31: =IF(AO31="",AN31,IF(AN31="",AO31,AN31*40/100+AO31*60/100))
B32: =IF(Şagirdlər!C31="","",Şagirdlər!C31) | C32: =IF(Şagirdlər!D31="","",Şagirdlər!D31) | D32: =IF(Şagirdlər!E31="","",Şagirdlər!E31) | E32: =IF(Şagirdlər!F31="","",Şagirdlər!F31) | F32: =IF(Şagirdlər!G31="","",Şagirdlər!G31) | G32: =IF(Şagirdlər!H31="","",Şagirdlər!H31) | H32: =IF(Şagirdlər!I31="","",Şagirdlər!I31) | I32: =IF(Şagirdlər!J31="","",Şagirdlər!J31) | S32: =IFERROR(AVERAGE(M32:R32),"") | U32: =IF(T32="",S32,IF(S32="",T32,S32*40/100+T32*60/100)) | X32: =IFERROR(AVERAGE(V32:W32),"") | AF32: =IFERROR(AVERAGE(Z32:AE32),"") | AH32: =IF(AG32="",AF32,IF(AF32="",AG32,AF32*40/100+AG32*60/100)) | AK32: =IFERROR(AVERAGE(AI32:AJ32),"") | AL32: =IFERROR(AVERAGE(L32,Y32),"") | AM32: =IFERROR(AVERAGE(X32,AK32),"") | AN32: =IFERROR(AVERAGE(S32,AF32),"") | AO32: =IFERROR(AVERAGE(T32,AG32),"") | AP32: =IF(AO32="",AN32,IF(AN32="",AO32,AN32*40/100+AO32*60/100))
B33: =IF(Şagirdlər!C32="","",Şagirdlər!C32) | C33: =IF(Şagirdlər!D32="","",Şagirdlər!D32) | D33: =IF(Şagirdlər!E32="","",Şagirdlər!E32) | E33: =IF(Şagirdlər!F32="","",Şagirdlər!F32) | F33: =IF(Şagirdlər!G32="","",Şagirdlər!G32) | G33: =IF(Şagirdlər!H32="","",Şagirdlər!H32) | H33: =IF(Şagirdlər!I32="","",Şagirdlər!I32) | I33: =IF(Şagirdlər!J32="","",Şagirdlər!J32) | S33: =IFERROR(AVERAGE(M33:R33),"") | U33: =IF(T33="",S33,IF(S33="",T33,S33*40/100+T33*60/100)) | X33: =IFERROR(AVERAGE(V33:W33),"") | AF33: =IFERROR(AVERAGE(Z33:AE33),"") | AH33: =IF(AG33="",AF33,IF(AF33="",AG33,AF33*40/100+AG33*60/100)) | AK33: =IFERROR(AVERAGE(AI33:AJ33),"") | AL33: =IFERROR(AVERAGE(L33,Y33),"") | AM33: =IFERROR(AVERAGE(X33,AK33),"") | AN33: =IFERROR(AVERAGE(S33,AF33),"") | AO33: =IFERROR(AVERAGE(T33,AG33),"") | AP33: =IF(AO33="",AN33,IF(AN33="",AO33,AN33*40/100+AO33*60/100))
B34: =IF(Şagirdlər!C33="","",Şagirdlər!C33) | C34: =IF(Şagirdlər!D33="","",Şagirdlər!D33) | D34: =IF(Şagirdlər!E33="","",Şagirdlər!E33) | E34: =IF(Şagirdlər!F33="","",Şagirdlər!F33) | F34: =IF(Şagirdlər!G33="","",Şagirdlər!G33) | G34: =IF(Şagirdlər!H33="","",Şagirdlər!H33) | H34: =IF(Şagirdlər!I33="","",Şagirdlər!I33) | I34: =IF(Şagirdlər!J33="","",Şagirdlər!J33) | S34: =IFERROR(AVERAGE(M34:R34),"") | U34: =IF(T34="",S34,IF(S34="",T34,S34*40/100+T34*60/100)) | X34: =IFERROR(AVERAGE(V34:W34),"") | AF34: =IFERROR(AVERAGE(Z34:AE34),"") | AH34: =IF(AG34="",AF34,IF(AF34="",AG34,AF34*40/100+AG34*60/100)) | AK34: =IFERROR(AVERAGE(AI34:AJ34),"") | AL34: =IFERROR(AVERAGE(L34,Y34),"") | AM34: =IFERROR(AVERAGE(X34,AK34),"") | AN34: =IFERROR(AVERAGE(S34,AF34),"") | AO34: =IFERROR(AVERAGE(T34,AG34),"") | AP34: =IF(AO34="",AN34,IF(AN34="",AO34,AN34*40/100+AO34*60/100))
B35: =IF(Şagirdlər!C34="","",Şagirdlər!C34) | C35: =IF(Şagirdlər!D34="","",Şagirdlər!D34) | D35: =IF(Şagirdlər!E34="","",Şagirdlər!E34) | E35: =IF(Şagirdlər!F34="","",Şagirdlər!F34) | F35: =IF(Şagirdlər!G34="","",Şagirdlər!G34) | G35: =IF(Şagirdlər!H34="","",Şagirdlər!H34) | H35: =IF(Şagirdlər!I34="","",Şagirdlər!I34) | I35: =IF(Şagirdlər!J34="","",Şagirdlər!J34) | S35: =IFERROR(AVERAGE(M35:R35),"") | U35: =IF(T35="",S35,IF(S35="",T35,S35*40/100+T35*60/100)) | X35: =IFERROR(AVERAGE(V35:W35),"") | AF35: =IFERROR(AVERAGE(Z35:AE35),"") | AH35: =IF(AG35="",AF35,IF(AF35="",AG35,AF35*40/100+AG35*60/100)) | AK35: =IFERROR(AVERAGE(AI35:AJ35),"") | AL35: =IFERROR(AVERAGE(L35,Y35),"") | AM35: =IFERROR(AVERAGE(X35,AK35),"") | AN35: =IFERROR(AVERAGE(S35,AF35),"") | AO35: =IFERROR(AVERAGE(T35,AG35),"") | AP35: =IF(AO35="",AN35,IF(AN35="",AO35,AN35*40/100+AO35*60/100))
B36: =IF(Şagirdlər!C35="","",Şagirdlər!C35) | C36: =IF(Şagirdlər!D35="","",Şagirdlər!D35) | D36: =IF(Şagirdlər!E35="","",Şagirdlər!E35) | E36: =IF(Şagirdlər!F35="","",Şagirdlər!F35) | F36: =IF(Şagirdlər!G35="","",Şagirdlər!G35) | G36: =IF(Şagirdlər!H35="","",Şagirdlər!H35) | H36: =IF(Şagirdlər!I35="","",Şagirdlər!I35) | I36: =IF(Şagirdlər!J35="","",Şagirdlər!J35) | S36: =IFERROR(AVERAGE(M36:R36),"") | U36: =IF(T36="",S36,IF(S36="",T36,S36*40/100+T36*60/100)) | X36: =IFERROR(AVERAGE(V36:W36),"") | AF36: =IFERROR(AVERAGE(Z36:AE36),"") | AH36: =IF(AG36="",AF36,IF(AF36="",AG36,AF36*40/100+AG36*60/100)) | AK36: =IFERROR(AVERAGE(AI36:AJ36),"") | AL36: =IFERROR(AVERAGE(L36,Y36),"") | AM36: =IFERROR(AVERAGE(X36,AK36),"") | AN36: =IFERROR(AVERAGE(S36,AF36),"") | AO36: =IFERROR(AVERAGE(T36,AG36),"") | AP36: =IF(AO36="",AN36,IF(AN36="",AO36,AN36*40/100+AO36*60/100))
B37: =IF(Şagirdlər!C36="","",Şagirdlər!C36) | C37: =IF(Şagirdlər!D36="","",Şagirdlər!D36) | D37: =IF(Şagirdlər!E36="","",Şagirdlər!E36) | E37: =IF(Şagirdlər!F36="","",Şagirdlər!F36) | F37: =IF(Şagirdlər!G36="","",Şagirdlər!G36) | G37: =IF(Şagirdlər!H36="","",Şagirdlər!H36) | H37: =IF(Şagirdlər!I36="","",Şagirdlər!I36) | I37: =IF(Şagirdlər!J36="","",Şagirdlər!J36) | S37: =IFERROR(AVERAGE(M37:R37),"") | U37: =IF(T37="",S37,IF(S37="",T37,S37*40/100+T37*60/100)) | X37: =IFERROR(AVERAGE(V37:W37),"") | AF37: =IFERROR(AVERAGE(Z37:AE37),"") | AH37: =IF(AG37="",AF37,IF(AF37="",AG37,AF37*40/100+AG37*60/100)) | AK37: =IFERROR(AVERAGE(AI37:AJ37),"") | AL37: =IFERROR(AVERAGE(L37,Y37),"") | AM37: =IFERROR(AVERAGE(X37,AK37),"") | AN37: =IFERROR(AVERAGE(S37,AF37),"") | AO37: =IFERROR(AVERAGE(T37,AG37),"") | AP37: =IF(AO37="",AN37,IF(AN37="",AO37,AN37*40/100+AO37*60/100))
... B55: =IF(Şagirdlər!C54="","",Şagirdlər!C54) | C55: =IF(Şagirdlər!D54="","",Şagirdlər!D54) | D55: =IF(Şagirdlər!E54="","",Şagirdlər!E54) | E55: =IF(Şagirdlər!F54="","",Şagirdlər!F54) | F55: =IF(Şagirdlər!G54="","",Şagirdlər!G54) | G55: =IF(Şagirdlər!H54="","",Şagirdlər!H54) | H55: =IF(Şagirdlər!I54="","",Şagirdlər!I54) | I55: =IF(Şagirdlər!J54="","",Şagirdlər!J54) | S55: =IFERROR(AVERAGE(M55:R55),"") | U55: =IF(T55="",S55,IF(S55="",T55,S55*40/100+T55*60/100)) | X55: =IFERROR(AVERAGE(V55:W55),"") | AF55: =IFERROR(AVERAGE(Z55:AE55),"") | AH55: =IF(AG55="",AF55,IF(AF55="",AG55,AF55*40/100+AG55*60/100)) | AK55: =IFERROR(AVERAGE(AI55:AJ55),"") | AL55: =IFERROR(AVERAGE(L55,Y55),"") | AM55: =IFERROR(AVERAGE(X55,AK55),"") | AN55: =IFERROR(AVERAGE(S55,AF55),"") | AO55: =IFERROR(AVERAGE(T55,AG55),"") | AP55: =IF(AO55="",AN55,IF(AN55="",AO55,AN55*40/100+AO55*60/100))
B56: Yekun | C56: =C2 -> 8 | D56: =E2 -> e | E56: =H2 -> Azərbaycan | K56: =IFERROR(AVERAGE(K6:K55),"") -> 63.75 | L56: =IFERROR(AVERAGE(L6:L55),"") | M56: =IFERROR(AVERAGE(M6:M55),"") -> 63.157895 | N56: =IFERROR(AVERAGE(N6:N55),"") -> 61.4 | O56: =IFERROR(AVERAGE(O6:O55),"") -> 58.15 | P56: =IFERROR(AVERAGE(P6:P55),"") | Q56: =IFERROR(AVERAGE(Q6:Q55),"") | R56: =IFERROR(AVERAGE(R6:R55),"") | ... AQ56: =IFERROR(AVERAGE(AQ6:AQ55),"")
B58: Səviyyələr üzrə paylanma (şagird sayı ilə) | J58: (80-100] | K58: =COUNTIFS(K6:K55,">80",K6:K55,"<=100") -> 3 | L58: =COUNTIFS(L6:L55,">80",L6:L55,"<=100") -> 0 | M58: =COUNTIFS(M6:M55,">80",M6:M55,"<=100") -> 2 | N58: =COUNTIFS(N6:N55,">80",N6:N55,"<=100") -> 2 | O58: =COUNTIFS(O6:O55,">80",O6:O55,"<=100") -> 2 | P58: =COUNTIFS(P6:P55,">80",P6:P55,"<=100") -> 0 | Q58: =COUNTIFS(Q6:Q55,">80",Q6:Q55,"<=100") -> 0 | R58: =COUNTIFS(R6:R55,">80",R6:R55,"<=100") -> 0 | ... AQ58: =COUNTIFS(AQ6:AQ55,">80",AQ6:AQ55,"<=100") -> 0
J59: (60-80] | K59: =COUNTIFS(K6:K55,">60",K6:K55,"<=80") -> 8 | L59: =COUNTIFS(L6:L55,">60",L6:L55,"<=80") -> 0 | M59: =COUNTIFS(M6:M55,">60",M6:M55,"<=80") -> 7 | N59: =COUNTIFS(N6:N55,">60",N6:N55,"<=80") -> 6 | O59: =COUNTIFS(O6:O55,">60",O6:O55,"<=80") -> 6 | P59: =COUNTIFS(P6:P55,">60",P6:P55,"<=80") -> 0 | Q59: =COUNTIFS(Q6:Q55,">60",Q6:Q55,"<=80") -> 0 | R59: =COUNTIFS(R6:R55,">60",R6:R55,"<=80") -> 0 | ... AQ59: =COUNTIFS(AQ6:AQ55,">60",AQ6:AQ55,"<=80") -> 0
J60: (30-60] | K60: =COUNTIFS(K6:K55,">30",K6:K55,"<=60") -> 9 | L60: =COUNTIFS(L6:L55,">30",L6:L55,"<=60") -> 0 | M60: =COUNTIFS(M6:M55,">30",M6:M55,"<=60") -> 10 | N60: =COUNTIFS(N6:N55,">30",N6:N55,"<=60") -> 12 | O60: =COUNTIFS(O6:O55,">30",O6:O55,"<=60") -> 12 | P60: =COUNTIFS(P6:P55,">30",P6:P55,"<=60") -> 0 | Q60: =COUNTIFS(Q6:Q55,">30",Q6:Q55,"<=60") -> 0 | R60: =COUNTIFS(R6:R55,">30",R6:R55,"<=60") -> 0 | ... AQ60: =COUNTIFS(AQ6:AQ55,">30",AQ6:AQ55,"<=60") -> 0
J61: [0-30] | K61: =COUNTIFS(K6:K55,">=0",K6:K55,"<=30") -> 0 | L61: =COUNTIFS(L6:L55,">=0",L6:L55,"<=30") -> 0 | M61: =COUNTIFS(M6:M55,">=0",M6:M55,"<=30") -> 0 | N61: =COUNTIFS(N6:N55,">=0",N6:N55,"<=30") -> 0 | O61: =COUNTIFS(O6:O55,">=0",O6:O55,"<=30") -> 0 | P61: =COUNTIFS(P6:P55,">=0",P6:P55,"<=30") -> 0 | Q61: =COUNTIFS(Q6:Q55,">=0",Q6:Q55,"<=30") -> 0 | R61: =COUNTIFS(R6:R55,">=0",R6:R55,"<=30") -> 0 | ... AQ61: =COUNTIFS(AQ6:AQ55,">=0",AQ6:AQ55,"<=30") -> 0
J62: Cəmi | K62: =SUM(K58:K61) -> 20 | L62: =SUM(L58:L61) -> 0 | M62: =SUM(M58:M61) -> 19 | N62: =SUM(N58:N61) -> 20 | O62: =SUM(O58:O61) -> 20 | P62: =SUM(P58:P61) -> 0 | Q62: =SUM(Q58:Q61) -> 0 | R62: =SUM(R58:R61) -> 0 | ... AQ62: =SUM(AQ58:AQ61) -> 0
B63: Səviyyələr üzrə paylanma (%-lə) | J63: =J58 -> (80-100] | K63: =IFERROR(K58*100/K62,"") -> 15 | L63: =IFERROR(L58*100/L62,"") | M63: =IFERROR(M58*100/M62,"") -> 10.526316 | N63: =IFERROR(N58*100/N62,"") -> 10 | O63: =IFERROR(O58*100/O62,"") -> 10 | P63: =IFERROR(P58*100/P62,"") | Q63: =IFERROR(Q58*100/Q62,"") | R63: =IFERROR(R58*100/R62,"") | ... AQ63: =IFERROR(AQ58*100/AQ62,"")
...

Sheet Əd
B1: Fənn üzrə nailiyyətlər cədvəli
B2: Sinif | C2: =Şagirdlər!D2 -> 8 | D2: İndeks | E2: =Şagirdlər!F2 -> e | F2: Bölmə | H2: =Şagirdlər!I2 -> Azərbaycan | K2: Fənn | N2: =Müəllimlər!C5 -> Ədəbiyyat | S2: Fənn müəllimi (soyadı, adı və atasının adı) | AB2: =Müəllimlər!D5 -> Səfərova Elnarə Yəhya | AL2: İllik dərs saatı | AP2: =Müəllimlər!E5 -> 68
B3: UTİS kod | C3: Şagird | F3: Cinsi | G3: Doğum tarixi | J3: İştirak edilməyən dərslərin sayı | K3: Öİ | L3: I yarımil üzrə nailiyyətlər | Y3: II yarımil üzrə nailiyyətlər | AL3: İllik nailiyyətlər
L4: D | M4: Summativ qiymətləndirmələr | V4: Monitorinq | Y4: D | Z4: Summativ qiymətləndirmələr | AI4: Monitorinq | AL4: İllik
C5: soyadı | D5: adı | E5: ata adı | G5: Gün | H5: Ay | I5: İl | K5: Ötən tədris ili üzrə illik nəticə | L5: Diaqnostik-1 | M5: KSQ | N5: KSQ | O5: KSQ | P5: KSQ | Q5: KSQ | R5: KSQ | S5: KSQ orta | T5: BSQ | U5: I yarımil | V5: Monitorinq-1 | W5: Monitorinq-2 | X5: Monitorinq orta | Y5: Diaqnostik-2 | Z5: KSQ | AA5: KSQ | AB5: KSQ | AC5: KSQ | AD5: KSQ | AE5: KSQ | AF5: KSQ orta | AG5: BSQ | AH5: II yarımil | AI5: Monitorinq-3 | AJ5: Monitorinq-4 | AK5: Monitorinq orta | AL5: "Diaqnostik" orta illik | AM5: "Monitorinq" orta illik | AN5: "KSQ orta" orta illik | AO5: "BSQ" orta illik | AP5: İllik | AQ5: Buraxılış imtahanı nəticəsi
B6: =IF(Şagirdlər!C5="","",Şagirdlər!C5) -> 1356498 | C6: =IF(Şagirdlər!D5="","",Şagirdlər!D5) -> Atayev | D6: =IF(Şagirdlər!E5="","",Şagirdlər!E5) -> Ayxan | E6: =IF(Şagirdlər!F5="","",Şagirdlər!F5) -> Zöhrab | F6: =IF(Şagirdlər!G5="","",Şagirdlər!G5) -> k | G6: =IF(Şagirdlər!H5="","",Şagirdlər!H5) -> 19 | H6: =IF(Şagirdlər!I5="","",Şagirdlər!I5) -> 9 | I6: =IF(Şagirdlər!J5="","",Şagirdlər!J5) -> 2007 | J6: 1 | K6: 50 | M6: 40 | N6: 45 | O6: 50 | S6: =IFERROR(AVERAGE(M6:R6),"") -> 45 | U6: =IF(T6="",S6,IF(S6="",T6,S6*40/100+T6*60/100)) -> 45 | X6: =IFERROR(AVERAGE(V6:W6),"") | AF6: =IFERROR(AVERAGE(Z6:AE6),"") | AH6: =IF(AG6="",AF6,IF(AF6="",AG6,AF6*40/100+AG6*60/100)) | AK6: =IFERROR(AVERAGE(AI6:AJ6),"") | AL6: =IFERROR(AVERAGE(L6,Y6),"") | AM6: =IFERROR(AVERAGE(X6,AK6),"") | AN6: =IFERROR(AVERAGE(S6,AF6),"") -> 45 | AO6: =IFERROR(AVERAGE(T6,AG6),"") | AP6: =IF(AO6="",AN6,IF(AN6="",AO6,AN6*40/100+AO6*60/100)) -> 45
B7: =IF(Şagirdlər!C6="","",Şagirdlər!C6) -> 1356404 | C7: =IF(Şagirdlər!D6="","",Şagirdlər!D6) -> Bayramlı | D7: =IF(Şagirdlər!E6="","",Şagirdlər!E6) -> Məhəmməd | E7: =IF(Şagirdlər!F6="","",Şagirdlər!F6) -> Rafiq | F7: =IF(Şagirdlər!G6="","",Şagirdlər!G6) -> k | G7: =IF(Şagirdlər!H6="","",Şagirdlər!H6) -> 22 | H7: =IF(Şagirdlər!I6="","",Şagirdlər!I6) -> 7 | I7: =IF(Şagirdlər!J6="","",Şagirdlər!J6) -> 2008 | K7: 53 | M7: 45 | N7: 50 | O7: 55 | S7: =IFERROR(AVERAGE(M7:R7),"") -> 50 | U7: =IF(T7="",S7,IF(S7="",T7,S7*40/100+T7*60/100)) -> 50 | X7: =IFERROR(AVERAGE(V7:W7),"") | AF7: =IFERROR(AVERAGE(Z7:AE7),"") | AH7: =IF(AG7="",AF7,IF(AF7="",AG7,AF7*40/100+AG7*60/100)) | AK7: =IFERROR(AVERAGE(AI7:AJ7),"") | AL7: =IFERROR(AVERAGE(L7,Y7),"") | AM7: =IFERROR(AVERAGE(X7,AK7),"") | AN7: =IFERROR(AVERAGE(S7,AF7),"") -> 50 | AO7: =IFERROR(AVERAGE(T7,AG7),"") | AP7: =IF(AO7="",AN7,IF(AN7="",AO7,AN7*40/100+AO7*60/100)) -> 50
B8: =IF(Şagirdlər!C7="","",Şagirdlər!C7) -> 1356298 | C8: =IF(Şagirdlər!D7="","",Şagirdlər!D7) -> Əhmədov | D8: =IF(Şagirdlər!E7="","",Şagirdlər!E7) -> Məhəmməd | E8: =IF(Şagirdlər!F7="","",Şagirdlər!F7) -> Şahin | F8: =IF(Şagirdlər!G7="","",Şagirdlər!G7) -> k | G8: =IF(Şagirdlər!H7="","",Şagirdlər!H7) -> 2 | H8: =IF(Şagirdlər!I7="","",Şagirdlər!I7) -> 2 | I8: =IF(Şagirdlər!J7="","",Şagirdlər!J7) -> 2008 | K8: 53 | M8: 35 | N8: 55 | O8: 50 | S8: =IFERROR(AVERAGE(M8:R8),"") -> 46.666667 | U8: =IF(T8="",S8,IF(S8="",T8,S8*40/100+T8*60/100)) -> 46.666667 | X8: =IFERROR(AVERAGE(V8:W8),"") | AF8: =IFERROR(AVERAGE(Z8:AE8),"") | AH8: =IF(AG8="",AF8,IF(AF8="",AG8,AF8*40/100+AG8*60/100)) | AK8: =IFERROR(AVERAGE(AI8:AJ8),"") | AL8: =IFERROR(AVERAGE(L8,Y8),"") | AM8: =IFERROR(AVERAGE(X8,AK8),"") | AN8: =IFERROR(AVERAGE(S8,AF8),"") -> 46.666667 | AO8: =IFERROR(AVERAGE(T8,AG8),"") | AP8: =IF(AO8="",AN8,IF(AN8="",AO8,AN8*40/100+AO8*60/100)) -> 46.666667
B9: =IF(Şagirdlər!C8="","",Şagirdlər!C8) -> 1356179 | C9: =IF(Şagirdlər!D8="","",Şagirdlər!D8) -> Əhmədova | D9: =IF(Şagirdlər!E8="","",Şagirdlər!E8) -> Məleykə | E9: =IF(Şagirdlər!F8="","",Şagirdlər!F8) -> Şahin | F9: =IF(Şagirdlər!G8="","",Şagirdlər!G8) -> q | G9: =IF(Şagirdlər!H8="","",Şagirdlər!H8) -> 17 | H9: =IF(Şagirdlər!I8="","",Şagirdlər!I8) -> 2 | I9: =IF(Şagirdlər!J8="","",Şagirdlər!J8) -> 2007 | K9: 65 | M9: 45 | N9: 60 | O9: 55 | S9: =IFERROR(AVERAGE(M9:R9),"") -> 53.333333 | U9: =IF(T9="",S9,IF(S9="",T9,S9*40/100+T9*60/100)) -> 53.333333 | X9: =IFERROR(AVERAGE(V9:W9),"") | AF9: =IFERROR(AVERAGE(Z9:AE9),"") | AH9: =IF(AG9="",AF9,IF(AF9="",AG9,AF9*40/100+AG9*60/100)) | AK9: =IFERROR(AVERAGE(AI9:AJ9),"") | AL9: =IFERROR(AVERAGE(L9,Y9),"") | AM9: =IFERROR(AVERAGE(X9,AK9),"") | AN9: =IFERROR(AVERAGE(S9,AF9),"") -> 53.333333 | AO9: =IFERROR(AVERAGE(T9,AG9),"") | AP9: =IF(AO9="",AN9,IF(AN9="",AO9,AN9*40/100+AO9*60/100)) -> 53.333333
B10: =IF(Şagirdlər!C9="","",Şagirdlər!C9) -> 1253147 | C10: =IF(Şagirdlər!D9="","",Şagirdlər!D9) -> Əsədov | D10: =IF(Şagirdlər!E9="","",Şagirdlər!E9) -> İlhan | E10: =IF(Şagirdlər!F9="","",Şagirdlər!F9) -> Şükür | F10: =IF(Şagirdlər!G9="","",Şagirdlər!G9) -> k | G10: =IF(Şagirdlər!H9="","",Şagirdlər!H9) -> 9 | H10: =IF(Şagirdlər!I9="","",Şagirdlər!I9) -> 3 | I10: =IF(Şagirdlər!J9="","",Şagirdlər!J9) -> 2008 | K10: 58 | M10: 60 | N10: 60 | O10: 69 | S10: =IFERROR(AVERAGE(M10:R10),"") -> 63 | U10: =IF(T10="",S10,IF(S10="",T10,S10*40/100+T10*60/100)) -> 63 | X10: =IFERROR(AVERAGE(V10:W10),"") | AF10: =IFERROR(AVERAGE(Z10:AE10),"") | AH10: =IF(AG10="",AF10,IF(AF10="",AG10,AF10*40/100+AG10*60/100)) | AK10: =IFERROR(AVERAGE(AI10:AJ10),"") | AL10: =IFERROR(AVERAGE(L10,Y10),"") | AM10: =IFERROR(AVERAGE(X10,AK10),"") | AN10: =IFERROR(AVERAGE(S10,AF10),"") -> 63 | AO10: =IFERROR(AVERAGE(T10,AG10),"") | AP10: =IF(AO10="",AN10,IF(AN10="",AO10,AN10*40/100+AO10*60/100)) -> 63
B11: =IF(Şagirdlər!C10="","",Şagirdlər!C10) -> 1031550 | C11: =IF(Şagirdlər!D10="","",Şagirdlər!D10) -> Hacızadə | D11: =IF(Şagirdlər!E10="","",Şagirdlər!E10) -> Nurcan | E11: =IF(Şagirdlər!F10="","",Şagirdlər!F10) -> Üzeyir | F11: =IF(Şagirdlər!G10="","",Şagirdlər!G10) -> q | G11: =IF(Şagirdlər!H10="","",Şagirdlər!H10) -> 11 | H11: =IF(Şagirdlər!I10="","",Şagirdlər!I10) -> 3 | I11: =IF(Şagirdlər!J10="","",Şagirdlər!J10) -> 2008 | K11: 100 | M11: 95 | N11: 100 | O11: 90 | S11: =IFERROR(AVERAGE(M11:R11),"") -> 95 | U11: =IF(T11="",S11,IF(S11="",T11,S11*40/100+T11*60/100)) -> 95 | X11: =IFERROR(AVERAGE(V11:W11),"") | AF11: =IFERROR(AVERAGE(Z11:AE11),"") | AH11: =IF(AG11="",AF11,IF(AF11="",AG11,AF11*40/100+AG11*60/100)) | AK11: =IFERROR(AVERAGE(AI11:AJ11),"") | AL11: =IFERROR(AVERAGE(L11,Y11),"") | AM11: =IFERROR(AVERAGE(X11,AK11),"") | AN11: =IFERROR(AVERAGE(S11,AF11),"") -> 95 | AO11: =IFERROR(AVERAGE(T11,AG11),"") | AP11: =IF(AO11="",AN11,IF(AN11="",AO11,AN11*40/100+AO11*60/100)) -> 95
B12: =IF(Şagirdlər!C11="","",Şagirdlər!C11) -> 1357286 | C12: =IF(Şagirdlər!D11="","",Şagirdlər!D11) -> Həsənov | D12: =IF(Şagirdlər!E11="","",Şagirdlər!E11) -> Mansur | E12: =IF(Şagirdlər!F11="","",Şagirdlər!F11) -> Elnur | F12: =IF(Şagirdlər!G11="","",Şagirdlər!G11) -> k | G12: =IF(Şagirdlər!H11="","",Şagirdlər!H11) -> 23 | H12: =IF(Şagirdlər!I11="","",Şagirdlər!I11) -> 10 | I12: =IF(Şagirdlər!J11="","",Şagirdlər!J11) -> 2007 | K12: 65 | M12: 85 | N12: 80 | O12: 70 | S12: =IFERROR(AVERAGE(M12:R12),"") -> 78.333333 | U12: =IF(T12="",S12,IF(S12="",T12,S12*40/100+T12*60/100)) -> 78.333333 | X12: =IFERROR(AVERAGE(V12:W12),"") | AF12: =IFERROR(AVERAGE(Z12:AE12),"") | AH12: =IF(AG12="",AF12,IF(AF12="",AG12,AF12*40/100+AG12*60/100)) | AK12: =IFERROR(AVERAGE(AI12:AJ12),"") | AL12: =IFERROR(AVERAGE(L12,Y12),"") | AM12: =IFERROR(AVERAGE(X12,AK12),"") | AN12: =IFERROR(AVERAGE(S12,AF12),"") -> 78.333333 | AO12: =IFERROR(AVERAGE(T12,AG12),"") | AP12: =IF(AO12="",AN12,IF(AN12="",AO12,AN12*40/100+AO12*60/100)) -> 78.333333
B13: =IF(Şagirdlər!C12="","",Şagirdlər!C12) -> 2428416 | C13: =IF(Şagirdlər!D12="","",Şagirdlər!D12) -> Hüseynli | D13: =IF(Şagirdlər!E12="","",Şagirdlər!E12) -> Hüseyn | E13: =IF(Şagirdlər!F12="","",Şagirdlər!F12) -> Vahid | F13: =IF(Şagirdlər!G12="","",Şagirdlər!G12) -> k | G13: =IF(Şagirdlər!H12="","",Şagirdlər!H12) -> 26 | H13: =IF(Şagirdlər!I12="","",Şagirdlər!I12) -> 12 | I13: =IF(Şagirdlər!J12="","",Şagirdlər!J12) -> 2007 | K13: 38 | M13: 35 | N13: 35 | O13: 40 | S13: =IFERROR(AVERAGE(M13:R13),"") -> 36.666667 | U13: =IF(T13="",S13,IF(S13="",T13,S13*40/100+T13*60/100)) -> 36.666667 | X13: =IFERROR(AVERAGE(V13:W13),"") | AF13: =IFERROR(AVERAGE(Z13:AE13),"") | AH13: =IF(AG13="",AF13,IF(AF13="",AG13,AF13*40/100+AG13*60/100)) | AK13: =IFERROR(AVERAGE(AI13:AJ13),"") | AL13: =IFERROR(AVERAGE(L13,Y13),"") | AM13: =IFERROR(AVERAGE(X13,AK13),"") | AN13: =IFERROR(AVERAGE(S13,AF13),"") -> 36.666667 | AO13: =IFERROR(AVERAGE(T13,AG13),"") | AP13: =IF(AO13="",AN13,IF(AN13="",AO13,AN13*40/100+AO13*60/100)) -> 36.666667
B14: =IF(Şagirdlər!C13="","",Şagirdlər!C13) -> 1356063 | C14: =IF(Şagirdlər!D13="","",Şagirdlər!D13) -> Hüseynova | D14: =IF(Şagirdlər!E13="","",Şagirdlər!E13) -> Şəhanə | E14: =IF(Şagirdlər!F13="","",Şagirdlər!F13) -> Teymur | F14: =IF(Şagirdlər!G13="","",Şagirdlər!G13) -> q | G14: =IF(Şagirdlər!H13="","",Şagirdlər!H13) -> 25 | H14: =IF(Şagirdlər!I13="","",Şagirdlər!I13) -> 8 | I14: =IF(Şagirdlər!J13="","",Şagirdlər!J13) -> 2008 | K14: 58 | M14: 75 | N14: 75 | O14: 75 | S14: =IFERROR(AVERAGE(M14:R14),"") -> 75 | U14: =IF(T14="",S14,IF(S14="",T14,S14*40/100+T14*60/100)) -> 75 | X14: =IFERROR(AVERAGE(V14:W14),"") | AF14: =IFERROR(AVERAGE(Z14:AE14),"") | AH14: =IF(AG14="",AF14,IF(AF14="",AG14,AF14*40/100+AG14*60/100)) | AK14: =IFERROR(AVERAGE(AI14:AJ14),"") | AL14: =IFERROR(AVERAGE(L14,Y14),"") | AM14: =IFERROR(AVERAGE(X14,AK14),"") | AN14: =IFERROR(AVERAGE(S14,AF14),"") -> 75 | AO14: =IFERROR(AVERAGE(T14,AG14),"") | AP14: =IF(AO14="",AN14,IF(AN14="",AO14,AN14*40/100+AO14*60/100)) -> 75
B15: =IF(Şagirdlər!C14="","",Şagirdlər!C14) -> 1355916 | C15: =IF(Şagirdlər!D14="","",Şagirdlər!D14) -> Xəlilzadə | D15: =IF(Şagirdlər!E14="","",Şagirdlər!E14) -> Fatimə | E15: =IF(Şagirdlər!F14="","",Şagirdlər!F14) -> Əziz | F15: =IF(Şagirdlər!G14="","",Şagirdlər!G14) -> q | G15: =IF(Şagirdlər!H14="","",Şagirdlər!H14) -> 27 | H15: =IF(Şagirdlər!I14="","",Şagirdlər!I14) -> 11 | I15: =IF(Şagirdlər!J14="","",Şagirdlər!J14) -> 2006 | K15: 56 | M15: 60 | N15: 65 | O15: 70 | S15: =IFERROR(AVERAGE(M15:R15),"") -> 65 | U15: =IF(T15="",S15,IF(S15="",T15,S15*40/100+T15*60/100)) -> 65 | X15: =IFERROR(AVERAGE(V15:W15),"") | AF15: =IFERROR(AVERAGE(Z15:AE15),"") | AH15: =IF(AG15="",AF15,IF(AF15="",AG15,AF15*40/100+AG15*60/100)) | AK15: =IFERROR(AVERAGE(AI15:AJ15),"") | AL15: =IFERROR(AVERAGE(L15,Y15),"") | AM15: =IFERROR(AVERAGE(X15,AK15),"") | AN15: =IFERROR(AVERAGE(S15,AF15),"") -> 65 | AO15: =IFERROR(AVERAGE(T15,AG15),"") | AP15: =IF(AO15="",AN15,IF(AN15="",AO15,AN15*40/100+AO15*60/100)) -> 65
B16: =IF(Şagirdlər!C15="","",Şagirdlər!C15) -> 1355576 | C16: =IF(Şagirdlər!D15="","",Şagirdlər!D15) -> İsayeva | D16: =IF(Şagirdlər!E15="","",Şagirdlər!E15) -> Rəbiyə | E16: =IF(Şagirdlər!F15="","",Şagirdlər!F15) -> Şəhavat | F16: =IF(Şagirdlər!G15="","",Şagirdlər!G15) -> q | G16: =IF(Şagirdlər!H15="","",Şagirdlər!H15) -> 29 | H16: =IF(Şagirdlər!I15="","",Şagirdlər!I15) -> 9 | I16: =IF(Şagirdlər!J15="","",Şagirdlər!J15) -> 2007 | K16: 54 | M16: 65 | N16: 61 | O16: 65 | S16: =IFERROR(AVERAGE(M16:R16),"") -> 63.666667 | U16: =IF(T16="",S16,IF(S16="",T16,S16*40/100+T16*60/100)) -> 63.666667 | X16: =IFERROR(AVERAGE(V16:W16),"") | AF16: =IFERROR(AVERAGE(Z16:AE16),"") | AH16: =IF(AG16="",AF16,IF(AF16="",AG16,AF16*40/100+AG16*60/100)) | AK16: =IFERROR(AVERAGE(AI16:AJ16),"") | AL16: =IFERROR(AVERAGE(L16,Y16),"") | AM16: =IFERROR(AVERAGE(X16,AK16),"") | AN16: =IFERROR(AVERAGE(S16,AF16),"") -> 63.666667 | AO16: =IFERROR(AVERAGE(T16,AG16),"") | AP16: =IF(AO16="",AN16,IF(AN16="",AO16,AN16*40/100+AO16*60/100)) -> 63.666667
B17: =IF(Şagirdlər!C16="","",Şagirdlər!C16) -> 1674572 | C17: =IF(Şagirdlər!D16="","",Şagirdlər!D16) -> Qasımov | D17: =IF(Şagirdlər!E16="","",Şagirdlər!E16) -> Şamil | E17: =IF(Şagirdlər!F16="","",Şagirdlər!F16) -> Ramin | F17: =IF(Şagirdlər!G16="","",Şagirdlər!G16) -> k | G17: =IF(Şagirdlər!H16="","",Şagirdlər!H16) -> 14 | H17: =IF(Şagirdlər!I16="","",Şagirdlər!I16) -> 6 | I17: =IF(Şagirdlər!J16="","",Şagirdlər!J16) -> 2006 | K17: 40 | M17: 35 | N17: 35 | O17: 35 | S17: =IFERROR(AVERAGE(M17:R17),"") -> 35 | U17: =IF(T17="",S17,IF(S17="",T17,S17*40/100+T17*60/100)) -> 35 | X17: =IFERROR(AVERAGE(V17:W17),"") | AF17: =IFERROR(AVERAGE(Z17:AE17),"") | AH17: =IF(AG17="",AF17,IF(AF17="",AG17,AF17*40/100+AG17*60/100)) | AK17: =IFERROR(AVERAGE(AI17:AJ17),"") | AL17: =IFERROR(AVERAGE(L17,Y17),"") | AM17: =IFERROR(AVERAGE(X17,AK17),"") | AN17: =IFERROR(AVERAGE(S17,AF17),"") -> 35 | AO17: =IFERROR(AVERAGE(T17,AG17),"") | AP17: =IF(AO17="",AN17,IF(AN17="",AO17,AN17*40/100+AO17*60/100)) -> 35
B18: =IF(Şagirdlər!C17="","",Şagirdlər!C17) -> 2002217 | C18: =IF(Şagirdlər!D17="","",Şagirdlər!D17) -> Qocayeva | D18: =IF(Şagirdlər!E17="","",Şagirdlər!E17) -> Fatimə | E18: =IF(Şagirdlər!F17="","",Şagirdlər!F17) -> Qüdrət | F18: =IF(Şagirdlər!G17="","",Şagirdlər!G17) -> q | G18: =IF(Şagirdlər!H17="","",Şagirdlər!H17) -> 16 | H18: =IF(Şagirdlər!I17="","",Şagirdlər!I17) -> 6 | I18: =IF(Şagirdlər!J17="","",Şagirdlər!J17) -> 2008 | K18: 65 | M18: 55 | N18: 60 | O18: 55 | S18: =IFERROR(AVERAGE(M18:R18),"") -> 56.666667 | U18: =IF(T18="",S18,IF(S18="",T18,S18*40/100+T18*60/100)) -> 56.666667 | X18: =IFERROR(AVERAGE(V18:W18),"") | AF18: =IFERROR(AVERAGE(Z18:AE18),"") | AH18: =IF(AG18="",AF18,IF(AF18="",AG18,AF18*40/100+AG18*60/100)) | AK18: =IFERROR(AVERAGE(AI18:AJ18),"") | AL18: =IFERROR(AVERAGE(L18,Y18),"") | AM18: =IFERROR(AVERAGE(X18,AK18),"") | AN18: =IFERROR(AVERAGE(S18,AF18),"") -> 56.666667 | AO18: =IFERROR(AVERAGE(T18,AG18),"") | AP18: =IF(AO18="",AN18,IF(AN18="",AO18,AN18*40/100+AO18*60/100)) -> 56.666667
... B25: =IF(Şagirdlər!C24="","",Şagirdlər!C24) -> 1402855 | C25: =IF(Şagirdlər!D24="","",Şagirdlər!D24) -> Məmmədov | D25: =IF(Şagirdlər!E24="","",Şagirdlər!E24) -> Raul | E25: =IF(Şagirdlər!F24="","",Şagirdlər!F24) -> Vügar | F25: =IF(Şagirdlər!G24="","",Şagirdlər!G24) -> k | G25: =IF(Şagirdlər!H24="","",Şagirdlər!H24) -> 9 | H25: =IF(Şagirdlər!I24="","",Şagirdlər!I24) -> 4 | I25: =IF(Şagirdlər!J24="","",Şagirdlər!J24) -> 2008 | K25: 87 | M25: 81 | N25: 85 | O25: 65 | S25: =IFERROR(AVERAGE(M25:R25),"") -> 77 | U25: =IF(T25="",S25,IF(S25="",T25,S25*40/100+T25*60/100)) -> 77 | X25: =IFERROR(AVERAGE(V25:W25),"") | AF25: =IFERROR(AVERAGE(Z25:AE25),"") | AH25: =IF(AG25="",AF25,IF(AF25="",AG25,AF25*40/100+AG25*60/100)) | AK25: =IFERROR(AVERAGE(AI25:AJ25),"") | AL25: =IFERROR(AVERAGE(L25,Y25),"") | AM25: =IFERROR(AVERAGE(X25,AK25),"") | AN25: =IFERROR(AVERAGE(S25,AF25),"") -> 77 | AO25: =IFERROR(AVERAGE(T25,AG25),"") | AP25: =IF(AO25="",AN25,IF(AN25="",AO25,AN25*40/100+AO25*60/100)) -> 77
B26: =IF(Şagirdlər!C25="","",Şagirdlər!C25) | C26: =IF(Şagirdlər!D25="","",Şagirdlər!D25) | D26: =IF(Şagirdlər!E25="","",Şagirdlər!E25) | E26: =IF(Şagirdlər!F25="","",Şagirdlər!F25) | F26: =IF(Şagirdlər!G25="","",Şagirdlər!G25) | G26: =IF(Şagirdlər!H25="","",Şagirdlər!H25) | H26: =IF(Şagirdlər!I25="","",Şagirdlər!I25) | I26: =IF(Şagirdlər!J25="","",Şagirdlər!J25) | S26: =IFERROR(AVERAGE(M26:R26),"") | U26: =IF(T26="",S26,IF(S26="",T26,S26*40/100+T26*60/100)) | X26: =IFERROR(AVERAGE(V26:W26),"") | AF26: =IFERROR(AVERAGE(Z26:AE26),"") | AH26: =IF(AG26="",AF26,IF(AF26="",AG26,AF26*40/100+AG26*60/100)) | AK26: =IFERROR(AVERAGE(AI26:AJ26),"") | AL26: =IFERROR(AVERAGE(L26,Y26),"") | AM26: =IFERROR(AVERAGE(X26,AK26),"") | AN26: =IFERROR(AVERAGE(S26,AF26),"") | AO26: =IFERROR(AVERAGE(T26,AG26),"") | AP26: =IF(AO26="",AN26,IF(AN26="",AO26,AN26*40/100+AO26*60/100))
B27: =IF(Şagirdlər!C26="","",Şagirdlər!C26) | C27: =IF(Şagirdlər!D26="","",Şagirdlər!D26) | D27: =IF(Şagirdlər!E26="","",Şagirdlər!E26) | E27: =IF(Şagirdlər!F26="","",Şagirdlər!F26) | F27: =IF(Şagirdlər!G26="","",Şagirdlər!G26) | G27: =IF(Şagirdlər!H26="","",Şagirdlər!H26) | H27: =IF(Şagirdlər!I26="","",Şagirdlər!I26) | I27: =IF(Şagirdlər!J26="","",Şagirdlər!J26) | S27: =IFERROR(AVERAGE(M27:R27),"") | U27: =IF(T27="",S27,IF(S27="",T27,S27*40/100+T27*60/100)) | X27: =IFERROR(AVERAGE(V27:W27),"") | AF27: =IFERROR(AVERAGE(Z27:AE27),"") | AH27: =IF(AG27="",AF27,IF(AF27="",AG27,AF27*40/100+AG27*60/100)) | AK27: =IFERROR(AVERAGE(AI27:AJ27),"") | AL27: =IFERROR(AVERAGE(L27,Y27),"") | AM27: =IFERROR(AVERAGE(X27,AK27),"") | AN27: =IFERROR(AVERAGE(S27,AF27),"") | AO27: =IFERROR(AVERAGE(T27,AG27),"") | AP27: =IF(AO27="",AN27,IF(AN27="",AO27,AN27*40/100+AO27*60/100))
B28: =IF(Şagirdlər!C27="","",Şagirdlər!C27) | C28: =IF(Şagirdlər!D27="","",Şagirdlər!D27) | D28: =IF(Şagirdlər!E27="","",Şagirdlər!E27) | E28: =IF(Şagirdlər!F27="","",Şagirdlər!F27) | F28: =IF(Şagirdlər!G27="","",Şagirdlər!G27) | G28: =IF(Şagirdlər!H27="","",Şagirdlər!H27) | H28: =IF(Şagirdlər!I27="","",Şagirdlər!I27) | I28: =IF(Şagirdlər!J27="","",Şagirdlər!J27) | S28: =IFERROR(AVERAGE(M28:R28),"") | U28: =IF(T28="",S28,IF(S28="",T28,S28*40/100+T28*60/100)) | X28: =IFERROR(AVERAGE(V28:W28),"") | AF28: =IFERROR(AVERAGE(Z28:AE28),"") | AH28: =IF(AG28="",AF28,IF(AF28="",AG28,AF28*40/100+AG28*60/100)) | AK28: =IFERROR(AVERAGE(AI28:AJ28),"") | AL28: =IFERROR(AVERAGE(L28,Y28),"") | AM28: =IFERROR(AVERAGE(X28,AK28),"") | AN28: =IFERROR(AVERAGE(S28,AF28),"") | AO28: =IFERROR(AVERAGE(T28,AG28),"") | AP28: =IF(AO28="",AN28,IF(AN28="",AO28,AN28*40/100+AO28*60/100))
B29: =IF(Şagirdlər!C28="","",Şagirdlər!C28) | C29: =IF(Şagirdlər!D28="","",Şagirdlər!D28) | D29: =IF(Şagirdlər!E28="","",Şagirdlər!E28) | E29: =IF(Şagirdlər!F28="","",Şagirdlər!F28) | F29: =IF(Şagirdlər!G28="","",Şagirdlər!G28) | G29: =IF(Şagirdlər!H28="","",Şagirdlər!H28) | H29: =IF(Şagirdlər!I28="","",Şagirdlər!I28) | I29: =IF(Şagirdlər!J28="","",Şagirdlər!J28) | S29: =IFERROR(AVERAGE(M29:R29),"") | U29: =IF(T29="",S29,IF(S29="",T29,S29*40/100+T29*60/100)) | X29: =IFERROR(AVERAGE(V29:W29),"") | AF29: =IFERROR(AVERAGE(Z29:AE29),"") | AH29: =IF(AG29="",AF29,IF(AF29="",AG29,AF29*40/100+AG29*60/100)) | AK29: =IFERROR(AVERAGE(AI29:AJ29),"") | AL29: =IFERROR(AVERAGE(L29,Y29),"") | AM29: =IFERROR(AVERAGE(X29,AK29),"") | AN29: =IFERROR(AVERAGE(S29,AF29),"") | AO29: =IFERROR(AVERAGE(T29,AG29),"") | AP29: =IF(AO29="",AN29,IF(AN29="",AO29,AN29*40/100+AO29*60/100))
B30: =IF(Şagirdlər!C29="","",Şagirdlər!C29) | C30: =IF(Şagirdlər!D29="","",Şagirdlər!D29) | D30: =IF(Şagirdlər!E29="","",Şagirdlər!E29) | E30: =IF(Şagirdlər!F29="","",Şagirdlər!F29) | F30: =IF(Şagirdlər!G29="","",Şagirdlər!G29) | G30: =IF(Şagirdlər!H29="","",Şagirdlər!H29) | H30: =IF(Şagirdlər!I29="","",Şagirdlər!I29) | I30: =IF(Şagirdlər!J29="","",Şagirdlər!J29) | S30: =IFERROR(AVERAGE(M30:R30),"") | U30: =IF(T30="",S30,IF(S30="",T30,S30*40/100+T30*60/100)) | X30: =IFERROR(AVERAGE(V30:W30),"") | AF30: =IFERROR(AVERAGE(Z30:AE30),"") | AH30: =IF(AG30="",AF30,IF(AF30="",AG30,AF30*40/100+AG30*60/100)) | AK30: =IFERROR(AVERAGE(AI30:AJ30),"") | AL30: =IFERROR(AVERAGE(L30,Y30),"") | AM30: =IFERROR(AVERAGE(X30,AK30),"") | AN30: =IFERROR(AVERAGE(S30,AF30),"") | AO30: =IFERROR(AVERAGE(T30,AG30),"") | AP30: =IF(AO30="",AN30,IF(AN30="",AO30,AN30*40/100+AO30*60/100))
B31: =IF(Şagirdlər!C30="","",Şagirdlər!C30) | C31: =IF(Şagirdlər!D30="","",Şagirdlər!D30) | D31: =IF(Şagirdlər!E30="","",Şagirdlər!E30) | E31: =IF(Şagirdlər!F30="","",Şagirdlər!F30) | F31: =IF(Şagirdlər!G30="","",Şagirdlər!G30) | G31: =IF(Şagirdlər!H30="","",Şagirdlər!H30) | H31: =IF(Şagirdlər!I30="","",Şagirdlər!I30) | I31: =IF(Şagirdlər!J30="","",Şagirdlər!J30) | S31: =IFERROR(AVERAGE(M31:R31),"") | U31: =IF(T31="",S31,IF(S31="",T31,S31*40/100+T31*60/100)) | X31: =IFERROR(AVERAGE(V31:W31),"") | AF31: =IFERROR(AVERAGE(Z31:AE31),"") | AH31: =IF(AG31="",AF31,IF(AF31="",AG31,AF31*40/100+AG31*60/100)) | AK31: =IFERROR(AVERAGE(AI31:AJ31),"") | AL31: =IFERROR(AVERAGE(L31,Y31),"") | AM31: =IFERROR(AVERAGE(X31,AK31),"") | AN31: =IFERROR(AVERAGE(S31,AF31),"") | AO31: =IFERROR(AVERAGE(T31,AG31),"") | AP31: =IF(AO31="",AN31,IF(AN31="",AO31,AN31*40/100+AO31*60/100))
