Workbook

Sheet Buraxılış 2021
A1: Diqqət! Aşağıdakı qırmızı xanaya təhsil müəssisəsinin UTİS kodunu daxil edin. | B1: Dövlət İmtahan Mərkəzi tərəfindən 2021-ci ildə IX siniflər üzrə keçirilən buraxılış imtahanlarının nəticələri | BP1: Azərbaycan bölməsi | CQ1: Rus bölməsi | DZ1: Ümumi
B2: Bölmələr | C2: Şagird sayı | D2: İştirak etməyən şagird sayı | E2: Tədris dili | F2: Riyaziyyat | G2: Xarici dil | H2: Azərbaycan dili | I2: Orta bal 3 fənn üzrə | J2: Orta faiz 3 fənn üzrə | K2: Orta faiz 4 fənn üzrə | L2: Tədris dili | R2: Riyaziyyat | X2: Xarici dil | AD2: Azərbaycan dili | AJ2: Ümumi 0 bal toplayan şagird sayı | AK2: Ümumi 300 bal toplayan şagird sayı | AL2: BŞTİ üzrə reytinq | AO2: Rayon üzrə reytinq | BP2: Şagird sayı | BQ2: İştirak etməyən şagird sayı | BR2: Tədris dili | BS2: Riyaziyyat | BT2: Xarici dil | BU2: Orta bal 3 fənn üzrə | BV2: Orta faiz 3 fənn üzrə | BW2: Tədris dili | CC2: Riyaziyyat | CI2: Xarici dil | CO2: Ümumi 0 bal toplayan şagird sayı | CP2: Ümumi 300 bal toplayan şagird sayı | CQ2: Şagird sayı | CR2: İştirak etməyən şagird sayı | CS2: Tədris dili | CT2: Riyaziyyat | CU2: Xarici dil | CV2: Azərbaycan dili | CW2: Orta bal 3 fənn üzrə | CX2: Orta faiz 3 fənn üzrə | CY2: Orta faiz 4 fənn üzrə | CZ2: Tədris dili | DF2: Riyaziyyat | DL2: Xarici dil | DR2: Azərbaycan dili | DX2: Ümumi 0 bal toplayan şagird sayı | DY2: Ümumi 300 bal toplayan şagird sayı | DZ2: Şagird sayı | EA2: İştirak etməyən şagird sayı | EB2: Tədris dili | EC2: Riyaziyyat | ED2: Xarici dil | EE2: Azərbaycan dili | EF2: Orta bal 3 fənn üzrə | EG2: Orta faiz 3 fənn üzrə | EH2: Orta faiz 4 fənn üzrə | EI2: Tədris dili | EO2: Riyaziyyat | EU2: Xarici dil | FA2: Azərbaycan dili | FG2: Ümumi 0 bal toplayan şagird sayı | FH2: Ümumi 300 bal toplayan şagird sayı | FI2: BŞTİ üzrə reytinq | FL2: Rayon üzrə reytinq
L3: [0-30] | M3: (30-60] | N3: (60-80] | O3: (80-100] | P3: 0 bal toplayan | Q3: 100 bal toplayan | R3: [0-30] | S3: (30-60] | T3: (60-80] | U3: (80-100] | V3: 0 bal toplayan | W3: 100 bal toplayan | X3: [0-30] | Y3: (30-60] | Z3: (60-80] | AA3: (80-100] | AB3: 0 bal toplayan | AC3: 100 bal toplayan | AD3: [0-30] | AE3: (30-60] | AF3: (60-80] | AG3: (80-100] | AH3: 0 bal toplayan | AI3: 100 bal toplayan | AL3: Azərbaycan bölməsi | AM3: Rus bölməsi | AN3: Ümumi | AO3: Azərbaycan bölməsi | AP3: Rus bölməsi | AQ3: Ümumi | BK3: Təhsil müəssisəsinin UTİS kodu | BL3: Təhsil müəsisəsinin adı | BM3: Təhsil müəssi-səsinin indeksi | BN3: Təhsil müəssisəsinin növü | BO3: Bölmələr | BW3: [0-30] | BX3: (30-60] | BY3: (60-80] | BZ3: (80-100] | CA3: 0 bal toplayan | CB3: 100 bal toplayan | CC3: [0-30] | CD3: (30-60] | CE3: (60-80] | CF3: (80-100] | CG3: 0 bal toplayan | CH3: 100 bal toplayan | CI3: [0-30] | CJ3: (30-60] | CK3: (60-80] | CL3: (80-100] | CM3: 0 bal toplayan | CN3: 100 bal toplayan | CZ3: [0-30] | DA3: (30-60] | DB3: (60-80] | DC3: (80-100] | DD3: 0 bal toplayan | DE3: 100 bal toplayan | DF3: [0-30] | DG3: (30-60] | DH3: (60-80] | DI3: (80-100] | DJ3: 0 bal toplayan | DK3: 100 bal toplayan | DL3: [0-30] | DM3: (30-60] | DN3: (60-80] | DO3: (80-100] | DP3: 0 bal toplayan | DQ3: 100 bal toplayan | DR3: [0-30] | DS3: (30-60] | DT3: (60-80] | DU3: (80-100] | DV3: 0 bal toplayan | DW3: 100 bal toplayan | EI3: [0-30] | EJ3: (30-60] | EK3: (60-80] | EL3: (80-100] | EM3: 0 bal toplayan | EN3: 100 bal toplayan | EO3: [0-30] | EP3: (30-60] | EQ3: (60-80] | ER3: (80-100] | ES3: 0 bal toplayan | ET3: 100 bal toplayan | EU3: [0-30] | EV3: (30-60] | EW3: (60-80] | EX3: (80-100] | EY3: 0 bal toplayan | EZ3: 100 bal toplayan | FA3: [0-30] | FB3: (30-60] | FC3: (60-80] | FD3: (80-100] | FE3: 0 bal toplayan | FF3: 100 bal toplayan | FI3: Azərbaycan bölməsi | FJ3: Rus bölməsi | FK3: Ümumi | FL3: Azərbaycan bölməsi | FM3: Rus bölməsi | FN3: Ümumi | FO3: Azərbaycan | FP3: Rus | FQ3: Ümumi
B4: Azərbaycan | C4: =VLOOKUP($A$4,$BK:$FN,6,0) -> #N/A | D4: =VLOOKUP($A$4,$BK:$FN,7,0) -> #N/A | E4: =VLOOKUP($A$4,$BK:$FN,8,0) -> #N/A | F4: =VLOOKUP($A$4,$BK:$FN,9,0) -> #N/A | G4: =VLOOKUP($A$4,$BK:$FN,10,0) -> #N/A | I4: =VLOOKUP($A$4,$BK:$FN,11,0) -> #N/A | J4: =VLOOKUP($A$4,$BK:$FN,12,0) -> #N/A | L4: =VLOOKUP($A$4,$BK:$FN,13,0) -> #N/A | M4: =VLOOKUP($A$4,$BK:$FN,14,0) -> #N/A | N4: =VLOOKUP($A$4,$BK:$FN,15,0) -> #N/A | O4: =VLOOKUP($A$4,$BK:$FN,16,0) -> #N/A | P4: =VLOOKUP($A$4,$BK:$FN,17,0) -> #N/A | Q4: =VLOOKUP($A$4,$BK:$FN,18,0) -> #N/A | R4: =VLOOKUP($A$4,$BK:$FN,19,0) -> #N/A | S4: =VLOOKUP($A$4,$BK:$FN,20,0) -> #N/A | T4: =VLOOKUP($A$4,$BK:$FN,21,0) -> #N/A | U4: =VLOOKUP($A$4,$BK:$FN,22,0) -> #N/A | V4: =VLOOKUP($A$4,$BK:$FN,23,0) -> #N/A | W4: =VLOOKUP($A$4,$BK:$FN,24,0) -> #N/A | X4: =VLOOKUP($A$4,$BK:$FN,25,0) -> #N/A | Y4: =VLOOKUP($A$4,$BK:$FN,26,0) -> #N/A | Z4: =VLOOKUP($A$4,$BK:$FN,27,0) -> #N/A | AA4: =VLOOKUP($A$4,$BK:$FN,28,0) -> #N/A | AB4: =VLOOKUP($A$4,$BK:$FN,29,0) -> #N/A | AC4: =VLOOKUP($A$4,$BK:$FN,30,0) -> #N/A | AJ4: =VLOOKUP($A$4,$BK:$FN,31,0) -> #N/A | AK4: =VLOOKUP($A$4,$BK:$FN,32,0) -> #N/A | AL4: =VLOOKUP($A$4,$BK:$FN,103,0) -> #N/A | AM4: =VLOOKUP($A$4,$BK:$FN,104,0) -> #N/A | AN4: =VLOOKUP($A$4,$BK:$FN,105,0) -> #N/A | AO4: =VLOOKUP($A$4,$BK:$FN,106,0) -> #N/A | AP4: =VLOOKUP($A$4,$BK:$FN,107,0) -> #N/A | AQ4: =VLOOKUP($A$4,$BK:$FN,108,0) -> #N/A | BK4: 321554343 | BL4: 3 nömrəli tam orta məktəb | BM4: 3 | BN4: tam orta məktəb | BO4: Azərbaycan | BP4: 95 | BQ4: 0 | BR4: 51.357895 | BS4: 45.094737 | BT4: 39.968421 | BU4: 136.42105 | BV4: 45.473684 | BW4: 15 | BX4: 50 | BY4: 24 | BZ4: 6 | CA4: 1 | CB4: 0 | CC4: 28 | CD4: 45 | CE4: 16 | CF4: 6 | CG4: 3 | CH4: 1 | CI4: 39 | CJ4: 38 | CK4: 10 | CL4: 8 | CM4: 1 | CN4: 1 | CO4: 0 | CP4: 0 | CQ4: 0 | CR4: 0 | CZ4: 0 | DA4: 0 | DB4: 0 | DC4: 0 | DD4: 0 | DE4: 0 | DF4: 0 | DG4: 0 | DH4: 0 | DI4: 0 | DJ4: 0 | DK4: 0 | DL4: 0 | DM4: 0 | DN4: 0 | DO4: 0 | DP4: 0 | DQ4: 0 | DR4: 0 | DS4: 0 | DT4: 0 | DU4: 0 | DV4: 0 | DW4: 0 | DX4: 0 | DY4: 0 | DZ4: 95 | EA4: 0 | EB4: 51.357895 | EC4: 45.094737 | ED4: 39.968421 | EF4: 136.42105 | EG4: 45.473684 | EH4: 45.473684 | EI4: 15 | EJ4: 50 | EK4: 24 | EL4: 6 | EM4: 1 | EN4: 0 | EO4: 28 | EP4: 45 | EQ4: 16 | ER4: 6 | ES4: 3 | ET4: 1 | EU4: 39 | EV4: 38 | EW4: 10 | EX4: 8 | EY4: 1 | EZ4: 1 | FA4: 0 | FB4: 0 | FC4: 0 | FD4: 0 | FE4: 0 | FF4: 0 | FG4: 0 | FH4: 0 | FI4: 109 | FK4: 126 | FL4: 6 | FN4: 12 | FO4: 34 | FP4: 19 | FQ4: 34 | FR4: Binəqədi | FS4: 313 | FT4: 134 | FU4: 313
A5: =VLOOKUP(A4,BK:BL,2,0) -> #N/A | B5: Rus | C5: =VLOOKUP($A$4,$BK:$FN,33,0) -> #N/A | D5: =VLOOKUP($A$4,$BK:$FN,34,0) -> #N/A | E5: =VLOOKUP($A$4,$BK:$FN,35,0) -> #N/A | F5: =VLOOKUP($A$4,$BK:$FN,36,0) -> #N/A | G5: =VLOOKUP($A$4,$BK:$FN,37,0) -> #N/A | H5: =VLOOKUP($A$4,$BK:$FN,38,0) -> #N/A | I5: =VLOOKUP($A$4,$BK:$FN,39,0) -> #N/A | J5: =VLOOKUP($A$4,$BK:$FN,40,0) -> #N/A | K5: =VLOOKUP($A$4,$BK:$FN,41,0) -> #N/A | L5: =VLOOKUP($A$4,$BK:$FN,42,0) -> #N/A | M5: =VLOOKUP($A$4,$BK:$FN,43,0) -> #N/A | N5: =VLOOKUP($A$4,$BK:$FN,44,0) -> #N/A | O5: =VLOOKUP($A$4,$BK:$FN,45,0) -> #N/A | P5: =VLOOKUP($A$4,$BK:$FN,46,0) -> #N/A | Q5: =VLOOKUP($A$4,$BK:$FN,47,0) -> #N/A | R5: =VLOOKUP($A$4,$BK:$FN,48,0) -> #N/A | S5: =VLOOKUP($A$4,$BK:$FN,49,0) -> #N/A | T5: =VLOOKUP($A$4,$BK:$FN,50,0) -> #N/A | U5: =VLOOKUP($A$4,$BK:$FN,51,0) -> #N/A | V5: =VLOOKUP($A$4,$BK:$FN,52,0) -> #N/A | W5: =VLOOKUP($A$4,$BK:$FN,53,0) -> #N/A | X5: =VLOOKUP($A$4,$BK:$FN,54,0) -> #N/A | Y5: =VLOOKUP($A$4,$BK:$FN,55,0) -> #N/A | Z5: =VLOOKUP($A$4,$BK:$FN,56,0) -> #N/A | AA5: =VLOOKUP($A$4,$BK:$FN,57,0) -> #N/A | AB5: =VLOOKUP($A$4,$BK:$FN,58,0) -> #N/A | AC5: =VLOOKUP($A$4,$BK:$FN,59,0) -> #N/A | AD5: =VLOOKUP($A$4,$BK:$FN,60,0) -> #N/A | AE5: =VLOOKUP($A$4,$BK:$FN,61,0) -> #N/A | AF5: =VLOOKUP($A$4,$BK:$FN,62,0) -> #N/A | AG5: =VLOOKUP($A$4,$BK:$FN,63,0) -> #N/A | AH5: =VLOOKUP($A$4,$BK:$FN,64,0) -> #N/A | AI5: =VLOOKUP($A$4,$BK:$FN,65,0) -> #N/A | AJ5: =VLOOKUP($A$4,$BK:$FN,66,0) -> #N/A | AK5: =VLOOKUP($A$4,$BK:$FN,67,0) -> #N/A | BL5: Uşaq-Gənclər İnkişaf Mərkəzi | BM5: 6 | BN5: UGİM | BO5: Azərbaycan, rus | BP5: 0 | BQ5: 0 | BW5: 0 | BX5: 0 | BY5: 0 | BZ5: 0 | CA5: 0 | CB5: 0 | CC5: 0 | CD5: 0 | CE5: 0 | CF5: 0 | CG5: 0 | CH5: 0 | CI5: 0 | CJ5: 0 | CK5: 0 | CL5: 0 | CM5: 0 | CN5: 0 | CO5: 0 | CP5: 0 | CQ5: 0 | CR5: 0 | CZ5: 0 | DA5: 0 | DB5: 0 | DC5: 0 | DD5: 0 | DE5: 0 | DF5: 0 | DG5: 0 | DH5: 0 | DI5: 0 | DJ5: 0 | DK5: 0 | DL5: 0 | DM5: 0 | DN5: 0 | DO5: 0 | DP5: 0 | DQ5: 0 | DR5: 0 | DS5: 0 | DT5: 0 | DU5: 0 | DV5: 0 | DW5: 0 | DX5: 0 | DY5: 0 | DZ5: 0 | EA5: 0 | EI5: 0 | EJ5: 0 | EK5: 0 | EL5: 0 | EM5: 0 | EN5: 0 | EO5: 0 | EP5: 0 | EQ5: 0 | ER5: 0 | ES5: 0 | ET5: 0 | EU5: 0 | EV5: 0 | EW5: 0 | EX5: 0 | EY5: 0 | EZ5: 0 | FA5: 0 | FB5: 0 | FC5: 0 | FD5: 0 | FE5: 0 | FF5: 0 | FG5: 0 | FH5: 0 | FO5: 34 | FP5: 19 | FQ5: 34 | FR5: Binəqədi | FS5: 313 | FT5: 134 | FU5: 313
B6: Ümumi | C6: =VLOOKUP($A$4,$BK:$FN,68,0) -> #N/A | D6: =VLOOKUP($A$4,$BK:$FN,69,0) -> #N/A | E6: =VLOOKUP($A$4,$BK:$FN,70,0) -> #N/A | F6: =VLOOKUP($A$4,$BK:$FN,71,0) -> #N/A | G6: =VLOOKUP($A$4,$BK:$FN,72,0) -> #N/A | H6: =VLOOKUP($A$4,$BK:$FN,73,0) -> #N/A | I6: =VLOOKUP($A$4,$BK:$FN,74,0) -> #N/A | J6: =VLOOKUP($A$4,$BK:$FN,75,0) -> #N/A | K6: =VLOOKUP($A$4,$BK:$FN,76,0) -> #N/A | L6: =VLOOKUP($A$4,$BK:$FN,77,0) -> #N/A | M6: =VLOOKUP($A$4,$BK:$FN,78,0) -> #N/A | N6: =VLOOKUP($A$4,$BK:$FN,79,0) -> #N/A | O6: =VLOOKUP($A$4,$BK:$FN,80,0) -> #N/A | P6: =VLOOKUP($A$4,$BK:$FN,81,0) -> #N/A | Q6: =VLOOKUP($A$4,$BK:$FN,82,0) -> #N/A | R6: =VLOOKUP($A$4,$BK:$FN,83,0) -> #N/A | S6: =VLOOKUP($A$4,$BK:$FN,84,0) -> #N/A | T6: =VLOOKUP($A$4,$BK:$FN,85,0) -> #N/A | U6: =VLOOKUP($A$4,$BK:$FN,86,0) -> #N/A | V6: =VLOOKUP($A$4,$BK:$FN,87,0) -> #N/A | W6: =VLOOKUP($A$4,$BK:$FN,88,0) -> #N/A | X6: =VLOOKUP($A$4,$BK:$FN,89,0) -> #N/A | Y6: =VLOOKUP($A$4,$BK:$FN,90,0) -> #N/A | Z6: =VLOOKUP($A$4,$BK:$FN,91,0) -> #N/A | AA6: =VLOOKUP($A$4,$BK:$FN,92,0) -> #N/A | AB6: =VLOOKUP($A$4,$BK:$FN,93,0) -> #N/A | AC6: =VLOOKUP($A$4,$BK:$FN,94,0) -> #N/A | AD6: =VLOOKUP($A$4,$BK:$FN,95,0) -> #N/A | AE6: =VLOOKUP($A$4,$BK:$FN,96,0) -> #N/A | AF6: =VLOOKUP($A$4,$BK:$FN,97,0) -> #N/A | AG6: =VLOOKUP($A$4,$BK:$FN,98,0) -> #N/A | AH6: =VLOOKUP($A$4,$BK:$FN,99,0) -> #N/A | AI6: =VLOOKUP($A$4,$BK:$FN,100,0) -> #N/A | AJ6: =VLOOKUP($A$4,$BK:$FN,101,0) -> #N/A | AK6: =VLOOKUP($A$4,$BK:$FN,102,0) -> #N/A | BK6: 747538865 | BL6: 30 nömrəli tam orta məktəb | BM6: 30 | BN6: tam orta məktəb | BO6: Azərbaycan, rus | BP6: 42 | BQ6: 0 | BR6: 42.904762 | BS6: 34.095238 | BT6: 32.690476 | BU6: 109.69048 | BV6: 36.563492 | BW6: 15 | BX6: 20 | BY6: 7 | BZ6: 0 | CA6: 0 | CB6: 0 | CC6: 19 | CD6: 20 | CE6: 3 | CF6: 0 | CG6: 0 | CH6: 0 | CI6: 24 | CJ6: 15 | CK6: 2 | CL6: 1 | CM6: 0 | CN6: 0 | CO6: 0 | CP6: 0 | CQ6: 18 | CR6: 0 | CS6: 57.055556 | CT6: 45.555556 | CU6: 47.333333 | CV6: 57.222222 | CW6: 149.94444 | CX6: 49.981481 | CY6: 51.791667 | CZ6: 0 | DA6: 11 | DB6: 6 | DC6: 1 | DD6: 0 | DE6: 0 | DF6: 3 | DG6: 11 | DH6: 1 | DI6: 3 | DJ6: 0 | DK6: 0 | DL6: 7 | DM6: 5 | DN6: 3 | DO6: 3 | DP6: 0 | DQ6: 0 | DR6: 1 | DS6: 11 | DT6: 5 | DU6: 1 | DV6: 0 | DW6: 0 | DX6: 0 | DY6: 0 | DZ6: 60 | EA6: 0 | EB6: 47.15 | EC6: 37.533333 | ED6: 37.083333 | EE6: 57.222222 | EF6: 121.76667 | EG6: 40.588889 | EH6: 41.131944 | EI6: 15 | EJ6: 31 | EK6: 13 | EL6: 1 | EM6: 0 | EN6: 0 | EO6: 22 | EP6: 31 | EQ6: 4 | ER6: 3 | ES6: 0 | ET6: 0 | EU6: 31 | EV6: 20 | EW6: 5 | EX6: 4 | EY6: 0 | EZ6: 0 | FA6: 1 | FB6: 11 | FC6: 5 | FD6: 1 | FE6: 0 | FF6: 0 | FG6: 0 | FH6: 0 | FI6: 243 | FJ6: 67 | FK6: 194 | FL6: 27 | FM6: 11 | FN6: 20 | FO6: 34 | FP6: 19 | FQ6: 34 | FR6: Binəqədi | FS6: 313 | FT6: 134 | FU6: 313
A7: Bakı Şəhəri üzrə Təhsil İdarəsi | C7: 34096 | D7: 146 | E7: =VLOOKUP($A$7,$BK:$FN,70,0) -> 51.190751 | F7: =VLOOKUP($A$7,$BK:$FN,71,0) -> 42.021915 | G7: =VLOOKUP($A$7,$BK:$FN,72,0) -> 41.307944 | H7: =VLOOKUP($A$7,$BK:$FN,73,0) -> 52.308901 | I7: =VLOOKUP($A$7,$BK:$FN,74,0) -> 134.50601 | J7: =VLOOKUP($A$7,$BK:$FN,75,0) -> 44.837477 | K7: =VLOOKUP($A$7,$BK:$FN,76,0) -> 44.840758 | AL7: =VLOOKUP($A$4,$BK:$FU,113,0) -> #N/A | AM7: =VLOOKUP($A$4,$BK:$FU,114,0) -> #N/A | AN7: =VLOOKUP($A$4,$BK:$FU,115,0) -> #N/A | AO7: =VLOOKUP($A$4,$BK:$FQ,109,0) -> #N/A | AP7: =VLOOKUP($A$4,$BK:$FQ,110,0) -> #N/A | AQ7: =VLOOKUP($A$4,$BK:$FQ,111,0) -> #N/A | BK7: 466471470 | BL7: 83 nömrəli məktəb-lisey | BM7: 83 | BN7: məktəb-lisey | BO7: Azərbaycan, rus | BP7: 99 | BQ7: 0 | BR7: 54.828283 | BS7: 49.050505 | BT7: 46.474747 | BU7: 150.35354 | BV7: 50.117845 | BW7: 11 | BX7: 54 | BY7: 25 | BZ7: 9 | CA7: 0 | CB7: 0 | CC7: 23 | CD7: 49 | CE7: 20 | CF7: 7 | CG7: 0 | CH7: 1 | CI7: 38 | CJ7: 34 | CK7: 17 | CL7: 10 | CM7: 0 | CN7: 1 | CO7: 0 | CP7: 0 | CQ7: 64 | CR7: 0 | CS7: 58.59375 | CT7: 47.625 | CU7: 52.984375 | CV7: 59.265625 | CW7: 159.20312 | CX7: 53.067708 | CY7: 54.617188 | CZ7: 8 | DA7: 25 | DB7: 22 | DC7: 9 | DD7: 0 | DE7: 0 | DF7: 18 | DG7: 30 | DH7: 8 | DI7: 8 | DJ7: 0 | DK7: 0 | DL7: 18 | DM7: 19 | DN7: 14 | DO7: 13 | DP7: 0 | DQ7: 1 | DR7: 6 | DS7: 24 | DT7: 29 | DU7: 5 | DV7: 0 | DW7: 0 | DX7: 0 | DY7: 0 | DZ7: 163 | EA7: 0 | EB7: 56.306748 | EC7: 48.490798 | ED7: 49.030675 | EE7: 59.265625 | EF7: 153.82822 | EG7: 51.276074 | EH7: 51.884458 | EI7: 19 | EJ7: 79 | EK7: 47 | EL7: 18 | EM7: 0 | EN7: 0 | EO7: 41 | EP7: 79 | EQ7: 28 | ER7: 15 | ES7: 0 | ET7: 1 | EU7: 56 | EV7: 53 | EW7: 31 | EX7: 23 | EY7: 0 | EZ7: 2 | FA7: 6 | FB7: 24 | FC7: 29 | FD7: 5 | FE7: 0 | FF7: 0 | FG7: 0 | FH7: 0 | FI7: 55 | FJ7: 42 | FK7: 55 | FL7: 2 | FM7: 6 | FN7: 2 | FO7: 34 | FP7: 19 | FQ7: 34 | FR7: Binəqədi | FS7: 313 | FT7: 134 | FU7: 313
BK8: 233824167 | BL8: 99 nömrəli tam orta məktəb | BM8: 99 | BN8: tam orta məktəb | BO8: Azərbaycan | BP8: 150 | BQ8: 8 | BR8: 43.802817 | BS8: 39.014085 | BT8: 32.211268 | BU8: 115.02817 | BV8: 38.342723 | BW8: 46 | BX8: 57 | BY8: 35 | BZ8: 4 | CA8: 4 | CB8: 0 | CC8: 64 | CD8: 49 | CE8: 19 | CF8: 10 | CG8: 6 | CH8: 1 | CI8: 84 | CJ8: 45 | CK8: 11 | CL8: 2 | CM8: 6 | CN8: 0 | CO8: 4 | CP8: 0 | CQ8: 0 | CR8: 0 | CZ8: 0 | DA8: 0 | DB8: 0 | DC8: 0 | DD8: 0 | DE8: 0 | DF8: 0 | DG8: 0 | DH8: 0 | DI8: 0 | DJ8: 0 | DK8: 0 | DL8: 0 | DM8: 0 | DN8: 0 | DO8: 0 | DP8: 0 | DQ8: 0 | DR8: 0 | DS8: 0 | DT8: 0 | DU8: 0 | DV8: 0 | DW8: 0 | DX8: 0 | DY8: 0 | DZ8: 150 | EA8: 8 | EB8: 43.802817 | EC8: 39.014085 | ED8: 32.211268 | EF8: 115.02817 | EG8: 38.342723 | EH8: 38.342723 | EI8: 46 | EJ8: 57 | EK8: 35 | EL8: 4 | EM8: 4 | EN8: 0 | EO8: 64 | EP8: 49 | EQ8: 19 | ER8: 10 | ES8: 6 | ET8: 1 | EU8: 84 | EV8: 45 | EW8: 11 | EX8: 2 | EY8: 6 | EZ8: 0 | FA8: 0 | FB8: 0 | FC8: 0 | FD8: 0 | FE8: 0 | FF8: 0 | FG8: 4 | FH8: 0 | FI8: 218 | FK8: 224 | FL8: 22 | FN8: 25 | FO8: 34 | FP8: 19 | FQ8: 34 | FR8: Binəqədi | FS8: 313 | FT8: 134 | FU8: 313
BK9: 509986830 | BL9: 100 nömrəli tam orta məktəb | BM9: 100 | BN9: tam orta məktəb | BO9: Azərbaycan, rus | BP9: 105 | BQ9: 0 | BR9: 42.771429 | BS9: 37.904762 | BT9: 34.342857 | BU9: 115.01905 | BV9: 38.339683 | BW9: 34 | BX9: 49 | BY9: 20 | BZ9: 2 | CA9: 0 | CB9: 0 | CC9: 46 | CD9: 42 | CE9: 11 | CF9: 6 | CG9: 0 | CH9: 3 | CI9: 57 | CJ9: 38 | CK9: 3 | CL9: 7 | CM9: 0 | CN9: 1 | CO9: 0 | CP9: 0 | CQ9: 34 | CR9: 0 | CS9: 59.676471 | CT9: 45.764706 | CU9: 58.352941 | CV9: 60.411765 | CW9: 163.79412 | CX9: 54.598039 | CY9: 56.051471 | CZ9: 1 | DA9: 16 | DB9: 15 | DC9: 2 | DD9: 0 | DE9: 0 | DF9: 9 | DG9: 17 | DH9: 5 | DI9: 3 | DJ9: 0 | DK9: 0 | DL9: 4 | DM9: 12 | DN9: 9 | DO9: 9 | DP9: 0 | DQ9: 0 | DR9: 3 | DS9: 11 | DT9: 17 | DU9: 3 | DV9: 0 | DW9: 0 | DX9: 0 | DY9: 0 | DZ9: 139 | EA9: 0 | EB9: 46.906475 | EC9: 39.827338 | ED9: 40.215827 | EE9: 60.411765 | EF9: 126.94964 | EG9: 42.316547 | EH9: 42.672062 | EI9: 35 | EJ9: 65 | EK9: 35 | EL9: 4 | EM9: 0 | EN9: 0 | EO9: 55 | EP9: 59 | EQ9: 16 | ER9: 9 | ES9: 0 | ET9: 3 | EU9: 61 | EV9: 50 | EW9: 12 | EX9: 16 | EY9: 0 | EZ9: 1 | FA9: 3 | FB9: 11 | FC9: 17 | FD9: 3 | FE9: 0 | FF9: 0 | FG9: 0 | FH9: 0 | FI9: 219 | FJ9: 34 | FK9: 168 | FL9: 23 | FM9: 4 | FN9: 17 | FO9: 34 | FP9: 19 | FQ9: 34 | FR9: Binəqədi | FS9: 313 | FT9: 134 | FU9: 313
BK10: 152156460 | BL10: 102 nömrəli tam orta məktəb | BM10: 102 | BN10: tam orta məktəb | BO10: Azərbaycan, rus | BP10: 49 | BQ10: 1 | BR10: 49.791667 | BS10: 43.25 | BT10: 41.520833 | BU10: 134.5625 | BV10: 44.854167 | BW10: 12 | BX10: 21 | BY10: 14 | BZ10: 1 | CA10: 0 | CB10: 0 | CC10: 11 | CD10: 30 | CE10: 4 | CF10: 3 | CG10: 0 | CH10: 0 | CI10: 23 | CJ10: 15 | CK10: 6 | CL10: 4 | CM10: 0 | CN10: 0 | CO10: 0 | CP10: 0 | CQ10: 72 | CR10: 0 | CS10: 63.527778 | CT10: 51.277778 | CU10: 55.430556 | CV10: 59.652778 | CW10: 170.23611 | CX10: 56.74537 | CY10: 57.472222 | CZ10: 5 | DA10: 24 | DB10: 31 | DC10: 12 | DD10: 0 | DE10: 0 | DF10: 16 | DG10: 35 | DH10: 12 | DI10: 9 | DJ10: 0 | DK10: 0 | DL10: 20 | DM10: 21 | DN10: 12 | DO10: 19 | DP10: 0 | DQ10: 4 | DR10: 9 | DS10: 29 | DT10: 24 | DU10: 10 | DV10: 0 | DW10: 1 | DX10: 0 | DY10: 0 | DZ10: 121 | EA10: 1 | EB10: 58.033333 | EC10: 48.066667 | ED10: 49.866667 | EE10: 59.652778 | EF10: 155.96667 | EG10: 51.988889 | EH10: 52.425 | EI10: 17 | EJ10: 45 | EK10: 45 | EL10: 13 | EM10: 0 | EN10: 0 | EO10: 27 | EP10: 65 | EQ10: 16 | ER10: 12 | ES10: 0 | ET10: 0 | EU10: 43 | EV10: 36 | EW10: 18 | EX10: 23 | EY10: 0 | EZ10: 4 | FA10: 9 | FB10: 29 | FC10: 24 | FD10: 10 | FE10: 0 | FF10: 1 | FG10: 0 | FH10: 0 | FI10: 115 | FJ10: 21 | FK10: 49 | FL10: 7 | FM10: 1 | FN10: 1 | FO10: 34 | FP10: 19 | FQ10: 34 | FR10: Binəqədi | FS10: 313 | FT10: 134 | FU10: 313
BK11: 951827026 | BL11: 103 nömrəli tam orta məktəb | BM11: 103 | BN11: tam orta məktəb | BO11: Azərbaycan | BP11: 95 | BQ11: 0 | BR11: 39.884211 | BS11: 32.884211 | BT11: 27.768421 | BU11: 100.53684 | BV11: 33.512281 | BW11: 41 | BX11: 34 | BY11: 19 | BZ11: 1 | CA11: 2 | CB11: 0 | CC11: 51 | CD11: 33 | CE11: 9 | CF11: 2 | CG11: 3 | CH11: 0 | CI11: 66 | CJ11: 23 | CK11: 6 | CL11: 0 | CM11: 2 | CN11: 0 | CO11: 2 | CP11: 0 | CQ11: 0 | CR11: 0 | CZ11: 0 | DA11: 0 | DB11: 0 | DC11: 0 | DD11: 0 | DE11: 0 | DF11: 0 | DG11: 0 | DH11: 0 | DI11: 0 | DJ11: 0 | DK11: 0 | DL11: 0 | DM11: 0 | DN11: 0 | DO11: 0 | DP11: 0 | DQ11: 0 | DR11: 0 | DS11: 0 | DT11: 0 | DU11: 0 | DV11: 0 | DW11: 0 | DX11: 0 | DY11: 0 | DZ11: 95 | EA11: 0 | EB11: 39.884211 | EC11: 32.884211 | ED11: 27.768421 | EF11: 100.53684 | EG11: 33.512281 | EH11: 33.512281 | EI11: 41 | EJ11: 34 | EK11: 19 | EL11: 1 | EM11: 2 | EN11: 0 | EO11: 51 | EP11: 33 | EQ11: 9 | ER11: 2 | ES11: 3 | ET11: 0 | EU11: 66 | EV11: 23 | EW11: 6 | EX11: 0 | EY11: 2 | EZ11: 0 | FA11: 0 | FB11: 0 | FC11: 0 | FD11: 0 | FE11: 0 | FF11: 0 | FG11: 2 | FH11: 0 | FI11: 269 | FK11: 273 | FL11: 33 | FN11: 33 | FO11: 34 | FP11: 19 | FQ11: 34 | FR11: Binəqədi | FS11: 313 | FT11: 134 | FU11: 313
BL12: 115 saylı xüsusi əyani-qiyabi tam orta məktəb-axşam məktəbi (11 saylı CÇM) | BM12: 115 | BN12: XƏQTOM | BO12: Azərbaycan, rus | BP12: 3 | BQ12: 0 | BR12: 36.666667 | BS12: 44 | BT12: 34.333333 | BU12: 115 | BV12: 38.333333 | BW12: 1 | BX12: 2 | BY12: 0 | BZ12: 0 | CA12: 0 | CB12: 0 | CC12: 0 | CD12: 3 | CE12: 0 | CF12: 0 | CG12: 0 | CH12: 0 | CI12: 0 | CJ12: 3 | CK12: 0 | CL12: 0 | CM12: 0 | CN12: 0 | CO12: 0 | CP12: 0 | CQ12: 0 | CR12: 0 | CZ12: 0 | DA12: 0 | DB12: 0 | DC12: 0 | DD12: 0 | DE12: 0 | DF12: 0 | DG12: 0 | DH12: 0 | DI12: 0 | DJ12: 0 | DK12: 0 | DL12: 0 | DM12: 0 | DN12: 0 | DO12: 0 | DP12: 0 | DQ12: 0 | DR12: 0 | DS12: 0 | DT12: 0 | DU12: 0 | DV12: 0 | DW12: 0 | DX12: 0 | DY12: 0 | DZ12: 3 | EA12: 0 | EB12: 36.666667 | EC12: 44 | ED12: 34.333333 | EF12: 115 | EG12: 38.333333 | EH12: 38.333333 | EI12: 1 | EJ12: 2 | EK12: 0 | EL12: 0 | EM12: 0 | EN12: 0 | EO12: 0 | EP12: 3 | EQ12: 0 | ER12: 0 | ES12: 0 | ET12: 0 | EU12: 0 | EV12: 3 | EW12: 0 | EX12: 0 | EY12: 0 | EZ12: 0 | FA12: 0 | FB12: 0 | FC12: 0 | FD12: 0 | FE12: 0 | FF12: 0 | FG12: 0 | FH12: 0 | FI12: 220 | FK12: 225 | FL12: 24 | FN12: 26 | FO12: 34 | FP12: 19 | FQ12: 34 | FR12: Binəqədi | FS12: 313 | FT12: 134 | FU12: 313
BK13: 542867191 | BL13: 115 nömrəli tam orta məktəb | BM13: 115 | BN13: tam orta məktəb | BO13: Azərbaycan, rus | BP13: 118 | BQ13: 0 | BR13: 51.016949 | BS13: 39.966102 | BT13: 41.364407 | BU13: 132.34746 | BV13: 44.115819 | BW13: 21 | BX13: 61 | BY13: 30 | BZ13: 6 | CA13: 2 | CB13: 0 | CC13: 47 | CD13: 49 | CE13: 17 | CF13: 5 | CG13: 3 | CH13: 0 | CI13: 47 | CJ13: 45 | CK13: 19 | CL13: 7 | CM13: 2 | CN13: 0 | CO13: 2 | CP13: 0 | CQ13: 26 | CR13: 0 | CS13: 56.846154 | CT13: 43.230769 | CU13: 57.230769 | CV13: 54.384615 | CW13: 157.30769 | CX13: 52.435897 | CY13: 52.923077 | CZ13: 3 | DA13: 12 | DB13: 8 | DC13: 3 | DD13: 0 | DE13: 0 | DF13: 9 | DG13: 12 | DH13: 3 | DI13: 2 | DJ13: 0 | DK13: 0 | DL13: 7 | DM13: 6 | DN13: 6 | DO13: 7 | DP13: 0 | DQ13: 1 | DR13: 4 | DS13: 11 | DT13: 11 | DU13: 0 | DV13: 0 | DW13: 0 | DX13: 0 | DY13: 0 | DZ13: 144 | EA13: 0 | EB13: 52.069444 | EC13: 40.555556 | ED13: 44.229167 | EE13: 54.384615 | EF13: 136.85417 | EG13: 45.618056 | EH13: 45.706019 | EI13: 24 | EJ13: 73 | EK13: 38 | EL13: 9 | EM13: 2 | EN13: 0 | EO13: 56 | EP13: 61 | EQ13: 20 | ER13: 7 | ES13: 3 | ET13: 0 | EU13: 54 | EV13: 51 | EW13: 25 | EX13: 14 | EY13: 2 | EZ13: 1 | FA13: 4 | FB13: 11 | FC13: 11 | FD13: 0 | FE13: 0 | FF13: 0 | FG13: 2 | FH13: 0 | FI13: 130 | FJ13: 46 | FK13: 124 | FL13: 12 | FM13: 7 | FN13: 10 | FO13: 34 | FP13: 19 | FQ13: 34 | FR13: Binəqədi | FS13: 313 | FT13: 134 | FU13: 313
BK14: 180574458 | BL14: 126 nömrəli tam orta məktəb | BM14: 126 | BN14: TN | BO14: Azərbaycan, rus | BP14: 65 | BQ14: 0 | BR14: 41.292308 | BS14: 33.969231 | BT14: 32.184615 | BU14: 107.44615 | BV14: 35.815385 | BW14: 23 | BX14: 31 | BY14: 9 | BZ14: 2 | CA14: 1 | CB14: 0 | CC14: 32 | CD14: 27 | CE14: 3 | CF14: 3 | CG14: 1 | CH14: 0 | CI14: 40 | CJ14: 18 | CK14: 6 | CL14: 1 | CM14: 1 | CN14: 0 | CO14: 1 | CP14: 0 | CQ14: 19 | CR14: 0 | CS14: 56.842105 | CT14: 45.894737 | CU14: 46.263158 | CV14: 51.578947 | CW14: 149 | CX14: 49.666667 | CY14: 50.144737 | CZ14: 3 | DA14: 6 | DB14: 7 | DC14: 3 | DD14: 0 | DE14: 0 | DF14: 5 | DG14: 9 | DH14: 3 | DI14: 2 | DJ14: 0 | DK14: 1 | DL14: 8 | DM14: 4 | DN14: 6 | DO14: 1 | DP14: 0 | DQ14: 0 | DR14: 3 | DS14: 10 | DT14: 5 | DU14: 1 | DV14: 0 | DW14: 0 | DX14: 0 | DY14: 0 | DZ14: 84 | EA14: 0 | EB14: 44.809524 | EC14: 36.666667 | ED14: 35.369048 | EE14: 51.578947 | EF14: 116.84524 | EG14: 38.948413 | EH14: 39.056548 | EI14: 26 | EJ14: 37 | EK14: 16 | EL14: 5 | EM14: 1 | EN14: 0 | EO14: 37 | EP14: 36 | EQ14: 6 | ER14: 5 | ES14: 1 | ET14: 1 | EU14: 48 | EV14: 22 | EW14: 12 | EX14: 2 | EY14: 1 | EZ14: 0 | FA14: 3 | FB14: 10 | FC14: 5 | FD14: 1 | FE14: 0 | FF14: 0 | FG14: 1 | FH14: 0 | FI14: 252 | FJ14: 70 | FK14: 218 | FL14: 29 | FM14: 13 | FN14: 24 | FO14: 34 | FP14: 19 | FQ14: 34 | FR14: Binəqədi | FS14: 313 | FT14: 134 | FU14: 313
BK15: 150425330 | BL15: 135 nömrəli tam orta məktəb | BM15: 135 | BN15: tam orta məktəb | BO15: Azərbaycan | BP15: 49 | BQ15: 0 | BR15: 45.693878 | BS15: 38.122449 | BT15: 42.795918 | BU15: 126.61224 | BV15: 42.204082 | BW15: 14 | BX15: 23 | BY15: 11 | BZ15: 1 | CA15: 1 | CB15: 0 | CC15: 21 | CD15: 19 | CE15: 8 | CF15: 1 | CG15: 2 | CH15: 0 | CI15: 19 | CJ15: 20 | CK15: 5 | CL15: 5 | CM15: 1 | CN15: 0 | CO15: 1 | CP15: 0 | CQ15: 0 | CR15: 0 | CZ15: 0 | DA15: 0 | DB15: 0 | DC15: 0 | DD15: 0 | DE15: 0 | DF15: 0 | DG15: 0 | DH15: 0 | DI15: 0 | DJ15: 0 | DK15: 0 | DL15: 0 | DM15: 0 | DN15: 0 | DO15: 0 | DP15: 0 | DQ15: 0 | DR15: 0 | DS15: 0 | DT15: 0 | DU15: 0 | DV15: 0 | DW15: 0 | DX15: 0 | DY15: 0 | DZ15: 49 | EA15: 0 | EB15: 45.693878 | EC15: 38.122449 | ED15: 42.795918 | EF15: 126.61224 | EG15: 42.204082 | EH15: 42.204082 | EI15: 14 | EJ15: 23 | EK15: 11 | EL15: 1 | EM15: 1 | EN15: 0 | EO15: 21 | EP15: 19 | EQ15: 8 | ER15: 1 | ES15: 2 | ET15: 0 | EU15: 19 | EV15: 20 | EW15: 5 | EX15: 5 | EY15: 1 | EZ15: 0 | FA15: 0 | FB15: 0 | FC15: 0 | FD15: 0 | FE15: 0 | FF15: 0 | FG15: 1 | FH15: 0 | FI15: 159 | FK15: 171 | FL15: 16 | FN15: 19 | FO15: 34 | FP15: 19 | FQ15: 34 | FR15: Binəqədi | FS15: 313 | FT15: 134 | FU15: 313
BK16: 306648932 | BL16: 143 nömrəli tam orta məktəb | BM16: 143 | BN16: tam orta məktəb | BO16: Azərbaycan, rus | BP16: 66 | BQ16: 0 | BR16: 52.924242 | BS16: 43.878788 | BT16: 36.560606 | BU16: 133.36364 | BV16: 44.454545 | BW16: 6 | BX16: 40 | BY16: 18 | BZ16: 2 | CA16: 0 | CB16: 0 | CC16: 18 | CD16: 38 | CE16: 7 | CF16: 3 | CG16: 0 | CH16: 0 | CI16: 30 | CJ16: 25 | CK16: 9 | CL16: 2 | CM16: 0 | CN16: 0 | CO16: 0 | CP16: 0 | CQ16: 23 | CR16: 0 | CS16: 57 | CT16: 37.913043 | CU16: 43.869565 | CV16: 58.695652 | CW16: 138.78261 | CX16: 46.26087 | CY16: 49.369565 | CZ16: 4 | DA16: 9 | DB16: 7 | DC16: 3 | DD16: 0 | DE16: 0 | DF16: 10 | DG16: 9 | DH16: 4 | DI16: 0 | DJ16: 0 | DK16: 0 | DL16: 10 | DM16: 9 | DN16: 1 | DO16: 3 | DP16: 0 | DQ16: 0 | DR16: 2 | DS16: 9 | DT16: 10 | DU16: 2 | DV16: 0 | DW16: 0 | DX16: 0 | DY16: 0 | DZ16: 89 | EA16: 0 | EB16: 53.977528 | EC16: 42.337079 | ED16: 38.449438 | EE16: 58.695652 | EF16: 134.76404 | EG16: 44.921348 | EH16: 45.724719 | EI16: 10 | EJ16: 49 | EK16: 25 | EL16: 5 | EM16: 0 | EN16: 0 | EO16: 28 | EP16: 47 | EQ16: 11 | ER16: 3 | ES16: 0 | ET16: 0 | EU16: 40 | EV16: 34 | EW16: 10 | EX16: 5 | EY16: 0 | EZ16: 0 | FA16: 2 | FB16: 9 | FC16: 10 | FD16: 2 | FE16: 0 | FF16: 0 | FG16: 0 | FH16: 0 | FI16: 123 | FJ16: 98 | FK16: 135 | FL16: 10 | FM16: 17 | FN16: 13 | FO16: 34 | FP16: 19 | FQ16: 34 | FR16: Binəqədi | FS16: 313 | FT16: 134 | FU16: 313
BK17: 750038450 | BL17: 144 nömrəli tam orta məktəb | BM17: 144 | BN17: tam orta məktəb | BO17: Azərbaycan | BP17: 70 | BQ17: 0 | BR17: 51.628571 | BS17: 48.057143 | BT17: 40.457143 | BU17: 140.14286 | BV17: 46.714286 | BW17: 12 | BX17: 36 | BY17: 20 | BZ17: 2 | CA17: 0 | CB17: 0 | CC17: 19 | CD17: 29 | CE17: 12 | CF17: 10 | CG17: 0 | CH17: 0 | CI17: 28 | CJ17: 27 | CK17: 10 | CL17: 5 | CM17: 1 | CN17: 0 | CO17: 0 | CP17: 0 | CQ17: 0 | CR17: 0 | CZ17: 0 | DA17: 0 | DB17: 0 | DC17: 0 | DD17: 0 | DE17: 0 | DF17: 0 | DG17: 0 | DH17: 0 | DI17: 0 | DJ17: 0 | DK17: 0 | DL17: 0 | DM17: 0 | DN17: 0 | DO17: 0 | DP17: 0 | DQ17: 0 | DR17: 0 | DS17: 0 | DT17: 0 | DU17: 0 | DV17: 0 | DW17: 0 | DX17: 0 | DY17: 0 | DZ17: 70 | EA17: 0 | EB17: 51.628571 | EC17: 48.057143 | ED17: 40.457143 | EF17: 140.14286 | EG17: 46.714286 | EH17: 46.714286 | EI17: 12 | EJ17: 36 | EK17: 20 | EL17: 2 | EM17: 0 | EN17: 0 | EO17: 19 | EP17: 29 | EQ17: 12 | ER17: 10 | ES17: 0 | ET17: 0 | EU17: 28 | EV17: 27 | EW17: 10 | EX17: 5 | EY17: 1 | EZ17: 0 | FA17: 0 | FB17: 0 | FC17: 0 | FD17: 0 | FE17: 0 | FF17: 0 | FG17: 0 | FH17: 0 | FI17: 99 | FK17: 109 | FL17: 4 | FN17: 6 | FO17: 34 | FP17: 19 | FQ17: 34 | FR17: Binəqədi | FS17: 313 | FT17: 134 | FU17: 313
BK18: 566880664 | BL18: 157 nömrəli tam orta məktəb | BM18: 157 | BN18: tam orta məktəb | BO18: Azərbaycan, rus | BP18: 69 | BQ18: 0 | BR18: 51.405797 | BS18: 49.73913 | BT18: 39.376812 | BU18: 140.52174 | BV18: 46.84058 | BW18: 13 | BX18: 35 | BY18: 19 | BZ18: 2 | CA18: 1 | CB18: 0 | CC18: 18 | CD18: 29 | CE18: 13 | CF18: 9 | CG18: 1 | CH18: 2 | CI18: 32 | CJ18: 23 | CK18: 11 | CL18: 3 | CM18: 0 | CN18: 0 | CO18: 0 | CP18: 0 | CQ18: 22 | CR18: 0 | CS18: 62.272727 | CT18: 42 | CU18: 47.818182 | CV18: 55.5 | CW18: 152.09091 | CX18: 50.69697 | CY18: 51.897727 | CZ18: 2 | DA18: 8 | DB18: 8 | DC18: 4 | DD18: 0 | DE18: 0 | DF18: 7 | DG18: 11 | DH18: 3 | DI18: 1 | DJ18: 1 | DK18: 0 | DL18: 7 | DM18: 7 | DN18: 6 | DO18: 2 | DP18: 0 | DQ18: 0 | DR18: 2 | DS18: 11 | DT18: 9 | DU18: 0 | DV18: 0 | DW18: 0 | DX18: 0 | DY18: 0 | DZ18: 91 | EA18: 0 | EB18: 54.032967 | EC18: 47.868132 | ED18: 41.417582 | EE18: 55.5 | EF18: 143.31868 | EG18: 47.772894 | EH18: 48.063187 | EI18: 15 | EJ18: 43 | EK18: 27 | EL18: 6 | EM18: 1 | EN18: 0 | EO18: 25 | EP18: 40 | EQ18: 16 | ER18: 10 | ES18: 2 | ET18: 2 | EU18: 39 | EV18: 30 | EW18: 17 | EX18: 5 | EY18: 0 | EZ18: 0 | FA18: 2 | FB18: 11 | FC18: 9 | FD18: 0 | FE18: 0 | FF18: 0 | FG18: 0 | FH18: 0 | FI18: 95 | FJ18: 61 | FK18: 95 | FL18: 3 | FM18: 10 | FN18: 5 | FO18: 34 | FP18: 19 | FQ18: 34 | FR18: Binəqədi | FS18: 313 | FT18: 134 | FU18: 313
BK19: 523653991 | BL19: 179 nömrəli tam orta məktəb | BM19: 179 | BN19: tam orta məktəb | BO19: Azərbaycan, rus | BP19: 236 | BQ19: 0 | BR19: 43.881356 | BS19: 36.661017 | BT19: 30.978814 | BU19: 111.52119 | BV19: 37.173729 | BW19: 78 | BX19: 107 | BY19: 45 | BZ19: 6 | CA19: 1 | CB19: 0 | CC19: 115 | CD19: 80 | CE19: 27 | CF19: 14 | CG19: 3 | CH19: 1 | CI19: 153 | CJ19: 60 | CK19: 15 | CL19: 8 | CM19: 2 | CN19: 0 | CO19: 1 | CP19: 0 | CQ19: 34 | CR19: 0 | CS19: 43.647059 | CT19: 37.529412 | CU19: 37.882353 | CV19: 61.058824 | CW19: 119.05882 | CX19: 39.686275 | CY19: 45.029412 | CZ19: 9 | DA19: 19 | DB19: 5 | DC19: 1 | DD19: 0 | DE19: 0 | DF19: 15 | DG19: 12 | DH19: 6 | DI19: 1 | DJ19: 0 | DK19: 0 | DL19: 16 | DM19: 11 | DN19: 4 | DO19: 3 | DP19: 1 | DQ19: 0 | DR19: 1 | DS19: 16 | DT19: 15 | DU19: 2 | DV19: 0 | DW19: 1 | DX19: 0 | DY19: 0 | DZ19: 270 | EA19: 0 | EB19: 43.851852 | EC19: 36.77037 | ED19: 31.848148 | EE19: 61.058824 | EF19: 112.47037 | EG19: 37.490123 | EH19: 38.162963 | EI19: 87 | EJ19: 126 | EK19: 50 | EL19: 7 | EM19: 1 | EN19: 0 | EO19: 130 | EP19: 92 | EQ19: 33 | ER19: 15 | ES19: 3 | ET19: 1 | EU19: 169 | EV19: 71 | EW19: 19 | EX19: 11 | EY19: 3 | EZ19: 0 | FA19: 1 | FB19: 16 | FC19: 15 | FD19: 2 | FE19: 0 | FF19: 1 | FG19: 1 | FH19: 0 | FI19: 235 | FJ19: 120 | FK19: 234 | FL19: 26 | FM19: 18 | FN19: 27 | FO19: 34 | FP19: 19 | FQ19: 34 | FR19: Binəqədi | FS19: 313 | FT19: 134 | FU19: 313
BK20: 891697193 | BL20: 182 nömrəli tam orta məktəb | BM20: 182 | BN20: tam orta məktəb | BO20: Azərbaycan | BP20: 363 | BQ20: 0 | BR20: 45.991736 | BS20: 41.564738 | BT20: 33.92011 | BU20: 121.47658 | BV20: 40.492195 | BW20: 98 | BX20: 181 | BY20: 69 | BZ20: 15 | CA20: 2 | CB20: 0 | CC20: 146 | CD20: 141 | CE20: 44 | CF20: 32 | CG20: 2 | CH20: 7 | CI20: 211 | CJ20: 98 | CK20: 39 | CL20: 15 | CM20: 2 | CN20: 0 | CO20: 0 | CP20: 0 | CQ20: 0 | CR20: 0 | CZ20: 0 | DA20: 0 | DB20: 0 | DC20: 0 | DD20: 0 | DE20: 0 | DF20: 0 | DG20: 0 | DH20: 0 | DI20: 0 | DJ20: 0 | DK20: 0 | DL20: 0 | DM20: 0 | DN20: 0 | DO20: 0 | DP20: 0 | DQ20: 0 | DR20: 0 | DS20: 0 | DT20: 0 | DU20: 0 | DV20: 0 | DW20: 0 | DX20: 0 | DY20: 0 | DZ20: 363 | EA20: 0 | EB20: 45.991736 | EC20: 41.564738 | ED20: 33.92011 | EF20: 121.47658 | EG20: 40.492195 | EH20: 40.492195 | EI20: 98 | EJ20: 181 | EK20: 69 | EL20: 15 | EM20: 2 | EN20: 0 | EO20: 146 | EP20: 141 | EQ20: 44 | ER20: 32 | ES20: 2 | ET20: 7 | EU20: 211 | EV20: 98 | EW20: 39 | EX20: 15 | EY20: 2 | EZ20: 0 | FA20: 0 | FB20: 0 | FC20: 0 | FD20: 0 | FE20: 0 | FF20: 0 | FG20: 0 | FH20: 0 | FI20: 183 | FK20: 196 | FL20: 19 | FN20: 21 | FO20: 34 | FP20: 19 | FQ20: 34 | FR20: Binəqədi | FS20: 313 | FT20: 134 | FU20: 313
BK21: 942021214 | BL21: 205 nömrəli tam orta məktəb | BM21: 205 | BN21: tam orta məktəb | BO21: Azərbaycan | BP21: 109 | BQ21: 0 | BR21: 40.330275 | BS21: 35.853211 | BT21: 30.981651 | BU21: 107.16514 | BV21: 35.721713 | BW21: 44 | BX21: 45 | BY21: 16 | BZ21: 4 | CA21: 2 | CB21: 0 | CC21: 54 | CD21: 39 | CE21: 10 | CF21: 6 | CG21: 2 | CH21: 0 | CI21: 72 | CJ21: 27 | CK21: 3 | CL21: 7 | CM21: 1 | CN21: 1 | CO21: 1 | CP21: 0 | CQ21: 0 | CR21: 0 | CZ21: 0 | DA21: 0 | DB21: 0 | DC21: 0 | DD21: 0 | DE21: 0 | DF21: 0 | DG21: 0 | DH21: 0 | DI21: 0 | DJ21: 0 | DK21: 0 | DL21: 0 | DM21: 0 | DN21: 0 | DO21: 0 | DP21: 0 | DQ21: 0 | DR21: 0 | DS21: 0 | DT21: 0 | DU21: 0 | DV21: 0 | DW21: 0 | DX21: 0 | DY21: 0 | DZ21: 109 | EA21: 0 | EB21: 40.330275 | EC21: 35.853211 | ED21: 30.981651 | EF21: 107.16514 | EG21: 35.721713 | EH21: 35.721713 | EI21: 44 | EJ21: 45 | EK21: 16 | EL21: 4 | EM21: 2 | EN21: 0 | EO21: 54 | EP21: 39 | EQ21: 10 | ER21: 6 | ES21: 2 | ET21: 0 | EU21: 72 | EV21: 27 | EW21: 3 | EX21: 7 | EY21: 1 | EZ21: 1 | FA21: 0 | FB21: 0 | FC21: 0 | FD21: 0 | FE21: 0 | FF21: 0 | FG21: 1 | FH21: 0 | FI21: 254 | FK21: 257 | FL21: 30 | FN21: 30 | FO21: 34 | FP21: 19 | FQ21: 34 | FR21: Binəqədi | FS21: 313 | FT21: 134 | FU21: 313
BK22: 677788676 | BL22: 217 nömrəli tam orta məktəb | BM22: 217 | BN22: tam orta məktəb | BO22: Azərbaycan | BP22: 224 | BQ22: 0 | BR22: 46.450893 | BS22: 38 | BT22: 32.834821 | BU22: 117.28571 | BV22: 39.095238 | BW22: 58 | BX22: 110 | BY22: 47 | BZ22: 9 | CA22: 4 | CB22: 0 | CC22: 103 | CD22: 81 | CE22: 26 | CF22: 14 | CG22: 4 | CH22: 1 | CI22: 139 | CJ22: 58 | CK22: 17 | CL22: 10 | CM22: 2 | CN22: 0 | CO22: 2 | CP22: 0 | CQ22: 0 | CR22: 0 | CZ22: 0 | DA22: 0 | DB22: 0 | DC22: 0 | DD22: 0 | DE22: 0 | DF22: 0 | DG22: 0 | DH22: 0 | DI22: 0 | DJ22: 0 | DK22: 0 | DL22: 0 | DM22: 0 | DN22: 0 | DO22: 0 | DP22: 0 | DQ22: 0 | DR22: 0 | DS22: 0 | DT22: 0 | DU22: 0 | DV22: 0 | DW22: 0 | DX22: 0 | DY22: 0 | DZ22: 224 | EA22: 0 | EB22: 46.450893 | EC22: 38 | ED22: 32.834821 | EF22: 117.28571 | EG22: 39.095238 | EH22: 39.095238 | EI22: 58 | EJ22: 110 | EK22: 47 | EL22: 9 | EM22: 4 | EN22: 0 | EO22: 103 | EP22: 81 | EQ22: 26 | ER22: 14 | ES22: 4 | ET22: 1 | EU22: 139 | EV22: 58 | EW22: 17 | EX22: 10 | EY22: 2 | EZ22: 0 | FA22: 0 | FB22: 0 | FC22: 0 | FD22: 0 | FE22: 0 | FF22: 0 | FG22: 2 | FH22: 0 | FI22: 207 | FK22: 213 | FL22: 20 | FN22: 23 | FO22: 34 | FP22: 19 | FQ22: 34 | FR22: Binəqədi | FS22: 313 | FT22: 134 | FU22: 313
BK23: 783942883 | BL23: 244 nömrəli tam orta məktəb | BM23: 244 | BN23: tam orta məktəb | BO23: Azərbaycan, rus | BP23: 167 | BQ23: 0 | BR23: 47.329341 | BS23: 35.185629 | BT23: 40.071856 | BU23: 122.58683 | BV23: 40.862275 | BW23: 34 | BX23: 94 | BY23: 37 | BZ23: 2 | CA23: 0 | CB23: 0 | CC23: 79 | CD23: 65 | CE23: 22 | CF23: 1 | CG23: 1 | CH23: 0 | CI23: 75 | CJ23: 58 | CK23: 24 | CL23: 10 | CM23: 1 | CN23: 1 | CO23: 0 | CP23: 0 | CQ23: 32 | CR23: 0 | CS23: 54.46875 | CT23: 41.75 | CU23: 51.46875 | CV23: 57.75 | CW23: 147.6875 | CX23: 49.229167 | CY23: 51.359375 | CZ23: 3 | DA23: 17 | DB23: 12 | DC23: 0 | DD23: 0 | DE23: 0 | DF23: 10 | DG23: 17 | DH23: 4 | DI23: 1 | DJ23: 0 | DK23: 0 | DL23: 5 | DM23: 17 | DN23: 6 | DO23: 4 | DP23: 0 | DQ23: 0 | DR23: 3 | DS23: 18 | DT23: 6 | DU23: 5 | DV23: 0 | DW23: 0 | DX23: 0 | DY23: 0 | DZ23: 199 | EA23: 0 | EB23: 48.477387 | EC23: 36.241206 | ED23: 41.904523 | EE23: 57.75 | EF23: 126.62312 | EG23: 42.207705 | EH23: 42.550251 | EI23: 37 | EJ23: 111 | EK23: 49 | EL23: 2 | EM23: 0 | EN23: 0 | EO23: 89 | EP23: 82 | EQ23: 26 | ER23: 2 | ES23: 1 | ET23: 0 | EU23: 80 | EV23: 75 | EW23: 30 | EX23: 14 | EY23: 1 | EZ23: 1 | FA23: 3 | FB23: 18 | FC23: 6 | FD23: 5 | FE23: 0 | FF23: 0 | FG23: 0 | FH23: 0 | FI23: 176 | FJ23: 76 | FK23: 170 | FL23: 18 | FM23: 14 | FN23: 18 | FO23: 34 | FP23: 19 | FQ23: 34 | FR23: Binəqədi | FS23: 313 | FT23: 134 | FU23: 313
BK24: 749261545 | BL24: 246 nömrəli məktəb-lisey | BM24: 246 | BN24: məktəb-lisey | BO24: Azərbaycan, rus | BP24: 111 | BQ24: 0 | BR24: 48.558559 | BS24: 43.243243 | BT24: 40.063063 | BU24: 131.86486 | BV24: 43.954955 | BW24: 24 | BX24: 56 | BY24: 24 | BZ24: 7 | CA24: 0 | CB24: 0 | CC24: 34 | CD24: 53 | CE24: 19 | CF24: 5 | CG24: 1 | CH24: 1 | CI24: 48 | CJ24: 40 | CK24: 17 | CL24: 6 | CM24: 1 | CN24: 0 | CO24: 0 | CP24: 0 | CQ24: 27 | CR24: 0 | CS24: 57.851852 | CT24: 46.962963 | CU24: 50.851852 | CV24: 57.555556 | CW24: 155.66667 | CX24: 51.888889 | CY24: 53.305556 | CZ24: 2 | DA24: 13 | DB24: 9 | DC24: 3 | DD24: 0 | DE24: 0 | DF24: 9 | DG24: 10 | DH24: 7 | DI24: 1 | DJ24: 0 | DK24: 0 | DL24: 9 | DM24: 7 | DN24: 5 | DO24: 6 | DP24: 0 | DQ24: 1 | DR24: 3 | DS24: 11 | DT24: 11 | DU24: 2 | DV24: 1 | DW24: 0 | DX24: 0 | DY24: 0 | DZ24: 138 | EA24: 0 | EB24: 50.376812 | EC24: 43.971014 | ED24: 42.173913 | EE24: 57.555556 | EF24: 136.52174 | EG24: 45.507246 | EH24: 45.78442 | EI24: 26 | EJ24: 69 | EK24: 33 | EL24: 10 | EM24: 0 | EN24: 0 | EO24: 43 | EP24: 63 | EQ24: 26 | ER24: 6 | ES24: 1 | ET24: 1 | EU24: 57 | EV24: 47 | EW24: 22 | EX24: 12 | EY24: 1 | EZ24: 1 | FA24: 3 | FB24: 11 | FC24: 11 | FD24: 2 | FE24: 1 | FF24: 0 | FG24: 0 | FH24: 0 | FI24: 131 | FJ24: 53 | FK24: 125 | FL24: 13 | FM24: 9 | FN24: 11 | FO24: 34 | FP24: 19 | FQ24: 34 | FR24: Binəqədi | FS24: 313 | FT24: 134 | FU24: 313
BK25: 341691360 | BL25: 248 nömrəli tam orta məktəb | BM25: 248 | BN25: tam orta məktəb | BO25: Azərbaycan, rus | BP25: 71 | BQ25: 0 | BR25: 46.098592 | BS25: 39.887324 | BT25: 38.929577 | BU25: 124.91549 | BV25: 41.638498 | BW25: 18 | BX25: 34 | BY25: 18 | BZ25: 1 | CA25: 1 | CB25: 0 | CC25: 34 | CD25: 21 | CE25: 12 | CF25: 4 | CG25: 1 | CH25: 0 | CI25: 36 | CJ25: 18 | CK25: 12 | CL25: 5 | CM25: 1 | CN25: 0 | CO25: 0 | CP25: 0 | CQ25: 37 | CR25: 0 | CS25: 56.432432 | CT25: 39.459459 | CU25: 48.297297 | CV25: 54.054054 | CW25: 144.18919 | CX25: 48.063063 | CY25: 49.560811 | CZ25: 3 | DA25: 18 | DB25: 12 | DC25: 4 | DD25: 0 | DE25: 0 | DF25: 17 | DG25: 15 | DH25: 3 | DI25: 2 | DJ25: 0 | DK25: 0 | DL25: 14 | DM25: 11 | DN25: 6 | DO25: 6 | DP25: 0 | DQ25: 0 | DR25: 5 | DS25: 20 | DT25: 9 | DU25: 3 | DV25: 0 | DW25: 0 | DX25: 0 | DY25: 0 | DZ25: 108 | EA25: 0 | EB25: 49.638889 | EC25: 39.740741 | ED25: 42.138889 | EE25: 54.054054 | EF25: 131.51852 | EG25: 43.839506 | EH25: 44.352623 | EI25: 21 | EJ25: 52 | EK25: 30 | EL25: 5 | EM25: 1 | EN25: 0 | EO25: 51 | EP25: 36 | EQ25: 15 | ER25: 6 | ES25: 1 | ET25: 0 | EU25: 50 | EV25: 29 | EW25: 18 | EX25: 11 | EY25: 1 | EZ25: 0 | FA25: 5 | FB25: 20 | FC25: 9 | FD25: 3 | FE25: 0 | FF25: 0 | FG25: 0 | FH25: 0 | FI25: 164 | FJ25: 87 | FK25: 144 | FL25: 17 | FM25: 16 | FN25: 16 | FO25: 34 | FP25: 19 | FQ25: 34 | FR25: Binəqədi | FS25: 313 | FT25: 134 | FU25: 313
BK26: 227519884 | BL26: 267 nömrəli məktəb-lisey | BM26: 267 | BN26: məktəb-lisey | BO26: Azərbaycan, rus | BP26: 60 | BQ26: 0 | BR26: 49.716667 | BS26: 39.8 | BT26: 38.15 | BU26: 127.66667 | BV26: 42.555556 | BW26: 11 | BX26: 36 | BY26: 10 | BZ26: 3 | CA26: 0 | CB26: 0 | CC26: 26 | CD26: 23 | CE26: 8 | CF26: 3 | CG26: 1 | CH26: 0 | CI26: 25 | CJ26: 29 | CK26: 3 | CL26: 3 | CM26: 0 | CN26: 0 | CO26: 0 | CP26: 0 | CQ26: 83 | CR26: 0 | CS26: 60.409639 | CT26: 51.13253 | CU26: 58.650602 | CV26: 56.927711 | CW26: 170.19277 | CX26: 56.730924 | CY26: 56.78012 | CZ26: 4 | DA26: 38 | DB26: 35 | DC26: 6 | DD26: 0 | DE26: 0 | DF26: 21 | DG26: 34 | DH26: 18 | DI26: 10 | DJ26: 0 | DK26: 0 | DL26: 14 | DM26: 30 | DN26: 20 | DO26: 19 | DP26: 0 | DQ26: 4 | DR26: 6 | DS26: 41 | DT26: 32 | DU26: 4 | DV26: 0 | DW26: 0 | DX26: 0 | DY26: 0 | DZ26: 143 | EA26: 0 | EB26: 55.923077 | EC26: 46.377622 | ED26: 50.048951 | EE26: 56.927711 | EF26: 152.34965 | EG26: 50.783217 | EH26: 50.811772 | EI26: 15 | EJ26: 74 | EK26: 45 | EL26: 9 | EM26: 0 | EN26: 0 | EO26: 47 | EP26: 57 | EQ26: 26 | ER26: 13 | ES26: 1 | ET26: 0 | EU26: 39 | EV26: 59 | EW26: 23 | EX26: 22 | EY26: 0 | EZ26: 4 | FA26: 6 | FB26: 41 | FC26: 32 | FD26: 4 | FE26: 0 | FF26: 0 | FG26: 0 | FH26: 0 | FI26: 152 | FJ26: 22 | FK26: 60 | FL26: 15 | FM26: 2 | FN26: 4 | FO26: 34 | FP26: 19 | FQ26: 34 | FR26: Binəqədi | FS26: 313 | FT26: 134 | FU26: 313
BK27: 793385579 | BL27: 276 nömrəli tam orta məktəb | BM27: 276 | BN27: tam orta məktəb | BO27: Azərbaycan, rus | BP27: 85 | BQ27: 0 | BR27: 47.776471 | BS27: 44.047059 | BT27: 40.941176 | BU27: 132.76471 | BV27: 44.254902 | BW27: 24 | BX27: 34 | BY27: 22 | BZ27: 5 | CA27: 0 | CB27: 0 | CC27: 39 | CD27: 20 | CE27: 14 | CF27: 12 | CG27: 1 | CH27: 3 | CI27: 39 | CJ27: 25 | CK27: 9 | CL27: 12 | CM27: 0 | CN27: 1 | CO27: 0 | CP27: 0 | CQ27: 44 | CR27: 0 | CS27: 58.545455 | CT27: 43.272727 | CU27: 47.590909 | CV27: 52.863636 | CW27: 149.40909 | CX27: 49.80303 | CY27: 50.568182 | CZ27: 4 | DA27: 19 | DB27: 18 | DC27: 3 | DD27: 0 | DE27: 0 | DF27: 16 | DG27: 19 | DH27: 7 | DI27: 2 | DJ27: 0 | DK27: 0 | DL27: 17 | DM27: 14 | DN27: 4 | DO27: 9 | DP27: 1 | DQ27: 1 | DR27: 8 | DS27: 20 | DT27: 15 | DU27: 1 | DV27: 0 | DW27: 0 | DX27: 0 | DY27: 0 | DZ27: 129 | EA27: 0 | EB27: 51.449612 | EC27: 43.782946 | ED27: 43.209302 | EE27: 52.863636 | EF27: 138.44186 | EG27: 46.147287 | EH27: 46.408269 | EI27: 28 | EJ27: 53 | EK27: 40 | EL27: 8 | EM27: 0 | EN27: 0 | EO27: 55 | EP27: 39 | EQ27: 21 | ER27: 14 | ES27: 1 | ET27: 3 | EU27: 56 | EV27: 39 | EW27: 13 | EX27: 21 | EY27: 1 | EZ27: 2 | FA27: 8 | FB27: 20 | FC27: 15 | FD27: 1 | FE27: 0 | FF27: 0 | FG27: 0 | FH27: 0 | FI27: 127 | FJ27: 69 | FK27: 119 | FL27: 11 | FM27: 12 | FN27: 8 | FO27: 34 | FP27: 19 | FQ27: 34 | FR27: Binəqədi | FS27: 313 | FT27: 134 | FU27: 313
BK28: 199201762 | BL28: 283 nömrəli tam orta məktəb | BM28: 283 | BN28: tam orta məktəb | BO28: Azərbaycan, rus | BP28: 103 | BQ28: 1 | BR28: 48.127451 | BS28: 41.058824 | BT28: 39.147059 | BU28: 128.33333 | BV28: 42.777778 | BW28: 26 | BX28: 51 | BY28: 20 | BZ28: 5 | CA28: 1 | CB28: 0 | CC28: 40 | CD28: 39 | CE28: 14 | CF28: 9 | CG28: 3 | CH28: 1 | CI28: 45 | CJ28: 39 | CK28: 12 | CL28: 6 | CM28: 1 | CN28: 0 | CO28: 0 | CP28: 0 | CQ28: 12 | CR28: 0 | CS28: 59.666667 | CT28: 51 | CU28: 59.416667 | CV28: 67.5 | CW28: 170.08333 | CX28: 56.694444 | CY28: 59.395833 | CZ28: 1 | DA28: 4 | DB28: 7 | DC28: 0 | DD28: 0 | DE28: 0 | DF28: 2 | DG28: 6 | DH28: 3 | DI28: 1 | DJ28: 0 | DK28: 0 | DL28: 2 | DM28: 3 | DN28: 4 | DO28: 3 | DP28: 0 | DQ28: 0 | DR28: 2 | DS28: 0 | DT28: 7 | DU28: 3 | DV28: 0 | DW28: 0 | DX28: 0 | DY28: 0 | DZ28: 115 | EA28: 1 | EB28: 49.342105 | EC28: 42.105263 | ED28: 41.280702 | EE28: 67.5 | EF28: 132.72807 | EG28: 44.24269 | EH28: 44.527047 | EI28: 27 | EJ28: 55 | EK28: 27 | EL28: 5 | EM28: 1 | EN28: 0 | EO28: 42 | EP28: 45 | EQ28: 17 | ER28: 10 | ES28: 3 | ET28: 1 | EU28: 47 | EV28: 42 | EW28: 16 | EX28: 9 | EY28: 1 | EZ28: 0 | FA28: 2 | FB28: 0 | FC28: 7 | FD28: 3 | FE28: 0 | FF28: 0 | FG28: 0 | FH28: 0 | FI28: 146 | FJ28: 23 | FK28: 142 | FL28: 14 | FM28: 3 | FN28: 15 | FO28: 34 | FP28: 19 | FQ28: 34 | FR28: Binəqədi | FS28: 313 | FT28: 134 | FU28: 313
BK29: 692159867 | BL29: 284 nömrəli tam orta məktəb | BM29: 284 | BN29: tam orta məktəb | BO29: Azərbaycan, rus | BP29: 228 | BQ29: 0 | BR29: 43.377193 | BS29: 33.807018 | BT29: 31.399123 | BU29: 108.58333 | BV29: 36.194444 | BW29: 68 | BX29: 114 | BY29: 43 | BZ29: 3 | CA29: 3 | CB29: 0 | CC29: 121 | CD29: 82 | CE29: 19 | CF29: 6 | CG29: 4 | CH29: 0 | CI29: 146 | CJ29: 62 | CK29: 13 | CL29: 7 | CM29: 4 | CN29: 0 | CO29: 3 | CP29: 0 | CQ29: 34 | CR29: 0 | CS29: 43.441176 | CT29: 38.941176 | CU29: 36.382353 | CV29: 54.235294 | CW29: 118.76471 | CX29: 39.588235 | CY29: 43.25 | CZ29: 14 | DA29: 10 | DB29: 5 | DC29: 5 | DD29: 0 | DE29: 0 | DF29: 15 | DG29: 10 | DH29: 7 | DI29: 2 | DJ29: 0 | DK29: 0 | DL29: 22 | DM29: 3 | DN29: 4 | DO29: 5 | DP29: 0 | DQ29: 0 | DR29: 7 | DS29: 15 | DT29: 7 | DU29: 5 | DV29: 0 | DW29: 0 | DX29: 0 | DY29: 0 | DZ29: 262 | EA29: 0 | EB29: 43.385496 | EC29: 34.473282 | ED29: 32.045802 | EE29: 54.235294 | EF29: 109.90458 | EG29: 36.63486 | EH29: 37.110051 | EI29: 82 | EJ29: 124 | EK29: 48 | EL29: 8 | EM29: 3 | EN29: 0 | EO29: 136 | EP29: 92 | EQ29: 26 | ER29: 8 | ES29: 4 | ET29: 0 | EU29: 168 | EV29: 65 | EW29: 17 | EX29: 12 | EY29: 4 | EZ29: 0 | FA29: 7 | FB29: 15 | FC29: 7 | FD29: 5 | FE29: 0 | FF29: 0 | FG29: 3 | FH29: 0 | FI29: 249 | FJ29: 121 | FK29: 248 | FL29: 28 | FM29: 19 | FN29: 29 | FO29: 34 | FP29: 19 | FQ29: 34 | FR29: Binəqədi | FS29: 313 | FT29: 134 | FU29: 313
BK30: 407697984 | BL30: 297 nömrəli tam orta məktəb | BM30: 297 | BN30: tam orta məktəb | BO30: Azərbaycan, rus | BP30: 154 | BQ30: 0 | BR30: 45.402597 | BS30: 37.636364 | BT30: 32.512987 | BU30: 115.55195 | BV30: 38.517316 | BW30: 46 | BX30: 75 | BY30: 29 | BZ30: 4 | CA30: 0 | CB30: 0 | CC30: 64 | CD30: 70 | CE30: 15 | CF30: 5 | CG30: 0 | CH30: 0 | CI30: 92 | CJ30: 50 | CK30: 8 | CL30: 4 | CM30: 0 | CN30: 1 | CO30: 0 | CP30: 0 | CQ30: 18 | CR30: 0 | CS30: 56.5 | CT30: 40.222222 | CU30: 49.111111 | CV30: 56.888889 | CW30: 145.83333 | CX30: 48.611111 | CY30: 50.680556 | CZ30: 2 | DA30: 9 | DB30: 5 | DC30: 2 | DD30: 0 | DE30: 0 | DF30: 7 | DG30: 9 | DH30: 2 | DI30: 0 | DJ30: 0 | DK30: 0 | DL30: 6 | DM30: 6 | DN30: 5 | DO30: 1 | DP30: 0 | DQ30: 0 | DR30: 2 | DS30: 7 | DT30: 8 | DU30: 1 | DV30: 0 | DW30: 0 | DX30: 0 | DY30: 0 | DZ30: 172 | EA30: 0 | EB30: 46.563953 | EC30: 37.906977 | ED30: 34.25 | EE30: 56.888889 | EF30: 118.72093 | EG30: 39.573643 | EH30: 39.790213 | EI30: 48 | EJ30: 84 | EK30: 34 | EL30: 6 | EM30: 0 | EN30: 0 | EO30: 71 | EP30: 79 | EQ30: 17 | ER30: 5 | ES30: 0 | ET30: 0 | EU30: 98 | EV30: 56 | EW30: 13 | EX30: 5 | EY30: 0 | EZ30: 1 | FA30: 2 | FB30: 7 | FC30: 8 | FD30: 1 | FE30: 0 | FF30: 0 | FG30: 0 | FH30: 0 | FI30: 215 | FJ30: 82 | FK30: 207 | FL30: 21 | FM30: 15 | FN30: 22 | FO30: 34 | FP30: 19 | FQ30: 34 | FR30: Binəqədi | FS30: 313 | FT30: 134 | FU30: 313
BK31: 558335700 | BL31: 298 nömrəli tam orta məktəb | BM31: 298 | BN31: tam orta məktəb | BO31: Azərbaycan | BP31: 63 | BQ31: 0 | BR31: 45.063492 | BS31: 37.079365 | BT31: 29.84127 | BU31: 111.98413 | BV31: 37.328042 | BW31: 19 | BX31: 27 | BY31: 17 | BZ31: 0 | CA31: 2 | CB31: 0 | CC31: 24 | CD31: 32 | CE31: 5 | CF31: 2 | CG31: 4 | CH31: 0 | CI31: 35 | CJ31: 24 | CK31: 3 | CL31: 1 | CM31: 1 | CN31: 0 | CO31: 1 | CP31: 0 | CQ31: 0 | CR31: 0 | CZ31: 0 | DA31: 0 | DB31: 0 | DC31: 0 | DD31: 0 | DE31: 0 | DF31: 0 | DG31: 0 | DH31: 0 | DI31: 0 | DJ31: 0 | DK31: 0 | DL31: 0 | DM31: 0 | DN31: 0 | DO31: 0 | DP31: 0 | DQ31: 0 | DR31: 0 | DS31: 0 | DT31: 0 | DU31: 0 | DV31: 0 | DW31: 0 | DX31: 0 | DY31: 0 | DZ31: 63 | EA31: 0 | EB31: 45.063492 | EC31: 37.079365 | ED31: 29.84127 | EF31: 111.98413 | EG31: 37.328042 | EH31: 37.328042 | EI31: 19 | EJ31: 27 | EK31: 17 | EL31: 0 | EM31: 2 | EN31: 0 | EO31: 24 | EP31: 32 | EQ31: 5 | ER31: 2 | ES31: 4 | ET31: 0 | EU31: 35 | EV31: 24 | EW31: 3 | EX31: 1 | EY31: 1 | EZ31: 0 | FA31: 0 | FB31: 0 | FC31: 0 | FD31: 0 | FE31: 0 | FF31: 0 | FG31: 1 | FH31: 0 | FI31: 230 | FK31: 237 | FL31: 25 | FN31: 28 | FO31: 34 | FP31: 19 | FQ31: 34 | FR31: Binəqədi | FS31: 313 | FT31: 134 | FU31: 313
BK32: 316299466 | BL32: 299 nömrəli məktəb-lisey | BM32: 299 | BN32: məktəb-lisey | BO32: Azərbaycan, rus | BP32: 149 | BQ32: 0 | BR32: 54.395973 | BS32: 48.966443 | BT32: 47.402685 | BU32: 150.7651 | BV32: 50.255034 | BW32: 21 | BX32: 69 | BY32: 46 | BZ32: 13 | CA32: 0 | CB32: 1 | CC32: 36 | CD32: 68 | CE32: 28 | CF32: 17 | CG32: 2 | CH32: 1 | CI32: 49 | CJ32: 54 | CK32: 25 | CL32: 21 | CM32: 0 | CN32: 1 | CO32: 0 | CP32: 0 | CQ32: 27 | CR32: 0 | CS32: 62.074074 | CT32: 46.666667 | CU32: 53.444444 | CV32: 62.259259 | CW32: 162.18519 | CX32: 54.061728 | CY32: 56.111111 | CZ32: 2 | DA32: 12 | DB32: 8 | DC32: 5 | DD32: 0 | DE32: 0 | DF32: 6 | DG32: 13 | DH32: 4 | DI32: 4 | DJ32: 0 | DK32: 0 | DL32: 10 | DM32: 6 | DN32: 4 | DO32: 7 | DP32: 0 | DQ32: 1 | DR32: 1 | DS32: 12 | DT32: 11 | DU32: 3 | DV32: 0 | DW32: 0 | DX32: 0 | DY32: 0 | DZ32: 176 | EA32: 0 | EB32: 55.573864 | EC32: 48.613636 | ED32: 48.329545 | EE32: 62.259259 | EF32: 152.51705 | EG32: 50.839015 | EH32: 51.153409 | EI32: 23 | EJ32: 81 | EK32: 54 | EL32: 18 | EM32: 0 | EN32: 1 | EO32: 42 | EP32: 81 | EQ32: 32 | ER32: 21 | ES32: 2 | ET32: 1 | EU32: 59 | EV32: 60 | EW32: 29 | EX32: 28 | EY32: 0 | EZ32: 2 | FA32: 1 | FB32: 12 | FC32: 11 | FD32: 3 | FE32: 0 | FF32: 0 | FG32: 0 | FH32: 0 | FI32: 54 | FJ32: 35 | FK32: 59 | FL32: 1 | FM32: 5 | FN32: 3 | FO32: 34 | FP32: 19 | FQ32: 34 | FR32: Binəqədi | FS32: 313 | FT32: 134 | FU32: 313
BK33: 896967625 | BL33: 300 nömrəli tam orta məktəb | BM33: 300 | BN33: tam orta məktəb | BO33: Azərbaycan, rus | BP33: 137 | BQ33: 0 | BR33: 52.211679 | BS33: 44.20438 | BT33: 38.10219 | BU33: 134.51825 | BV33: 44.839416 | BW33: 28 | BX33: 59 | BY33: 43 | BZ33: 7 | CA33: 0 | CB33: 0 | CC33: 42 | CD33: 61 | CE33: 23 | CF33: 11 | CG33: 0 | CH33: 1 | CI33: 62 | CJ33: 51 | CK33: 17 | CL33: 7 | CM33: 0 | CN33: 0 | CO33: 0 | CP33: 0 | CQ33: 29 | CR33: 0 | CS33: 59.827586 | CT33: 43.310345 | CU33: 53.034483 | CV33: 51.344828 | CW33: 156.17241 | CX33: 52.057471 | CY33: 51.87931 | CZ33: 3 | DA33: 11 | DB33: 10 | DC33: 5 | DD33: 0 | DE33: 0 | DF33: 8 | DG33: 17 | DH33: 3 | DI33: 1 | DJ33: 0 | DK33: 0 | DL33: 8 | DM33: 9 | DN33: 5 | DO33: 7 | DP33: 0 | DQ33: 0 | DR33: 7 | DS33: 13 | DT33: 6 | DU33: 3 | DV33: 0 | DW33: 0 | DX33: 0 | DY33: 0 | DZ33: 166 | EA33: 0 | EB33: 53.542169 | EC33: 44.048193 | ED33: 40.710843 | EE33: 51.344828 | EF33: 138.3012 | EG33: 46.100402 | EH33: 46.069277 | EI33: 31 | EJ33: 70 | EK33: 53 | EL33: 12 | EM33: 0 | EN33: 0 | EO33: 50 | EP33: 78 | EQ33: 26 | ER33: 12 | ES33: 0 | ET33: 1 | EU33: 70 | EV33: 60 | EW33: 22 | EX33: 14 | EY33: 0 | EZ33: 0 | FA33: 7 | FB33: 13 | FC33: 6 | FD33: 3 | FE33: 0 | FF33: 0 | FG33: 0 | FH33: 0 | FI33: 116 | FJ33: 50 | FK33: 120 | FL33: 8 | FM33: 8 | FN33: 9 | FO33: 34 | FP33: 19 | FQ33: 34 | FR33: Binəqədi | FS33: 313 | FT33: 134 | FU33: 313
BK34: 647738207 | BL34: 301 nömrəli tam orta məktəb | BM34: 301 | BN34: tam orta məktəb | BO34: Azərbaycan | BP34: 84 | BQ34: 0 | BR34: 40.083333 | BS34: 34.190476 | BT34: 31.952381 | BU34: 106.22619 | BV34: 35.40873 | BW34: 31 | BX34: 35 | BY34: 17 | BZ34: 1 | CA34: 3 | CB34: 0 | CC34: 47 | CD34: 24 | CE34: 10 | CF34: 3 | CG34: 1 | CH34: 1 | CI34: 53 | CJ34: 22 | CK34: 6 | CL34: 3 | CM34: 2 | CN34: 0 | CO34: 1 | CP34: 0 | CQ34: 0 | CR34: 0 | CZ34: 0 | DA34: 0 | DB34: 0 | DC34: 0 | DD34: 0 | DE34: 0 | DF34: 0 | DG34: 0 | DH34: 0 | DI34: 0 | DJ34: 0 | DK34: 0 | DL34: 0 | DM34: 0 | DN34: 0 | DO34: 0 | DP34: 0 | DQ34: 0 | DR34: 0 | DS34: 0 | DT34: 0 | DU34: 0 | DV34: 0 | DW34: 0 | DX34: 0 | DY34: 0 | DZ34: 84 | EA34: 0 | EB34: 40.083333 | EC34: 34.190476 | ED34: 31.952381 | EF34: 106.22619 | EG34: 35.40873 | EH34: 35.40873 | EI34: 31 | EJ34: 35 | EK34: 17 | EL34: 1 | EM34: 3 | EN34: 0 | EO34: 47 | EP34: 24 | EQ34: 10 | ER34: 3 | ES34: 1 | ET34: 1 | EU34: 53 | EV34: 22 | EW34: 6 | EX34: 3 | EY34: 2 | EZ34: 0 | FA34: 0 | FB34: 0 | FC34: 0 | FD34: 0 | FE34: 0 | FF34: 0 | FG34: 1 | FH34: 0 | FI34: 256 | FK34: 262 | FL34: 32 | FN34: 32 | FO34: 34 | FP34: 19 | FQ34: 34 | FR34: Binəqədi | FS34: 313 | FT34: 134 | FU34: 313
BK35: 415956063 | BL35: 306 nömrəli tam orta məktəb | BM35: 306 | BN35: tam orta məktəb | BO35: Azərbaycan | BP35: 88 | BQ35: 0 | BR35: 41.238636 | BS35: 36.090909 | BT35: 29.068182 | BU35: 106.39773 | BV35: 35.465909 | BW35: 29 | BX35: 47 | BY35: 11 | BZ35: 1 | CA35: 0 | CB35: 0 | CC35: 37 | CD35: 42 | CE35: 6 | CF35: 3 | CG35: 0 | CH35: 1 | CI35: 56 | CJ35: 28 | CK35: 3 | CL35: 1 | CM35: 0 | CN35: 0 | CO35: 0 | CP35: 0 | CQ35: 0 | CR35: 0 | CZ35: 0 | DA35: 0 | DB35: 0 | DC35: 0 | DD35: 0 | DE35: 0 | DF35: 0 | DG35: 0 | DH35: 0 | DI35: 0 | DJ35: 0 | DK35: 0 | DL35: 0 | DM35: 0 | DN35: 0 | DO35: 0 | DP35: 0 | DQ35: 0 | DR35: 0 | DS35: 0 | DT35: 0 | DU35: 0 | DV35: 0 | DW35: 0 | DX35: 0 | DY35: 0 | DZ35: 88 | EA35: 0 | EB35: 41.238636 | EC35: 36.090909 | ED35: 29.068182 | EF35: 106.39773 | EG35: 35.465909 | EH35: 35.465909 | EI35: 29 | EJ35: 47 | EK35: 11 | EL35: 1 | EM35: 0 | EN35: 0 | EO35: 37 | EP35: 42 | EQ35: 6 | ER35: 3 | ES35: 0 | ET35: 1 | EU35: 56 | EV35: 28 | EW35: 3 | EX35: 1 | EY35: 0 | EZ35: 0 | FA35: 0 | FB35: 0 | FC35: 0 | FD35: 0 | FE35: 0 | FF35: 0 | FG35: 0 | FH35: 0 | FI35: 255 | FK35: 261 | FL35: 31 | FN35: 31 | FO35: 34 | FP35: 19 | FQ35: 34 | FR35: Binəqədi | FS35: 313 | FT35: 134 | FU35: 313
BK36: 485798325 | BL36: 313 nömrəli tam orta məktəb | BM36: 313 | BN36: tam orta məktəb | BO36: Azərbaycan | BP36: 151 | BQ36: 0 | BR36: 53.880795 | BS36: 47.549669 | BT36: 38.092715 | BU36: 139.52318 | BV36: 46.507726 | BW36: 22 | BX36: 77 | BY36: 39 | BZ36: 13 | CA36: 0 | CB36: 0 | CC36: 43 | CD36: 67 | CE36: 26 | CF36: 15 | CG36: 0 | CH36: 1 | CI36: 70 | CJ36: 56 | CK36: 17 | CL36: 8 | CM36: 0 | CN36: 0 | CO36: 0 | CP36: 0 | CQ36: 0 | CR36: 0 | CZ36: 0 | DA36: 0 | DB36: 0 | DC36: 0 | DD36: 0 | DE36: 0 | DF36: 0 | DG36: 0 | DH36: 0 | DI36: 0 | DJ36: 0 | DK36: 0 | DL36: 0 | DM36: 0 | DN36: 0 | DO36: 0 | DP36: 0 | DQ36: 0 | DR36: 0 | DS36: 0 | DT36: 0 | DU36: 0 | DV36: 0 | DW36: 0 | DX36: 0 | DY36: 0 | DZ36: 151 | EA36: 0 | EB36: 53.880795 | EC36: 47.549669 | ED36: 38.092715 | EF36: 139.52318 | EG36: 46.507726 | EH36: 46.507726 | EI36: 22 | EJ36: 77 | EK36: 39 | EL36: 13 | EM36: 0 | EN36: 0 | EO36: 43 | EP36: 67 | EQ36: 26 | ER36: 15 | ES36: 0 | ET36: 1 | EU36: 70 | EV36: 56 | EW36: 17 | EX36: 8 | EY36: 0 | EZ36: 0 | FA36: 0 | FB36: 0 | FC36: 0 | FD36: 0 | FE36: 0 | FF36: 0 | FG36: 0 | FH36: 0 | FI36: 101 | FK36: 110 | FL36: 5 | FN36: 7 | FO36: 34 | FP36: 19 | FQ36: 34 | FR36: Binəqədi | FS36: 313 | FT36: 134 | FU36: 313
BK37: 532167695 | BL37: 314 nömrəli tam orta məktəb | BM37: 314 | BN37: tam orta məktəb | BO37: Azərbaycan | BP37: 147 | BQ37: 3 | BR37: 49.944444 | BS37: 45.583333 | BT37: 37.902778 | BU37: 133.43056 | BV37: 44.476852 | BW37: 38 | BX37: 57 | BY37: 42 | BZ37: 7 | CA37: 0 | CB37: 0 | CC37: 44 | CD37: 62 | CE37: 25 | CF37: 13 | CG37: 1 | CH37: 1 | CI37: 69 | CJ37: 51 | CK37: 18 | CL37: 6 | CM37: 0 | CN37: 1 | CO37: 0 | CP37: 0 | CQ37: 0 | CR37: 0 | CZ37: 0 | DA37: 0 | DB37: 0 | DC37: 0 | DD37: 0 | DE37: 0 | DF37: 0 | DG37: 0 | DH37: 0 | DI37: 0 | DJ37: 0 | DK37: 0 | DL37: 0 | DM37: 0 | DN37: 0 | DO37: 0 | DP37: 0 | DQ37: 0 | DR37: 0 | DS37: 0 | DT37: 0 | DU37: 0 | DV37: 0 | DW37: 0 | DX37: 0 | DY37: 0 | DZ37: 147 | EA37: 3 | EB37: 49.944444 | EC37: 45.583333 | ED37: 37.902778 | EF37: 133.43056 | EG37: 44.476852 | EH37: 44.476852 | EI37: 38 | EJ37: 57 | EK37: 42 | EL37: 7 | EM37: 0 | EN37: 0 | EO37: 44 | EP37: 62 | EQ37: 25 | ER37: 13 | ES37: 1 | ET37: 1 | EU37: 69 | EV37: 51 | EW37: 18 | EX37: 6 | EY37: 0 | EZ37: 1 | FA37: 0 | FB37: 0 | FC37: 0 | FD37: 0 | FE37: 0 | FF37: 0 | FG37: 0 | FH37: 0 | FI37: 122 | FK37: 139 | FL37: 9 | FN37: 14 | FO37: 34 | FP37: 19 | FQ37: 34 | FR37: Binəqədi | FS37: 313 | FT37: 134 | FU37: 313
BK38: 618081585 | BL38: 11 nömrəli xüsusi təhsil məktəbi-əqli məhdudiyyətli uşaqlar üçün | BM38: 11 | BN38: XTM | BO38: Azərbaycan | BP38: 0 | BQ38: 0 | BW38: 0 | BX38: 0 | BY38: 0 | BZ38: 0 | CA38: 0 | CB38: 0 | CC38: 0 | CD38: 0 | CE38: 0 | CF38: 0 | CG38: 0 | CH38: 0 | CI38: 0 | CJ38: 0 | CK38: 0 | CL38: 0 | CM38: 0 | CN38: 0 | CO38: 0 | CP38: 0 | CQ38: 0 | CR38: 0 | CZ38: 0 | DA38: 0 | DB38: 0 | DC38: 0 | DD38: 0 | DE38: 0 | DF38: 0 | DG38: 0 | DH38: 0 | DI38: 0 | DJ38: 0 | DK38: 0 | DL38: 0 | DM38: 0 | DN38: 0 | DO38: 0 | DP38: 0 | DQ38: 0 | DR38: 0 | DS38: 0 | DT38: 0 | DU38: 0 | DV38: 0 | DW38: 0 | DX38: 0 | DY38: 0 | DZ38: 0 | EA38: 0 | EI38: 0 | EJ38: 0 | EK38: 0 | EL38: 0 | EM38: 0 | EN38: 0 | EO38: 0 | EP38: 0 | EQ38: 0 | ER38: 0 | ES38: 0 | ET38: 0 | EU38: 0 | EV38: 0 | EW38: 0 | EX38: 0 | EY38: 0 | EZ38: 0 | FA38: 0 | FB38: 0 | FC38: 0 | FD38: 0 | FE38: 0 | FF38: 0 | FG38: 0 | FH38: 0 | FO38: 21 | FP38: 10 | FQ38: 21 | FR38: Nərimanov | FS38: 313 | FT38: 134 | FU38: 313
BK39: 764548582 | BL39: 34 nömrəli tam orta məktəb | BM39: 34 | BN39: tam orta məktəb | BO39: Azərbaycan | BP39: 67 | BQ39: 0 | BR39: 57.38806 | BS39: 45.373134 | BT39: 44.343284 | BU39: 147.10448 | BV39: 49.034826 | BW39: 10 | BX39: 26 | BY39: 22 | BZ39: 9 | CA39: 0 | CB39: 0 | CC39: 26 | CD39: 20 | CE39: 13 | CF39: 8 | CG39: 1 | CH39: 0 | CI39: 28 | CJ39: 18 | CK39: 13 | CL39: 8 | CM39: 0 | CN39: 0 | CO39: 0 | CP39: 0 | CQ39: 0 | CR39: 0 | CZ39: 0 | DA39: 0 | DB39: 0 | DC39: 0 | DD39: 0 | DE39: 0 | DF39: 0 | DG39: 0 | DH39: 0 | DI39: 0 | DJ39: 0 | DK39: 0 | DL39: 0 | DM39: 0 | DN39: 0 | DO39: 0 | DP39: 0 | DQ39: 0 | DR39: 0 | DS39: 0 | DT39: 0 | DU39: 0 | DV39: 0 | DW39: 0 | DX39: 0 | DY39: 0 | DZ39: 67 | EA39: 0 | EB39: 57.38806 | EC39: 45.373134 | ED39: 44.343284 | EF39: 147.10448 | EG39: 49.034826 | EH39: 49.034826 | EI39: 10 | EJ39: 26 | EK39: 22 | EL39: 9 | EM39: 0 | EN39: 0 | EO39: 26 | EP39: 20 | EQ39: 13 | ER39: 8 | ES39: 1 | ET39: 0 | EU39: 28 | EV39: 18 | EW39: 13 | EX39: 8 | EY39: 0 | EZ39: 0 | FA39: 0 | FB39: 0 | FC39: 0 | FD39: 0 | FE39: 0 | FF39: 0 | FG39: 0 | FH39: 0 | FI39: 66 | FK39: 72 | FL39: 10 | FN39: 9 | FO39: 21 | FP39: 10 | FQ39: 21 | FR39: Nərimanov | FS39: 313 | FT39: 134 | FU39: 313
BK40: 310686851 | BL40: 36 nömrəli tam orta məktəb | BM40: 36 | BN40: tam orta məktəb | BO40: Azərbaycan | BP40: 84 | BQ40: 0 | BR40: 55.285714 | BS40: 41.238095 | BT40: 43.690476 | BU40: 140.21429 | BV40: 46.738095 | BW40: 13 | BX40: 33 | BY40: 26 | BZ40: 12 | CA40: 1 | CB40: 0 | CC40: 36 | CD40: 28 | CE40: 13 | CF40: 7 | CG40: 0 | CH40: 3 | CI40: 34 | CJ40: 28 | CK40: 16 | CL40: 6 | CM40: 0 | CN40: 0 | CO40: 0 | CP40: 0 | CQ40: 0 | CR40: 0 | CZ40: 0 | DA40: 0 | DB40: 0 | DC40: 0 | DD40: 0 | DE40: 0 | DF40: 0 | DG40: 0 | DH40: 0 | DI40: 0 | DJ40: 0 | DK40: 0 | DL40: 0 | DM40: 0 | DN40: 0 | DO40: 0 | DP40: 0 | DQ40: 0 | DR40: 0 | DS40: 0 | DT40: 0 | DU40: 0 | DV40: 0 | DW40: 0 | DX40: 0 | DY40: 0 | DZ40: 84 | EA40: 0 | EB40: 55.285714 | EC40: 41.238095 | ED40: 43.690476 | EF40: 140.21429 | EG40: 46.738095 | EH40: 46.738095 | EI40: 13 | EJ40: 33 | EK40: 26 | EL40: 12 | EM40: 1 | EN40: 0 | EO40: 36 | EP40: 28 | EQ40: 13 | ER40: 7 | ES40: 0 | ET40: 3 | EU40: 34 | EV40: 28 | EW40: 16 | EX40: 6 | EY40: 0 | EZ40: 0 | FA40: 0 | FB40: 0 | FC40: 0 | FD40: 0 | FE40: 0 | FF40: 0 | FG40: 0 | FH40: 0 | FI40: 98 | FK40: 108 | FL40: 12 | FN40: 13 | FO40: 21 | FP40: 10 | FQ40: 21 | FR40: Nərimanov | FS40: 313 | FT40: 134 | FU40: 313
...

Sheet Buraxılış 2022
A1: Diqqət! Aşağıdakı qırmızı xanaya təhsil müəssisəsinin UTİS kodunu daxil edin. | B1: Dövlət İmtahan Mərkəzi tərəfindən 2022-ci ildə IX siniflər üzrə keçirilən buraxılış imtahanlarının nəticələri | BP1: Azərbaycan bölməsi | CQ1: Rus bölməsi | DZ1: Ümumi
B2: Bölmələr | C2: Şagird sayı | D2: İştirak etməyən şagird sayı | E2: Tədris dili | F2: Riyaziyyat | G2: Xarici dil | H2: Azərbaycan dili | I2: Orta bal 3 fənn üzrə | J2: Orta faiz 3 fənn üzrə | K2: Orta faiz 4 fənn üzrə | L2: Tədris dili | R2: Riyaziyyat | X2: Xarici dil | AD2: Azərbaycan dili | AJ2: Ümumi 0 bal toplayan şagird sayı | AK2: Ümumi 300 bal toplayan şagird sayı | AL2: BŞTİ üzrə reytinq | AO2: Rayon üzrə reytinq | BP2: Şagird sayı | BQ2: İştirak etməyən şagird sayı | BR2: Tədris dili | BS2: Riyaziyyat | BT2: Xarici dil | BU2: Orta bal 3 fənn üzrə | BV2: Orta faiz 3 fənn üzrə | BW2: Tədris dili | CC2: Riyaziyyat | CI2: Xarici dil | CO2: Ümumi 0 bal toplayan şagird sayı | CP2: Ümumi 300 bal toplayan şagird sayı | CQ2: Şagird sayı | CR2: İştirak etməyən şagird sayı | CS2: Tədris dili | CT2: Riyaziyyat | CU2: Xarici dil | CV2: Azərbaycan dili | CW2: Orta bal 3 fənn üzrə | CX2: Orta faiz 3 fənn üzrə | CY2: Orta faiz 4 fənn üzrə | CZ2: Tədris dili | DF2: Riyaziyyat | DL2: Xarici dil | DR2: Azərbaycan dili | DX2: Ümumi 0 bal toplayan şagird sayı | DY2: Ümumi 300 bal toplayan şagird sayı | DZ2: Şagird sayı | EA2: İştirak etməyən şagird sayı | EB2: Tədris dili | EC2: Riyaziyyat | ED2: Xarici dil | EE2: Azərbaycan dili | EF2: Orta bal 3 fənn üzrə | EG2: Orta faiz 3 fənn üzrə | EH2: Orta faiz 4 fənn üzrə | EI2: Tədris dili | EO2: Riyaziyyat | EU2: Xarici dil | FA2: Azərbaycan dili | FG2: Ümumi 0 bal toplayan şagird sayı | FH2: Ümumi 300 bal toplayan şagird sayı | FI2: BŞTİ üzrə reytinq | FL2: Rayon üzrə reytinq
