Workbook

Sheet Nəticələr dioqramla
E1: 2017-2018-ci tədris ili | O1: 2018-2019-cu tədris ili | Y1: 2019-2020-ci tədris ili | AI1: 2020-2021-ci tədris ili | AS1: 2021-2022-ci tədris ili
A2: Təhlili görmək üçün yaşıl xanaya indeksi daxil edin | C2: İndeks | D2: Növ | E2: Şagird sayı | F2: Tədris dili | G2: Riyaziyyat | H2: Xarici dil | I2: Azərbaycan dili | J2: Orta bal 2 fənn üzrə | K2: Orta faiz 2 fənn üzrə | L2: BŞTİ üzrə reytinq | M2: Dinamika | O2: Şagird sayı | P2: Tədris dili | Q2: Riyaziyyat | R2: Xarici dil | S2: Azərbaycan dili | T2: Orta bal 2 fənn üzrə | U2: Orta faiz 2 fənn üzrə | V2: BŞTİ üzrə reytinq | W2: Dinamika | Y2: Şagird sayı | Z2: Tədris dili | AA2: Riyaziyyat | AB2: Xarici dil | AC2: Azərbaycan dili | AD2: Orta bal 3 fənn üzrə | AE2: Orta faiz 3 fənn üzrə | AF2: BŞTİ üzrə reytinq | AG2: Dinamika | AI2: Şagird sayı | AJ2: Tədris dili | AK2: Riyaziyyat | AL2: Xarici dil | AM2: Azərbaycan dili | AN2: Orta bal 3 fənn üzrə | AO2: Orta faiz 3 fənn üzrə | AP2: BŞTİ üzrə reytinq | AQ2: Dinamika | AS2: Şagird sayı | AT2: Tədris dili | AU2: Riyaziyyat | AV2: Xarici dil | AW2: Azərbaycan dili | AX2: Orta bal 3 fənn üzrə | AY2: Orta faiz 3 fənn üzrə | AZ2: BŞTİ üzrə reytinq | BA2: Dinamika
C3: 99 | D3: =IF(VLOOKUP($C$3,İndekslər!$C$3:$BA$326,2,0)="","",VLOOKUP($C$3,İndekslər!$C$3:$BA$326,2,0)) -> tam orta məktəb | E3: =IF(VLOOKUP($C$3,İndekslər!$C$3:$BA$326,3,0)="","",VLOOKUP($C$3,İndekslər!$C$3:$BA$326,3,0)) -> 131 | F3: =IF(VLOOKUP($C$3,İndekslər!$C$3:$BA$326,4,0)="","",VLOOKUP($C$3,İndekslər!$C$3:$BA$326,4,0)) -> 51.365649 | G3: =IF(VLOOKUP($C$3,İndekslər!$C$3:$BA$326,5,0)="","",VLOOKUP($C$3,İndekslər!$C$3:$BA$326,5,0)) -> 39.020611 | H3: =IF(VLOOKUP($C$3,İndekslər!$C$3:$BA$326,6,0)="","",VLOOKUP($C$3,İndekslər!$C$3:$BA$326,6,0)) | I3: =IF(VLOOKUP($C$3,İndekslər!$C$3:$BA$326,7,0)="","",VLOOKUP($C$3,İndekslər!$C$3:$BA$326,7,0)) | J3: =IF(VLOOKUP($C$3,İndekslər!$C$3:$BA$326,8,0)="","",VLOOKUP($C$3,İndekslər!$C$3:$BA$326,8,0)) -> 90.38626 | K3: =IF(VLOOKUP($C$3,İndekslər!$C$3:$BA$326,9,0)="","",VLOOKUP($C$3,İndekslər!$C$3:$BA$326,9,0)) -> 45.19313 | L3: =IF(VLOOKUP($C$3,İndekslər!$C$3:$BA$326,10,0)="","",VLOOKUP($C$3,İndekslər!$C$3:$BA$326,10,0)) -> 172 | M3: =IF(VLOOKUP($C$3,İndekslər!$C$3:$BA$326,11,0)="","",VLOOKUP($C$3,İndekslər!$C$3:$BA$326,11,0)) -> -0.78187023 | O3: =IF(VLOOKUP($C$3,İndekslər!$C$3:$BA$326,13,0)="","",VLOOKUP($C$3,İndekslər!$C$3:$BA$326,13,0)) -> 130 | P3: =IF(VLOOKUP($C$3,İndekslər!$C$3:$BA$326,14,0)="","",VLOOKUP($C$3,İndekslər!$C$3:$BA$326,14,0)) -> 53.676923 | Q3: =IF(VLOOKUP($C$3,İndekslər!$C$3:$BA$326,15,0)="","",VLOOKUP($C$3,İndekslər!$C$3:$BA$326,15,0)) -> 39.276923 | R3: =IF(VLOOKUP($C$3,İndekslər!$C$3:$BA$326,16,0)="","",VLOOKUP($C$3,İndekslər!$C$3:$BA$326,16,0)) -> 35.7 | S3: =IF(VLOOKUP($C$3,İndekslər!$C$3:$BA$326,17,0)="","",VLOOKUP($C$3,İndekslər!$C$3:$BA$326,17,0)) | T3: =IF(VLOOKUP($C$3,İndekslər!$C$3:$BA$326,18,0)="","",VLOOKUP($C$3,İndekslər!$C$3:$BA$326,18,0)) -> 92.953846 | U3: =IF(VLOOKUP($C$3,İndekslər!$C$3:$BA$326,19,0)="","",VLOOKUP($C$3,İndekslər!$C$3:$BA$326,19,0)) -> 46.476923 | V3: =IF(VLOOKUP($C$3,İndekslər!$C$3:$BA$326,20,0)="","",VLOOKUP($C$3,İndekslər!$C$3:$BA$326,20,0)) -> 153 | W3: =IF(VLOOKUP($C$3,İndekslər!$C$3:$BA$326,21,0)="","",VLOOKUP($C$3,İndekslər!$C$3:$BA$326,21,0)) -> 1.2837933 | Y3: =IF(VLOOKUP($C$3,İndekslər!$C$3:$BA$326,23,0)="","",VLOOKUP($C$3,İndekslər!$C$3:$BA$326,23,0)) -> 134 | Z3: =IF(VLOOKUP($C$3,İndekslər!$C$3:$BA$326,24,0)="","",VLOOKUP($C$3,İndekslər!$C$3:$BA$326,24,0)) -> 52.80916 | AA3: =IF(VLOOKUP($C$3,İndekslər!$C$3:$BA$326,25,0)="","",VLOOKUP($C$3,İndekslər!$C$3:$BA$326,25,0)) -> 49.969466 | AB3: =IF(VLOOKUP($C$3,İndekslər!$C$3:$BA$326,26,0)="","",VLOOKUP($C$3,İndekslər!$C$3:$BA$326,26,0)) -> 36.709924 | AC3: =IF(VLOOKUP($C$3,İndekslər!$C$3:$BA$326,27,0)="","",VLOOKUP($C$3,İndekslər!$C$3:$BA$326,27,0)) | AD3: =IF(VLOOKUP($C$3,İndekslər!$C$3:$BA$326,28,0)="","",VLOOKUP($C$3,İndekslər!$C$3:$BA$326,28,0)) -> 139.48855 | AE3: =IF(VLOOKUP($C$3,İndekslər!$C$3:$BA$326,29,0)="","",VLOOKUP($C$3,İndekslər!$C$3:$BA$326,29,0)) -> 46.496183 | AF3: =IF(VLOOKUP($C$3,İndekslər!$C$3:$BA$326,30,0)="","",VLOOKUP($C$3,İndekslər!$C$3:$BA$326,30,0)) -> 175 | AG3: =IF(VLOOKUP($C$3,İndekslər!$C$3:$BA$326,31,0)="","",VLOOKUP($C$3,İndekslər!$C$3:$BA$326,31,0)) -> 0.019260129 | AI3: =IF(VLOOKUP($C$3,İndekslər!$C$3:$BA$326,33,0)="","",VLOOKUP($C$3,İndekslər!$C$3:$BA$326,33,0)) -> 142 | AJ3: =IF(VLOOKUP($C$3,İndekslər!$C$3:$BA$326,34,0)="","",VLOOKUP($C$3,İndekslər!$C$3:$BA$326,34,0)) -> 43.802817 | AK3: =IF(VLOOKUP($C$3,İndekslər!$C$3:$BA$326,35,0)="","",VLOOKUP($C$3,İndekslər!$C$3:$BA$326,35,0)) -> 39.014085 | AL3: =IF(VLOOKUP($C$3,İndekslər!$C$3:$BA$326,36,0)="","",VLOOKUP($C$3,İndekslər!$C$3:$BA$326,36,0)) -> 32.211268 | AM3: =IF(VLOOKUP($C$3,İndekslər!$C$3:$BA$326,37,0)="","",VLOOKUP($C$3,İndekslər!$C$3:$BA$326,37,0)) | AN3: =IF(VLOOKUP($C$3,İndekslər!$C$3:$BA$326,38,0)="","",VLOOKUP($C$3,İndekslər!$C$3:$BA$326,38,0)) -> 115.02817 | AO3: =IF(VLOOKUP($C$3,İndekslər!$C$3:$BA$326,39,0)="","",VLOOKUP($C$3,İndekslər!$C$3:$BA$326,39,0)) -> 38.342723 | AP3: =IF(VLOOKUP($C$3,İndekslər!$C$3:$BA$326,40,0)="","",VLOOKUP($C$3,İndekslər!$C$3:$BA$326,40,0)) -> 224 | AQ3: =IF(VLOOKUP($C$3,İndekslər!$C$3:$BA$326,41,0)="","",VLOOKUP($C$3,İndekslər!$C$3:$BA$326,41,0)) -> -8.1534602 | AS3: =IF(VLOOKUP($C$3,İndekslər!$C$3:$BA$326,43,0)="","",VLOOKUP($C$3,İndekslər!$C$3:$BA$326,43,0)) -> 135 | AT3: =IF(VLOOKUP($C$3,İndekslər!$C$3:$BA$326,44,0)="","",VLOOKUP($C$3,İndekslər!$C$3:$BA$326,44,0)) -> 54.821094 | AU3: =IF(VLOOKUP($C$3,İndekslər!$C$3:$BA$326,45,0)="","",VLOOKUP($C$3,İndekslər!$C$3:$BA$326,45,0)) -> 32.075 | AV3: =IF(VLOOKUP($C$3,İndekslər!$C$3:$BA$326,46,0)="","",VLOOKUP($C$3,İndekslər!$C$3:$BA$326,46,0)) -> 36.485937 | AW3: =IF(VLOOKUP($C$3,İndekslər!$C$3:$BA$326,47,0)="","",VLOOKUP($C$3,İndekslər!$C$3:$BA$326,47,0)) | AX3: =IF(VLOOKUP($C$3,İndekslər!$C$3:$BA$326,48,0)="","",VLOOKUP($C$3,İndekslər!$C$3:$BA$326,48,0)) -> 123.38203 | AY3: =IF(VLOOKUP($C$3,İndekslər!$C$3:$BA$326,49,0)="","",VLOOKUP($C$3,İndekslər!$C$3:$BA$326,49,0)) -> 41.127344 | AZ3: =IF(VLOOKUP($C$3,İndekslər!$C$3:$BA$326,50,0)="","",VLOOKUP($C$3,İndekslər!$C$3:$BA$326,50,0)) -> 146 | BA3: =IF(VLOOKUP($C$3,İndekslər!$C$3:$BA$326,51,0)="","",VLOOKUP($C$3,İndekslər!$C$3:$BA$326,51,0)) -> 2.7846207

Sheet İndekslər
E1: 2017-2018-ci tədris ili | O1: 2018-2019-cu tədris ili | Y1: 2019-2020-cu tədris ili | AI1: 2020-2021-ci tədris ili | AS1: 2021-2022-ci tədris ili
A2: № | B2: Rayon | C2: Ümumi təhsil müəssisəsinin indeksi | D2: Növ | E2: Şagird sayı | F2: Tədris dili | G2: Riyaziyyat | H2: Xarici dil | I2: Azərbaycan dili | J2: Orta bal 2 fənn üzrə | K2: Orta faiz 2 fənn üzrə | L2: BŞTİ üzrə reytinq | M2: Dinamika | O2: Şagird sayı | P2: Tədris dili | Q2: Riyaziyyat | R2: Xarici dil | S2: Azərbaycan dili | T2: Orta bal 2 fənn üzrə | U2: Orta faiz 2 fənn üzrə | V2: BŞTİ üzrə reytinq | W2: Dinamika | Y2: Şagird sayı | Z2: Tədris dili | AA2: Riyaziyyat | AB2: Xarici dil | AC2: Azərbaycan dili | AD2: Orta bal 3 fənn üzrə | AE2: Orta faiz 3 fənn üzrə | AF2: BŞTİ üzrə reytinq | AG2: Dinamika | AI2: Şagird sayı | AJ2: Tədris dili | AK2: Riyaziyyat | AL2: Xarici dil | AM2: Azərbaycan dili | AN2: Orta bal 3 fənn üzrə | AO2: Orta faiz 3 fənn üzrə | AP2: BŞTİ üzrə reytinq | AQ2: Dinamika | AS2: Şagird sayı | AT2: Tədris dili | AU2: Riyaziyyat | AV2: Xarici dil | AW2: Azərbaycan dili | AX2: Orta bal 3 fənn üzrə | AY2: Orta faiz 3 fənn üzrə | AZ2: BŞTİ üzrə reytinq | BA2: Dinamika
A3: Orta nəticələr | B3: Bakı | C3: BŞTİ | D3: Bütün | E3: 27084 | F3: 52.95597 | G3: 40.073498 | J3: 93.029468 | K3: 46.514734 | M3: -0.48 | O3: 27690 | P3: 51.697217 | Q3: 41.761968 | R3: 37.279878 | T3: 93.459184 | U3: 46.729592 | W3: 0.21485808 | Y3: 35227 | Z3: 54.751401 | AA3: 49.314722 | AB3: 39.797179 | AD3: 143.8633 | AE3: 47.954434 | AG3: 1.2248417 | AI3: 34096 | AJ3: 51.190751 | AK3: 42.021915 | AL3: 41.307944 | AM3: 52.308901 | AN3: 134.50601 | AO3: 44.837477 | AQ3: =AO3-AE3 -> -3.1169572 | AS3: 34813 | AT3: 54.484055 | AU3: 33.023661 | AV3: 38.848735 | AW3: 56.899834 | AX3: 126.35645 | AY3: 42.118817 | BA3: =AY3-AO3 -> -2.7186598
A4: 1 | B4: Binəqədi | C4: 3 | D4: tam orta məktəb | E4: 88 | F4: 64.354545 | G4: 47.285227 | J4: 111.63977 | K4: 55.819886 | L4: 35 | M4: 3.6698864 | O4: 89 | P4: 60.651685 | Q4: 47.617978 | R4: 41.94382 | T4: 108.26966 | U4: 54.134831 | V4: 39 | W4: -1.6850549 | Y4: 139 | Z4: 57.597222 | AA4: 48.541667 | AB4: 40.625 | AD4: 146.76389 | AE4: 48.921296 | AF4: 136 | AG4: -5.2135352 | AI4: 95 | AJ4: 51.357895 | AK4: 45.094737 | AL4: 39.968421 | AN4: 136.42105 | AO4: 45.473684 | AP4: 126 | AQ4: -3.4476121 | AS4: 132 | AT4: 64.293939 | AU4: 40.356818 | AV4: 45.834091 | AX4: 150.48485 | AY4: 50.161616 | AZ4: 33 | BA4: 4.687932
A5: 2 | B5: Binəqədi | C5: 6u | D5: UGİM | AS5: 0
A6: 3 | B6: Binəqədi | C6: 30 | D6: tam orta məktəb | E6: 32 | F6: 53.6625 | G6: 41.21875 | J6: 94.88125 | K6: 47.440625 | L6: 144 | M6: 2.0537829 | O6: 45 | P6: 50.066667 | Q6: 39.266667 | R6: 42.644444 | T6: 89.333333 | U6: 44.666667 | V6: 186 | W6: -2.7739583 | Y6: 47 | Z6: 58.621622 | AA6: 60.621622 | AB6: 45.945946 | AD6: 165.18919 | AE6: 55.063063 | AF6: 37 | AG6: 10.396396 | AI6: 60 | AJ6: 47.15 | AK6: 37.533333 | AL6: 37.083333 | AM6: 57.222222 | AN6: 121.76667 | AO6: 40.588889 | AP6: 194 | AQ6: -14.474174 | AS6: 45 | AT6: 51.875556 | AU6: 32.768889 | AV6: 36.271111 | AW6: 57.615385 | AX6: 120.91556 | AY6: 40.305185 | AZ6: 161 | BA6: -0.2837037
A7: 4 | B7: Binəqədi | C7: 83 | D7: məktəb-lisey | E7: 125 | F7: 67.2984 | G7: 57.044 | J7: 124.3424 | K7: 62.1712 | L7: 11 | M7: 5.0712 | O7: 147 | P7: 64.44898 | Q7: 53.517007 | R7: 53.55102 | T7: 117.96599 | U7: 58.982993 | V7: 18 | W7: -3.1882068 | Y7: 175 | Z7: 66.666667 | AA7: 60.943262 | AB7: 51.808511 | AD7: 179.41844 | AE7: 59.806147 | AF7: 14 | AG7: 0.82315337 | AI7: 163 | AJ7: 56.306748 | AK7: 48.490798 | AL7: 49.030675 | AM7: 59.265625 | AN7: 153.82822 | AO7: 51.276074 | AP7: 55 | AQ7: -8.530073 | AS7: 167 | AT7: 68.638922 | AU7: 40.982036 | AV7: 52.743114 | AW7: 62.561404 | AX7: 162.36407 | AY7: 54.121357 | AZ7: 14 | BA7: 2.8452837
A8: 5 | B8: Binəqədi | C8: 99 | D8: tam orta məktəb | E8: 131 | F8: 51.365649 | G8: 39.020611 | J8: 90.38626 | K8: 45.19313 | L8: 172 | M8: -0.78187023 | O8: 130 | P8: 53.676923 | Q8: 39.276923 | R8: 35.7 | T8: 92.953846 | U8: 46.476923 | V8: 153 | W8: 1.2837933 | Y8: 134 | Z8: 52.80916 | AA8: 49.969466 | AB8: 36.709924 | AD8: 139.48855 | AE8: 46.496183 | AF8: 175 | AG8: 0.019260129 | AI8: 142 | AJ8: 43.802817 | AK8: 39.014085 | AL8: 32.211268 | AN8: 115.02817 | AO8: 38.342723 | AP8: 224 | AQ8: -8.1534602 | AS8: 135 | AT8: 54.821094 | AU8: 32.075 | AV8: 36.485937 | AX8: 123.38203 | AY8: 41.127344 | AZ8: 146 | BA8: 2.7846207
A9: 6 | B9: Binəqədi | C9: 100 | D9: tam orta məktəb | E9: 82 | F9: 48.460976 | G9: 34.776829 | J9: 83.237805 | K9: 41.618902 | L9: 225 | M9: -2.3279157 | O9: 110 | P9: 51.990909 | Q9: 42.463636 | R9: 35.272727 | T9: 94.454545 | U9: 47.227273 | V9: 133 | W9: 5.6083703 | Y9: 135 | Z9: 53 | AA9: 50.522523 | AB9: 38.441441 | AD9: 141.96396 | AE9: 47.321321 | AF9: 162 | AG9: 0.094048594 | AI9: 139 | AJ9: 46.906475 | AK9: 39.827338 | AL9: 40.215827 | AM9: 60.411765 | AN9: 126.94964 | AO9: 42.316547 | AP9: 168 | AQ9: -5.0047746 | AS9: 135 | AT9: 56.305926 | AU9: 32.388889 | AV9: 39.200741 | AW9: 53.875 | AX9: 127.89556 | AY9: 42.631852 | AZ9: 127 | BA9: 0.31530509
A10: 7 | B10: Binəqədi | C10: 102 | D10: tam orta məktəb | E10: 61 | F10: 60.342623 | G10: 47.688525 | J10: 108.03115 | K10: 54.015574 | L10: 51 | M10: -0.98580238 | O10: 86 | P10: 54.906977 | Q10: 48.430233 | R10: 47.127907 | T10: 103.33721 | U10: 51.668605 | V10: 75 | W10: -2.3469691 | Y10: 104 | Z10: 62.731707 | AA10: 52.865854 | AB10: 47.45122 | AD10: 163.04878 | AE10: 54.349593 | AF10: 41 | AG10: 2.6809888 | AI10: 121 | AJ10: 58.033333 | AK10: 48.066667 | AL10: 49.866667 | AM10: 59.652778 | AN10: 155.96667 | AO10: 51.988889 | AP10: 49 | AQ10: -2.3607046 | AS10: 100 | AT10: 62.342 | AU10: 36.568 | AV10: 43.467 | AW10: 64.606557 | AX10: 142.377 | AY10: 47.459 | AZ10: 58 | BA10: -4.5298889
A11: 8 | B11: Binəqədi | C11: 103 | D11: tam orta məktəb | E11: 49 | F11: 48.65102 | G11: 34.053061 | J11: 82.704082 | K11: 41.352041 | L11: 231 | M11: -0.58049887 | O11: 86 | P11: 47.197674 | Q11: 33.790698 | R11: 28.476744 | T11: 80.988372 | U11: 40.494186 | V11: 252 | W11: -0.85785477 | Y11: 106 | Z11: 44.107143 | AA11: 40.845238 | AB11: 31.880952 | AD11: 116.83333 | AE11: 38.944444 | AF11: 279 | AG11: -1.5497416 | AI11: 95 | AJ11: 39.884211 | AK11: 32.884211 | AL11: 27.768421 | AN11: 100.53684 | AO11: 33.512281 | AP11: 272 | AQ11: -5.4321637 | AS11: 109 | AT11: 46.690741 | AU11: 25.368519 | AV11: 29.027778 | AX11: 101.08704 | AY11: 33.695679 | AZ11: 265 | BA11: 0.18339831
A12: 9 | B12: Binəqədi | C12: 115x | D12: XƏQTOM | AS12: 7 | AT12: 30.657143 | AU12: 28.071429 | AV12: 15.114286 | AX12: 73.842857 | AY12: 24.614286 | AZ12: 307 | BA12: #VALUE!
A13: 10 | B13: Binəqədi | C13: 115 | D13: tam orta məktəb | E13: 123 | F13: 57.10813 | G13: 41.430894 | J13: 98.539024 | K13: 49.269512 | L13: 117 | M13: -1.7808211 | O13: 149 | P13: 53.817568 | Q13: 42.810811 | R13: 41.993243 | T13: 96.628378 | U13: 48.314189 | V13: 123 | W13: -0.95532301 | Y13: 135 | Z13: 58.611111 | AA13: 53.402778 | AB13: 43.194444 | AD13: 155.20833 | AE13: 51.736111 | AF13: 71 | AG13: 3.4219219 | AI13: 144 | AJ13: 52.069444 | AK13: 40.555556 | AL13: 44.229167 | AM13: 54.384615 | AN13: 136.85417 | AO13: 45.618056 | AP13: 124 | AQ13: -6.1180556 | AS13: 132 | AT13: 57.454545 | AU13: 31.694697 | AV13: 39.592424 | AW13: 53.222222 | AX13: 128.74167 | AY13: 42.913889 | AZ13: 121 | BA13: -2.7041667
A14: 11 | B14: Binəqədi | C14: 126 | D14: TN | E14: 53 | F14: 56.318868 | G14: 41.456604 | J14: 97.775472 | K14: 48.887736 | L14: 123 | M14: 2.1885692 | O14: 73 | P14: 49.236111 | Q14: 35.736111 | R14: 33.055556 | T14: 84.972222 | U14: 42.486111 | V14: 216 | W14: -6.4016247 | Y14: 85 | Z14: 52.589041 | AA14: 42.767123 | AB14: 36.863014 | AD14: 132.21918 | AE14: 44.073059 | AF14: 227 | AG14: 1.5869482 | AI14: 84 | AJ14: 44.809524 | AK14: 36.666667 | AL14: 35.369048 | AM14: 51.578947 | AN14: 116.84524 | AO14: 38.948413 | AP14: 218 | AQ14: -5.1246467 | AS14: 80 | AT14: 54.131646 | AU14: 27.674684 | AV14: 38.34557 | AW14: 52.8 | AX14: 120.1519 | AY14: 40.050633 | AZ14: 163 | BA14: 1.1022202
A15: 12 | B15: Binəqədi | C15: 135 | D15: tam orta məktəb | E15: 43 | F15: 50.734884 | G15: 37.755814 | J15: 88.490698 | K15: 44.245349 | L15: 189 | M15: 0.71284884 | O15: 43 | P15: 51.627907 | Q15: 46.093023 | R15: 40.674419 | T15: 97.72093 | U15: 48.860465 | V15: 115 | W15: 4.6151163 | Y15: 56 | Z15: 49.714286 | AA15: 46.02381 | AB15: 36.738095 | AD15: 132.47619 | AE15: 44.15873 | AF15: 225 | AG15: -4.701735 | AI15: 49 | AJ15: 45.693878 | AK15: 38.122449 | AL15: 42.795918 | AN15: 126.61224 | AO15: 42.204082 | AP15: 171 | AQ15: -1.9546485 | AS15: 54 | AT15: 55.524074 | AU15: 31.446296 | AV15: 41.942593 | AX15: 128.91296 | AY15: 42.970988 | AZ15: 118 | BA15: 0.76690602
A16: 13 | B16: Binəqədi | C16: 143 | D16: tam orta məktəb | E16: 74 | F16: 62.343243 | G16: 42.145946 | J16: 104.48919 | K16: 52.244595 | L16: 73 | M16: 1.9985946 | O16: 58 | P16: 55.741379 | Q16: 43.965517 | R16: 41.724138 | T16: 99.706897 | U16: 49.853448 | V16: 104 | W16: -2.3911463 | Y16: 89 | Z16: 59.783784 | AA16: 51.256757 | AB16: 44.121622 | AD16: 155.16216 | AE16: 51.720721 | AF16: 73 | AG16: 1.8672724 | AI16: 89 | AJ16: 53.977528 | AK16: 42.337079 | AL16: 38.449438 | AM16: 58.695652 | AN16: 134.76404 | AO16: 44.921348 | AP16: 135 | AQ16: -6.7993724 | AS16: 91 | AT16: 56.659341 | AU16: 27.49011 | AV16: 38.979121 | AW16: 63.772727 | AX16: 123.12857 | AY16: 41.042857 | AZ16: 147 | BA16: -3.8784912
A17: 14 | B17: Binəqədi | C17: 144 | D17: tam orta məktəb | E17: 51 | F17: 59.04902 | G17: 47.688235 | J17: 106.73725 | K17: 53.368627 | L17: 56 | M17: 5.8280614 | O17: 49 | P17: 61.857143 | Q17: 48.918367 | R17: 44.510204 | T17: 110.77551 | U17: 55.387755 | V17: 29 | W17: 2.0191277 | Y17: 70 | Z17: 57.903226 | AA17: 54.080645 | AB17: 42.209677 | AD17: 154.19355 | AE17: 51.397849 | AF17: 82 | AG17: -3.9899056 | AI17: 70 | AJ17: 51.628571 | AK17: 48.057143 | AL17: 40.457143 | AN17: 140.14286 | AO17: 46.714286 | AP17: 110 | AQ17: -4.6835637 | AS17: 68 | AT17: 57.627941 | AU17: 34.605882 | AV17: 39.529412 | AX17: 131.76324 | AY17: 43.921078 | AZ17: 102 | BA17: -2.7932073
A18: 15 | B18: Binəqədi | C18: 157 | D18: tam orta məktəb | E18: 95 | F18: 57.996842 | G18: 46.284211 | J18: 104.28105 | K18: 52.140526 | L18: 74 | M18: -2.3961404 | O18: 89 | P18: 55.247191 | Q18: 48.921348 | R18: 43.460674 | T18: 104.16854 | U18: 52.08427 | V18: 67 | W18: -0.056256653 | Y18: 110 | Z18: 56.886076 | AA18: 50.303797 | AB18: 40.759494 | AD18: 147.94937 | AE18: 49.316456 | AF18: 128 | AG18: -2.767814 | AI18: 91 | AJ18: 54.032967 | AK18: 47.868132 | AL18: 41.417582 | AM18: 55.5 | AN18: 143.31868 | AO18: 47.772894 | AP18: 96 | AQ18: -1.5435619 | AS18: 107 | AT18: 59.491589 | AU18: 38.248598 | AV18: 43.542056 | AW18: 57.1875 | AX18: 141.28224 | AY18: 47.094081 | AZ18: 62 | BA18: -0.67881278
A19: 16 | B19: Binəqədi | C19: 179 | D19: tam orta məktəb | E19: 193 | F19: 52.366839 | G19: 39.431088 | J19: 91.797927 | K19: 45.898964 | L19: 162 | M19: 2.1570718 | O19: 202 | P19: 43.282178 | Q19: 33.316832 | R19: 30.787129 | T19: 76.59901 | U19: 38.299505 | V19: 271 | W19: -7.5994588 | Y19: 262 | Z19: 53.118421 | AA19: 43.991228 | AB19: 38.412281 | AD19: 135.52193 | AE19: 45.173977 | AF19: 203 | AG19: 6.8744717 | AI19: 270 | AJ19: 43.851852 | AK19: 36.77037 | AL19: 31.848148 | AM19: 61.058824 | AN19: 112.47037 | AO19: 37.490123 | AP19: 233 | AQ19: -7.6838532 | AS19: 258 | AT19: 46.229134 | AU19: 24.413386 | AV19: 29.516535 | AW19: 55.583333 | AX19: 100.15906 | AY19: 33.386352 | AZ19: 268 | BA19: -4.1037718
A20: 17 | B20: Binəqədi | C20: 182 | D20: tam orta məktəb | E20: 254 | F20: 49.93189 | G20: 38.291339 | J20: 88.223228 | K20: 44.111614 | L20: 191 | M20: -0.88919883 | O20: 276 | P20: 50.610909 | Q20: 38.272727 | R20: 36.592727 | T20: 88.883636 | U20: 44.441818 | V20: 188 | W20: 0.33020401 | Y20: 414 | Z20: 51.582759 | AA20: 45.541379 | AB20: 37.972414 | AD20: 135.09655 | AE20: 45.032184 | AF20: 208 | AG20: 0.59036573 | AI20: 363 | AJ20: 45.991736 | AK20: 41.564738 | AL20: 33.92011 | AN20: 121.47658 | AO20: 40.492195 | AP20: 196 | AQ20: -4.5399892 | AS20: 415 | AT20: 52.037772 | AU20: 29.79201 | AV20: 33.639467 | AX20: 115.46925 | AY20: 38.48975 | AZ20: 195 | BA20: -2.0024449
A21: 18 | B21: Binəqədi | C21: 205 | D21: tam orta məktəb | E21: 112 | F21: 42.292857 | G21: 31.232143 | J21: 73.525 | K21: 36.7625 | L21: 266 | M21: -4.9513554 | O21: 90 | P21: 48.977778 | Q21: 39.466667 | R21: 32.022222 | T21: 88.444444 | U21: 44.222222 | V21: 194 | W21: 7.4597222 | Y21: 116 | Z21: 51 | AA21: 45.009174 | AB21: 37.275229 | AD21: 133.2844 | AE21: 44.428135 | AF21: 218 | AG21: 0.20591233 | AI21: 109 | AJ21: 40.330275 | AK21: 35.853211 | AL21: 30.981651 | AN21: 107.16514 | AO21: 35.721713 | AP21: 256 | AQ21: -8.706422 | AS21: 115 | AT21: 50.60087 | AU21: 25.633043 | AV21: 33.142609 | AX21: 109.37652 | AY21: 36.458841 | AZ21: 234 | BA21: 0.73712804
A22: 19 | B22: Binəqədi | C22: 217 | D22: tam orta məktəb | E22: 189 | F22: 50.810582 | G22: 35.872487 | J22: 86.683069 | K22: 43.341534 | L22: 202 | M22: -6.5986295 | O22: 188 | P22: 51.271277 | Q22: 40.691489 | R22: 34.856383 | T22: 91.962766 | U22: 45.981383 | V22: 159 | W22: 2.6398486 | Y22: 236 | Z22: 53.946078 | AA22: 48.941176 | AB22: 35.784314 | AD22: 138.67157 | AE22: 46.223856 | AF22: 181 | AG22: 0.24247323 | AI22: 224 | AJ22: 46.450893 | AK22: 38 | AL22: 32.834821 | AN22: 117.28571 | AO22: 39.095238 | AP22: 213 | AQ22: -7.1286181 | AS22: 229 | AT22: 49.210965 | AU22: 26.892982 | AV22: 30.735965 | AX22: 106.83991 | AY22: 35.613304 | AZ22: 244 | BA22: -3.481934
A23: 20 | B23: Binəqədi | C23: 244 | D23: tam orta məktəb | E23: 167 | F23: 58.407784 | G23: 46.824551 | J23: 105.23234 | K23: 52.616168 | L23: 71 | M23: -2.1457529 | O23: 154 | P23: 58.681818 | Q23: 45.805195 | R23: 44.844156 | T23: 104.48701 | U23: 52.243506 | V23: 64 | W23: -0.37266117 | Y23: 208 | Z23: 59.204969 | AA23: 53.57764 | AB23: 42.298137 | AD23: 155.08075 | AE23: 51.693582 | AF23: 74 | AG23: -0.54992471 | AI23: 199 | AJ23: 48.477387 | AK23: 36.241206 | AL23: 41.904523 | AN23: 126.62312 | AO23: 42.207705 | AP23: 170 | AQ23: -9.4858766 | AS23: 207 | AT23: 60.372947 | AU23: 34.483092 | AV23: 42.070531 | AW23: 58.611111 | AX23: 136.92657 | AY23: 45.64219 | AZ23: 87 | BA23: 3.4344848
A24: 21 | B24: Binəqədi | C24: 246 | D24: məktəb-lisey | E24: 98 | F24: 61.991837 | G24: 44.304082 | J24: 106.29592 | K24: 53.147959 | L24: 61 | M24: 3.84332 | O24: 111 | P24: 58.198198 | Q24: 46.63964 | R24: 44.324324 | T24: 104.83784 | U24: 52.418919 | V24: 61 | W24: -0.72904026 | Y24: 145 | Z24: 55.99115 | AA24: 51.893805 | AB24: 41.884956 | AD24: 149.76991 | AE24: 49.923304 | AF24: 116 | AG24: -2.4956151 | AI24: 138 | AJ24: 50.376812 | AK24: 43.971014 | AL24: 42.173913 | AM24: 57.555556 | AN24: 136.52174 | AO24: 45.507246 | AP24: 125 | AQ24: -4.4160575 | AS24: 138 | AT24: 59.938971 | AU24: 36.7 | AV24: 42.343382 | AW24: 59.444444 | AX24: 138.98235 | AY24: 46.327451 | AZ24: 74 | BA24: 0.8202046
A25: 22 | B25: Binəqədi | C25: 248 | D25: tam orta məktəb | E25: 92 | F25: 54.191304 | G25: 40.740217 | J25: 94.931522 | K25: 47.465761 | L25: 143 | M25: -4.5474259 | O25: 120 | P25: 53.666667 | Q25: 47.85 | R25: 44.066667 | T25: 101.51667 | U25: 50.758333 | V25: 92 | W25: 3.2925725 | Y25: 141 | Z25: 57.145455 | AA25: 51.1 | AB25: 44.590909 | AD25: 152.83636 | AE25: 50.945455 | AF25: 93 | AG25: 0.18712121 | AI25: 108 | AJ25: 49.638889 | AK25: 39.740741 | AL25: 42.138889 | AM25: 54.054054 | AN25: 131.51852 | AO25: 43.839506 | AP25: 144 | AQ25: -7.1059484 | AS25: 145 | AT25: 60.911034 | AU25: 36.266897 | AV25: 46.131724 | AW25: 58.166667 | AX25: 143.30966 | AY25: 47.769885 | AZ25: 56 | BA25: 3.9303789
A26: 23 | B26: Binəqədi | C26: 267 | D26: məktəb-lisey | E26: 100 | F26: 60.894 | G26: 50.849 | J26: 111.743 | K26: 55.8715 | L26: 34 | M26: 2.7819839 | O26: 110 | P26: 58.272727 | Q26: 51.281818 | R26: 46.309091 | T26: 109.55455 | U26: 54.777273 | V26: 34 | W26: -1.0942273 | Y26: 142 | Z26: 62.378151 | AA26: 55.831933 | AB26: 49.042017 | AD26: 167.2521 | AE26: 55.7507 | AF26: 30 | AG26: 0.97342755 | AI26: 143 | AJ26: 55.923077 | AK26: 46.377622 | AL26: 50.048951 | AM26: 56.927711 | AN26: 152.34965 | AO26: 50.783217 | AP26: 60 | AQ26: -4.9674835 | AS26: 133 | AT26: 61.586466 | AU26: 37.155639 | AV26: 44.73609 | AW26: 57.435484 | AX26: 143.4782 | AY26: 47.826065 | AZ26: 55 | BA26: -2.9571516
A27: 24 | B27: Binəqədi | C27: 276 | D27: tam orta məktəb | E27: 100 | F27: 56.342 | G27: 45.409 | J27: 101.751 | K27: 50.8755 | L27: 96 | M27: 3.5153936 | O27: 101 | P27: 54.059406 | Q27: 46.722772 | R27: 42.80198 | T27: 100.78218 | U27: 50.391089 | V27: 99 | W27: -0.48441089 | Y27: 135 | Z27: 57.487179 | AA27: 50.017094 | AB27: 44.547009 | AD27: 152.05128 | AE27: 50.683761 | AF27: 97 | AG27: 0.29267157 | AI27: 129 | AJ27: 51.449612 | AK27: 43.782946 | AL27: 43.209302 | AM27: 52.863636 | AN27: 138.44186 | AO27: 46.147287 | AP27: 120 | AQ27: -4.5364739 | AS27: 132 | AT27: 59.577863 | AU27: 31.258015 | AV27: 45.754198 | AW27: 54.822222 | AX27: 136.59008 | AY27: 45.530025 | AZ27: 90 | BA27: -0.61726138
A28: 25 | B28: Binəqədi | C28: 283 | D28: tam orta məktəb | E28: 92 | F28: 58.786957 | G28: 47.01087 | J28: 105.79783 | K28: 52.898913 | L28: 63 | M28: 1.4440217 | O28: 93 | P28: 60.752688 | Q28: 56.860215 | R28: 46.354839 | T28: 117.6129 | U28: 58.806452 | V28: 20 | W28: 5.9075386 | Y28: 112 | Z28: 61.279279 | AA28: 56.828829 | AB28: 45.459459 | AD28: 163.56757 | AE28: 54.522523 | AF28: 39 | AG28: -4.2839291 | AI28: 115 | AJ28: 49.342105 | AK28: 42.105263 | AL28: 41.280702 | AM28: 67.5 | AN28: 132.72807 | AO28: 44.24269 | AP28: 142 | AQ28: -10.279832 | AS28: 107 | AT28: 54.299038 | AU28: 33.236538 | AV28: 38.881731 | AW28: 60.5 | AX28: 126.41731 | AY28: 42.139103 | AZ28: 131 | BA28: -2.1035875
A29: 26 | B29: Binəqədi | C29: 284 | D29: tam orta məktəb | E29: 163 | F29: 51.160123 | G29: 38.988957 | J29: 90.14908 | K29: 45.07454 | L29: 173 | M29: 1.6289616 | O29: 215 | P29: 48.893023 | Q29: 38.283721 | R29: 33.52093 | T29: 87.176744 | U29: 43.588372 | V29: 202 | W29: -1.4861678 | Y29: 264 | Z29: 49.900901 | AA29: 46.671171 | AB29: 35.783784 | AD29: 132.35586 | AE29: 44.118619 | AF29: 226 | AG29: 0.53024653 | AI29: 262 | AJ29: 43.385496 | AK29: 34.473282 | AL29: 32.045802 | AM29: 54.235294 | AN29: 109.90458 | AO29: 36.63486 | AP29: 247 | AQ29: -7.4837586 | AS29: 284 | AT29: 50.148043 | AU29: 27.853025 | AV29: 32.301779 | AW29: 61.605263 | AX29: 110.30285 | AY29: 36.767616 | AZ29: 229 | BA29: 0.13275561
A30: 27 | B30: Binəqədi | C30: 297 | D30: tam orta məktəb | E30: 141 | F30: 58.648936 | G30: 42.180851 | J30: 100.82979 | K30: 50.414894 | L30: 101 | M30: 2.5568399 | O30: 155 | P30: 49.409091 | Q30: 40.344156 | R30: 37.623377 | T30: 89.753247 | U30: 44.876623 | V30: 184 | W30: -5.5382702 | Y30: 204 | Z30: 55.216049 | AA30: 47.876543 | AB30: 38.320988 | AD30: 141.41358 | AE30: 47.13786 | AF30: 165 | AG30: 2.2612367 | AI30: 172 | AJ30: 46.563953 | AK30: 37.906977 | AL30: 34.25 | AM30: 56.888889 | AN30: 118.72093 | AO30: 39.573643 | AP30: 207 | AQ30: -7.5642167 | AS30: 198 | AT30: 57.983838 | AU30: 33.034848 | AV30: 38.218687 | AW30: 53.59375 | AX30: 129.23737 | AY30: 43.079125 | AZ30: 114 | BA30: 3.5054812
A31: 28 | B31: Binəqədi | C31: 298 | D31: tam orta məktəb | E31: 67 | F31: 47.089552 | G31: 33.147761 | J31: 80.237313 | K31: 40.118657 | L31: 245 | M31: -8.8988036 | O31: 66 | P31: 52.484848 | Q31: 35.712121 | R31: 30.80303 | T31: 88.19697 | U31: 44.098485 | V31: 196 | W31: 3.9798281 | Y31: 80 | Z31: 58.590909 | AA31: 41.340909 | AB31: 34.522727 | AD31: 134.45455 | AE31: 44.818182 | AF31: 213 | AG31: 0.71969697 | AI31: 63 | AJ31: 45.063492 | AK31: 37.079365 | AL31: 29.84127 | AN31: 111.98413 | AO31: 37.328042 | AP31: 236 | AQ31: -7.4901395 | AS31: 77 | AT31: 57.397368 | AU31: 27.443421 | AV31: 31.969737 | AX31: 116.81053 | AY31: 38.936842 | AZ31: 188 | BA31: 1.6087998
A32: 29 | B32: Binəqədi | C32: 299 | D32: məktəb-lisey | E32: 167 | F32: 58.663473 | G32: 47.979641 | J32: 106.64311 | K32: 53.321557 | L32: 59 | M32: 1.4789762 | O32: 160 | P32: 56.59375 | Q32: 47.61875 | R32: 44.3 | T32: 104.2125 | U32: 52.10625 | V32: 65 | W32: -1.2153069 | Y32: 205 | Z32: 63.857143 | AA32: 59.068783 | AB32: 46.137566 | AD32: 169.06349 | AE32: 56.354497 | AF32: 27 | AG32: 4.2482474 | AI32: 176 | AJ32: 55.573864 | AK32: 48.613636 | AL32: 48.329545 | AM32: 62.259259 | AN32: 152.51705 | AO32: 50.839015 | AP32: 59 | AQ32: -5.5154822 | AS32: 193 | AT32: 62.97772 | AU32: 38.170984 | AV32: 43.994301 | AW32: 65.064516 | AX32: 145.14301 | AY32: 48.381002 | AZ32: 48 | BA32: -2.4580134
A33: 30 | B33: Binəqədi | C33: 300 | D33: tam orta məktəb | E33: 108 | F33: 49.942593 | G33: 34.07963 | J33: 84.022222 | K33: 42.011111 | L33: 220 | M33: -7.1453774 | O33: 131 | P33: 51.40458 | Q33: 38.374046 | R33: 35.664122 | T33: 89.778626 | U33: 44.889313 | V33: 183 | W33: 2.8782019 | Y33: 154 | Z33: 55.89916 | AA33: 47.89916 | AB33: 40.815126 | AD33: 144.61345 | AE33: 48.204482 | AF33: 148 | AG33: 3.3151688 | AI33: 166 | AJ33: 53.542169 | AK33: 44.048193 | AL33: 40.710843 | AM33: 51.344828 | AN33: 138.3012 | AO33: 46.100402 | AP33: 121 | AQ33: -2.1040802 | AS33: 148 | AT33: 58.948299 | AU33: 29.740816 | AV33: 39.213605 | AW33: 65.925926 | AX33: 127.90272 | AY33: 42.63424 | AZ33: 126 | BA33: -3.4661612
A34: 31 | B34: Binəqədi | C34: 301 | D34: tam orta məktəb | E34: 76 | F34: 48.2 | G34: 34.969737 | J34: 83.169737 | K34: 41.584868 | L34: 226 | M34: -1.149677 | O34: 62 | P34: 41.822581 | Q34: 33.209677 | R34: 27.096774 | T34: 75.032258 | U34: 37.516129 | V34: 277 | W34: -4.0687394 | Y34: 78 | Z34: 47.029412 | AA34: 44.352941 | AB34: 31.264706 | AD34: 122.64706 | AE34: 40.882353 | AF34: 265 | AG34: 3.3662239 | AI34: 84 | AJ34: 40.083333 | AK34: 34.190476 | AL34: 31.952381 | AN34: 106.22619 | AO34: 35.40873 | AP34: 261 | AQ34: -5.4736228 | AS34: 75 | AT34: 48.954667 | AU34: 24.464 | AV34: 30.157333 | AX34: 103.576 | AY34: 34.525333 | AZ34: 259 | BA34: -0.88339683
A35: 32 | B35: Binəqədi | C35: 306 | D35: tam orta məktəb | E35: 69 | F35: 43.2 | G35: 32.507246 | J35: 75.707246 | K35: 37.853623 | L35: 260 | M35: -6.2830435 | O35: 66 | P35: 43.227273 | Q35: 33.363636 | R35: 31.257576 | T35: 76.590909 | U35: 38.295455 | V35: 272 | W35: 0.44183136 | Y35: 115 | Z35: 50.883721 | AA35: 46.383721 | AB35: 36.372093 | AD35: 133.63953 | AE35: 44.546512 | AF35: 217 | AG35: 6.2510571 | AI35: 88 | AJ35: 41.238636 | AK35: 36.090909 | AL35: 29.068182 | AN35: 106.39773 | AO35: 35.465909 | AP35: 260 | AQ35: -9.0806025 | AS35: 112 | AT35: 47.203571 | AU35: 22.833929 | AV35: 30.245536 | AX35: 100.28304 | AY35: 33.427679 | AZ35: 267 | BA35: -2.0382305
A36: 33 | B36: Binəqədi | C36: 313 | D36: tam orta məktəb | E36: 109 | F36: 68.276147 | G36: 50.433945 | J36: 118.71009 | K36: 59.355046 | L36: 15 | M36: 2.8435516 | O36: 108 | P36: 67.018519 | Q36: 51.240741 | R36: 41.694444 | T36: 118.25926 | U36: 59.12963 | V36: 17 | W36: -0.22541624 | Y36: 194 | Z36: 63.808 | AA36: 53.792 | AB36: 43.008 | AD36: 160.608 | AE36: 53.536 | AF36: 52 | AG36: -5.5936296 | AI36: 151 | AJ36: 53.880795 | AK36: 47.549669 | AL36: 38.092715 | AN36: 139.52318 | AO36: 46.507726 | AP36: 111 | AQ36: -7.0282737 | AS36: 189 | AT36: 57.443617 | AU36: 31.471809 | AV36: 37.264362 | AX36: 126.17979 | AY36: 42.059929 | AZ36: 133 | BA36: -4.4477972
A37: 34 | B37: Binəqədi | C37: 314 | D37: tam orta məktəb | E37: 104 | F37: 58.344231 | G37: 45.443269 | J37: 103.7875 | K37: 51.89375 | L37: 81 | M37: -0.31967593 | O37: 141 | P37: 53.928571 | Q37: 48.557143 | R37: 40.8 | T37: 102.48571 | U37: 51.242857 | V37: 84 | W37: -0.65089286 | Y37: 178 | Z37: 56.948905 | AA37: 50.510949 | AB37: 36.737226 | AD37: 144.19708 | AE37: 48.065693 | AF37: 149 | AG37: -3.1771637 | AI37: 147 | AJ37: 49.944444 | AK37: 45.583333 | AL37: 37.902778 | AN37: 133.43056 | AO37: 44.476852 | AP37: 139 | AQ37: -3.5888416 | AS37: 175 | AT37: 55.984118 | AU37: 31.771765 | AV37: 37.266471 | AX37: 125.02235 | AY37: 41.674118 | AZ37: 137 | BA37: -2.8027342
A38: 35 | B38: Nərimanov | C38: 11x | D38: XTM | AS38: 0
A39: 36 | B39: Nərimanov | C39: 34 | D39: tam orta məktəb | E39: 62 | F39: 52.432258 | G39: 42.683871 | J39: 95.116129 | K39: 47.558065 | L39: 141 | M39: -6.4205069 | O39: 37 | P39: 53.864865 | Q39: 48.27027 | R39: 38 | T39: 102.13514 | U39: 51.067568 | V39: 86 | W39: 3.5095031 | Y39: 54 | Z39: 61.904762 | AA39: 51.714286 | AB39: 44.428571 | AD39: 158.04762 | AE39: 52.68254 | AF39: 64 | AG39: 1.6149721 | AI39: 67 | AJ39: 57.38806 | AK39: 45.373134 | AL39: 44.343284 | AN39: 147.10448 | AO39: 49.034826 | AP39: 73 | AQ39: -3.6477138 | AS39: 52 | AT39: 48.17451 | AU39: 37.607843 | AV39: 37.190196 | AX39: 122.97255 | AY39: 40.99085 | AZ39: 149 | BA39: -8.0439762
A40: 37 | B40: Nərimanov | C40: 36 | D40: tam orta məktəb | E40: 67 | F40: 50.449254 | G40: 37.992537 | J40: 88.441791 | K40: 44.220896 | L40: 190 | M40: 3.7719159 | O40: 61 | P40: 54.377049 | Q40: 41.754098 | R40: 41.590164 | T40: 96.131148 | U40: 48.065574 | V40: 126 | W40: 3.8446782 | Y40: 93 | Z40: 56.560976 | AA40: 52.195122 | AB40: 42.963415 | AD40: 151.71951 | AE40: 50.573171 | AF40: 102 | AG40: 2.507597 | AI40: 84 | AJ40: 55.285714 | AK40: 41.238095 | AL40: 43.690476 | AN40: 140.21429 | AO40: 46.738095 | AP40: 109 | AQ40: -3.8350755 | AS40: 96 | AT40: 48.021978 | AU40: 34.445055 | AV40: 36.718681 | AX40: 119.18571 | AY40: 39.728571 | AZ40: 170 | BA40: -7.0095238
...
