Workbook

Sheet Ümumi baza
B1: 0 | C1: Azərbaycan | D1: Aşağıdakı sütunlarda heç bir qeyd aparmayın! | AG1: 1 | AH1: Azərbaycan | AI1: Aşağıdakı sütunlarda heç bir qeyd aparmayın! | BL1: 2 | BM1: Azərbaycan | BN1: Aşağıdakı sütunlarda heç bir qeyd aparmayın! | CQ1: 3 | CR1: Azərbaycan | CS1: Aşağıdakı sütunlarda heç bir qeyd aparmayın! | DV1: 4 | DW1: Azərbaycan | DX1: Aşağıdakı sütunlarda heç bir qeyd aparmayın! | FA1: 5 | FB1: Azərbaycan | FC1: Aşağıdakı sütunlarda heç bir qeyd aparmayın! | GF1: 6 | GG1: Azərbaycan | GH1: Aşağıdakı sütunlarda heç bir qeyd aparmayın! | HK1: 7 | HL1: Azərbaycan | HM1: Aşağıdakı sütunlarda heç bir qeyd aparmayın! | IP1: 8 | IQ1: Azərbaycan | IR1: Aşağıdakı sütunlarda heç bir qeyd aparmayın! | JU1: 9 | JV1: Azərbaycan | JW1: Aşağıdakı sütunlarda heç bir qeyd aparmayın! | KZ1: 10 | LA1: Azərbaycan | LB1: Aşağıdakı sütunlarda heç bir qeyd aparmayın! | ME1: 11 | MF1: Azərbaycan | MG1: Aşağıdakı sütunlarda heç bir qeyd aparmayın!
F2: Şagird sayı | I2: Buraxılan dərslərin faizi | M2: I yarımil üzrə nəticələr | S2: II yarımil üzrə nəticələr | Y2: Tədris ili üzrə nəticələr | AK2: Şagird sayı | AN2: Buraxılan dərslərin faizi | AR2: I yarımil üzrə nəticələr | AX2: II yarımil üzrə nəticələr | BD2: Tədris ili üzrə nəticələr | BP2: Şagird sayı | BS2: Buraxılan dərslərin faizi | BW2: I yarımil üzrə nəticələr | CC2: II yarımil üzrə nəticələr | CI2: Tədris ili üzrə nəticələr | CU2: Şagird sayı | CX2: Buraxılan dərslərin faizi | DB2: I yarımil üzrə nəticələr | DH2: II yarımil üzrə nəticələr | DN2: Tədris ili üzrə nəticələr | DZ2: Şagird sayı | EC2: Buraxılan dərslərin faizi | EG2: I yarımil üzrə nəticələr | EM2: II yarımil üzrə nəticələr | ES2: Tədris ili üzrə nəticələr | FE2: Şagird sayı | FH2: Buraxılan dərslərin faizi | FL2: I yarımil üzrə nəticələr | FR2: II yarımil üzrə nəticələr | FX2: Tədris ili üzrə nəticələr | GJ2: Şagird sayı | GM2: Buraxılan dərslərin faizi | GQ2: I yarımil üzrə nəticələr | GW2: II yarımil üzrə nəticələr | HC2: Tədris ili üzrə nəticələr | HO2: Şagird sayı | HR2: Buraxılan dərslərin faizi | HV2: I yarımil üzrə nəticələr | IB2: II yarımil üzrə nəticələr | IH2: Tədris ili üzrə nəticələr | IT2: Şagird sayı | IW2: Buraxılan dərslərin faizi | JA2: I yarımil üzrə nəticələr | JG2: II yarımil üzrə nəticələr | JM2: Tədris ili üzrə nəticələr | JY2: Şagird sayı | KB2: Buraxılan dərslərin faizi | KF2: I yarımil üzrə nəticələr | KL2: II yarımil üzrə nəticələr | KR2: Tədris ili üzrə nəticələr | LD2: Şagird sayı | LG2: Buraxılan dərslərin faizi | LK2: I yarımil üzrə nəticələr | LQ2: II yarımil üzrə nəticələr | LW2: Tədris ili üzrə nəticələr | MI2: Şagird sayı | ML2: Buraxılan dərslərin faizi | MP2: I yarımil üzrə nəticələr | MV2: II yarımil üzrə nəticələr | NB2: Tədris ili üzrə nəticələr
B3: Fənnin kodu | C3: Fənn | D3: İllik dərs saatı | E3: Bölmə | F3: oğlanlar | G3: qızlar | H3: cəmi | I3: oğlanlar | J3: qızlar | K3: cəmi | L3: Ötən tədris ili üzrə illik nəticə | M3: Diaqnostik 1 | N3: Monitorinq 1 | O3: Monitorinq 2 | P3: KSQ orta | Q3: BSQ | R3: I yarımil | S3: Diaqnostik 2 | T3: Monitorinq 3 | U3: Monitorinq 4 | V3: KSQ orta | W3: BSQ | X3: II yarımil | Y3: "Diaqnostik" orta illik | Z3: "Monitorinq" orta illik | AA3: "KSQ orta" orta illik | AB3: "BSQ" orta illik | AC3: İllik | AD3: Buraxılış imtahanı nəticəsi | AG3: Fənnin kodu | AH3: Fənn | AI3: İllik dərs saatı | AJ3: Bölmə | AK3: oğlanlar | AL3: qızlar | AM3: cəmi | AN3: oğlanlar | AO3: qızlar | AP3: cəmi | AQ3: Ötən tədris ili üzrə illik nəticə | AR3: Diaqnostik 1 | AS3: Monitorinq 1 | AT3: Monitorinq 2 | AU3: KSQ orta | AV3: BSQ | AW3: I yarımil | AX3: Diaqnostik 2 | AY3: Monitorinq 3 | AZ3: Monitorinq 4 | BA3: KSQ orta | BB3: BSQ | BC3: II yarımil | BD3: "Diaqnostik" orta illik | BE3: "Monitorinq" orta illik | BF3: "KSQ orta" orta illik | BG3: "BSQ" orta illik | BH3: İllik | BI3: Buraxılış imtahanı nəticəsi | BL3: Fənnin kodu | BM3: Fənn | BN3: İllik dərs saatı | BO3: Bölmə | BP3: oğlanlar | BQ3: qızlar | BR3: cəmi | BS3: oğlanlar | BT3: qızlar | BU3: cəmi | BV3: Ötən tədris ili üzrə illik nəticə | BW3: Diaqnostik 1 | BX3: Monitorinq 1 | BY3: Monitorinq 2 | BZ3: KSQ orta | CA3: BSQ | CB3: I yarımil | CC3: Diaqnostik 2 | CD3: Monitorinq 3 | CE3: Monitorinq 4 | CF3: KSQ orta | CG3: BSQ | CH3: II yarımil | CI3: "Diaqnostik" orta illik | CJ3: "Monitorinq" orta illik | CK3: "KSQ orta" orta illik | CL3: "BSQ" orta illik | CM3: İllik | CN3: Buraxılış imtahanı nəticəsi | CQ3: Fənnin kodu | CR3: Fənn | CS3: İllik dərs saatı | CT3: Bölmə | CU3: oğlanlar | CV3: qızlar | CW3: cəmi | CX3: oğlanlar | CY3: qızlar | CZ3: cəmi | DA3: Ötən tədris ili üzrə illik nəticə | DB3: Diaqnostik 1 | DC3: Monitorinq 1 | DD3: Monitorinq 2 | DE3: KSQ orta | DF3: BSQ | DG3: I yarımil | DH3: Diaqnostik 2 | DI3: Monitorinq 3 | DJ3: Monitorinq 4 | DK3: KSQ orta | DL3: BSQ | DM3: II yarımil | DN3: "Diaqnostik" orta illik | DO3: "Monitorinq" orta illik | DP3: "KSQ orta" orta illik | DQ3: "BSQ" orta illik | DR3: İllik | DS3: Buraxılış imtahanı nəticəsi | DV3: Fənnin kodu | DW3: Fənn | DX3: İllik dərs saatı | DY3: Bölmə | DZ3: oğlanlar | EA3: qızlar | EB3: cəmi | EC3: oğlanlar | ED3: qızlar | EE3: cəmi | EF3: Ötən tədris ili üzrə illik nəticə | EG3: Diaqnostik 1 | EH3: Monitorinq 1 | EI3: Monitorinq 2 | EJ3: KSQ orta | EK3: BSQ | EL3: I yarımil | EM3: Diaqnostik 2 | EN3: Monitorinq 3 | EO3: Monitorinq 4 | EP3: KSQ orta | EQ3: BSQ | ER3: II yarımil | ES3: "Diaqnostik" orta illik | ET3: "Monitorinq" orta illik | EU3: "KSQ orta" orta illik | EV3: "BSQ" orta illik | EW3: İllik | EX3: Buraxılış imtahanı nəticəsi | FA3: Fənnin kodu | FB3: Fənn | FC3: İllik dərs saatı | FD3: Bölmə | FE3: oğlanlar | FF3: qızlar | FG3: cəmi | FH3: oğlanlar | FI3: qızlar | FJ3: cəmi | FK3: Ötən tədris ili üzrə illik nəticə | FL3: Diaqnostik 1 | FM3: Monitorinq 1 | FN3: Monitorinq 2 | FO3: KSQ orta | FP3: BSQ | FQ3: I yarımil | FR3: Diaqnostik 2 | FS3: Monitorinq 3 | FT3: Monitorinq 4 | FU3: KSQ orta | FV3: BSQ | FW3: II yarımil | FX3: "Diaqnostik" orta illik | FY3: "Monitorinq" orta illik | FZ3: "KSQ orta" orta illik | GA3: "BSQ" orta illik | GB3: İllik | GC3: Buraxılış imtahanı nəticəsi | GF3: Fənnin kodu | GG3: Fənn | GH3: İllik dərs saatı | GI3: Bölmə | GJ3: oğlanlar | GK3: qızlar | GL3: cəmi | GM3: oğlanlar | GN3: qızlar | GO3: cəmi | GP3: Ötən tədris ili üzrə illik nəticə | GQ3: Diaqnostik 1 | GR3: Monitorinq 1 | GS3: Monitorinq 2 | GT3: KSQ orta | GU3: BSQ | GV3: I yarımil | GW3: Diaqnostik 2 | GX3: Monitorinq 3 | GY3: Monitorinq 4 | GZ3: KSQ orta | HA3: BSQ | HB3: II yarımil | HC3: "Diaqnostik" orta illik | HD3: "Monitorinq" orta illik | HE3: "KSQ orta" orta illik | HF3: "BSQ" orta illik | HG3: İllik | HH3: Buraxılış imtahanı nəticəsi | HK3: Fənnin kodu | HL3: Fənn | HM3: İllik dərs saatı | HN3: Bölmə | HO3: oğlanlar | HP3: qızlar | HQ3: cəmi | HR3: oğlanlar | HS3: qızlar | HT3: cəmi | HU3: Ötən tədris ili üzrə illik nəticə | HV3: Diaqnostik 1 | HW3: Monitorinq 1 | HX3: Monitorinq 2 | HY3: KSQ orta | HZ3: BSQ | IA3: I yarımil | IB3: Diaqnostik 2 | IC3: Monitorinq 3 | ID3: Monitorinq 4 | IE3: KSQ orta | IF3: BSQ | IG3: II yarımil | IH3: "Diaqnostik" orta illik | II3: "Monitorinq" orta illik | IJ3: "KSQ orta" orta illik | IK3: "BSQ" orta illik | IL3: İllik | IM3: Buraxılış imtahanı nəticəsi | IP3: Fənnin kodu | IQ3: Fənn | IR3: İllik dərs saatı | IS3: Bölmə | IT3: oğlanlar | IU3: qızlar | IV3: cəmi | IW3: oğlanlar | IX3: qızlar | IY3: cəmi | IZ3: Ötən tədris ili üzrə illik nəticə | JA3: Diaqnostik 1 | JB3: Monitorinq 1 | JC3: Monitorinq 2 | JD3: KSQ orta | JE3: BSQ | JF3: I yarımil | JG3: Diaqnostik 2 | JH3: Monitorinq 3 | JI3: Monitorinq 4 | JJ3: KSQ orta | JK3: BSQ | JL3: II yarımil | JM3: "Diaqnostik" orta illik | JN3: "Monitorinq" orta illik | JO3: "KSQ orta" orta illik | JP3: "BSQ" orta illik | JQ3: İllik | JR3: Buraxılış imtahanı nəticəsi | JU3: Fənnin kodu | JV3: Fənn | JW3: İllik dərs saatı | JX3: Bölmə | JY3: oğlanlar | JZ3: qızlar | KA3: cəmi | KB3: oğlanlar | KC3: qızlar | KD3: cəmi | KE3: Ötən tədris ili üzrə illik nəticə | KF3: Diaqnostik 1 | KG3: Monitorinq 1 | KH3: Monitorinq 2 | KI3: KSQ orta | KJ3: BSQ | KK3: I yarımil | KL3: Diaqnostik 2 | KM3: Monitorinq 3 | KN3: Monitorinq 4 | KO3: KSQ orta | KP3: BSQ | KQ3: II yarımil | KR3: "Diaqnostik" orta illik | KS3: "Monitorinq" orta illik | KT3: "KSQ orta" orta illik | KU3: "BSQ" orta illik | KV3: İllik | KW3: Buraxılış imtahanı nəticəsi | KZ3: Fənnin kodu | LA3: Fənn | LB3: İllik dərs saatı | LC3: Bölmə | LD3: oğlanlar | LE3: qızlar | LF3: cəmi | LG3: oğlanlar | LH3: qızlar | LI3: cəmi | LJ3: Ötən tədris ili üzrə illik nəticə | LK3: Diaqnostik 1 | LL3: Monitorinq 1 | LM3: Monitorinq 2 | LN3: KSQ orta | LO3: BSQ | LP3: I yarımil | LQ3: Diaqnostik 2 | LR3: Monitorinq 3 | LS3: Monitorinq 4 | LT3: KSQ orta | LU3: BSQ | LV3: II yarımil | LW3: "Diaqnostik" orta illik | LX3: "Monitorinq" orta illik | LY3: "KSQ orta" orta illik | LZ3: "BSQ" orta illik | MA3: İllik | MB3: Buraxılış imtahanı nəticəsi | ME3: Fənnin kodu | MF3: Fənn | MG3: İllik dərs saatı | MH3: Bölmə | MI3: oğlanlar | MJ3: qızlar | MK3: cəmi | ML3: oğlanlar | MM3: qızlar | MN3: cəmi | MO3: Ötən tədris ili üzrə illik nəticə | MP3: Diaqnostik 1 | MQ3: Monitorinq 1 | MR3: Monitorinq 2 | MS3: KSQ orta | MT3: BSQ | MU3: I yarımil | MV3: Diaqnostik 2 | MW3: Monitorinq 3 | MX3: Monitorinq 4 | MY3: KSQ orta | MZ3: BSQ | NA3: II yarımil | NB3: "Diaqnostik" orta illik | NC3: "Monitorinq" orta illik | ND3: "KSQ orta" orta illik | NE3: "BSQ" orta illik | NF3: İllik | NG3: Buraxılış imtahanı nəticəsi
AG4: 101 | AH4: Tədris dili | AI4: 1394 | AJ4: 0 | AK4: 12 | AL4: 10 | AM4: 22 | BJ4: Ümumi | BL4: 101 | BM4: Tədris dili | BN4: 2151 | BO4: 0 | BP4: 75 | BQ4: 53 | BR4: 128 | BZ4: 74.696943 | CB4: 74.696943 | CF4: 79.537397 | CH4: 79.537397 | CK4: 77.024965 | CM4: 77.024965 | CO4: Ümumi | CQ4: 101 | CR4: Tədris dili | CS4: 1530 | CT4: 0 | CU4: 89 | CV4: 61 | CW4: 150 | DA4: 75.527991 | DB4: 61.642628 | DE4: 76.146114 | DG4: 76.146114 | DK4: 76.971742 | DM4: 76.971742 | DN4: 61.642628 | DP4: 76.327976 | DR4: 76.327976 | DT4: Ümumi | DV4: 101 | DW4: Tədris dili | DX4: 1853 | DY4: 0 | DZ4: 52 | EA4: 41 | EB4: 93 | EF4: 71.230857 | EJ4: 71.520543 | EK4: 70.534685 | EL4: 70.942813 | EP4: 72.953031 | EQ4: 74.325846 | ER4: 73.49996 | EU4: 72.158571 | EV4: 72.052222 | EW4: 72.094762 | EY4: Ümumi | FA4: 101 | FB4: Tədris dili | FC4: 1035 | FD4: 0 | FE4: 84 | FF4: 50 | FG4: 134 | FH4: 1.1964205 | FI4: 1.881221 | FJ4: 1.3700981 | FK4: 71.816591 | FO4: 59.231676 | FP4: 62.535098 | FQ4: 61.213729 | FU4: 61.590502 | FV4: 64.030928 | FW4: 62.918329 | FZ4: 60.3569 | GA4: 63.048474 | GB4: 61.971844 | GD4: Ümumi | GF4: 101 | GG4: Tədris dili | GH4: 1032 | GI4: 0 | GJ4: 67 | GK4: 67 | GL4: 134 | GP4: 72.234428 | GT4: 65.309084 | GU4: 70.53288 | GV4: 68.410158 | GZ4: 65.794104 | HA4: 65.67648 | HB4: 65.782713 | HE4: 65.334592 | HF4: 68.047099 | HG4: 67.530668 | HI4: Ümumi | HK4: 101 | HL4: Tədris dili | HM4: 822 | HN4: 0 | HO4: 80 | HP4: 52 | HQ4: 132 | HR4: 1.5209344 | HS4: 2.0257877 | HT4: 1.741812 | HU4: 68.15147 | HY4: 61.553552 | HZ4: 55.453871 | IA4: 57.553637 | IE4: 61.209603 | IF4: 60.488544 | IG4: 60.654788 | IJ4: 61.596949 | IK4: 58.162086 | IL4: 59.536031 | IN4: Ümumi | IP4: 101 | IQ4: Tədris dili | IR4: 714 | IS4: 0 | IT4: 80 | IU4: 65 | IV4: 145 | IW4: 0.23231515 | IX4: 0.20608243 | IY4: 0.20735983 | IZ4: 67.888101 | JD4: 65.358644 | JE4: 65.237316 | JF4: 65.285847 | JJ4: 68.189333 | JK4: 66.376238 | JL4: 67.164556 | JO4: 66.786459 | JP4: 65.820733 | JQ4: 66.207024 | JS4: Ümumi | JU4: 101 | JV4: Tədris dili | JW4: 515.5 | JX4: 0 | JY4: 54 | JZ4: 53 | KA4: 107 | KE4: 69.632367 | KI4: 68.030372 | KJ4: 61.717515 | KK4: 64.30361 | KO4: 72.268317 | KP4: 73.39368 | KQ4: 72.943535 | KT4: 69.99798 | KU4: 67.630159 | KV4: 68.624549 | KW4: 54.177762 | KX4: Ümumi | KZ4: 101 | LA4: Tədris dili | LB4: 583 | LC4: 0 | LD4: 48 | LE4: 37 | LF4: 85 | LG4: 0.4909112 | LH4: 0.33053221 | LI4: 0.44659817 | LJ4: 68.861962 | LN4: 67.142388 | LO4: 59.624191 | LP4: 62.63147 | LT4: 66.38868 | LU4: 67.883943 | LV4: 67.284766 | LY4: 66.735759 | LZ4: 63.711895 | MA4: 64.92144 | MB4: 5.7142857 | MC4: Ümumi | ME4: 101 | MF4: Tədris dili | MG4: 544 | MH4: 0 | MI4: 21 | MJ4: 32 | MK4: 53 | MO4: 69.351791 | MS4: 76.261221 | MT4: 78.761148 | MU4: 77.501594 | MY4: 78.568978 | MZ4: 80.128838 | NA4: 79.516005 | ND4: 77.4151 | NE4: 79.444993 | NF4: 78.633035 | NG4: 54.537555 | NH4: Ümumi
AH5: Fənn olimpiadaları | AI5: 0 | AJ5: 0 | AK5: 0 | AL5: 0 | AM5: 0 | AN5: 0 | AO5: 0 | AP5: 0 | BJ5: Oğlanlar | BM5: Fənn olimpiadaları | BN5: 0 | BO5: 0 | BP5: 0 | BQ5: 0 | BR5: 0 | BS5: 138 | BT5: 85 | BU5: 223 | CO5: Oğlanlar | CR5: Fənn olimpiadaları | CS5: 0 | CT5: 0 | CU5: 0 | CV5: 0 | CW5: 0 | CX5: 476 | CY5: 293 | CZ5: 769 | DA5: 70.664041 | DB5: 19.163165 | DC5: 0 | DD5: 0 | DE5: 72.442665 | DF5: 0 | DG5: 72.442665 | DH5: 0 | DI5: 0 | DJ5: 0 | DK5: 72.512102 | DL5: 0 | DM5: 72.512102 | DN5: 19.163165 | DO5: 0 | DP5: 73.932993 | DQ5: 0 | DR5: 73.932993 | DS5: 0 | DT5: Oğlanlar | DW5: Fənn olimpiadaları | DX5: 0 | DY5: 0 | DZ5: 0 | EA5: 0 | EB5: 0 | EC5: 132 | ED5: 98 | EE5: 230 | EY5: Oğlanlar | FB5: Fənn olimpiadaları | FC5: 0 | FD5: 0 | FE5: 0 | FF5: 0 | FG5: 0 | FH5: 166 | FI5: 163 | FJ5: 329 | FK5: 67.567586 | FL5: 0 | FM5: 0 | FN5: 0 | FO5: 57.352123 | FP5: 60.825683 | FQ5: 59.436259 | FR5: 0 | FS5: 0 | FT5: 0 | FU5: 60.760857 | FV5: 61.59434 | FW5: 61.624583 | FX5: 0 | FY5: 0 | FZ5: 59.355832 | GA5: 61.775402 | GB5: 60.807574 | GC5: 0 | GD5: Oğlanlar | GG5: Fənn olimpiadaları | GH5: 0 | GI5: 0 | GJ5: 0 | GK5: 0 | GL5: 0 | GM5: 101 | GN5: 81 | GO5: 182 | HI5: Oğlanlar | HL5: Fənn olimpiadaları | HM5: 0 | HN5: 0 | HO5: 0 | HP5: 0 | HQ5: 0 | HR5: 176 | HS5: 158 | HT5: 334 | HU5: 55.393663 | HV5: 0 | HW5: 0 | HX5: 0 | HY5: 61.476601 | HZ5: 55.784528 | IA5: 57.917441 | IB5: 0 | IC5: 0 | ID5: 0 | IE5: 58.497765 | IF5: 57.786281 | IG5: 58.24275 | IH5: 0 | II5: 0 | IJ5: 50.234713 | IK5: 47.095064 | IL5: 48.350923 | IM5: 0 | IN5: Oğlanlar | IQ5: Fənn olimpiadaları | IR5: 0 | IS5: 0 | IT5: 0 | IU5: 0 | IV5: 0 | IW5: 16 | IX5: 17 | IY5: 33 | IZ5: 63.795811 | JA5: 0 | JB5: 0 | JC5: 0 | JD5: 60.513224 | JE5: 60.611864 | JF5: 60.572408 | JG5: 0 | JH5: 0 | JI5: 0 | JJ5: 62.637447 | JK5: 61.421107 | JL5: 61.907643 | JM5: 0 | JN5: 0 | JO5: 62.119167 | JP5: 61.438563 | JQ5: 61.710805 | JR5: 0 | JS5: Oğlanlar | JV5: Fənn olimpiadaları | JW5: 0 | JX5: 0 | JY5: 0 | JZ5: 0 | KA5: 0 | KB5: 217 | KC5: 119 | KD5: 336 | KX5: Oğlanlar | LA5: Fənn olimpiadaları | LB5: 0 | LC5: 0 | LD5: 0 | LE5: 0 | LF5: 0 | LG5: 27 | LH5: 14 | LI5: 41 | LJ5: 64.684211 | LK5: 0 | LL5: 0 | LM5: 0 | LN5: 63.687583 | LO5: 56.158237 | LP5: 59.169975 | LQ5: 0 | LR5: 0 | LS5: 0 | LT5: 60.756613 | LU5: 66.170198 | LV5: 62.913855 | LW5: 0 | LX5: 0 | LY5: 63.306328 | LZ5: 61.394481 | MA5: 62.15922 | MB5: 0.52631579 | MC5: Oğlanlar | MF5: Fənn olimpiadaları | MG5: 0 | MH5: 0 | MI5: 0 | MJ5: 0 | MK5: 0 | ML5: 75 | MM5: 61 | MN5: 136 | NH5: Oğlanlar
AH6: Fənn müsabiqələri | AI6: 0 | AJ6: 0 | AK6: 0 | AL6: 0 | AM6: 0 | BJ6: Qızlar | BM6: Fənn müsabiqələri | BN6: 0 | BO6: 0 | BP6: 0 | BQ6: 0 | BR6: 0 | CO6: Qızlar | CR6: Fənn müsabiqələri | CS6: 0 | CT6: 0 | CU6: 0 | CV6: 0 | CW6: 0 | DA6: 74.784259 | DB6: 22.592593 | DC6: 0 | DD6: 0 | DE6: 79.068673 | DF6: 0 | DG6: 79.068673 | DH6: 0 | DI6: 0 | DJ6: 0 | DK6: 76.410301 | DL6: 0 | DM6: 76.410301 | DN6: 22.592593 | DO6: 0 | DP6: 78.561246 | DQ6: 0 | DR6: 78.561246 | DS6: 0 | DT6: Qızlar | DW6: Fənn müsabiqələri | DX6: 0 | DY6: 0 | DZ6: 0 | EA6: 0 | EB6: 0 | EY6: Qızlar | FB6: Fənn müsabiqələri | FC6: 0 | FD6: 0 | FE6: 0 | FF6: 0 | FG6: 0 | FK6: 72.307998 | FL6: 0 | FM6: 0 | FN6: 0 | FO6: 61.560989 | FP6: 64.721978 | FQ6: 63.457582 | FR6: 0 | FS6: 0 | FT6: 0 | FU6: 61.617247 | FV6: 65.340537 | FW6: 63.851221 | FX6: 0 | FY6: 0 | FZ6: 62.064812 | GA6: 65.461813 | GB6: 64.103013 | GC6: 0 | GD6: Qızlar | GG6: Fənn müsabiqələri | GH6: 0 | GI6: 0 | GJ6: 0 | GK6: 0 | GL6: 0 | HI6: Qızlar | HL6: Fənn müsabiqələri | HM6: 0 | HN6: 0 | HO6: 0 | HP6: 0 | HQ6: 0 | HU6: 53.169643 | HV6: 0 | HW6: 0 | HX6: 0 | HY6: 58.443651 | HZ6: 53.25119 | IA6: 54.708175 | IB6: 0 | IC6: 0 | ID6: 0 | IE6: 62.084821 | IF6: 59.428571 | IG6: 60.574405 | IH6: 0 | II6: 0 | IJ6: 53.839732 | IK6: 50.185119 | IL6: 51.646964 | IM6: 0 | IN6: Qızlar | IQ6: Fənn müsabiqələri | IR6: 0 | IS6: 0 | IT6: 0 | IU6: 0 | IV6: 0 | IZ6: 74.504906 | JA6: 0 | JB6: 0 | JC6: 0 | JD6: 72.850477 | JE6: 72.398469 | JF6: 72.579273 | JG6: 0 | JH6: 0 | JI6: 0 | JJ6: 74.128777 | JK6: 70.874608 | JL6: 72.703748 | JM6: 0 | JN6: 0 | JO6: 74.050852 | JP6: 72.6177 | JQ6: 73.190961 | JR6: 0 | JS6: Qızlar | JV6: Fənn müsabiqələri | JW6: 0 | JX6: 0 | JY6: 0 | JZ6: 0 | KA6: 0 | KX6: Qızlar | LA6: Fənn müsabiqələri | LB6: 0 | LC6: 0 | LD6: 0 | LE6: 0 | LF6: 0 | LJ6: 73.801136 | LK6: 0 | LL6: 0 | LM6: 0 | LN6: 74.570265 | LO6: 66.624242 | LP6: 69.802652 | LQ6: 0 | LR6: 0 | LS6: 0 | LT6: 71.51553 | LU6: 70.140152 | LV6: 70.690303 | LW6: 0 | LX6: 0 | LY6: 74.034375 | LZ6: 69.461742 | MA6: 71.290795 | MB6: 0 | MC6: Qızlar | MF6: Fənn müsabiqələri | MG6: 0 | MH6: 0 | MI6: 0 | MJ6: 0 | MK6: 0 | NH6: Qızlar
AH7: Təqdimat Müsabiqələri | AI7: 0 | AJ7: 0 | AK7: 0 | AL7: 0 | AM7: 0 | BJ7: (80-100] | BM7: Təqdimat Müsabiqələri | BN7: 0 | BO7: 0 | BP7: 0 | BQ7: 0 | BR7: 0 | BZ7: 46.08252 | CB7: 46.08252 | CF7: 56.322504 | CH7: 56.322504 | CK7: 50.484929 | CM7: 50.484929 | CO7: (80-100] | CR7: Təqdimat Müsabiqələri | CS7: 0 | CT7: 0 | CU7: 0 | CV7: 0 | CW7: 0 | DA7: 43.983945 | DB7: 21.634615 | DE7: 47.843831 | DG7: 47.843831 | DK7: 46.962121 | DM7: 46.962121 | DN7: 21.634615 | DP7: 48.217949 | DR7: 48.217949 | DT7: (80-100] | DW7: Təqdimat Müsabiqələri | DX7: 0 | DY7: 0 | DZ7: 0 | EA7: 0 | EB7: 0 | EF7: 46.183457 | EJ7: 39.845346 | EK7: 40.655363 | EL7: 39.495342 | EP7: 42.689629 | EQ7: 44.884226 | ER7: 45.440617 | EU7: 38.248108 | EV7: 39.087378 | EW7: 40.211716 | EY7: (80-100] | FB7: Təqdimat Müsabiqələri | FC7: 0 | FD7: 0 | FE7: 0 | FF7: 0 | FG7: 0 | FK7: 32.484754 | FO7: 16.73138 | FP7: 25.086691 | FQ7: 20.166056 | FU7: 17.230576 | FV7: 25.79092 | FW7: 23.358075 | FZ7: 17.936508 | GA7: 20.091575 | GB7: 19.218559 | GD7: (80-100] | GG7: Təqdimat Müsabiqələri | GH7: 0 | GI7: 0 | GJ7: 0 | GK7: 0 | GL7: 0 | GP7: 44.490373 | GT7: 28.613943 | GU7: 40.154121 | GV7: 37.418379 | GZ7: 33.119034 | HA7: 36.426609 | HB7: 35.60719 | HE7: 30.435755 | HF7: 35.899933 | HG7: 37.16367 | HI7: (80-100] | HL7: Təqdimat Müsabiqələri | HM7: 0 | HN7: 0 | HO7: 0 | HP7: 0 | HQ7: 0 | HU7: 33.806204 | HY7: 17.786423 | HZ7: 21.037376 | IA7: 16.01106 | IE7: 22.237352 | IF7: 21.532781 | IG7: 18.302676 | IJ7: 21.049499 | IK7: 20.376984 | IL7: 20.815581 | IN7: (80-100] | IQ7: Təqdimat Müsabiqələri | IR7: 0 | IS7: 0 | IT7: 0 | IU7: 0 | IV7: 0 | IZ7: 31.322335 | JD7: 21.490535 | JE7: 23.985967 | JF7: 22.503046 | JJ7: 28.331748 | JK7: 26.7891 | JL7: 28.162501 | JO7: 27.066332 | JP7: 22.986397 | JQ7: 24.185258 | JS7: (80-100] | JV7: Təqdimat Müsabiqələri | JW7: 0 | JX7: 0 | JY7: 0 | JZ7: 0 | KA7: 0 | KE7: 36.769841 | KI7: 33.293005 | KJ7: 23.981811 | KK7: 32.978165 | KO7: 41.75469 | KP7: 39.936508 | KQ7: 40.345599 | KT7: 36.794372 | KU7: 30.746753 | KV7: 32.588023 | KW7: 16.787993 | KX7: (80-100] | LA7: Təqdimat Müsabiqələri | LB7: 0 | LC7: 0 | LD7: 0 | LE7: 0 | LF7: 0 | LJ7: 21.674641 | LN7: 20.7365 | LO7: 19.366598 | LP7: 18.050809 | LT7: 12.828947 | LU7: 20.864662 | LV7: 17.828947 | LY7: 15.962919 | LZ7: 16.555594 | MA7: 17.925496 | MB7: 0 | MC7: (80-100] | MF7: Təqdimat Müsabiqələri | MG7: 0 | MH7: 0 | MI7: 0 | MJ7: 0 | MK7: 0 | MO7: 43.220029 | MS7: 49.625365 | MT7: 43.686038 | MU7: 47.733918 | MY7: 57.410453 | MZ7: 57.483553 | NA7: 61.50402 | ND7: 51.260965 | NE7: 61.57712 | NF7: 57.410453 | NG7: 5.9027778 | NH7: (80-100]
AH8: Məntiq olimpiadası | AI8: 0 | AJ8: 0 | AK8: 0 | AL8: 0 | AM8: 0 | BJ8: (60-80] | BM8: Məntiq olimpiadası | BN8: 0 | BO8: 0 | BP8: 0 | BQ8: 0 | BR8: 0 | BZ8: 32.895593 | CB8: 32.895593 | CF8: 29.136994 | CH8: 29.136994 | CK8: 31.959076 | CM8: 31.959076 | CO8: (60-80] | CR8: Məntiq olimpiadası | CS8: 0 | CT8: 0 | CU8: 0 | CV8: 0 | CW8: 0 | DA8: 32.764518 | DB8: 25.480769 | DE8: 33.020624 | DG8: 33.020624 | DK8: 36.957071 | DM8: 36.957071 | DN8: 25.480769 | DP8: 35.008547 | DR8: 35.008547 | DT8: (60-80] | DW8: Məntiq olimpiadası | DX8: 0 | DY8: 0 | DZ8: 0 | EA8: 0 | EB8: 0 | EF8: 19.811137 | EJ8: 30.752981 | EK8: 32.297499 | EL8: 32.973115 | EP8: 30.987996 | EQ8: 32.913157 | ER8: 30.96313 | EU8: 35.668793 | EV8: 34.306359 | EW8: 33.566264 | EY8: (60-80] | FB8: Məntiq olimpiadası | FC8: 0 | FD8: 0 | FE8: 0 | FF8: 0 | FG8: 0 | FK8: 43.902464 | FO8: 32.583028 | FP8: 33.927961 | FQ8: 36.540904 | FU8: 38.88921 | FV8: 34.073485 | FW8: 35.990457 | FZ8: 36.529304 | GA8: 38.949939 | GB8: 39.630647 | GD8: (60-80] | GG8: Məntiq olimpiadası | GH8: 0 | GI8: 0 | GJ8: 0 | GK8: 0 | GL8: 0 | GP8: 29.065902 | GT8: 34.060712 | GU8: 28.337791 | GV8: 27.629286 | GZ8: 28.454626 | HA8: 25.62015 | HB8: 25.922562 | HE8: 32.857856 | HF8: 28.009015 | HG8: 26.087246 | HI8: (60-80] | HL8: Məntiq olimpiadası | HM8: 0 | HN8: 0 | HO8: 0 | HP8: 0 | HQ8: 0 | HU8: 30.216781 | HY8: 34.708238 | HZ8: 25.442792 | IA8: 33.418383 | IE8: 29.297792 | IF8: 30.913734 | IG8: 31.925333 | IJ8: 30.947568 | IK8: 29.306418 | IL8: 28.829002 | IN8: (60-80] | IQ8: Məntiq olimpiadası | IR8: 0 | IS8: 0 | IT8: 0 | IU8: 0 | IV8: 0 | IZ8: 31.563267 | JD8: 41.086511 | JE8: 42.615658 | JF8: 43.729234 | JJ8: 41.199293 | JK8: 40.524214 | JL8: 40.606407 | JO8: 36.976879 | JP8: 42.810463 | JQ8: 43.108689 | JS8: (60-80] | JV8: Məntiq olimpiadası | JW8: 0 | JX8: 0 | JY8: 0 | JZ8: 0 | KA8: 0 | KE8: 28.112554 | KI8: 33.675439 | KJ8: 31.01986 | KK8: 27.483937 | KO8: 30.909812 | KP8: 37.021645 | KQ8: 35.945887 | KT8: 31.139971 | KU8: 33.934343 | KV8: 33.501443 | KW8: 25.952096 | KX8: (60-80] | LA8: Məntiq olimpiadası | LB8: 0 | LC8: 0 | LD8: 0 | LE8: 0 | LF8: 0 | LJ8: 57.123206 | LN8: 52.326592 | LO8: 45.5702 | LP8: 48.076466 | LT8: 52.332536 | LU8: 52.278423 | LV8: 54.7189 | LY8: 52.732734 | LZ8: 43.493987 | MA8: 48.098259 | MB8: 0 | MC8: (60-80] | MF8: Məntiq olimpiadası | MG8: 0 | MH8: 0 | MI8: 0 | MJ8: 0 | MK8: 0 | MO8: 25.35636 | MS8: 34.402412 | MT8: 47.980629 | MU8: 46.710526 | MY8: 32.867325 | MZ8: 30.089547 | NA8: 27.384868 | ND8: 35.891813 | NE8: 30.089547 | NF8: 34.256213 | NG8: 38.057383 | NH8: (60-80]
AH9: STEAM yarışları | AI9: 0 | AJ9: 0 | AK9: 0 | AL9: 0 | AM9: 0 | BJ9: (30-60] | BM9: STEAM yarışları | BN9: 0 | BO9: 0 | BP9: 0 | BQ9: 0 | BR9: 0 | BZ9: 21.021887 | CB9: 21.021887 | CF9: 14.540501 | CH9: 14.540501 | CK9: 17.555995 | CM9: 17.555995 | CO9: (30-60] | CR9: STEAM yarışları | CS9: 0 | CT9: 0 | CU9: 0 | CV9: 0 | CW9: 0 | DA9: 23.251537 | DB9: 38.301282 | DE9: 18.494519 | DG9: 18.494519 | DK9: 16.080808 | DM9: 16.080808 | DN9: 38.301282 | DP9: 16.132479 | DR9: 16.132479 | DT9: (30-60] | DW9: STEAM yarışları | DX9: 0 | DY9: 0 | DZ9: 0 | EA9: 0 | EB9: 0 | EF9: 34.005406 | EJ9: 29.401673 | EK9: 26.253487 | EL9: 27.531544 | EP9: 26.322375 | EQ9: 22.202617 | ER9: 23.596252 | EU9: 26.083099 | EV9: 26.606263 | EW9: 26.22202 | EY9: (30-60] | FB9: STEAM yarışları | FC9: 0 | FD9: 0 | FE9: 0 | FF9: 0 | FG9: 0 | FK9: 23.612782 | FO9: 45.852259 | FP9: 37.652015 | FQ9: 39.959707 | FU9: 43.880213 | FV9: 40.135595 | FW9: 40.651468 | FZ9: 44.700855 | GA9: 38.458486 | GB9: 40.31746 | GD9: (30-60] | GG9: STEAM yarışları | GH9: 0 | GI9: 0 | GJ9: 0 | GK9: 0 | GL9: 0 | GP9: 26.443725 | GT9: 36.645073 | GU9: 31.508088 | GV9: 34.952335 | GZ9: 37.746068 | HA9: 37.238956 | HB9: 37.07569 | HE9: 36.706389 | HF9: 36.091052 | HG9: 36.749084 | HI9: (30-60] | HL9: STEAM yarışları | HM9: 0 | HN9: 0 | HO9: 0 | HP9: 0 | HQ9: 0 | HU9: 35.977015 | HY9: 43.635011 | HZ9: 44.692982 | IA9: 42.468345 | IE9: 45.748129 | IF9: 46.093168 | IG9: 47.696289 | IJ9: 45.690994 | IK9: 45.175121 | IL9: 48.181504 | IN9: (30-60] | IQ9: STEAM yarışları | IR9: 0 | IS9: 0 | IT9: 0 | IU9: 0 | IV9: 0 | IZ9: 37.114398 | JD9: 37.422955 | JE9: 33.398375 | JF9: 33.76772 | JJ9: 30.468959 | JK9: 32.686686 | JL9: 31.231092 | JO9: 35.956789 | JP9: 34.203139 | JQ9: 32.706052 | JS9: (30-60] | JV9: STEAM yarışları | JW9: 0 | JX9: 0 | JY9: 0 | JZ9: 0 | KA9: 0 | KE9: 35.117605 | KI9: 31.031556 | KJ9: 35.21364 | KK9: 35.28393 | KO9: 26.502165 | KP9: 23.041847 | KQ9: 23.708514 | KT9: 29.89899 | KU9: 33.818903 | KV9: 33.910534 | KW9: 34.851902 | KX9: (30-60] | LA9: STEAM yarışları | LB9: 0 | LC9: 0 | LD9: 0 | LE9: 0 | LF9: 0 | LJ9: 21.202153 | LN9: 25.849951 | LO9: 25.177073 | LP9: 29.524899 | LT9: 34.838517 | LU9: 23.285486 | LV9: 27.452153 | LY9: 31.304348 | LZ9: 39.95042 | MA9: 33.976245 | MB9: 0 | MC9: (30-60] | MF9: STEAM yarışları | MG9: 0 | MH9: 0 | MI9: 0 | MJ9: 0 | MK9: 0 | MO9: 31.423611 | MS9: 15.972222 | MT9: 8.3333333 | MU9: 5.5555556 | MY9: 9.7222222 | MZ9: 12.426901 | NA9: 11.111111 | ND9: 12.847222 | NE9: 8.3333333 | NF9: 8.3333333 | NG9: 45.970395 | NH9: (30-60]
AH10: Digər milli və beynəlxalq olimpiada, yarış və müsabiqələr | AI10: 0 | AJ10: 0 | AK10: 0 | AL10: 0 | AM10: 0 | BJ10: [0-30] | BM10: Digər milli və beynəlxalq olimpiada, yarış və müsabiqələr | BN10: 0 | BO10: 0 | BP10: 0 | BQ10: 0 | BR10: 0 | BZ10: 0 | CB10: 0 | CF10: 0 | CH10: 0 | CK10: 0 | CM10: 0 | CO10: [0-30] | CR10: Digər milli və beynəlxalq olimpiada, yarış və müsabiqələr | CS10: 0 | CT10: 0 | CU10: 0 | CV10: 0 | CW10: 0 | DA10: 0 | DB10: 14.583333 | DE10: 0.64102564 | DG10: 0.64102564 | DK10: 0 | DM10: 0 | DN10: 14.583333 | DP10: 0.64102564 | DR10: 0.64102564 | DT10: [0-30] | DW10: Digər milli və beynəlxalq olimpiada, yarış və müsabiqələr | DX10: 0 | DY10: 0 | DZ10: 0 | EA10: 0 | EB10: 0 | EF10: 0 | EJ10: 0 | EK10: 0.79365079 | EL10: 0 | EP10: 0 | EQ10: 0 | ER10: 0 | EU10: 0 | EV10: 0 | EW10: 0 | EY10: [0-30] | FB10: Digər milli və beynəlxalq olimpiada, yarış və müsabiqələr | FC10: 0 | FD10: 0 | FE10: 0 | FF10: 0 | FG10: 0 | FK10: 0 | FO10: 4.8333333 | FP10: 3.3333333 | FQ10: 3.3333333 | FU10: 0 | FV10: 0 | FW10: 0 | FZ10: 0.83333333 | GA10: 2.5 | GB10: 0.83333333 | GD10: [0-30] | GG10: Digər milli və beynəlxalq olimpiada, yarış və müsabiqələr | GH10: 0 | GI10: 0 | GJ10: 0 | GK10: 0 | GL10: 0 | GP10: 0 | GT10: 0.68027211 | GU10: 0 | GV10: 0 | GZ10: 0.68027211 | HA10: 0.71428571 | HB10: 1.3945578 | HE10: 0 | HF10: 0 | HG10: 0 | HI10: [0-30] | HL10: Digər milli və beynəlxalq olimpiada, yarış və müsabiqələr | HM10: 0 | HN10: 0 | HO10: 0 | HP10: 0 | HQ10: 0 | HU10: 0 | HY10: 3.870328 | HZ10: 8.8268497 | IA10: 8.1022121 | IE10: 2.7167277 | IF10: 1.4603175 | IG10: 2.0757021 | IJ10: 2.3119393 | IK10: 5.1414769 | IL10: 2.173913 | IN10: [0-30] | IQ10: Digər milli və beynəlxalq olimpiada, yarış və müsabiqələr | IR10: 0 | IS10: 0 | IT10: 0 | IU10: 0 | IV10: 0 | IZ10: 0 | JD10: 0 | JE10: 0 | JF10: 0 | JJ10: 0 | JK10: 0 | JL10: 0 | JO10: 0 | JP10: 0 | JQ10: 0 | JS10: [0-30] | JV10: Digər milli və beynəlxalq olimpiada, yarış və müsabiqələr | JW10: 0 | JX10: 0 | JY10: 0 | JZ10: 0 | KA10: 0 | KE10: 0 | KI10: 2 | KJ10: 9.784689 | KK10: 4.2539683 | KO10: 0.83333333 | KP10: 0 | KQ10: 0 | KT10: 2.1666667 | KU10: 1.5 | KV10: 0 | KW10: 22.408009 | KX10: [0-30] | LA10: Digər milli və beynəlxalq olimpiada, yarış və müsabiqələr | LB10: 0 | LC10: 0 | LD10: 0 | LE10: 0 | LF10: 0 | LJ10: 0 | LN10: 1.0869565 | LO10: 9.8861284 | LP10: 4.3478261 | LT10: 0 | LU10: 3.5714286 | LV10: 0 | LY10: 0 | LZ10: 0 | MA10: 0 | MB10: 100 | MC10: [0-30] | MF10: Digər milli və beynəlxalq olimpiada, yarış və müsabiqələr | MG10: 0 | MH10: 0 | MI10: 0 | MJ10: 0 | MK10: 0 | MO10: 0 | MS10: 0 | MT10: 0 | MU10: 0 | MY10: 0 | MZ10: 0 | NA10: 0 | ND10: 0 | NE10: 0 | NF10: 0 | NG10: 10.069444 | NH10: [0-30]
AG11: 102 | AH11: Ədəbiyyat | AI11: 0 | AJ11: 0 | AK11: 12 | AL11: 10 | AM11: 22 | BJ11: Ümumi | BL11: 102 | BM11: Ədəbiyyat | BN11: 0 | BO11: 0 | BP11: 75 | BQ11: 53 | BR11: 128 | CO11: Ümumi | CQ11: 102 | CR11: Ədəbiyyat | CS11: 0 | CT11: 0 | CU11: 89 | CV11: 61 | CW11: 150 | DT11: Ümumi | DV11: 102 | DW11: Ədəbiyyat | DX11: 0 | DY11: 0 | DZ11: 52 | EA11: 41 | EB11: 93 | EY11: Ümumi | FA11: 102 | FB11: Ədəbiyyat | FC11: 377 | FD11: 0 | FE11: 84 | FF11: 50 | FG11: 134 | FH11: 0.78210268 | FI11: 1.638027 | FJ11: 1.0133412 | FO11: 61.621255 | FQ11: 61.621255 | FU11: 65.760699 | FW11: 65.760699 | FZ11: 63.712943 | GB11: 63.712943 | GD11: Ümumi | GF11: 102 | GG11: Ədəbiyyat | GH11: 482 | GI11: 0 | GJ11: 67 | GK11: 67 | GL11: 134 | GP11: 74.886297 | GT11: 69.697071 | GU11: 76.521739 | GV11: 69.708251 | GZ11: 70.028802 | HB11: 70.028802 | HE11: 69.735316 | HF11: 76.521739 | HG11: 69.960911 | HI11: Ümumi | HK11: 102 | HL11: Ədəbiyyat | HM11: 410 | HN11: 0 | HO11: 80 | HP11: 52 | HQ11: 132 | HR11: 2.6554914 | HS11: 3.1391307 | HT11: 2.8319016 | HU11: 70.445086 | HY11: 62.697932 | IA11: 62.697932 | IB11: 65.26087 | IE11: 65.360175 | IG11: 65.360175 | IH11: 65.26087 | IJ11: 63.682309 | IL11: 63.682309 | IN11: Ümumi | IP11: 102 | IQ11: Ədəbiyyat | IR11: 476 | IS11: 0 | IT11: 80 | IU11: 65 | IV11: 145 | IW11: 0.20957101 | IX11: 0.22208884 | IY11: 0.21722304 | IZ11: 71.531868 | JD11: 64.55596 | JF11: 64.55596 | JJ11: 67.392942 | JL11: 67.392942 | JO11: 65.959604 | JQ11: 65.959604 | JS11: Ümumi | JU11: 102 | JV11: Ədəbiyyat | JW11: 344 | JX11: 0 | JY11: 54 | JZ11: 53 | KA11: 107 | KE11: 70.210736 | KI11: 71.966099 | KJ11: 64.073608 | KK11: 67.341318 | KO11: 71.01211 | KP11: 76.04289 | KQ11: 74.030578 | KT11: 71.583855 | KU11: 70.102547 | KV11: 70.76257 | KX11: Ümumi | KZ11: 102 | LA11: Ədəbiyyat | LB11: 310 | LC11: 0 | LD11: 48 | LE11: 37 | LF11: 85 | LJ11: 69.348485 | LN11: 66.734718 | LO11: 70.631579 | LP11: 66.49349 | LT11: 71.449004 | LU11: 75.157895 | LV11: 70.549784 | LY11: 69.190258 | LZ11: 72.894737 | MA11: 68.621223 | MB11: 5 | MC11: Ümumi | ME11: 102 | MF11: Ədəbiyyat | MG11: 272 | MH11: 0 | MI11: 21 | MJ11: 32 | MK11: 53 | MO11: 66.823556 | MS11: 69.353862 | MT11: 74.368787 | MU11: 72.362817 | MY11: 74.866502 | MZ11: 78.927997 | NA11: 77.303399 | ND11: 70.52627 | NE11: 76.405336 | NF11: 74.05371 | NH11: Ümumi
AH12: Fənn olimpiadaları | AI12: 0 | AJ12: 0 | AK12: 0 | AL12: 0 | AM12: 0 | AN12: 0 | AO12: 0 | AP12: 0 | BJ12: Oğlanlar | BM12: Fənn olimpiadaları | BN12: 0 | BO12: 0 | BP12: 0 | BQ12: 0 | BR12: 0 | BS12: 0 | BT12: 0 | BU12: 0 | CO12: Oğlanlar | CR12: Fənn olimpiadaları | CS12: 0 | CT12: 0 | CU12: 0 | CV12: 0 | CW12: 0 | CX12: 0 | CY12: 0 | CZ12: 0 | DA12: 0 | DB12: 0 | DC12: 0 | DD12: 0 | DE12: 0 | DF12: 0 | DG12: 0 | DH12: 0 | DI12: 0 | DJ12: 0 | DK12: 0 | DL12: 0 | DM12: 0 | DN12: 0 | DO12: 0 | DP12: 0 | DQ12: 0 | DR12: 0 | DS12: 0 | DT12: Oğlanlar | DW12: Fənn olimpiadaları | DX12: 0 | DY12: 0 | DZ12: 0 | EA12: 0 | EB12: 0 | EC12: 0 | ED12: 0 | EE12: 0 | EY12: Oğlanlar | FB12: Fənn olimpiadaları | FC12: 0 | FD12: 0 | FE12: 0 | FF12: 0 | FG12: 0 | FH12: 37 | FI12: 50 | FJ12: 87 | FK12: 0 | FL12: 0 | FM12: 0 | FN12: 0 | FO12: 59.024951 | FP12: 0 | FQ12: 59.024951 | FR12: 0 | FS12: 0 | FT12: 0 | FU12: 64.273244 | FV12: 0 | FW12: 64.273244 | FX12: 0 | FY12: 0 | FZ12: 61.966349 | GA12: 0 | GB12: 61.966349 | GC12: 0 | GD12: Oğlanlar | GG12: Fənn olimpiadaları | GH12: 0 | GI12: 0 | GJ12: 0 | GK12: 0 | GL12: 0 | GM12: 48 | GN12: 44 | GO12: 92 | HI12: Oğlanlar | HL12: Fənn olimpiadaları | HM12: 0 | HN12: 0 | HO12: 0 | HP12: 0 | HQ12: 0 | HR12: 155 | HS12: 113 | HT12: 268 | HU12: 57.263923 | HV12: 0 | HW12: 0 | HX12: 0 | HY12: 60.975455 | HZ12: 0 | IA12: 60.975455 | IB12: 10.566667 | IC12: 0 | ID12: 0 | IE12: 62.064957 | IF12: 0 | IG12: 62.064957 | IH12: 10.566667 | II12: 0 | IJ12: 61.819869 | IK12: 0 | IL12: 61.819869 | IM12: 0 | IN12: Oğlanlar | IQ12: Fənn olimpiadaları | IR12: 0 | IS12: 0 | IT12: 0 | IU12: 0 | IV12: 0 | IW12: 10 | IX12: 13 | IY12: 23 | IZ12: 67.489939 | JA12: 0 | JB12: 0 | JC12: 0 | JD12: 60.513147 | JE12: 0 | JF12: 60.513147 | JG12: 0 | JH12: 0 | JI12: 0 | JJ12: 62.358887 | JK12: 0 | JL12: 62.358887 | JM12: 0 | JN12: 0 | JO12: 61.912208 | JP12: 0 | JQ12: 61.912208 | JR12: 0 | JS12: Oğlanlar | JV12: Fənn olimpiadaları | JW12: 0 | JX12: 0 | JY12: 0 | JZ12: 0 | KA12: 0 | KB12: 92 | KC12: 45 | KD12: 137 | KX12: Oğlanlar | LA12: Fənn olimpiadaları | LB12: 0 | LC12: 0 | LD12: 0 | LE12: 0 | LF12: 0 | LG12: 12 | LH12: 0 | LI12: 12 | LJ12: 48.935236 | LK12: 0 | LL12: 0 | LM12: 0 | LN12: 46.706838 | LO12: 17 | LP12: 46.606838 | LQ12: 0 | LR12: 0 | LS12: 0 | LT12: 49.584211 | LU12: 19.642857 | LV12: 50.179925 | LW12: 0 | LX12: 0 | LY12: 48.50298 | LZ12: 18.321429 | MA12: 48.750838 | MB12: 0.19736842 | MC12: Oğlanlar | MF12: Fənn olimpiadaları | MG12: 0 | MH12: 0 | MI12: 0 | MJ12: 0 | MK12: 0 | ML12: 15 | MM12: 14 | MN12: 29 | NH12: Oğlanlar
AH13: Fənn müsabiqələri | AI13: 0 | AJ13: 0 | AK13: 0 | AL13: 0 | AM13: 0 | BJ13: Qızlar | BM13: Fənn müsabiqələri | BN13: 0 | BO13: 0 | BP13: 0 | BQ13: 0 | BR13: 0 | CO13: Qızlar | CR13: Fənn müsabiqələri | CS13: 0 | CT13: 0 | CU13: 0 | CV13: 0 | CW13: 0 | DA13: 0 | DB13: 0 | DC13: 0 | DD13: 0 | DE13: 0 | DF13: 0 | DG13: 0 | DH13: 0 | DI13: 0 | DJ13: 0 | DK13: 0 | DL13: 0 | DM13: 0 | DN13: 0 | DO13: 0 | DP13: 0 | DQ13: 0 | DR13: 0 | DS13: 0 | DT13: Qızlar | DW13: Fənn müsabiqələri | DX13: 0 | DY13: 0 | DZ13: 0 | EA13: 0 | EB13: 0 | EY13: Qızlar | FB13: Fənn müsabiqələri | FC13: 0 | FD13: 0 | FE13: 0 | FF13: 0 | FG13: 0 | FK13: 0 | FL13: 0 | FM13: 0 | FN13: 0 | FO13: 64.534351 | FP13: 0 | FQ13: 64.534351 | FR13: 0 | FS13: 0 | FT13: 0 | FU13: 68.002788 | FV13: 0 | FW13: 68.002788 | FX13: 0 | FY13: 0 | FZ13: 66.268569 | GA13: 0 | GB13: 66.268569 | GC13: 0 | GD13: Qızlar | GG13: Fənn müsabiqələri | GH13: 0 | GI13: 0 | GJ13: 0 | GK13: 0 | GL13: 0 | HI13: Qızlar | HL13: Fənn müsabiqələri | HM13: 0 | HN13: 0 | HO13: 0 | HP13: 0 | HQ13: 0 | HU13: 54.793452 | HV13: 0 | HW13: 0 | HX13: 0 | HY13: 63.193254 | HZ13: 0 | IA13: 63.193254 | IB13: 10.321429 | IC13: 0 | ID13: 0 | IE13: 66.006349 | IF13: 0 | IG13: 66.006349 | IH13: 10.321429 | II13: 0 | IJ13: 66.334921 | IK13: 0 | IL13: 66.334921 | IM13: 0 | IN13: Qızlar | IQ13: Fənn müsabiqələri | IR13: 0 | IS13: 0 | IT13: 0 | IU13: 0 | IV13: 0 | IZ13: 76.810636 | JA13: 0 | JB13: 0 | JC13: 0 | JD13: 71.307548 | JE13: 0 | JF13: 71.307548 | JG13: 0 | JH13: 0 | JI13: 0 | JJ13: 72.412559 | JK13: 0 | JL13: 72.412559 | JM13: 0 | JN13: 0 | JO13: 72.438285 | JP13: 0 | JQ13: 72.438285 | JR13: 0 | JS13: Qızlar | JV13: Fənn müsabiqələri | JW13: 0 | JX13: 0 | JY13: 0 | JZ13: 0 | KA13: 0 | KX13: Qızlar | LA13: Fənn müsabiqələri | LB13: 0 | LC13: 0 | LD13: 0 | LE13: 0 | LF13: 0 | LJ13: 56.138258 | LK13: 0 | LL13: 0 | LM13: 0 | LN13: 57.18892 | LO13: 18.041667 | LP13: 56.960795 | LQ13: 0 | LR13: 0 | LS13: 0 | LT13: 57.484848 | LU13: 18.291667 | LV13: 54.466515 | LW13: 0 | LX13: 0 | LY13: 58.396544 | LZ13: 18.166667 | MA13: 57.576231 | MB13: 0 | MC13: Qızlar | MF13: Fənn müsabiqələri | MG13: 0 | MH13: 0 | MI13: 0 | MJ13: 0 | MK13: 0 | NH13: Qızlar
AH14: Təqdimat Müsabiqələri | AI14: 0 | AJ14: 0 | AK14: 0 | AL14: 0 | AM14: 0 | BJ14: (80-100] | BM14: Təqdimat Müsabiqələri | BN14: 0 | BO14: 0 | BP14: 0 | BQ14: 0 | BR14: 0 | CO14: (80-100] | CR14: Təqdimat Müsabiqələri | CS14: 0 | CT14: 0 | CU14: 0 | CV14: 0 | CW14: 0 | DT14: (80-100] | DW14: Təqdimat Müsabiqələri | DX14: 0 | DY14: 0 | DZ14: 0 | EA14: 0 | EB14: 0 | EY14: (80-100] | FB14: Təqdimat Müsabiqələri | FC14: 0 | FD14: 0 | FE14: 0 | FF14: 0 | FG14: 0 | FO14: 18.064713 | FQ14: 18.064713 | FU14: 28.171551 | FW14: 28.171551 | FZ14: 19.371184 | GB14: 19.371184 | GD14: (80-100] | GG14: Təqdimat Müsabiqələri | GH14: 0 | GI14: 0 | GJ14: 0 | GK14: 0 | GL14: 0 | GP14: 48.685176 | GT14: 38.583952 | GU14: 52.173913 | GV14: 38.583952 | GZ14: 39.657686 | HB14: 39.657686 | HE14: 39.472194 | HF14: 52.173913 | HG14: 39.472194 | HI14: (80-100] | HL14: Təqdimat Müsabiqələri | HM14: 0 | HN14: 0 | HO14: 0 | HP14: 0 | HQ14: 0 | HU14: 40.050648 | HY14: 24.479405 | IA14: 24.479405 | IB14: 30.434783 | IE14: 30.348384 | IG14: 30.348384 | IH14: 30.434783 | IJ14: 24.56044 | IL14: 24.56044 | IN14: (80-100] | IQ14: Təqdimat Müsabiqələri | IR14: 0 | IS14: 0 | IT14: 0 | IU14: 0 | IV14: 0 | IZ14: 39.610262 | JD14: 22.072835 | JF14: 22.072835 | JJ14: 24.073375 | JL14: 24.073375 | JO14: 21.333408 | JQ14: 21.333408 | JS14: (80-100] | JV14: Təqdimat Müsabiqələri | JW14: 0 | JX14: 0 | JY14: 0 | JZ14: 0 | KA14: 0 | KE14: 35.809524 | KI14: 37.629908 | KJ14: 33.924964 | KK14: 33.661806 | KO14: 37.94209 | KP14: 50.987545 | KQ14: 45.917559 | KT14: 37.974368 | KU14: 37.809524 | KV14: 39.89542 | KX14: (80-100] | LA14: Təqdimat Müsabiqələri | LB14: 0 | LC14: 0 | LD14: 0 | LE14: 0 | LF14: 0 | LJ14: 17.38437 | LN14: 18.899522 | LO14: 26.315789 | LP14: 18.899522 | LT14: 30.576441 | LU14: 36.842105 | LV14: 22.486772 | LY14: 24.162679 | LZ14: 31.578947 | MA14: 24.162679 | MB14: 0 | MC14: (80-100] | MF14: Təqdimat Müsabiqələri | MG14: 0 | MH14: 0 | MI14: 0 | MJ14: 0 | MK14: 0 | MO14: 40.515351 | MS14: 37.664474 | MT14: 39.199561 | MU14: 35.032895 | MY14: 40.296053 | MZ14: 44.462719 | NA14: 45.705409 | ND14: 40.222953 | NE14: 45.924708 | NF14: 41.684942 | NH14: (80-100]
AH15: Məntiq olimpiadası | AI15: 0 | AJ15: 0 | AK15: 0 | AL15: 0 | AM15: 0 | BJ15: (60-80] | BM15: Məntiq olimpiadası | BN15: 0 | BO15: 0 | BP15: 0 | BQ15: 0 | BR15: 0 | CO15: (60-80] | CR15: Məntiq olimpiadası | CS15: 0 | CT15: 0 | CU15: 0 | CV15: 0 | CW15: 0 | DT15: (60-80] | DW15: Məntiq olimpiadası | DX15: 0 | DY15: 0 | DZ15: 0 | EA15: 0 | EB15: 0 | EY15: (60-80] | FB15: Məntiq olimpiadası | FC15: 0 | FD15: 0 | FE15: 0 | FF15: 0 | FG15: 0 | FO15: 41.912698 | FQ15: 41.912698 | FU15: 40.695971 | FW15: 40.695971 | FZ15: 44.76801 | GB15: 44.76801 | GD15: (60-80] | GG15: Məntiq olimpiadası | GH15: 0 | GI15: 0 | GJ15: 0 | GK15: 0 | GL15: 0 | GP15: 30.956166 | GT15: 30.618605 | GU15: 39.130435 | GV15: 30.618605 | GZ15: 29.678309 | HB15: 29.678309 | HE15: 29.867157 | HF15: 39.130435 | HG15: 28.438585 | HI15: (60-80] | HL15: Məntiq olimpiadası | HM15: 0 | HN15: 0 | HO15: 0 | HP15: 0 | HQ15: 0 | HU15: 28.753013 | HY15: 31.922197 | IA15: 31.922197 | IB15: 43.478261 | IE15: 28.419202 | IG15: 28.419202 | IH15: 43.478261 | IJ15: 32.420502 | IL15: 32.420502 | IN15: (60-80] | IQ15: Məntiq olimpiadası | IR15: 0 | IS15: 0 | IT15: 0 | IU15: 0 | IV15: 0 | IZ15: 30.571587 | JD15: 39.988226 | JF15: 39.988226 | JJ15: 48.983031 | JL15: 48.983031 | JO15: 43.712464 | JQ15: 43.712464 | JS15: (60-80] | JV15: Məntiq olimpiadası | JW15: 0 | JX15: 0 | JY15: 0 | JZ15: 0 | KA15: 0 | KE15: 33.041126 | KI15: 30.228108 | KJ15: 27.188312 | KK15: 29.8838 | KO15: 31.581074 | KP15: 27.145857 | KQ15: 30.958267 | KT15: 32.434875 | KU15: 30.318903 | KV15: 29.549897 | KX15: (60-80] | LA15: Məntiq olimpiadası | LB15: 0 | LC15: 0 | LD15: 0 | LE15: 0 | LF15: 0 | LJ15: 64.194577 | LN15: 54.708411 | LO15: 68.421053 | LP15: 54.708411 | LT15: 51.002506 | LU15: 57.894737 | LV15: 60.846561 | LY15: 49.445253 | LZ15: 68.421053 | MA15: 49.445253 | MB15: 0 | MC15: (60-80] | MF15: Məntiq olimpiadası | MG15: 0 | MH15: 0 | MI15: 0 | MJ15: 0 | MK15: 0 | MO15: 28.48136 | MS15: 22.304459 | MT15: 46.463816 | MU15: 52.019371 | MY15: 50.054825 | MZ15: 45.888158 | NA15: 44.645468 | ND15: 26.169591 | NE15: 38.523392 | NF15: 45.888158 | NH15: (60-80]
AH16: STEAM yarışları | AI16: 0 | AJ16: 0 | AK16: 0 | AL16: 0 | AM16: 0 | BJ16: (30-60] | BM16: STEAM yarışları | BN16: 0 | BO16: 0 | BP16: 0 | BQ16: 0 | BR16: 0 | CO16: (30-60] | CR16: STEAM yarışları | CS16: 0 | CT16: 0 | CU16: 0 | CV16: 0 | CW16: 0 | DT16: (30-60] | DW16: STEAM yarışları | DX16: 0 | DY16: 0 | DZ16: 0 | EA16: 0 | EB16: 0 | EY16: (30-60] | FB16: STEAM yarışları | FC16: 0 | FD16: 0 | FE16: 0 | FF16: 0 | FG16: 0 | FO16: 36.855922 | FQ16: 36.855922 | FU16: 31.132479 | FW16: 31.132479 | FZ16: 34.194139 | GB16: 34.194139 | GD16: (30-60] | GG16: STEAM yarışları | GH16: 0 | GI16: 0 | GJ16: 0 | GK16: 0 | GL16: 0 | GP16: 20.358659 | GT16: 30.797443 | GU16: 8.6956522 | GV16: 30.797443 | GZ16: 30.664005 | HB16: 30.664005 | HE16: 30.660649 | HF16: 8.6956522 | HG16: 32.08922 | HI16: (30-60] | HL16: STEAM yarışları | HM16: 0 | HN16: 0 | HO16: 0 | HP16: 0 | HQ16: 0 | HU16: 31.196339 | HY16: 41.27193 | IA16: 41.27193 | IB16: 26.086957 | IE16: 40.591389 | IG16: 40.591389 | IH16: 26.086957 | IJ16: 42.294421 | IL16: 42.294421 | IN16: (30-60] | IQ16: STEAM yarışları | IR16: 0 | IS16: 0 | IT16: 0 | IU16: 0 | IV16: 0 | IZ16: 29.818151 | JD16: 37.93894 | JF16: 37.93894 | JJ16: 26.943594 | JL16: 26.943594 | JO16: 34.954127 | JQ16: 34.954127 | JS16: (30-60] | JV16: STEAM yarışları | JW16: 0 | JX16: 0 | JY16: 0 | JZ16: 0 | KA16: 0 | KE16: 30.3557 | KI16: 30.681666 | KJ16: 31.886724 | KK16: 33.406775 | KO16: 30.476836 | KP16: 21.866598 | KQ16: 23.124174 | KT16: 29.590757 | KU16: 30.371573 | KV16: 30.554682 | KX16: (30-60] | LA16: STEAM yarışları | LB16: 0 | LC16: 0 | LD16: 0 | LE16: 0 | LF16: 0 | LJ16: 18.421053 | LN16: 23.493516 | LO16: 5.2631579 | LP16: 23.493516 | LT16: 18.421053 | LU16: 5.2631579 | LV16: 16.666667 | LY16: 26.392067 | LZ16: 0 | MA16: 26.392067 | MB16: 0 | MC16: (30-60] | MF16: STEAM yarışları | MG16: 0 | MH16: 0 | MI16: 0 | MJ16: 0 | MK16: 0 | MO16: 31.003289 | MS16: 38.642178 | MT16: 14.336623 | MU16: 12.947734 | MY16: 9.6491228 | MZ16: 9.6491228 | NA16: 9.6491228 | ND16: 32.218567 | NE16: 15.551901 | NF16: 12.426901 | NH16: (30-60]
AH17: Digər milli və beynəlxalq olimpiada, yarış və müsabiqələr | AI17: 0 | AJ17: 0 | AK17: 0 | AL17: 0 | AM17: 0 | BJ17: [0-30] | BM17: Digər milli və beynəlxalq olimpiada, yarış və müsabiqələr | BN17: 0 | BO17: 0 | BP17: 0 | BQ17: 0 | BR17: 0 | CO17: [0-30] | CR17: Digər milli və beynəlxalq olimpiada, yarış və müsabiqələr | CS17: 0 | CT17: 0 | CU17: 0 | CV17: 0 | CW17: 0 | DT17: [0-30] | DW17: Digər milli və beynəlxalq olimpiada, yarış və müsabiqələr | DX17: 0 | DY17: 0 | DZ17: 0 | EA17: 0 | EB17: 0 | EY17: [0-30] | FB17: Digər milli və beynəlxalq olimpiada, yarış və müsabiqələr | FC17: 0 | FD17: 0 | FE17: 0 | FF17: 0 | FG17: 0 | FO17: 3.1666667 | FQ17: 3.1666667 | FU17: 0 | FW17: 0 | FZ17: 1.6666667 | GB17: 1.6666667 | GD17: [0-30] | GG17: Digər milli və beynəlxalq olimpiada, yarış və müsabiqələr | GH17: 0 | GI17: 0 | GJ17: 0 | GK17: 0 | GL17: 0 | GP17: 0 | GT17: 0 | GU17: 0 | GV17: 0 | GZ17: 0 | HB17: 0 | HE17: 0 | HF17: 0 | HG17: 0 | HI17: [0-30] | HL17: Digər milli və beynəlxalq olimpiada, yarış və müsabiqələr | HM17: 0 | HN17: 0 | HO17: 0 | HP17: 0 | HQ17: 0 | HU17: 0 | HY17: 2.3264683 | IA17: 2.3264683 | IB17: 0 | IE17: 0.64102564 | IG17: 0.64102564 | IH17: 0 | IJ17: 0.72463768 | IL17: 0.72463768 | IN17: [0-30] | IQ17: Digər milli və beynəlxalq olimpiada, yarış və müsabiqələr | IR17: 0 | IS17: 0 | IT17: 0 | IU17: 0 | IV17: 0 | IZ17: 0 | JD17: 0 | JF17: 0 | JJ17: 0 | JL17: 0 | JO17: 0 | JQ17: 0 | JS17: [0-30] | JV17: Digər milli və beynəlxalq olimpiada, yarış və müsabiqələr | JW17: 0 | JX17: 0 | JY17: 0 | JZ17: 0 | KA17: 0 | KE17: 0.79365079 | KI17: 1.4603175 | KJ17: 7 | KK17: 3.047619 | KO17: 0 | KP17: 0 | KQ17: 0 | KT17: 0 | KU17: 1.5 | KV17: 0 | KX17: [0-30] | LA17: Digər milli və beynəlxalq olimpiada, yarış və müsabiqələr | LB17: 0 | LC17: 0 | LD17: 0 | LE17: 0 | LF17: 0 | LJ17: 0 | LN17: 2.8985507 | LO17: 0 | LP17: 2.8985507 | LT17: 0 | LU17: 0 | LV17: 0 | LY17: 0 | LZ17: 0 | MA17: 0 | MB17: 100 | MC17: [0-30] | MF17: Digər milli və beynəlxalq olimpiada, yarış və müsabiqələr | MG17: 0 | MH17: 0 | MI17: 0 | MJ17: 0 | MK17: 0 | MO17: 0 | MS17: 1.3888889 | MT17: 0 | MU17: 0 | MY17: 0 | MZ17: 0 | NA17: 0 | ND17: 1.3888889 | NE17: 0 | NF17: 0 | NH17: [0-30]
AG18: 103 | AH18: Dövlət dili | AI18: 0 | AJ18: 0 | AK18: 12 | AL18: 10 | AM18: 22 | BJ18: Ümumi | BL18: 103 | BM18: Dövlət dili | BN18: 0 | BO18: 0 | BP18: 75 | BQ18: 53 | BR18: 128 | CO18: Ümumi | CQ18: 103 | CR18: Dövlət dili | CS18: 0 | CT18: 0 | CU18: 89 | CV18: 61 | CW18: 150 | DT18: Ümumi | DV18: 103 | DW18: Dövlət dili | DX18: 0 | DY18: 0 | DZ18: 52 | EA18: 41 | EB18: 93 | EY18: Ümumi | FA18: 103 | FB18: Dövlət dili | FC18: 0 | FD18: 0 | FE18: 84 | FF18: 50 | FG18: 134 | GD18: Ümumi | GF18: 103 | GG18: Dövlət dili | GH18: 0 | GI18: 0 | GJ18: 67 | GK18: 67 | GL18: 134 | HI18: Ümumi | HK18: 103 | HL18: Dövlət dili | HM18: 0 | HN18: 0 | HO18: 80 | HP18: 52 | HQ18: 132 | IN18: Ümumi | IP18: 103 | IQ18: Dövlət dili | IR18: 0 | IS18: 0 | IT18: 81 | IU18: 65 | IV18: 146 | JS18: Ümumi | JU18: 103 | JV18: Dövlət dili | JW18: 0 | JX18: 0 | JY18: 54 | JZ18: 53 | KA18: 107 | KX18: Ümumi | KZ18: 103 | LA18: Dövlət dili | LB18: 0 | LC18: 0 | LD18: 49 | LE18: 37 | LF18: 86 | MC18: Ümumi | ME18: 103 | MF18: Dövlət dili | MG18: 0 | MH18: 0 | MI18: 21 | MJ18: 32 | MK18: 53 | NH18: Ümumi
AH19: Fənn olimpiadaları | AI19: 0 | AJ19: 0 | AK19: 0 | AL19: 0 | AM19: 0 | AN19: 0 | AO19: 0 | AP19: 0 | BJ19: Oğlanlar | BM19: Fənn olimpiadaları | BN19: 0 | BO19: 0 | BP19: 0 | BQ19: 0 | BR19: 0 | BS19: 0 | BT19: 0 | BU19: 0 | CO19: Oğlanlar | CR19: Fənn olimpiadaları | CS19: 0 | CT19: 0 | CU19: 0 | CV19: 0 | CW19: 0 | CX19: 0 | CY19: 0 | CZ19: 0 | DA19: 0 | DB19: 0 | DC19: 0 | DD19: 0 | DE19: 0 | DF19: 0 | DG19: 0 | DH19: 0 | DI19: 0 | DJ19: 0 | DK19: 0 | DL19: 0 | DM19: 0 | DN19: 0 | DO19: 0 | DP19: 0 | DQ19: 0 | DR19: 0 | DS19: 0 | DT19: Oğlanlar | DW19: Fənn olimpiadaları | DX19: 0 | DY19: 0 | DZ19: 0 | EA19: 0 | EB19: 0 | EC19: 0 | ED19: 0 | EE19: 0 | EY19: Oğlanlar | FB19: Fənn olimpiadaları | FC19: 0 | FD19: 0 | FE19: 0 | FF19: 0 | FG19: 0 | FH19: 0 | FI19: 0 | FJ19: 0 | FK19: 0 | FL19: 0 | FM19: 0 | FN19: 0 | FO19: 0 | FP19: 0 | FQ19: 0 | FR19: 0 | FS19: 0 | FT19: 0 | FU19: 0 | FV19: 0 | FW19: 0 | FX19: 0 | FY19: 0 | FZ19: 0 | GA19: 0 | GB19: 0 | GC19: 0 | GD19: Oğlanlar | GG19: Fənn olimpiadaları | GH19: 0 | GI19: 0 | GJ19: 0 | GK19: 0 | GL19: 0 | GM19: 0 | GN19: 0 | GO19: 0 | HI19: Oğlanlar | HL19: Fənn olimpiadaları | HM19: 0 | HN19: 0 | HO19: 0 | HP19: 0 | HQ19: 0 | HR19: 0 | HS19: 0 | HT19: 0 | HU19: 0 | HV19: 0 | HW19: 0 | HX19: 0 | HY19: 0 | HZ19: 0 | IA19: 0 | IB19: 0 | IC19: 0 | ID19: 0 | IE19: 0 | IF19: 0 | IG19: 0 | IH19: 0 | II19: 0 | IJ19: 0 | IK19: 0 | IL19: 0 | IM19: 0 | IN19: Oğlanlar | IQ19: Fənn olimpiadaları | IR19: 0 | IS19: 0 | IT19: 0 | IU19: 0 | IV19: 0 | IW19: 0 | IX19: 0 | IY19: 0 | IZ19: 0 | JA19: 0 | JB19: 0 | JC19: 0 | JD19: 0 | JE19: 0 | JF19: 0 | JG19: 0 | JH19: 0 | JI19: 0 | JJ19: 0 | JK19: 0 | JL19: 0 | JM19: 0 | JN19: 0 | JO19: 0 | JP19: 0 | JQ19: 0 | JR19: 0 | JS19: Oğlanlar | JV19: Fənn olimpiadaları | JW19: 0 | JX19: 0 | JY19: 0 | JZ19: 0 | KA19: 0 | KB19: 0 | KC19: 0 | KD19: 0 | KX19: Oğlanlar | LA19: Fənn olimpiadaları | LB19: 0 | LC19: 0 | LD19: 0 | LE19: 0 | LF19: 0 | LG19: 0 | LH19: 0 | LI19: 0 | LJ19: 0 | LK19: 0 | LL19: 0 | LM19: 0 | LN19: 0 | LO19: 0 | LP19: 0 | LQ19: 0 | LR19: 0 | LS19: 0 | LT19: 0 | LU19: 0 | LV19: 0 | LW19: 0 | LX19: 0 | LY19: 0 | LZ19: 0 | MA19: 0 | MB19: 0 | MC19: Oğlanlar | MF19: Fənn olimpiadaları | MG19: 0 | MH19: 0 | MI19: 0 | MJ19: 0 | MK19: 0 | ML19: 0 | MM19: 0 | MN19: 0 | NH19: Oğlanlar
AH20: Fənn müsabiqələri | AI20: 0 | AJ20: 0 | AK20: 0 | AL20: 0 | AM20: 0 | BJ20: Qızlar | BM20: Fənn müsabiqələri | BN20: 0 | BO20: 0 | BP20: 0 | BQ20: 0 | BR20: 0 | CO20: Qızlar | CR20: Fənn müsabiqələri | CS20: 0 | CT20: 0 | CU20: 0 | CV20: 0 | CW20: 0 | DA20: 0 | DB20: 0 | DC20: 0 | DD20: 0 | DE20: 0 | DF20: 0 | DG20: 0 | DH20: 0 | DI20: 0 | DJ20: 0 | DK20: 0 | DL20: 0 | DM20: 0 | DN20: 0 | DO20: 0 | DP20: 0 | DQ20: 0 | DR20: 0 | DS20: 0 | DT20: Qızlar | DW20: Fənn müsabiqələri | DX20: 0 | DY20: 0 | DZ20: 0 | EA20: 0 | EB20: 0 | EY20: Qızlar | FB20: Fənn müsabiqələri | FC20: 0 | FD20: 0 | FE20: 0 | FF20: 0 | FG20: 0 | FK20: 0 | FL20: 0 | FM20: 0 | FN20: 0 | FO20: 0 | FP20: 0 | FQ20: 0 | FR20: 0 | FS20: 0 | FT20: 0 | FU20: 0 | FV20: 0 | FW20: 0 | FX20: 0 | FY20: 0 | FZ20: 0 | GA20: 0 | GB20: 0 | GC20: 0 | GD20: Qızlar | GG20: Fənn müsabiqələri | GH20: 0 | GI20: 0 | GJ20: 0 | GK20: 0 | GL20: 0 | HI20: Qızlar | HL20: Fənn müsabiqələri | HM20: 0 | HN20: 0 | HO20: 0 | HP20: 0 | HQ20: 0 | HU20: 0 | HV20: 0 | HW20: 0 | HX20: 0 | HY20: 0 | HZ20: 0 | IA20: 0 | IB20: 0 | IC20: 0 | ID20: 0 | IE20: 0 | IF20: 0 | IG20: 0 | IH20: 0 | II20: 0 | IJ20: 0 | IK20: 0 | IL20: 0 | IM20: 0 | IN20: Qızlar | IQ20: Fənn müsabiqələri | IR20: 0 | IS20: 0 | IT20: 0 | IU20: 0 | IV20: 0 | IZ20: 0 | JA20: 0 | JB20: 0 | JC20: 0 | JD20: 0 | JE20: 0 | JF20: 0 | JG20: 0 | JH20: 0 | JI20: 0 | JJ20: 0 | JK20: 0 | JL20: 0 | JM20: 0 | JN20: 0 | JO20: 0 | JP20: 0 | JQ20: 0 | JR20: 0 | JS20: Qızlar | JV20: Fənn müsabiqələri | JW20: 0 | JX20: 0 | JY20: 0 | JZ20: 0 | KA20: 0 | KX20: Qızlar | LA20: Fənn müsabiqələri | LB20: 0 | LC20: 0 | LD20: 0 | LE20: 0 | LF20: 0 | LJ20: 0 | LK20: 0 | LL20: 0 | LM20: 0 | LN20: 0 | LO20: 0 | LP20: 0 | LQ20: 0 | LR20: 0 | LS20: 0 | LT20: 0 | LU20: 0 | LV20: 0 | LW20: 0 | LX20: 0 | LY20: 0 | LZ20: 0 | MA20: 0 | MB20: 0 | MC20: Qızlar | MF20: Fənn müsabiqələri | MG20: 0 | MH20: 0 | MI20: 0 | MJ20: 0 | MK20: 0 | NH20: Qızlar
AH21: Təqdimat Müsabiqələri | AI21: 0 | AJ21: 0 | AK21: 0 | AL21: 0 | AM21: 0 | BJ21: (80-100] | BM21: Təqdimat Müsabiqələri | BN21: 0 | BO21: 0 | BP21: 0 | BQ21: 0 | BR21: 0 | CO21: (80-100] | CR21: Təqdimat Müsabiqələri | CS21: 0 | CT21: 0 | CU21: 0 | CV21: 0 | CW21: 0 | DT21: (80-100] | DW21: Təqdimat Müsabiqələri | DX21: 0 | DY21: 0 | DZ21: 0 | EA21: 0 | EB21: 0 | EY21: (80-100] | FB21: Təqdimat Müsabiqələri | FC21: 0 | FD21: 0 | FE21: 0 | FF21: 0 | FG21: 0 | GD21: (80-100] | GG21: Təqdimat Müsabiqələri | GH21: 0 | GI21: 0 | GJ21: 0 | GK21: 0 | GL21: 0 | HI21: (80-100] | HL21: Təqdimat Müsabiqələri | HM21: 0 | HN21: 0 | HO21: 0 | HP21: 0 | HQ21: 0 | IN21: (80-100] | IQ21: Təqdimat Müsabiqələri | IR21: 0 | IS21: 0 | IT21: 0 | IU21: 0 | IV21: 0 | JS21: (80-100] | JV21: Təqdimat Müsabiqələri | JW21: 0 | JX21: 0 | JY21: 0 | JZ21: 0 | KA21: 0 | KX21: (80-100] | LA21: Təqdimat Müsabiqələri | LB21: 0 | LC21: 0 | LD21: 0 | LE21: 0 | LF21: 0 | MC21: (80-100] | MF21: Təqdimat Müsabiqələri | MG21: 0 | MH21: 0 | MI21: 0 | MJ21: 0 | MK21: 0 | NH21: (80-100]
AH22: Məntiq olimpiadası | AI22: 0 | AJ22: 0 | AK22: 0 | AL22: 0 | AM22: 0 | BJ22: (60-80] | BM22: Məntiq olimpiadası | BN22: 0 | BO22: 0 | BP22: 0 | BQ22: 0 | BR22: 0 | CO22: (60-80] | CR22: Məntiq olimpiadası | CS22: 0 | CT22: 0 | CU22: 0 | CV22: 0 | CW22: 0 | DT22: (60-80] | DW22: Məntiq olimpiadası | DX22: 0 | DY22: 0 | DZ22: 0 | EA22: 0 | EB22: 0 | EY22: (60-80] | FB22: Məntiq olimpiadası | FC22: 0 | FD22: 0 | FE22: 0 | FF22: 0 | FG22: 0 | GD22: (60-80] | GG22: Məntiq olimpiadası | GH22: 0 | GI22: 0 | GJ22: 0 | GK22: 0 | GL22: 0 | HI22: (60-80] | HL22: Məntiq olimpiadası | HM22: 0 | HN22: 0 | HO22: 0 | HP22: 0 | HQ22: 0 | IN22: (60-80] | IQ22: Məntiq olimpiadası | IR22: 0 | IS22: 0 | IT22: 0 | IU22: 0 | IV22: 0 | JS22: (60-80] | JV22: Məntiq olimpiadası | JW22: 0 | JX22: 0 | JY22: 0 | JZ22: 0 | KA22: 0 | KX22: (60-80] | LA22: Məntiq olimpiadası | LB22: 0 | LC22: 0 | LD22: 0 | LE22: 0 | LF22: 0 | MC22: (60-80] | MF22: Məntiq olimpiadası | MG22: 0 | MH22: 0 | MI22: 0 | MJ22: 0 | MK22: 0 | NH22: (60-80]
AH23: STEAM yarışları | AI23: 0 | AJ23: 0 | AK23: 0 | AL23: 0 | AM23: 0 | BJ23: (30-60] | BM23: STEAM yarışları | BN23: 0 | BO23: 0 | BP23: 0 | BQ23: 0 | BR23: 0 | CO23: (30-60] | CR23: STEAM yarışları | CS23: 0 | CT23: 0 | CU23: 0 | CV23: 0 | CW23: 0 | DT23: (30-60] | DW23: STEAM yarışları | DX23: 0 | DY23: 0 | DZ23: 0 | EA23: 0 | EB23: 0 | EY23: (30-60] | FB23: STEAM yarışları | FC23: 0 | FD23: 0 | FE23: 0 | FF23: 0 | FG23: 0 | GD23: (30-60] | GG23: STEAM yarışları | GH23: 0 | GI23: 0 | GJ23: 0 | GK23: 0 | GL23: 0 | HI23: (30-60] | HL23: STEAM yarışları | HM23: 0 | HN23: 0 | HO23: 0 | HP23: 0 | HQ23: 0 | IN23: (30-60] | IQ23: STEAM yarışları | IR23: 0 | IS23: 0 | IT23: 0 | IU23: 0 | IV23: 0 | JS23: (30-60] | JV23: STEAM yarışları | JW23: 0 | JX23: 0 | JY23: 0 | JZ23: 0 | KA23: 0 | KX23: (30-60] | LA23: STEAM yarışları | LB23: 0 | LC23: 0 | LD23: 0 | LE23: 0 | LF23: 0 | MC23: (30-60] | MF23: STEAM yarışları | MG23: 0 | MH23: 0 | MI23: 0 | MJ23: 0 | MK23: 0 | NH23: (30-60]
AH24: Digər milli və beynəlxalq olimpiada, yarış və müsabiqələr | AI24: 0 | AJ24: 0 | AK24: 0 | AL24: 0 | AM24: 0 | BJ24: [0-30] | BM24: Digər milli və beynəlxalq olimpiada, yarış və müsabiqələr | BN24: 0 | BO24: 0 | BP24: 0 | BQ24: 0 | BR24: 0 | CO24: [0-30] | CR24: Digər milli və beynəlxalq olimpiada, yarış və müsabiqələr | CS24: 0 | CT24: 0 | CU24: 0 | CV24: 0 | CW24: 0 | DT24: [0-30] | DW24: Digər milli və beynəlxalq olimpiada, yarış və müsabiqələr | DX24: 0 | DY24: 0 | DZ24: 0 | EA24: 0 | EB24: 0 | EY24: [0-30] | FB24: Digər milli və beynəlxalq olimpiada, yarış və müsabiqələr | FC24: 0 | FD24: 0 | FE24: 0 | FF24: 0 | FG24: 0 | GD24: [0-30] | GG24: Digər milli və beynəlxalq olimpiada, yarış və müsabiqələr | GH24: 0 | GI24: 0 | GJ24: 0 | GK24: 0 | GL24: 0 | HI24: [0-30] | HL24: Digər milli və beynəlxalq olimpiada, yarış və müsabiqələr | HM24: 0 | HN24: 0 | HO24: 0 | HP24: 0 | HQ24: 0 | IN24: [0-30] | IQ24: Digər milli və beynəlxalq olimpiada, yarış və müsabiqələr | IR24: 0 | IS24: 0 | IT24: 0 | IU24: 0 | IV24: 0 | JS24: [0-30] | JV24: Digər milli və beynəlxalq olimpiada, yarış və müsabiqələr | JW24: 0 | JX24: 0 | JY24: 0 | JZ24: 0 | KA24: 0 | KX24: [0-30] | LA24: Digər milli və beynəlxalq olimpiada, yarış və müsabiqələr | LB24: 0 | LC24: 0 | LD24: 0 | LE24: 0 | LF24: 0 | MC24: [0-30] | MF24: Digər milli və beynəlxalq olimpiada, yarış və müsabiqələr | MG24: 0 | MH24: 0 | MI24: 0 | MJ24: 0 | MK24: 0 | NH24: [0-30]
AG25: 104 | AH25: Xarici dil | AI25: 102.34 | AJ25: 0 | AK25: 12 | AL25: 10 | AM25: 22 | BJ25: Ümumi | BL25: 104 | BM25: Xarici dil | BN25: 68.34 | BO25: 0 | BP25: 75 | BQ25: 53 | BR25: 128 | BZ25: 67.103968 | CB25: 67.103968 | CF25: 67.261669 | CH25: 67.261669 | CK25: 67.179703 | CM25: 67.179703 | CO25: Ümumi | CQ25: 104 | CR25: Xarici dil | CS25: 136 | CT25: 0 | CU25: 89 | CV25: 61 | CW25: 150 | DA25: 68.44489 | DE25: 59.569371 | DG25: 59.569371 | DK25: 60.049815 | DM25: 60.049815 | DP25: 59.556345 | DR25: 59.556345 | DT25: Ümumi | DV25: 104 | DW25: Xarici dil | DX25: 172.69 | DY25: 0 | DZ25: 52 | EA25: 41 | EB25: 93 | EF25: 67.325963 | EJ25: 60.023485 | EK25: 64.146218 | EL25: 62.404835 | EP25: 63.648065 | EQ25: 63.143727 | ER25: 63.378044 | EU25: 61.855416 | EV25: 63.64127 | EW25: 62.926928 | EY25: Ümumi | FA25: 104 | FB25: Xarici dil | FC25: 136 | FD25: 0 | FE25: 84 | FF25: 50 | FG25: 134 | FO25: 56.84859 | FP25: 54.279011 | FQ25: 55.306842 | FU25: 55.242226 | FV25: 53.434219 | FW25: 54.157422 | FZ25: 56.11077 | GA25: 53.903175 | GB25: 54.786213 | GD25: Ümumi | GF25: 104 | GG25: Xarici dil | GH25: 102516.1 | GI25: 0 | GJ25: 67 | GK25: 67 | GL25: 134 | GP25: 70.919274 | GT25: 56.555491 | GU25: 62.032438 | GV25: 59.841659 | GZ25: 60.683498 | HA25: 64.817821 | HB25: 63.164092 | HE25: 58.478293 | HF25: 63.119225 | HG25: 61.262852 | HI25: Ümumi | HK25: 104 | HL25: Xarici dil | HM25: 208.105 | HN25: 0 | HO25: 80 | HP25: 52 | HQ25: 132 | HU25: 68.578481 | HY25: 55.690404 | HZ25: 58.45833 | IA25: 57.350604 | IE25: 55.688403 | IF25: 59.971584 | IG25: 58.674978 | IJ25: 55.408579 | IK25: 58.651271 | IL25: 57.354194 | IN25: Ümumi | IP25: 104 | IQ25: Xarici dil | IR25: 408.102 | IS25: 0 | IT25: 80 | IU25: 65 | IV25: 145 | IZ25: 67.655372 | JD25: 56.22254 | JE25: 62.749179 | JF25: 60.142333 | JJ25: 58.596306 | JK25: 62.67765 | JL25: 60.93734 | JO25: 57.258138 | JP25: 62.680999 | JQ25: 60.511854 | JS25: Ümumi | JU25: 104 | JV25: Xarici dil | JW25: 415.602 | JX25: 0 | JY25: 54 | JZ25: 53 | KA25: 107 | KE25: 64.752128 | KI25: 61.970772 | KJ25: 56.248117 | KK25: 58.407205 | KO25: 63.651715 | KP25: 66.44596 | KQ25: 65.328262 | KT25: 62.752183 | KU25: 61.347038 | KV25: 61.820286 | KW25: 36.865768 | KX25: Ümumi | KZ25: 104 | LA25: Xarici dil | LB25: 451 | LC25: 0 | LD25: 48 | LE25: 37 | LF25: 85 | LJ25: 65.935407 | LN25: 65.79754 | LO25: 61.548055 | LP25: 63.247849 | LT25: 67.923086 | LU25: 63.899522 | LV25: 65.508947 | LY25: 67.003347 | LZ25: 62.905606 | MA25: 64.544703 | MB25: 2.75 | MC25: Ümumi | ME25: 104 | MF25: Xarici dil | MG25: 544 | MH25: 0 | MI25: 21 | MJ25: 32 | MK25: 53 | MO25: 75.143823 | MS25: 72.633589 | MT25: 76.841648 | MU25: 75.158425 | MY25: 77.25 | MZ25: 82.508894 | NA25: 79.033169 | ND25: 74.941795 | NE25: 77.625548 | NF25: 76.552047 | NG25: 44.177175 | NH25: Ümumi
AH26: Fənn olimpiadaları | AI26: 0 | AJ26: 0 | AK26: 0 | AL26: 0 | AM26: 0 | AN26: 0 | AO26: 0 | AP26: 0 | BJ26: Oğlanlar | BM26: Fənn olimpiadaları | BN26: 0 | BO26: 0 | BP26: 0 | BQ26: 0 | BR26: 0 | BS26: 7 | BT26: 8 | BU26: 15 | CO26: Oğlanlar | CR26: Fənn olimpiadaları | CS26: 0 | CT26: 0 | CU26: 0 | CV26: 0 | CW26: 0 | CX26: 33 | CY26: 13 | CZ26: 46 | DA26: 63.387751 | DB26: 0 | DC26: 0 | DD26: 0 | DE26: 55.449492 | DF26: 0 | DG26: 55.449492 | DH26: 0 | DI26: 0 | DJ26: 0 | DK26: 54.947537 | DL26: 0 | DM26: 54.947537 | DN26: 0 | DO26: 0 | DP26: 55.938098 | DQ26: 0 | DR26: 55.938098 | DS26: 0 | DT26: Oğlanlar | DW26: Fənn olimpiadaları | DX26: 0 | DY26: 0 | DZ26: 0 | EA26: 0 | EB26: 0 | EC26: 7 | ED26: 4 | EE26: 11 | EY26: Oğlanlar | FB26: Fənn olimpiadaları | FC26: 0 | FD26: 0 | FE26: 0 | FF26: 0 | FG26: 0 | FH26: 21 | FI26: 57 | FJ26: 78 | FK26: 0 | FL26: 0 | FM26: 0 | FN26: 0 | FO26: 54.734799 | FP26: 53.492113 | FQ26: 53.989187 | FR26: 0 | FS26: 0 | FT26: 0 | FU26: 54.100305 | FV26: 52.191843 | FW26: 52.955228 | FX26: 0 | FY26: 0 | FZ26: 55.14921 | GA26: 53.502664 | GB26: 54.161283 | GC26: 0 | GD26: Oğlanlar | GG26: Fənn olimpiadaları | GH26: 0 | GI26: 0 | GJ26: 0 | GK26: 0 | GL26: 0 | GM26: 36 | GN26: 40 | GO26: 76 | HI26: Oğlanlar | HL26: Fənn olimpiadaları | HM26: 0 | HN26: 0 | HO26: 0 | HP26: 0 | HQ26: 0 | HR26: 134 | HS26: 83 | HT26: 217 | HU26: 55.441103 | HV26: 0 | HW26: 0 | HX26: 0 | HY26: 55.451086 | HZ26: 58.059984 | IA26: 57.01557 | IB26: 0 | IC26: 0 | ID26: 0 | IE26: 54.74036 | IF26: 57.604375 | IG26: 56.71518 | IH26: 0 | II26: 0 | IJ26: 55.530559 | IK26: 58.097331 | IL26: 57.070622 | IM26: 0 | IN26: Oğlanlar | IQ26: Fənn olimpiadaları | IR26: 0 | IS26: 0 | IT26: 0 | IU26: 0 | IV26: 0 | IW26: 16 | IX26: 10 | IY26: 26 | IZ26: 64.805373 | JA26: 0 | JB26: 0 | JC26: 0 | JD26: 52.568467 | JE26: 59.313476 | JF26: 56.619441 | JG26: 0 | JH26: 0 | JI26: 0 | JJ26: 54.659861 | JK26: 56.432976 | JL26: 56.04373 | JM26: 0 | JN26: 0 | JO26: 53.843601 | JP26: 58.647577 | JQ26: 56.725987 | JR26: 0 | JS26: Oğlanlar | JV26: Fənn olimpiadaları | JW26: 0 | JX26: 0 | JY26: 0 | JZ26: 0 | KA26: 0 | KB26: 54 | KC26: 29 | KD26: 83 | KX26: Oğlanlar | LA26: Fənn olimpiadaları | LB26: 0 | LC26: 0 | LD26: 0 | LE26: 0 | LF26: 0 | LG26: 13 | LH26: 14 | LI26: 27 | LJ26: 29.413534 | LK26: 0 | LL26: 0 | LM26: 0 | LN26: 31.534774 | LO26: 28.347744 | LP26: 29.622556 | LQ26: 0 | LR26: 0 | LS26: 0 | LT26: 35.206203 | LU26: 32.140977 | LV26: 33.367068 | LW26: 0 | LX26: 0 | LY26: 33.840883 | LZ26: 30.737782 | MA26: 31.979023 | MB26: 0.14473684 | MC26: Oğlanlar | MF26: Fənn olimpiadaları | MG26: 0 | MH26: 0 | MI26: 0 | MJ26: 0 | MK26: 0 | ML26: 25 | MM26: 8 | MN26: 33 | NH26: Oğlanlar
