Workbook

Sheet Müqayisəli təhlil
A2: Hörmətli Həmkarlar, siz qırmızı rəngli hissədə İndekslər səhifəsində qeyd olunmuş təhsil müəssisəsinin indeksini yazmaqla məlumatları daxil edə bilərsiniz. | B2: Təhsil müəssisəsinin indeksi | C2: Növ | D2: VIII sinif monitorinq | O2: 14 fevral 2022-ci il tarixli monitorinq | Z2: 14 fevral 2022-ci il tarixli monitorinq | AK2: 15 mart 2022-ci il tarixli monitorinq | AV2: Monitorinqlər üzrə orta nəticələr | BG2: Buraxılış imtahanı | BR2: Ölkə üzrə reytinq
D3: Monitorinq VIII | O3: Monitorinq 1 | Z3: Monitorinq 2 | AK3: Monitorinq 3 | AV3: Monitorinq orta | BG3: Buraxılış
D4: Şagird sayı | E4: Tədris dili | F4: Riyaziyyat | G4: Xarici dil | H4: Orta faiz 3 fənn üzrə | I4: Yekun bal | J4: Rayon üzrə reytinq | K4: BŞTİ üzrə reytinq | L4: 0-30 bal aralığı faizlə | O4: Şagird sayı | P4: Tədris dili | Q4: Riyaziyyat | R4: Xarici dil | S4: Orta faiz 3 fənn üzrə | T4: Yekun bal | U4: Rayon üzrə reytinq | V4: BŞTİ üzrə reytinq | W4: 0-30 bal aralığı faizlə | Z4: Şagird sayı | AA4: Tədris dili | AB4: Riyaziyyat | AC4: Xarici dil | AD4: Orta faiz 3 fənn üzrə | AE4: Yekun bal | AF4: Rayon üzrə reytinq | AG4: BŞTİ üzrə reytinq | AH4: 0-30 bal aralığı faizlə | AK4: Şagird sayı | AL4: Tədris dili | AM4: Riyaziyyat | AN4: Xarici dil | AO4: Orta faiz 3 fənn üzrə | AP4: Yekun bal | AQ4: Rayon üzrə reytinq | AR4: BŞTİ üzrə reytinq | AS4: 0-30 bal aralığı faizlə | AV4: Şagird sayı | AW4: Tədris dili | AX4: Riyaziyyat | AY4: Xarici dil | AZ4: Orta faiz 3 fənn üzrə | BA4: Yekun bal | BB4: Rayon üzrə reytinq | BC4: BŞTİ üzrə reytinq | BD4: 0-30 bal aralığı faizlə | BG4: Şagird sayı | BH4: Tədris dili | BI4: Riyaziyyat | BJ4: Xarici dil | BK4: Orta faiz 3 fənn üzrə | BL4: Yekun bal | BM4: Rayon üzrə reytinq | BN4: BŞTİ üzrə reytinq | BO4: 0-30 bal aralığı faizlə
L5: Tədris dili | M5: Riyaziyyat | N5: Xarici dil | W5: Tədris dili | X5: Riyaziyyat | Y5: Xarici dil | AH5: Tədris dili | AI5: Riyaziyyat | AJ5: Xarici dil | AS5: Tədris dili | AT5: Riyaziyyat | AU5: Xarici dil | BD5: Tədris dili | BE5: Riyaziyyat | BF5: Xarici dil | BO5: Tədris dili | BP5: Riyaziyyat | BQ5: Xarici dil
B6: 99 | C6: =IF(VLOOKUP($B$6,İndekslər!$C$5:$BR$535,2,0)="","",VLOOKUP($B$6,İndekslər!$C$5:$BR$535,2,0)) -> tam orta məktəb | D6: =IF(VLOOKUP($B$6,İndekslər!$C$5:$BR$535,3,0)="","",VLOOKUP($B$6,İndekslər!$C$5:$BR$535,3,0)) | E6: =IF(VLOOKUP($B$6,İndekslər!$C$5:$BR$535,4,0)="","",VLOOKUP($B$6,İndekslər!$C$5:$BR$535,4,0)) -> 58.666667 | F6: =IF(VLOOKUP($B$6,İndekslər!$C$5:$BR$535,5,0)="","",VLOOKUP($B$6,İndekslər!$C$5:$BR$535,5,0)) -> 47.6 | G6: =IF(VLOOKUP($B$6,İndekslər!$C$5:$BR$535,6,0)="","",VLOOKUP($B$6,İndekslər!$C$5:$BR$535,6,0)) -> 40 | H6: =IF(VLOOKUP($B$6,İndekslər!$C$5:$BR$535,7,0)="","",VLOOKUP($B$6,İndekslər!$C$5:$BR$535,7,0)) -> 48.755556 | I6: =IF(VLOOKUP($B$6,İndekslər!$C$5:$BR$535,8,0)="","",VLOOKUP($B$6,İndekslər!$C$5:$BR$535,8,0)) -> 146.26667 | J6: =IF(VLOOKUP($B$6,İndekslər!$C$5:$BR$535,9,0)="","",VLOOKUP($B$6,İndekslər!$C$5:$BR$535,9,0)) -> 14 | K6: =IF(VLOOKUP($B$6,İndekslər!$C$5:$BR$535,10,0)="","",VLOOKUP($B$6,İndekslər!$C$5:$BR$535,10,0)) -> 94 | L6: =IF(VLOOKUP($B$6,İndekslər!$C$5:$BR$535,11,0)="","",VLOOKUP($B$6,İndekslər!$C$5:$BR$535,11,0)) | M6: =IF(VLOOKUP($B$6,İndekslər!$C$5:$BR$535,12,0)="","",VLOOKUP($B$6,İndekslər!$C$5:$BR$535,12,0)) | N6: =IF(VLOOKUP($B$6,İndekslər!$C$5:$BR$535,13,0)="","",VLOOKUP($B$6,İndekslər!$C$5:$BR$535,13,0)) | O6: =IF(VLOOKUP($B$6,İndekslər!$C$5:$BR$535,14,0)="","",VLOOKUP($B$6,İndekslər!$C$5:$BR$535,14,0)) -> 127 | P6: =IF(VLOOKUP($B$6,İndekslər!$C$5:$BR$535,15,0)="","",VLOOKUP($B$6,İndekslər!$C$5:$BR$535,15,0)) -> 46.272966 | Q6: =IF(VLOOKUP($B$6,İndekslər!$C$5:$BR$535,16,0)="","",VLOOKUP($B$6,İndekslər!$C$5:$BR$535,16,0)) -> 45.574803 | R6: =IF(VLOOKUP($B$6,İndekslər!$C$5:$BR$535,17,0)="","",VLOOKUP($B$6,İndekslər!$C$5:$BR$535,17,0)) -> 44.80315 | S6: =IF(VLOOKUP($B$6,İndekslər!$C$5:$BR$535,18,0)="","",VLOOKUP($B$6,İndekslər!$C$5:$BR$535,18,0)) -> 45.550306 | T6: =IF(VLOOKUP($B$6,İndekslər!$C$5:$BR$535,19,0)="","",VLOOKUP($B$6,İndekslər!$C$5:$BR$535,19,0)) -> 136.65092 | U6: =IF(VLOOKUP($B$6,İndekslər!$C$5:$BR$535,20,0)="","",VLOOKUP($B$6,İndekslər!$C$5:$BR$535,20,0)) -> 24 | V6: =IF(VLOOKUP($B$6,İndekslər!$C$5:$BR$535,21,0)="","",VLOOKUP($B$6,İndekslər!$C$5:$BR$535,21,0)) -> 200 | W6: =IF(VLOOKUP($B$6,İndekslər!$C$5:$BR$535,22,0)="","",VLOOKUP($B$6,İndekslər!$C$5:$BR$535,22,0)) -> 31.496063 | X6: =IF(VLOOKUP($B$6,İndekslər!$C$5:$BR$535,23,0)="","",VLOOKUP($B$6,İndekslər!$C$5:$BR$535,23,0)) -> 37.795276 | Y6: =IF(VLOOKUP($B$6,İndekslər!$C$5:$BR$535,24,0)="","",VLOOKUP($B$6,İndekslər!$C$5:$BR$535,24,0)) -> 40.15748 | Z6: =IF(VLOOKUP($B$6,İndekslər!$C$5:$BR$535,25,0)="","",VLOOKUP($B$6,İndekslər!$C$5:$BR$535,25,0)) -> 130 | AA6: =IF(VLOOKUP($B$6,İndekslər!$C$5:$BR$535,26,0)="","",VLOOKUP($B$6,İndekslər!$C$5:$BR$535,26,0)) -> 57.924161 | AB6: =IF(VLOOKUP($B$6,İndekslər!$C$5:$BR$535,27,0)="","",VLOOKUP($B$6,İndekslər!$C$5:$BR$535,27,0)) -> 70.049587 | AC6: =IF(VLOOKUP($B$6,İndekslər!$C$5:$BR$535,28,0)="","",VLOOKUP($B$6,İndekslər!$C$5:$BR$535,28,0)) -> 59.003256 | AD6: =IF(VLOOKUP($B$6,İndekslər!$C$5:$BR$535,29,0)="","",VLOOKUP($B$6,İndekslər!$C$5:$BR$535,29,0)) -> 62.325668 | AE6: =IF(VLOOKUP($B$6,İndekslər!$C$5:$BR$535,30,0)="","",VLOOKUP($B$6,İndekslər!$C$5:$BR$535,30,0)) -> 186.977 | AF6: =IF(VLOOKUP($B$6,İndekslər!$C$5:$BR$535,31,0)="","",VLOOKUP($B$6,İndekslər!$C$5:$BR$535,31,0)) -> 3 | AG6: =IF(VLOOKUP($B$6,İndekslər!$C$5:$BR$535,32,0)="","",VLOOKUP($B$6,İndekslər!$C$5:$BR$535,32,0)) -> 16 | AH6: =IF(VLOOKUP($B$6,İndekslər!$C$5:$BR$535,33,0)="","",VLOOKUP($B$6,İndekslər!$C$5:$BR$535,33,0)) -> 0.82644628 | AI6: =IF(VLOOKUP($B$6,İndekslər!$C$5:$BR$535,34,0)="","",VLOOKUP($B$6,İndekslər!$C$5:$BR$535,34,0)) -> 1.6528926 | AJ6: =IF(VLOOKUP($B$6,İndekslər!$C$5:$BR$535,35,0)="","",VLOOKUP($B$6,İndekslər!$C$5:$BR$535,35,0)) -> 0.82644628 | AK6: =IF(VLOOKUP($B$6,İndekslər!$C$5:$BR$535,36,0)="","",VLOOKUP($B$6,İndekslər!$C$5:$BR$535,36,0)) -> 130 | AL6: =IF(VLOOKUP($B$6,İndekslər!$C$5:$BR$535,37,0)="","",VLOOKUP($B$6,İndekslər!$C$5:$BR$535,37,0)) -> 65.943044 | AM6: =IF(VLOOKUP($B$6,İndekslər!$C$5:$BR$535,38,0)="","",VLOOKUP($B$6,İndekslər!$C$5:$BR$535,38,0)) -> 59.591837 | AN6: =IF(VLOOKUP($B$6,İndekslər!$C$5:$BR$535,39,0)="","",VLOOKUP($B$6,İndekslər!$C$5:$BR$535,39,0)) -> 59.593838 | AO6: =IF(VLOOKUP($B$6,İndekslər!$C$5:$BR$535,40,0)="","",VLOOKUP($B$6,İndekslər!$C$5:$BR$535,40,0)) -> 61.709573 | AP6: =IF(VLOOKUP($B$6,İndekslər!$C$5:$BR$535,41,0)="","",VLOOKUP($B$6,İndekslər!$C$5:$BR$535,41,0)) -> 185.12872 | AQ6: =IF(VLOOKUP($B$6,İndekslər!$C$5:$BR$535,42,0)="","",VLOOKUP($B$6,İndekslər!$C$5:$BR$535,42,0)) -> 7 | AR6: =IF(VLOOKUP($B$6,İndekslər!$C$5:$BR$535,43,0)="","",VLOOKUP($B$6,İndekslər!$C$5:$BR$535,43,0)) -> 33 | AS6: =IF(VLOOKUP($B$6,İndekslər!$C$5:$BR$535,44,0)="","",VLOOKUP($B$6,İndekslər!$C$5:$BR$535,44,0)) -> 1.5873016 | AT6: =IF(VLOOKUP($B$6,İndekslər!$C$5:$BR$535,45,0)="","",VLOOKUP($B$6,İndekslər!$C$5:$BR$535,45,0)) -> 0.79365079 | AU6: =IF(VLOOKUP($B$6,İndekslər!$C$5:$BR$535,46,0)="","",VLOOKUP($B$6,İndekslər!$C$5:$BR$535,46,0)) -> 1.5873016 | AV6: =IF(VLOOKUP($B$6,İndekslər!$C$5:$BR$535,47,0)="","",VLOOKUP($B$6,İndekslər!$C$5:$BR$535,47,0)) -> 129 | AW6: =IF(VLOOKUP($B$6,İndekslər!$C$5:$BR$535,48,0)="","",VLOOKUP($B$6,İndekslər!$C$5:$BR$535,48,0)) -> 56.71339 | AX6: =IF(VLOOKUP($B$6,İndekslər!$C$5:$BR$535,49,0)="","",VLOOKUP($B$6,İndekslər!$C$5:$BR$535,49,0)) -> 58.405409 | AY6: =IF(VLOOKUP($B$6,İndekslər!$C$5:$BR$535,50,0)="","",VLOOKUP($B$6,İndekslər!$C$5:$BR$535,50,0)) -> 54.466748 | AZ6: =IF(VLOOKUP($B$6,İndekslər!$C$5:$BR$535,51,0)="","",VLOOKUP($B$6,İndekslər!$C$5:$BR$535,51,0)) -> 56.528516 | BA6: =IF(VLOOKUP($B$6,İndekslər!$C$5:$BR$535,52,0)="","",VLOOKUP($B$6,İndekslər!$C$5:$BR$535,52,0)) -> 169.58555 | BB6: =IF(VLOOKUP($B$6,İndekslər!$C$5:$BR$535,53,0)="","",VLOOKUP($B$6,İndekslər!$C$5:$BR$535,53,0)) -> 10 | BC6: =IF(VLOOKUP($B$6,İndekslər!$C$5:$BR$535,54,0)="","",VLOOKUP($B$6,İndekslər!$C$5:$BR$535,54,0)) -> 59 | BD6: =IF(VLOOKUP($B$6,İndekslər!$C$5:$BR$535,55,0)="","",VLOOKUP($B$6,İndekslər!$C$5:$BR$535,55,0)) -> 1.2068739 | BE6: =IF(VLOOKUP($B$6,İndekslər!$C$5:$BR$535,56,0)="","",VLOOKUP($B$6,İndekslər!$C$5:$BR$535,56,0)) -> 1.2232717 | BF6: =IF(VLOOKUP($B$6,İndekslər!$C$5:$BR$535,57,0)="","",VLOOKUP($B$6,İndekslər!$C$5:$BR$535,57,0)) -> 1.2068739 | BG6: =IF(VLOOKUP($B$6,İndekslər!$C$5:$BR$535,58,0)="","",VLOOKUP($B$6,İndekslər!$C$5:$BR$535,58,0)) -> 135 | BH6: =IF(VLOOKUP($B$6,İndekslər!$C$5:$BR$535,59,0)="","",VLOOKUP($B$6,İndekslər!$C$5:$BR$535,59,0)) -> 54.821094 | BI6: =IF(VLOOKUP($B$6,İndekslər!$C$5:$BR$535,60,0)="","",VLOOKUP($B$6,İndekslər!$C$5:$BR$535,60,0)) -> 32.075 | BJ6: =IF(VLOOKUP($B$6,İndekslər!$C$5:$BR$535,61,0)="","",VLOOKUP($B$6,İndekslər!$C$5:$BR$535,61,0)) -> 36.485937 | BK6: =IF(VLOOKUP($B$6,İndekslər!$C$5:$BR$535,62,0)="","",VLOOKUP($B$6,İndekslər!$C$5:$BR$535,62,0)) -> 41.127344 | BL6: =IF(VLOOKUP($B$6,İndekslər!$C$5:$BR$535,63,0)="","",VLOOKUP($B$6,İndekslər!$C$5:$BR$535,63,0)) -> 123.38203 | BM6: =IF(VLOOKUP($B$6,İndekslər!$C$5:$BR$535,64,0)="","",VLOOKUP($B$6,İndekslər!$C$5:$BR$535,64,0)) -> 20 | BN6: =IF(VLOOKUP($B$6,İndekslər!$C$5:$BR$535,65,0)="","",VLOOKUP($B$6,İndekslər!$C$5:$BR$535,65,0)) -> 146 | BO6: =IF(VLOOKUP($B$6,İndekslər!$C$5:$BR$535,66,0)="","",VLOOKUP($B$6,İndekslər!$C$5:$BR$535,66,0)) -> 18.75 | BP6: =IF(VLOOKUP($B$6,İndekslər!$C$5:$BR$535,67,0)="","",VLOOKUP($B$6,İndekslər!$C$5:$BR$535,67,0)) -> 60.9375 | BQ6: =IF(VLOOKUP($B$6,İndekslər!$C$5:$BR$535,68,0)="","",VLOOKUP($B$6,İndekslər!$C$5:$BR$535,68,0)) -> 50.78125 | BR6: =IF(VLOOKUP($B$6,İndekslər!$C$5:$BS$535,69,0)="","",VLOOKUP($B$6,İndekslər!$C$5:$BS$535,69,0))

Sheet İndekslər
A1: Bakı Şəhəri üzrə Təhsil İdarəsinin tabeliyində olan təhsil müəssisələrində IX siniflərin buraxılış imtahanı monitorinqinin və buraxılış imtahanlarının müqayisəli səciyyəsi
A2: № | B2: Rayon | C2: Təhsil müəssisəsinin indeksi | D2: Növ | E2: 8-ci sinif monitorinq | P2: 10 dekabr 2021-ci il tarixli monitorinq | AA2: 15 fevral 2022-ci il tarixli monitorinq | AL2: 16 mart 2022-ci il tarixli monitorinq | AW2: Monitorinqlər üzrə orta nəticələr | BH2: Buraxılış imtahanı | BS2: Ölkə üzrə reytinq
E3: Şagird sayı | F3: Tədris dili | G3: Riyaziyyat | H3: Xarici dil | I3: Orta faiz 3 fənn üzrə | J3: Yekun bal | K3: Rayon üzrə reytinq | L3: BŞTİ üzrə reytinq | M3: 0-30 bal aralığı faizlə | P3: Şagird sayı | Q3: Tədris dili | R3: Riyaziyyat | S3: Xarici dil | T3: Orta faiz 3 fənn üzrə | U3: Yekun bal | V3: Rayon üzrə reytinq | W3: BŞTİ üzrə reytinq | X3: 0-30 bal aralığı faizlə | AA3: Şagird sayı | AB3: Tədris dili | AC3: Riyaziyyat | AD3: Xarici dil | AE3: Orta faiz 3 fənn üzrə | AF3: Yekun bal | AG3: Rayon üzrə reytinq | AH3: BŞTİ üzrə reytinq | AI3: 0-30 bal aralığı faizlə | AL3: Şagird sayı | AM3: Tədris dili | AN3: Riyaziyyat | AO3: Xarici dil | AP3: Orta faiz 3 fənn üzrə | AQ3: Yekun bal | AR3: Rayon üzrə reytinq | AS3: BŞTİ üzrə reytinq | AT3: 0-30 bal aralığı faizlə | AW3: Şagird sayı | AX3: Tədris dili | AY3: Riyaziyyat | AZ3: Xarici dil | BA3: Orta faiz 3 fənn üzrə | BB3: Yekun bal | BC3: Rayon üzrə reytinq | BD3: BŞTİ üzrə reytinq | BE3: 0-30 bal aralığı faizlə | BH3: Şagird sayı | BI3: Tədris dili | BJ3: Riyaziyyat | BK3: Xarici dil | BL3: Orta faiz 3 fənn üzrə | BM3: Yekun bal | BN3: Rayon üzrə reytinq | BO3: BŞTİ üzrə reytinq | BP3: 0-30 bal aralığı faizlə
M4: Tədris dili | N4: Riyaziyyat | O4: Xarici dil | X4: Tədris dili | Y4: Riyaziyyat | Z4: Xarici dil | AI4: Tədris dili | AJ4: Riyaziyyat | AK4: Xarici dil | AT4: Tədris dili | AU4: Riyaziyyat | AV4: Xarici dil | BE4: Tədris dili | BF4: Riyaziyyat | BG4: Xarici dil | BP4: Tədris dili | BQ4: Riyaziyyat | BR4: Xarici dil
A5: 0 | B5: Bakı | C5: BŞTİ | D5: Ümumi | F5: =AVERAGE(F6:F535) -> 47.571837 | G5: =AVERAGE(G6:G535) -> 45.896898 | H5: =AVERAGE(H6:H535) -> 39.292826 | I5: =AVERAGE(I6:I535) -> 44.256245 | J5: =AVERAGE(J6:J535) -> 132.63188 | P5: =SUM(P6:P535) -> 31877 | Q5: =AVERAGE(Q6:Q535) -> 51.702818 | R5: =AVERAGE(R6:R535) -> 47.656235 | S5: =AVERAGE(S6:S535) -> 51.870922 | T5: =AVERAGE(T6:T535) -> 50.39222 | U5: =AVERAGE(U6:U535) -> 151.06046 | X5: 16 | Y5: 24 | Z5: 24 | AA5: 33710 | AB5: 43.213183 | AC5: 45.594652 | AD5: 48.003108 | AE5: 45.539334 | AF5: 136.49923 | AI5: 27.423183 | AJ5: 26.859017 | AK5: 25.51742 | AL5: 34173 | AM5: 57.392848 | AN5: 36.928456 | AO5: 53.879294 | AP5: 49.378118 | AQ5: 148.2006 | AT5: 12.534571 | AU5: 39.917237 | AV5: 20.329741 | AW5: =AVERAGE(E5,AA5,AL5) -> 33941.5 | AX5: =AVERAGE(F5,AB5,AM5) -> 49.392623 | AY5: =AVERAGE(G5,AC5,AN5) -> 42.806668 | AZ5: =AVERAGE(H5,AD5,AO5) -> 47.058409 | BA5: =AVERAGE(I5,AE5,AP5) -> 46.391232 | BB5: =AVERAGE(J5,AF5,AQ5) -> 139.11057 | BE5: =AVERAGE(M5,AI5,AT5) -> 19.978877 | BF5: =AVERAGE(N5,AJ5,AU5) -> 33.388127 | BG5: =AVERAGE(O5,AK5,AV5) -> 22.92358 | BH5: 34813 | BI5: 54.484055 | BJ5: 33.023661 | BK5: 38.848735 | BL5: 42.118817 | BM5: 126.35645 | BP5: 19 | BQ5: 55 | BR5: 47
A6: 1 | B6: Binəqədi | C6: 3 | D6: tam orta məktəb | F6: 56.666667 | G6: 58.4 | H6: 40 | I6: =IF(F6="","",AVERAGE(F6:H6)) -> 51.688889 | J6: =IF(F6="","",SUM(F6:H6)) -> 155.06667 | K6: =IF(J6="","",(RANK(J6,$J$6:$J$39))) -> 11 | L6: =IF(J6="","",(RANK(J6,$J$6:$J$535))) -> 65 | P6: 127 | Q6: 58.005249 | R6: 55.559055 | S6: 68.635171 | T6: 60.733158 | U6: 182.19948 | V6: 8 | W6: 52 | X6: 13.385827 | Y6: 11.023622 | Z6: 5.511811 | AA6: 146 | AB6: 52.022059 | AC6: 56.368534 | AD6: 65.435606 | AE6: 57.942066 | AF6: 173.8262 | AG6: 8 | AH6: 35 | AI6: 12.5 | AJ6: 10.15625 | AK6: 10.655738 | AL6: 138 | AM6: 70.19141 | AN6: 51.090312 | AO6: 73.333333 | AP6: 64.769979 | AQ6: 194.61506 | AR6: 3 | AS6: 16 | AT6: 3.1746032 | AU6: 11.111111 | AV6: 1.6260163 | AW6: =AVERAGE(P6,AA6,AL6) -> 137 | AX6: =AVERAGE(Q6,AB6,AM6) -> 60.072906 | AY6: =AVERAGE(R6,AC6,AN6) -> 54.339301 | AZ6: =AVERAGE(S6,AD6,AO6) -> 69.134703 | BA6: =AVERAGE(T6,AE6,AP6) -> 61.148401 | BB6: =AVERAGE(U6,AF6,AQ6) -> 183.54691 | BC6: =IF(BB6="","",(RANK(BB6,$BB$6:$BB$39))) -> 4 | BD6: =IF(BB6="","",(RANK(BB6,$BB$6:$BB$535))) -> 24 | BE6: =AVERAGE(M6,AI6,AT6) -> 7.8373016 | BF6: =AVERAGE(N6,AJ6,AU6) -> 10.633681 | BG6: =AVERAGE(O6,AK6,AV6) -> 6.140877 | BH6: 132 | BI6: 64.293939 | BJ6: 40.356818 | BK6: 45.834091 | BL6: 50.161616 | BM6: 150.48485 | BN6: 2 | BO6: 33 | BP6: 8.3333333 | BQ6: 41.666667 | BR6: 32.575758 | BT6: 3
A7: 2 | B7: Binəqədi | C7: 6u | D7: UGİM | I7: =IF(F7="","",AVERAGE(F7:H7)) | J7: =IF(F7="","",SUM(F7:H7)) | K7: =IF(J7="","",(RANK(J7,$J$6:$J$39))) | L7: =IF(J7="","",(RANK(J7,$J$6:$J$535))) | BC7: =IF(BB7="","",(RANK(BB7,$BB$6:$BB$39))) | BD7: =IF(BB7="","",(RANK(BB7,$BB$6:$BB$535))) | BT7: 6
A8: 3 | B8: Binəqədi | C8: 30 | D8: tam orta məktəb | F8: 54 | G8: 48 | H8: 31 | I8: =IF(F8="","",AVERAGE(F8:H8)) -> 44.333333 | J8: =IF(F8="","",SUM(F8:H8)) -> 133 | K8: =IF(J8="","",(RANK(J8,$J$6:$J$39))) -> 21 | L8: =IF(J8="","",(RANK(J8,$J$6:$J$535))) -> 147 | P8: 44 | Q8: 46.818182 | R8: 38.818182 | S8: 44.166667 | T8: 43.267677 | U8: 129.80303 | V8: 29 | W8: 237 | X8: 18.181818 | Y8: 47.727273 | Z8: 29.545455 | AA8: 41 | AB8: 40.674319 | AC8: 43.707317 | AD8: 50.554324 | AE8: 44.978653 | AF8: 134.93596 | AG8: 23 | AH8: 158 | AI8: 26.829268 | AJ8: 17.073171 | AK8: 21.95122 | AL8: 45 | AM8: 50.130719 | AN8: 37.206349 | AO8: 49.673203 | AP8: 45.67009 | AQ8: 137.01027 | AR8: 29 | AS8: 203 | AT8: 15.555556 | AU8: 37.777778 | AV8: 26.666667 | AW8: =AVERAGE(P8,AA8,AL8) -> 43.333333 | AX8: =AVERAGE(Q8,AB8,AM8) -> 45.874406 | AY8: =AVERAGE(R8,AC8,AN8) -> 39.910616 | AZ8: =AVERAGE(S8,AD8,AO8) -> 48.131398 | BA8: =AVERAGE(T8,AE8,AP8) -> 44.638807 | BB8: =AVERAGE(U8,AF8,AQ8) -> 133.91642 | BC8: =IF(BB8="","",(RANK(BB8,$BB$6:$BB$39))) -> 29 | BD8: =IF(BB8="","",(RANK(BB8,$BB$6:$BB$535))) -> 203 | BE8: =AVERAGE(M8,AI8,AT8) -> 21.192412 | BF8: =AVERAGE(N8,AJ8,AU8) -> 27.425474 | BG8: =AVERAGE(O8,AK8,AV8) -> 24.308943 | BH8: 45 | BI8: 51.875556 | BJ8: 32.768889 | BK8: 36.271111 | BL8: 40.305185 | BM8: 120.91556 | BN8: 22 | BO8: 161 | BP8: 15.555556 | BQ8: 55.555556 | BR8: 46.666667 | BT8: 30
A9: 4 | B9: Binəqədi | C9: 83 | D9: məktəb-lisey | F9: 47.333333 | G9: 48 | H9: 46 | I9: =IF(F9="","",AVERAGE(F9:H9)) -> 47.111111 | J9: =IF(F9="","",SUM(F9:H9)) -> 141.33333 | K9: =IF(J9="","",(RANK(J9,$J$6:$J$39))) -> 18 | L9: =IF(J9="","",(RANK(J9,$J$6:$J$535))) -> 122 | P9: 162 | Q9: 62.078189 | R9: 51.111111 | S9: 60.493827 | T9: 57.894376 | U9: 173.68313 | V9: 13 | W9: 73 | X9: 3.7037037 | Y9: 17.283951 | Z9: 14.197531 | AA9: 161 | AB9: 51.223968 | AC9: 51.403727 | AD9: 64.088086 | AE9: 55.571927 | AF9: 166.71578 | AG9: 10 | AH9: 48 | AI9: 15.52795 | AJ9: 23.602484 | AK9: 11.180124 | AL9: 160 | AM9: 64.595588 | AN9: 36.339286 | AO9: 63.984462 | AP9: 54.927696 | AQ9: 164.91934 | AR9: 13 | AS9: 83 | AT9: 6.2893082 | AU9: 36.25 | AV9: 16.455696 | AW9: =AVERAGE(P9,AA9,AL9) -> 161 | AX9: =AVERAGE(Q9,AB9,AM9) -> 59.299248 | AY9: =AVERAGE(R9,AC9,AN9) -> 46.284708 | AZ9: =AVERAGE(S9,AD9,AO9) -> 62.855458 | BA9: =AVERAGE(T9,AE9,AP9) -> 56.131333 | BB9: =AVERAGE(U9,AF9,AQ9) -> 168.43941 | BC9: =IF(BB9="","",(RANK(BB9,$BB$6:$BB$39))) -> 12 | BD9: =IF(BB9="","",(RANK(BB9,$BB$6:$BB$535))) -> 64 | BE9: =AVERAGE(M9,AI9,AT9) -> 10.908629 | BF9: =AVERAGE(N9,AJ9,AU9) -> 29.926242 | BG9: =AVERAGE(O9,AK9,AV9) -> 13.81791 | BH9: 167 | BI9: 68.638922 | BJ9: 40.982036 | BK9: 52.743114 | BL9: 54.121357 | BM9: 162.36407 | BN9: 1 | BO9: 14 | BP9: 4.7904192 | BQ9: 41.317365 | BR9: 22.754491 | BT9: 83
A10: 5 | B10: Binəqədi | C10: 99 | D10: tam orta məktəb | F10: 58.666667 | G10: 47.6 | H10: 40 | I10: =IF(F10="","",AVERAGE(F10:H10)) -> 48.755556 | J10: =IF(F10="","",SUM(F10:H10)) -> 146.26667 | K10: =IF(J10="","",(RANK(J10,$J$6:$J$39))) -> 14 | L10: =IF(J10="","",(RANK(J10,$J$6:$J$535))) -> 94 | P10: 127 | Q10: 46.272966 | R10: 45.574803 | S10: 44.80315 | T10: 45.550306 | U10: 136.65092 | V10: 24 | W10: 200 | X10: 31.496063 | Y10: 37.795276 | Z10: 40.15748 | AA10: 130 | AB10: 57.924161 | AC10: 70.049587 | AD10: 59.003256 | AE10: 62.325668 | AF10: 186.977 | AG10: 3 | AH10: 16 | AI10: 0.82644628 | AJ10: 1.6528926 | AK10: 0.82644628 | AL10: 130 | AM10: 65.943044 | AN10: 59.591837 | AO10: 59.593838 | AP10: 61.709573 | AQ10: 185.12872 | AR10: 7 | AS10: 33 | AT10: 1.5873016 | AU10: 0.79365079 | AV10: 1.5873016 | AW10: =AVERAGE(P10,AA10,AL10) -> 129 | AX10: =AVERAGE(Q10,AB10,AM10) -> 56.71339 | AY10: =AVERAGE(R10,AC10,AN10) -> 58.405409 | AZ10: =AVERAGE(S10,AD10,AO10) -> 54.466748 | BA10: =AVERAGE(T10,AE10,AP10) -> 56.528516 | BB10: =AVERAGE(U10,AF10,AQ10) -> 169.58555 | BC10: =IF(BB10="","",(RANK(BB10,$BB$6:$BB$39))) -> 10 | BD10: =IF(BB10="","",(RANK(BB10,$BB$6:$BB$535))) -> 59 | BE10: =AVERAGE(M10,AI10,AT10) -> 1.2068739 | BF10: =AVERAGE(N10,AJ10,AU10) -> 1.2232717 | BG10: =AVERAGE(O10,AK10,AV10) -> 1.2068739 | BH10: 135 | BI10: 54.821094 | BJ10: 32.075 | BK10: 36.485937 | BL10: 41.127344 | BM10: 123.38203 | BN10: 20 | BO10: 146 | BP10: 18.75 | BQ10: 60.9375 | BR10: 50.78125 | BT10: 99
A11: 6 | B11: Binəqədi | C11: 100 | D11: tam orta məktəb | F11: 54.666667 | G11: 39.2 | H11: 37.666667 | I11: =IF(F11="","",AVERAGE(F11:H11)) -> 43.844444 | J11: =IF(F11="","",SUM(F11:H11)) -> 131.53333 | K11: =IF(J11="","",(RANK(J11,$J$6:$J$39))) -> 22 | L11: =IF(J11="","",(RANK(J11,$J$6:$J$535))) -> 152 | P11: 117 | Q11: 59.487179 | R11: 59.794872 | S11: 62.090395 | T11: 60.462121 | U11: 181.37245 | V11: 10 | W11: 57 | X11: 6.8376068 | Y11: 5.1282051 | Z11: 12.711864 | AA11: 136 | AB11: 49.434389 | AC11: 50.184615 | AD11: 60.4662 | AE11: 53.361735 | AF11: 160.0852 | AG11: 11 | AH11: 64 | AI11: 21.705426 | AJ11: 19.379845 | AK11: 17.886179 | AL11: 136 | AM11: 60.094118 | AN11: 40.419397 | AO11: 64.735003 | AP11: 54.594616 | AQ11: 165.24852 | AR11: 12 | AS11: 80 | AT11: 9.6 | AU11: 33.944954 | AV11: 6.9306931 | AW11: =AVERAGE(P11,AA11,AL11) -> 129.66667 | AX11: =AVERAGE(Q11,AB11,AM11) -> 56.338562 | AY11: =AVERAGE(R11,AC11,AN11) -> 50.132961 | AZ11: =AVERAGE(S11,AD11,AO11) -> 62.430533 | BA11: =AVERAGE(T11,AE11,AP11) -> 56.139491 | BB11: =AVERAGE(U11,AF11,AQ11) -> 168.90206 | BC11: =IF(BB11="","",(RANK(BB11,$BB$6:$BB$39))) -> 11 | BD11: =IF(BB11="","",(RANK(BB11,$BB$6:$BB$535))) -> 62 | BE11: =AVERAGE(M11,AI11,AT11) -> 15.652713 | BF11: =AVERAGE(N11,AJ11,AU11) -> 26.6624 | BG11: =AVERAGE(O11,AK11,AV11) -> 12.408436 | BH11: 135 | BI11: 56.305926 | BJ11: 32.388889 | BK11: 39.200741 | BL11: 42.631852 | BM11: 127.89556 | BN11: 16 | BO11: 127 | BP11: 14.074074 | BQ11: 48.888889 | BR11: 42.962963 | BT11: 100
A12: 7 | B12: Binəqədi | C12: 102 | D12: tam orta məktəb | F12: 61.666667 | G12: 72 | H12: 75 | I12: =IF(F12="","",AVERAGE(F12:H12)) -> 69.555556 | J12: =IF(F12="","",SUM(F12:H12)) -> 208.66667 | K12: =IF(J12="","",(RANK(J12,$J$6:$J$39))) -> 2 | L12: =IF(J12="","",(RANK(J12,$J$6:$J$535))) -> 4 | P12: 97 | Q12: 68.14433 | R12: 58.762887 | S12: 66.563574 | T12: 64.490263 | U12: 193.47079 | V12: 4 | W12: 26 | X12: 6.185567 | Y12: 5.1546392 | Z12: 13.402062 | AA12: 102 | AB12: 58.549932 | AC12: 56.093023 | AD12: 60.427807 | AE12: 58.410438 | AF12: 175.07076 | AG12: 7 | AH12: 33 | AI12: 10.465116 | AJ12: 10.465116 | AK12: 9.4117647 | AL12: 100 | AM12: 53.716871 | AN12: 30.486656 | AO12: 63.606981 | AP12: 49.27017 | AQ12: 147.81051 | AR12: 24 | AS12: 151 | AT12: 13.186813 | AU12: 49.450549 | AV12: 5.4945055 | AW12: =AVERAGE(P12,AA12,AL12) -> 99.666667 | AX12: =AVERAGE(Q12,AB12,AM12) -> 60.137044 | AY12: =AVERAGE(R12,AC12,AN12) -> 48.447522 | AZ12: =AVERAGE(S12,AD12,AO12) -> 63.532788 | BA12: =AVERAGE(T12,AE12,AP12) -> 57.39029 | BB12: =AVERAGE(U12,AF12,AQ12) -> 172.11735 | BC12: =IF(BB12="","",(RANK(BB12,$BB$6:$BB$39))) -> 8 | BD12: =IF(BB12="","",(RANK(BB12,$BB$6:$BB$535))) -> 52 | BE12: =AVERAGE(M12,AI12,AT12) -> 11.825965 | BF12: =AVERAGE(N12,AJ12,AU12) -> 29.957833 | BG12: =AVERAGE(O12,AK12,AV12) -> 7.4531351 | BH12: 100 | BI12: 62.342 | BJ12: 36.568 | BK12: 43.467 | BL12: 47.459 | BM12: 142.377 | BN12: 6 | BO12: 58 | BP12: 11 | BQ12: 40 | BR12: 30 | BT12: 102
A13: 8 | B13: Binəqədi | C13: 103 | D13: tam orta məktəb | F13: 34.666667 | G13: 23.2 | H13: 17.666667 | I13: =IF(F13="","",AVERAGE(F13:H13)) -> 25.177778 | J13: =IF(F13="","",SUM(F13:H13)) -> 75.533333 | K13: =IF(J13="","",(RANK(J13,$J$6:$J$39))) -> 32 | L13: =IF(J13="","",(RANK(J13,$J$6:$J$535))) -> 298 | P13: 86 | Q13: 43.79845 | R13: 38.046512 | S13: 40.232558 | T13: 40.692506 | U13: 122.07752 | V13: 31 | W13: 266 | X13: 32.55814 | Y13: 48.837209 | Z13: 50 | AA13: 108 | AB13: 37.790698 | AC13: 37.906977 | AD13: 36.976912 | AE13: 37.446427 | AF13: 112.67459 | AG13: 31 | AH13: 241 | AI13: 44.186047 | AJ13: 47.674419 | AK13: 50 | AL13: 108 | AM13: 49.873498 | AN13: 36.473118 | AO13: 39.23102 | AP13: 41.859212 | AQ13: 125.57764 | AR13: 31 | AS13: 246 | AT13: 26.88172 | AU13: 41.935484 | AV13: 47.826087 | AW13: =AVERAGE(P13,AA13,AL13) -> 100.66667 | AX13: =AVERAGE(Q13,AB13,AM13) -> 43.820882 | AY13: =AVERAGE(R13,AC13,AN13) -> 37.475536 | AZ13: =AVERAGE(S13,AD13,AO13) -> 38.813497 | BA13: =AVERAGE(T13,AE13,AP13) -> 39.999382 | BB13: =AVERAGE(U13,AF13,AQ13) -> 120.10991 | BC13: =IF(BB13="","",(RANK(BB13,$BB$6:$BB$39))) -> 32 | BD13: =IF(BB13="","",(RANK(BB13,$BB$6:$BB$535))) -> 262 | BE13: =AVERAGE(M13,AI13,AT13) -> 35.533883 | BF13: =AVERAGE(N13,AJ13,AU13) -> 44.804951 | BG13: =AVERAGE(O13,AK13,AV13) -> 48.913043 | BH13: 109 | BI13: 46.690741 | BJ13: 25.368519 | BK13: 29.027778 | BL13: 33.695679 | BM13: 101.08704 | BN13: 30 | BO13: 265 | BP13: 31.481481 | BQ13: 67.592593 | BR13: 63.888889 | BT13: 103
A14: 9 | B14: Binəqədi | C14: 115x | D14: XƏQTOM | I14: =IF(F14="","",AVERAGE(F14:H14)) | J14: =IF(F14="","",SUM(F14:H14)) | K14: =IF(J14="","",(RANK(J14,$J$6:$J$39))) | L14: =IF(J14="","",(RANK(J14,$J$6:$J$535))) | BC14: =IF(BB14="","",(RANK(BB14,$BB$6:$BB$39))) | BD14: =IF(BB14="","",(RANK(BB14,$BB$6:$BB$535))) | BH14: 7 | BI14: 30.657143 | BJ14: 28.071429 | BK14: 15.114286 | BL14: 24.614286 | BM14: 73.842857 | BN14: 33 | BO14: 307 | BP14: 71.428571 | BQ14: 85.714286 | BR14: 100 | BT14: 115
A15: 10 | B15: Binəqədi | C15: 115 | D15: tam orta məktəb | F15: 61.333333 | G15: 66.4 | H15: 60 | I15: =IF(F15="","",AVERAGE(F15:H15)) -> 62.577778 | J15: =IF(F15="","",SUM(F15:H15)) -> 187.73333 | K15: =IF(J15="","",(RANK(J15,$J$6:$J$39))) -> 4 | L15: =IF(J15="","",(RANK(J15,$J$6:$J$535))) -> 15 | P15: 130 | Q15: 65.461538 | R15: 66.092308 | S15: 66.615385 | T15: 66.05641 | U15: 198.16923 | V15: 3 | W15: 18 | X15: 4.6153846 | Y15: 6.25 | Z15: 7.6923077 | AA15: 133 | AB15: 62.428843 | AC15: 66.548387 | AD15: 62.952102 | AE15: 63.976444 | AF15: 191.92933 | AG15: 2 | AH15: 12 | AI15: 8.0645161 | AJ15: 2.4193548 | AK15: 4.0322581 | AL15: 132 | AM15: 71.098687 | AN15: 62.715466 | AO15: 76.859504 | AP15: 70.224553 | AQ15: 210.67366 | AR15: 1 | AS15: 6 | AT15: 1.6528926 | AU15: 8.3333333 | AV15: 1.7094017 | AW15: =AVERAGE(P15,AA15,AL15) -> 131.66667 | AX15: =AVERAGE(Q15,AB15,AM15) -> 66.329689 | AY15: =AVERAGE(R15,AC15,AN15) -> 65.11872 | AZ15: =AVERAGE(S15,AD15,AO15) -> 68.808997 | BA15: =AVERAGE(T15,AE15,AP15) -> 66.752469 | BB15: =AVERAGE(U15,AF15,AQ15) -> 200.25741 | BC15: =IF(BB15="","",(RANK(BB15,$BB$6:$BB$39))) -> 2 | BD15: =IF(BB15="","",(RANK(BB15,$BB$6:$BB$535))) -> 9 | BE15: =AVERAGE(M15,AI15,AT15) -> 4.8587043 | BF15: =AVERAGE(N15,AJ15,AU15) -> 5.3763441 | BG15: =AVERAGE(O15,AK15,AV15) -> 2.8708299 | BH15: 132 | BI15: 57.454545 | BJ15: 31.694697 | BK15: 39.592424 | BL15: 42.913889 | BM15: 128.74167 | BN15: 14 | BO15: 121 | BP15: 19.69697 | BQ15: 56.818182 | BR15: 40.151515 | BT15: 115
A16: 11 | B16: Binəqədi | C16: 126 | D16: TN | F16: 40.666667 | G16: 45.6 | H16: 38 | I16: =IF(F16="","",AVERAGE(F16:H16)) -> 41.422222 | J16: =IF(F16="","",SUM(F16:H16)) -> 124.26667 | K16: =IF(J16="","",(RANK(J16,$J$6:$J$39))) -> 24 | L16: =IF(J16="","",(RANK(J16,$J$6:$J$535))) -> 174 | P16: 73 | Q16: 50 | R16: 39.287671 | S16: 44.200913 | T16: 44.496195 | U16: 133.48858 | V16: 26 | W16: 217 | X16: 19.178082 | Y16: 43.835616 | Z16: 36.986301 | AA16: 77 | AB16: 47.326203 | AC16: 49.558442 | AD16: 53.482881 | AE16: 50.122509 | AF16: 150.36753 | AG16: 15 | AH16: 97 | AI16: 14.285714 | AJ16: 10.38961 | AK16: 19.480519 | AL16: 61 | AM16: 68.707811 | AN16: 38.173302 | AO16: 66.297011 | AP16: 57.726041 | AQ16: 173.17812 | AR16: 9 | AS16: 57 | AT16: 4.9180328 | AU16: 13.114754 | AV16: 8.1967213 | AW16: =AVERAGE(P16,AA16,AL16) -> 70.333333 | AX16: =AVERAGE(Q16,AB16,AM16) -> 55.344671 | AY16: =AVERAGE(R16,AC16,AN16) -> 42.339805 | AZ16: =AVERAGE(S16,AD16,AO16) -> 54.660268 | BA16: =AVERAGE(T16,AE16,AP16) -> 50.781582 | BB16: =AVERAGE(U16,AF16,AQ16) -> 152.34474 | BC16: =IF(BB16="","",(RANK(BB16,$BB$6:$BB$39))) -> 18 | BD16: =IF(BB16="","",(RANK(BB16,$BB$6:$BB$535))) -> 117 | BE16: =AVERAGE(M16,AI16,AT16) -> 9.6018735 | BF16: =AVERAGE(N16,AJ16,AU16) -> 11.752182 | BG16: =AVERAGE(O16,AK16,AV16) -> 13.83862 | BH16: 80 | BI16: 54.131646 | BJ16: 27.674684 | BK16: 38.34557 | BL16: 40.050633 | BM16: 120.1519 | BN16: 23 | BO16: 163 | BP16: 22.78481 | BQ16: 59.493671 | BR16: 45.56962 | BT16: 126
A17: 12 | B17: Binəqədi | C17: 135 | D17: tam orta məktəb | F17: 51.666667 | G17: 50.8 | H17: 43.333333 | I17: =IF(F17="","",AVERAGE(F17:H17)) -> 48.6 | J17: =IF(F17="","",SUM(F17:H17)) -> 145.8 | K17: =IF(J17="","",(RANK(J17,$J$6:$J$39))) -> 15 | L17: =IF(J17="","",(RANK(J17,$J$6:$J$535))) -> 96 | P17: 48 | Q17: 50.833333 | R17: 59.25 | S17: 55.972222 | T17: 55.351852 | U17: 166.05556 | V17: 14 | W17: 91 | X17: 8.3333333 | Y17: 8.3333333 | Z17: 10.416667 | AA17: 53 | AB17: 50.113122 | AC17: 57.153846 | AD17: 71.678322 | AE17: 59.64843 | AF17: 178.94529 | AG17: 5 | AH17: 26 | AI17: 21.153846 | AJ17: 1.9230769 | AK17: 7.6923077 | AL17: 54 | AM17: 79.62963 | AN17: 44.338624 | AO17: 69.444444 | AP17: 64.470899 | AQ17: 193.4127 | AR17: 4 | AS17: 18 | AT17: 4.0816327 | AU17: 16.666667 | AV17: 0 | AW17: =AVERAGE(P17,AA17,AL17) -> 51.666667 | AX17: =AVERAGE(Q17,AB17,AM17) -> 60.192028 | AY17: =AVERAGE(R17,AC17,AN17) -> 53.580823 | AZ17: =AVERAGE(S17,AD17,AO17) -> 65.698329 | BA17: =AVERAGE(T17,AE17,AP17) -> 59.823727 | BB17: =AVERAGE(U17,AF17,AQ17) -> 179.47118 | BC17: =IF(BB17="","",(RANK(BB17,$BB$6:$BB$39))) -> 6 | BD17: =IF(BB17="","",(RANK(BB17,$BB$6:$BB$535))) -> 31 | BE17: =AVERAGE(M17,AI17,AT17) -> 12.617739 | BF17: =AVERAGE(N17,AJ17,AU17) -> 9.2948718 | BG17: =AVERAGE(O17,AK17,AV17) -> 3.8461538 | BH17: 54 | BI17: 55.524074 | BJ17: 31.446296 | BK17: 41.942593 | BL17: 42.970988 | BM17: 128.91296 | BN17: 13 | BO17: 118 | BP17: 14.814815 | BQ17: 50 | BR17: 27.777778 | BT17: 135
A18: 13 | B18: Binəqədi | C18: 143 | D18: tam orta məktəb | F18: 46.666667 | G18: 34.8 | H18: 36.666667 | I18: =IF(F18="","",AVERAGE(F18:H18)) -> 39.377778 | J18: =IF(F18="","",SUM(F18:H18)) -> 118.13333 | K18: =IF(J18="","",(RANK(J18,$J$6:$J$39))) -> 26 | L18: =IF(J18="","",(RANK(J18,$J$6:$J$535))) -> 200 | P18: 87 | Q18: 48.659004 | R18: 36.643678 | S18: 45.517241 | T18: 43.606641 | U18: 130.81992 | V18: 28 | W18: 231 | X18: 18.390805 | Y18: 45.977011 | Z18: 34.482759 | AA18: 91 | AB18: 48.663102 | AC18: 35.995298 | AD18: 49.139118 | AE18: 44.599173 | AF18: 133.79752 | AG18: 26 | AH18: 162 | AI18: 11.363636 | AJ18: 44.318182 | AK18: 28.409091 | AL18: 91 | AM18: 60.872439 | AN18: 35.601926 | AO18: 49.405155 | AP18: 48.626507 | AQ18: 145.87952 | AR18: 25 | AS18: 162 | AT18: 8.988764 | AU18: 38.202247 | AV18: 22.47191 | AW18: =AVERAGE(P18,AA18,AL18) -> 89.666667 | AX18: =AVERAGE(Q18,AB18,AM18) -> 52.731515 | AY18: =AVERAGE(R18,AC18,AN18) -> 36.080301 | AZ18: =AVERAGE(S18,AD18,AO18) -> 48.020505 | BA18: =AVERAGE(T18,AE18,AP18) -> 45.610774 | BB18: =AVERAGE(U18,AF18,AQ18) -> 136.83232 | BC18: =IF(BB18="","",(RANK(BB18,$BB$6:$BB$39))) -> 26 | BD18: =IF(BB18="","",(RANK(BB18,$BB$6:$BB$535))) -> 184 | BE18: =AVERAGE(M18,AI18,AT18) -> 10.1762 | BF18: =AVERAGE(N18,AJ18,AU18) -> 41.260215 | BG18: =AVERAGE(O18,AK18,AV18) -> 25.440501 | BH18: 91 | BI18: 56.659341 | BJ18: 27.49011 | BK18: 38.979121 | BL18: 41.042857 | BM18: 123.12857 | BN18: 21 | BO18: 147 | BP18: 19.78022 | BQ18: 67.032967 | BR18: 41.758242 | BT18: 143
A19: 14 | B19: Binəqədi | C19: 144 | D19: tam orta məktəb | F19: 55.333333 | G19: 60.8 | H19: 65 | I19: =IF(F19="","",AVERAGE(F19:H19)) -> 60.377778 | J19: =IF(F19="","",SUM(F19:H19)) -> 181.13333 | K19: =IF(J19="","",(RANK(J19,$J$6:$J$39))) -> 6 | L19: =IF(J19="","",(RANK(J19,$J$6:$J$535))) -> 21 | P19: 66 | Q19: 63.535354 | R19: 55.090909 | S19: 67.020202 | T19: 61.882155 | U19: 185.64646 | V19: 7 | W19: 46 | X19: 3.030303 | Y19: 9.0909091 | Z19: 3.030303 | AA19: 68 | AB19: 46.280277 | AC19: 50.470588 | AD19: 54.144385 | AE19: 50.298417 | AF19: 150.89525 | AG19: 14 | AH19: 94 | AI19: 11.764706 | AJ19: 13.235294 | AK19: 7.3529412 | AL19: 67 | AM19: 61.413521 | AN19: 38.03838 | AO19: 54.214223 | AP19: 51.222041 | AQ19: 153.66612 | AR19: 20 | AS19: 128 | AT19: 4.4776119 | AU19: 41.791045 | AV19: 8.9552239 | AW19: =AVERAGE(P19,AA19,AL19) -> 67 | AX19: =AVERAGE(Q19,AB19,AM19) -> 57.076384 | AY19: =AVERAGE(R19,AC19,AN19) -> 47.866626 | AZ19: =AVERAGE(S19,AD19,AO19) -> 58.459603 | BA19: =AVERAGE(T19,AE19,AP19) -> 54.467538 | BB19: =AVERAGE(U19,AF19,AQ19) -> 163.40261 | BC19: =IF(BB19="","",(RANK(BB19,$BB$6:$BB$39))) -> 15 | BD19: =IF(BB19="","",(RANK(BB19,$BB$6:$BB$535))) -> 79 | BE19: =AVERAGE(M19,AI19,AT19) -> 8.1211589 | BF19: =AVERAGE(N19,AJ19,AU19) -> 27.513169 | BG19: =AVERAGE(O19,AK19,AV19) -> 8.1540825 | BH19: 68 | BI19: 57.627941 | BJ19: 34.605882 | BK19: 39.529412 | BL19: 43.921078 | BM19: 131.76324 | BN19: 11 | BO19: 102 | BP19: 11.764706 | BQ19: 50 | BR19: 38.235294 | BT19: 144
A20: 15 | B20: Binəqədi | C20: 157 | D20: tam orta məktəb | F20: 64.666667 | G20: 71.2 | H20: 69.333333 | I20: =IF(F20="","",AVERAGE(F20:H20)) -> 68.4 | J20: =IF(F20="","",SUM(F20:H20)) -> 205.2 | K20: =IF(J20="","",(RANK(J20,$J$6:$J$39))) -> 3 | L20: =IF(J20="","",(RANK(J20,$J$6:$J$535))) -> 8 | P20: 91 | Q20: 63.589744 | R20: 61.978022 | S20: 66.007326 | T20: 63.858364 | U20: 191.57509 | V20: 5 | W20: 29 | X20: 6.5934066 | Y20: 5.4945055 | Z20: 4.3956044 | AA20: 107 | AB20: 50.262085 | AC20: 59.762376 | AD20: 56.705671 | AE20: 55.576711 | AF20: 166.73013 | AG20: 9 | AH20: 47 | AI20: 21.782178 | AJ20: 10.891089 | AK20: 20.792079 | AL20: 107 | AM20: 58.986928 | AN20: 34.34992 | AO20: 65.980392 | AP20: 53.082011 | AQ20: 159.31724 | AR20: 16 | AS20: 105 | AT20: 10 | AU20: 42.696629 | AV20: 8.8888889 | AW20: =AVERAGE(P20,AA20,AL20) -> 101.66667 | AX20: =AVERAGE(Q20,AB20,AM20) -> 57.612919 | AY20: =AVERAGE(R20,AC20,AN20) -> 52.030106 | AZ20: =AVERAGE(S20,AD20,AO20) -> 62.897796 | BA20: =AVERAGE(T20,AE20,AP20) -> 57.505695 | BB20: =AVERAGE(U20,AF20,AQ20) -> 172.54082 | BC20: =IF(BB20="","",(RANK(BB20,$BB$6:$BB$39))) -> 7 | BD20: =IF(BB20="","",(RANK(BB20,$BB$6:$BB$535))) -> 50 | BE20: =AVERAGE(M20,AI20,AT20) -> 15.891089 | BF20: =AVERAGE(N20,AJ20,AU20) -> 26.793859 | BG20: =AVERAGE(O20,AK20,AV20) -> 14.840484 | BH20: 107 | BI20: 59.491589 | BJ20: 38.248598 | BK20: 43.542056 | BL20: 47.094081 | BM20: 141.28224 | BN20: 7 | BO20: 62 | BP20: 17.757009 | BQ20: 40.186916 | BR20: 29.906542 | BT20: 157
A21: 16 | B21: Binəqədi | C21: 179 | D21: tam orta məktəb | F21: 49.333333 | G21: 49.2 | H21: 40 | I21: =IF(F21="","",AVERAGE(F21:H21)) -> 46.177778 | J21: =IF(F21="","",SUM(F21:H21)) -> 138.53333 | K21: =IF(J21="","",(RANK(J21,$J$6:$J$39))) -> 19 | L21: =IF(J21="","",(RANK(J21,$J$6:$J$535))) -> 126 | P21: 224 | Q21: 44.419643 | R21: 44.660714 | S21: 43.258929 | T21: 44.113095 | U21: 132.33929 | V21: 27 | W21: 225 | X21: 28.571429 | Y21: 23.660714 | Z21: 32.142857 | AA21: 237 | AB21: 35.604368 | AC21: 49.046414 | AD21: 38.473341 | AE21: 41.041374 | AF21: 123.12412 | AG21: 28 | AH21: 196 | AI21: 43.037975 | AJ21: 22.649573 | AK21: 32.067511 | AL21: 248 | AM21: 48.161765 | AN21: 32.211982 | AO21: 41.816888 | AP21: 40.730211 | AQ21: 122.19063 | AR21: 32 | AS21: 256 | AT21: 21.370968 | AU21: 42.741935 | AV21: 31.854839 | AW21: =AVERAGE(P21,AA21,AL21) -> 236.33333 | AX21: =AVERAGE(Q21,AB21,AM21) -> 42.728592 | AY21: =AVERAGE(R21,AC21,AN21) -> 41.973036 | AZ21: =AVERAGE(S21,AD21,AO21) -> 41.183053 | BA21: =AVERAGE(T21,AE21,AP21) -> 41.96156 | BB21: =AVERAGE(U21,AF21,AQ21) -> 125.88468 | BC21: =IF(BB21="","",(RANK(BB21,$BB$6:$BB$39))) -> 30 | BD21: =IF(BB21="","",(RANK(BB21,$BB$6:$BB$535))) -> 233 | BE21: =AVERAGE(M21,AI21,AT21) -> 32.204471 | BF21: =AVERAGE(N21,AJ21,AU21) -> 32.695754 | BG21: =AVERAGE(O21,AK21,AV21) -> 31.961175 | BH21: 258 | BI21: 46.229134 | BJ21: 24.413386 | BK21: 29.516535 | BL21: 33.386352 | BM21: 100.15906 | BN21: 32 | BO21: 268 | BP21: 27.165354 | BQ21: 70.472441 | BR21: 61.417323 | BT21: 179
A22: 17 | B22: Binəqədi | C22: 182 | D22: tam orta məktəb | F22: 50 | G22: 49.2 | H22: 45.333333 | I22: =IF(F22="","",AVERAGE(F22:H22)) -> 48.177778 | J22: =IF(F22="","",SUM(F22:H22)) -> 144.53333 | K22: =IF(J22="","",(RANK(J22,$J$6:$J$39))) -> 16 | L22: =IF(J22="","",(RANK(J22,$J$6:$J$535))) -> 109 | P22: 390 | Q22: 53.931624 | R22: 48.421594 | S22: 50.410256 | T22: 50.923296 | U22: 152.76347 | V22: 19 | W22: 131 | X22: 11.794872 | Y22: 21.8509 | Z22: 27.948718 | AA22: 414 | AB22: 42.998963 | AC22: 50.707548 | AD22: 47.164339 | AE22: 46.95695 | AF22: 140.87085 | AG22: 18 | AH22: 129 | AI22: 29.471033 | AJ22: 21.969697 | AK22: 27.20403 | AL22: 417 | AM22: 59.007353 | AN22: 45.863095 | AO22: 54.500077 | AP22: 53.088819 | AQ22: 159.37052 | AR22: 15 | AS22: 104 | AT22: 18.229167 | AU22: 30.989583 | AV22: 25.721785 | AW22: =AVERAGE(P22,AA22,AL22) -> 407 | AX22: =AVERAGE(Q22,AB22,AM22) -> 51.979313 | AY22: =AVERAGE(R22,AC22,AN22) -> 48.330746 | AZ22: =AVERAGE(S22,AD22,AO22) -> 50.691557 | BA22: =AVERAGE(T22,AE22,AP22) -> 50.323022 | BB22: =AVERAGE(U22,AF22,AQ22) -> 151.00162 | BC22: =IF(BB22="","",(RANK(BB22,$BB$6:$BB$39))) -> 19 | BD22: =IF(BB22="","",(RANK(BB22,$BB$6:$BB$535))) -> 121 | BE22: =AVERAGE(M22,AI22,AT22) -> 23.8501 | BF22: =AVERAGE(N22,AJ22,AU22) -> 26.47964 | BG22: =AVERAGE(O22,AK22,AV22) -> 26.462908 | BH22: 415 | BI22: 52.037772 | BJ22: 29.79201 | BK22: 33.639467 | BL22: 38.48975 | BM22: 115.46925 | BN22: 25 | BO22: 195 | BP22: 23.970944 | BQ22: 64.891041 | BR22: 56.416465 | BT22: 182
A23: 18 | B23: Binəqədi | C23: 205 | D23: tam orta məktəb | F23: 46.666667 | G23: 38 | H23: 29.333333 | I23: =IF(F23="","",AVERAGE(F23:H23)) -> 38 | J23: =IF(F23="","",SUM(F23:H23)) -> 114 | K23: =IF(J23="","",(RANK(J23,$J$6:$J$39))) -> 28 | L23: =IF(J23="","",(RANK(J23,$J$6:$J$535))) -> 221 | P23: 110 | Q23: 46.181818 | R23: 43.527273 | S23: 44.545455 | T23: 44.751515 | U23: 134.25455 | V23: 25 | W23: 214 | X23: 30 | Y23: 34.545455 | Z23: 36.363636 | AA23: 115 | AB23: 60.172693 | AC23: 44.366972 | AD23: 44.147901 | AE23: 49.562522 | AF23: 148.68757 | AG23: 16 | AH23: 101 | AI23: 35.555556 | AJ23: 22.018349 | AK23: 32.110092 | AL23: 115 | AM23: 61.154273 | AN23: 50.862534 | AO23: 51.193119 | AP23: 54.403308 | AQ23: 163.20993 | AR23: 14 | AS23: 88 | AT23: 12.264151 | AU23: 34.736842 | AV23: 16.037736 | AW23: =AVERAGE(P23,AA23,AL23) -> 113.33333 | AX23: =AVERAGE(Q23,AB23,AM23) -> 55.836261 | AY23: =AVERAGE(R23,AC23,AN23) -> 46.25226 | AZ23: =AVERAGE(S23,AD23,AO23) -> 46.628825 | BA23: =AVERAGE(T23,AE23,AP23) -> 49.572449 | BB23: =AVERAGE(U23,AF23,AQ23) -> 148.71735 | BC23: =IF(BB23="","",(RANK(BB23,$BB$6:$BB$39))) -> 21 | BD23: =IF(BB23="","",(RANK(BB23,$BB$6:$BB$535))) -> 132 | BE23: =AVERAGE(M23,AI23,AT23) -> 23.909853 | BF23: =AVERAGE(N23,AJ23,AU23) -> 28.377595 | BG23: =AVERAGE(O23,AK23,AV23) -> 24.073914 | BH23: 115 | BI23: 50.60087 | BJ23: 25.633043 | BK23: 33.142609 | BL23: 36.458841 | BM23: 109.37652 | BN23: 27 | BO23: 234 | BP23: 26.956522 | BQ23: 67.826087 | BR23: 54.782609 | BT23: 205
A24: 19 | B24: Binəqədi | C24: 217 | D24: tam orta məktəb | F24: 53.333333 | G24: 40 | H24: 25 | I24: =IF(F24="","",AVERAGE(F24:H24)) -> 39.444444 | J24: =IF(F24="","",SUM(F24:H24)) -> 118.33333 | K24: =IF(J24="","",(RANK(J24,$J$6:$J$39))) -> 25 | L24: =IF(J24="","",(RANK(J24,$J$6:$J$535))) -> 198 | P24: 216 | Q24: 43.117284 | R24: 35.518519 | S24: 34.722222 | T24: 37.786008 | U24: 113.35802 | V24: 32 | W24: 283 | X24: 31.481481 | Y24: 51.173709 | Z24: 54.166667 | AA24: 233 | AB24: 34.106056 | AC24: 40.492611 | AD24: 37.871324 | AE24: 37.489997 | AF24: 112.46999 | AG24: 32 | AH24: 242 | AI24: 42.364532 | AJ24: 29.064039 | AK24: 40.394089 | AL24: 231 | AM24: 72.972136 | AN24: 28.917293 | AO24: 48.529412 | AP24: 50.139614 | AQ24: 150.41884 | AR24: 22 | AS24: 138 | AT24: 4.2105263 | AU24: 58.421053 | AV24: 23.684211 | AW24: =AVERAGE(P24,AA24,AL24) -> 226.66667 | AX24: =AVERAGE(Q24,AB24,AM24) -> 50.065159 | AY24: =AVERAGE(R24,AC24,AN24) -> 34.976141 | AZ24: =AVERAGE(S24,AD24,AO24) -> 40.374319 | BA24: =AVERAGE(T24,AE24,AP24) -> 41.805206 | BB24: =AVERAGE(U24,AF24,AQ24) -> 125.41562 | BC24: =IF(BB24="","",(RANK(BB24,$BB$6:$BB$39))) -> 31 | BD24: =IF(BB24="","",(RANK(BB24,$BB$6:$BB$535))) -> 236 | BE24: =AVERAGE(M24,AI24,AT24) -> 23.287529 | BF24: =AVERAGE(N24,AJ24,AU24) -> 43.742546 | BG24: =AVERAGE(O24,AK24,AV24) -> 32.03915 | BH24: 229 | BI24: 49.210965 | BJ24: 26.892982 | BK24: 30.735965 | BL24: 35.613304 | BM24: 106.83991 | BN24: 28 | BO24: 244 | BP24: 22.807018 | BQ24: 67.105263 | BR24: 58.77193 | BT24: 217
A25: 20 | B25: Binəqədi | C25: 244 | D25: tam orta məktəb | F25: 69.666667 | G25: 76 | H25: 66.666667 | I25: =IF(F25="","",AVERAGE(F25:H25)) -> 70.777778 | J25: =IF(F25="","",SUM(F25:H25)) -> 212.33333 | K25: =IF(J25="","",(RANK(J25,$J$6:$J$39))) -> 1 | L25: =IF(J25="","",(RANK(J25,$J$6:$J$535))) -> 2 | P25: 203 | Q25: 65.92775 | R25: 74.738916 | S25: 71.36289 | T25: 70.676519 | U25: 212.02956 | V25: 1 | W25: 7 | X25: 4.9261084 | Y25: 2.6315789 | Z25: 2.955665 | AA25: 208 | AB25: 62.15208 | AC25: 68.721951 | AD25: 66.111611 | AE25: 65.564349 | AF25: 196.98564 | AG25: 1 | AH25: 7 | AI25: 3.9408867 | AJ25: 8.3333333 | AK25: 8 | AL25: 206 | AM25: 69.503862 | AN25: 52.594172 | AO25: 70.617501 | AP25: 64.153978 | AQ25: 192.71553 | AR25: 5 | AS25: 22 | AT25: 3.5532995 | AU25: 21 | AV25: 6.5 | AW25: =AVERAGE(P25,AA25,AL25) -> 205.66667 | AX25: =AVERAGE(Q25,AB25,AM25) -> 65.861231 | AY25: =AVERAGE(R25,AC25,AN25) -> 65.35168 | AZ25: =AVERAGE(S25,AD25,AO25) -> 69.364001 | BA25: =AVERAGE(T25,AE25,AP25) -> 66.798282 | BB25: =AVERAGE(U25,AF25,AQ25) -> 200.57691 | BC25: =IF(BB25="","",(RANK(BB25,$BB$6:$BB$39))) -> 1 | BD25: =IF(BB25="","",(RANK(BB25,$BB$6:$BB$535))) -> 8 | BE25: =AVERAGE(M25,AI25,AT25) -> 3.7470931 | BF25: =AVERAGE(N25,AJ25,AU25) -> 14.666667 | BG25: =AVERAGE(O25,AK25,AV25) -> 7.25 | BH25: 207 | BI25: 60.372947 | BJ25: 34.483092 | BK25: 42.070531 | BL25: 45.64219 | BM25: 136.92657 | BN25: 9 | BO25: 87 | BP25: 13.52657 | BQ25: 52.173913 | BR25: 39.613527 | BT25: 244
A26: 21 | B26: Binəqədi | C26: 246 | D26: məktəb-lisey | F26: 50 | G26: 58.4 | H26: 52 | I26: =IF(F26="","",AVERAGE(F26:H26)) -> 53.466667 | J26: =IF(F26="","",SUM(F26:H26)) -> 160.4 | K26: =IF(J26="","",(RANK(J26,$J$6:$J$39))) -> 10 | L26: =IF(J26="","",(RANK(J26,$J$6:$J$535))) -> 52 | P26: 124 | Q26: 55.77957 | R26: 55.806452 | S26: 64.811828 | T26: 58.799283 | U26: 176.39785 | V26: 11 | W26: 66 | X26: 15.322581 | Y26: 16.129032 | Z26: 16.129032 | AA26: 139 | AB26: 44.093539 | AC26: 44.845528 | AD26: 49.864499 | AE26: 46.236888 | AF26: 138.80357 | AG26: 20 | AH26: 139 | AI26: 19.672131 | AJ26: 19.512195 | AK26: 17.886179 | AL26: 138 | AM26: 55.738881 | AN26: 37.560976 | AO26: 61.262554 | AP26: 51.520803 | AQ26: 154.56241 | AR26: 19 | AS26: 125 | AT26: 13.00813 | AU26: 34.95935 | AV26: 19.512195 | AW26: =AVERAGE(P26,AA26,AL26) -> 133.66667 | AX26: =AVERAGE(Q26,AB26,AM26) -> 51.870663 | AY26: =AVERAGE(R26,AC26,AN26) -> 46.070985 | AZ26: =AVERAGE(S26,AD26,AO26) -> 58.646293 | BA26: =AVERAGE(T26,AE26,AP26) -> 52.185658 | BB26: =AVERAGE(U26,AF26,AQ26) -> 156.58794 | BC26: =IF(BB26="","",(RANK(BB26,$BB$6:$BB$39))) -> 17 | BD26: =IF(BB26="","",(RANK(BB26,$BB$6:$BB$535))) -> 100 | BE26: =AVERAGE(M26,AI26,AT26) -> 16.340131 | BF26: =AVERAGE(N26,AJ26,AU26) -> 27.235772 | BG26: =AVERAGE(O26,AK26,AV26) -> 18.699187 | BH26: 138 | BI26: 59.938971 | BJ26: 36.7 | BK26: 42.343382 | BL26: 46.327451 | BM26: 138.98235 | BN26: 8 | BO26: 74 | BP26: 16.176471 | BQ26: 46.323529 | BR26: 38.970588 | BT26: 246
... A39: 34 | B39: Binəqədi | C39: 314 | D39: tam orta məktəb | F39: 30 | G39: 31.2 | H39: 23 | I39: =IF(F39="","",AVERAGE(F39:H39)) -> 28.066667 | J39: =IF(F39="","",SUM(F39:H39)) -> 84.2 | K39: =IF(J39="","",(RANK(J39,$J$6:$J$39))) -> 30 | L39: =IF(J39="","",(RANK(J39,$J$6:$J$535))) -> 288 | P39: 155 | Q39: 55.333333 | R39: 49.212903 | S39: 47.182796 | T39: 50.576344 | U39: 151.72903 | V39: 20 | W39: 137 | X39: 12.903226 | Y39: 26.451613 | Z39: 25.806452 | AA39: 178 | AB39: 40.973631 | AC39: 40.165517 | AD39: 39.205852 | AE39: 40.115 | AF39: 120.345 | AG39: 29 | AH39: 213 | AI39: 28.275862 | AJ39: 40 | AK39: 42.068966 | AL39: 178 | AM39: 61.407563 | AN39: 31.038027 | AO39: 58.197747 | AP39: 50.416195 | AQ39: 150.64334 | AR39: 21 | AS39: 136 | AT39: 9.4202899 | AU39: 58.273381 | AV39: 22.900763 | AW39: =AVERAGE(P39,AA39,AL39) -> 170.33333 | AX39: =AVERAGE(Q39,AB39,AM39) -> 52.571509 | AY39: =AVERAGE(R39,AC39,AN39) -> 40.138816 | AZ39: =AVERAGE(S39,AD39,AO39) -> 48.195465 | BA39: =AVERAGE(T39,AE39,AP39) -> 47.035846 | BB39: =AVERAGE(U39,AF39,AQ39) -> 140.90579 | BC39: =IF(BB39="","",(RANK(BB39,$BB$6:$BB$39))) -> 23 | BD39: =IF(BB39="","",(RANK(BB39,$BB$6:$BB$535))) -> 163 | BE39: =AVERAGE(M39,AI39,AT39) -> 18.848076 | BF39: =AVERAGE(N39,AJ39,AU39) -> 49.136691 | BG39: =AVERAGE(O39,AK39,AV39) -> 32.484864 | BH39: 175 | BI39: 55.984118 | BJ39: 31.771765 | BK39: 37.266471 | BL39: 41.674118 | BM39: 125.02235 | BN39: 19 | BO39: 137 | BP39: 20 | BQ39: 58.823529 | BR39: 48.823529 | BT39: 314
A40: 35 | B40: Nərimanov | C40: 11x | D40: XTM | I40: =IF(F40="","",AVERAGE(F40:H40)) | J40: =IF(F40="","",SUM(F40:H40)) | K40: =IF(J40="","",(RANK(J40,$J$40:$J$60))) | L40: =IF(J40="","",(RANK(J40,$J$6:$J$535))) | BC40: =IF(BB40="","",(RANK(BB40,$BB$40:$BB$60))) | BD40: =IF(BB40="","",(RANK(BB40,$BB$6:$BB$535))) | BT40: 11
A41: 36 | B41: Nərimanov | C41: 34 | D41: tam orta məktəb | F41: 46.666667 | G41: 44 | H41: 34.666667 | I41: =IF(F41="","",AVERAGE(F41:H41)) -> 41.777778 | J41: =IF(F41="","",SUM(F41:H41)) -> 125.33333 | K41: =IF(J41="","",(RANK(J41,$J$40:$J$60))) -> 14 | L41: =IF(J41="","",(RANK(J41,$J$6:$J$535))) -> 172 | P41: 47 | Q41: 55.390071 | R41: 52.851064 | S41: 46.241135 | T41: 51.49409 | U41: 154.48227 | V41: 14 | W41: 121 | X41: 14.893617 | Y41: 23.404255 | Z41: 29.787234 | AA41: 52 | AB41: 50.120048 | AC41: 54.367347 | AD41: 47.680891 | AE41: 50.722762 | AF41: 152.16829 | AG41: 8 | AH41: 87 | AI41: 12.244898 | AJ41: 16.326531 | AK41: 24.489796 | AL41: 52 | AM41: 61.138924 | AN41: 38.480243 | AO41: 47.18398 | AP41: 48.934382 | AQ41: 146.80315 | AR41: 12 | AS41: 159 | AT41: 10.638298 | AU41: 46.808511 | AV41: 25.531915 | AW41: =AVERAGE(P41,AA41,AL41) -> 50.333333 | AX41: =AVERAGE(Q41,AB41,AM41) -> 55.549681 | AY41: =AVERAGE(R41,AC41,AN41) -> 48.566218 | AZ41: =AVERAGE(S41,AD41,AO41) -> 47.035335 | BA41: =AVERAGE(T41,AE41,AP41) -> 50.383745 | BB41: =AVERAGE(U41,AF41,AQ41) -> 151.15123 | BC41: =IF(BB41="","",(RANK(BB41,$BB$40:$BB$60))) -> 12 | BD41: =IF(BB41="","",(RANK(BB41,$BB$6:$BB$535))) -> 120 | BE41: =AVERAGE(M41,AI41,AT41) -> 11.441598 | BF41: =AVERAGE(N41,AJ41,AU41) -> 31.567521 | BG41: =AVERAGE(O41,AK41,AV41) -> 25.010855 | BH41: 52 | BI41: 48.17451 | BJ41: 37.607843 | BK41: 37.190196 | BL41: 40.99085 | BM41: 122.97255 | BN41: 10 | BO41: 149 | BP41: 21.568627 | BQ41: 45.098039 | BR41: 58.823529 | BT41: 34
A42: 37 | B42: Nərimanov | C42: 36 | D42: tam orta məktəb | F42: 39 | G42: 54.4 | H42: 24.666667 | I42: =IF(F42="","",AVERAGE(F42:H42)) -> 39.355556 | J42: =IF(F42="","",SUM(F42:H42)) -> 118.06667 | K42: =IF(J42="","",(RANK(J42,$J$40:$J$60))) -> 17 | L42: =IF(J42="","",(RANK(J42,$J$6:$J$535))) -> 202 | P42: 84 | Q42: 61.269841 | R42: 54.952381 | S42: 57.261905 | T42: 57.828042 | U42: 173.48413 | V42: 11 | W42: 75 | X42: 11.904762 | Y42: 17.857143 | Z42: 15.47619 | AA42: 87 | AB42: 56.962025 | AC42: 60.883117 | AD42: 57.416268 | AE42: 58.572802 | AF42: 175.26141 | AG42: 4 | AH42: 32 | AI42: 11.538462 | AJ42: 7.7922078 | AK42: 13.157895 | AL42: 93 | AM42: 58.569354 | AN42: 45.388788 | AO42: 58.484163 | AP42: 54.301276 | AQ42: 162.4423 | AR42: 7 | AS42: 93 | AT42: 6.1728395 | AU42: 10.126582 | AV42: 11.538462 | AW42: =AVERAGE(P42,AA42,AL42) -> 88 | AX42: =AVERAGE(Q42,AB42,AM42) -> 58.93374 | AY42: =AVERAGE(R42,AC42,AN42) -> 53.741429 | AZ42: =AVERAGE(S42,AD42,AO42) -> 57.720779 | BA42: =AVERAGE(T42,AE42,AP42) -> 56.900707 | BB42: =AVERAGE(U42,AF42,AQ42) -> 170.39595 | BC42: =IF(BB42="","",(RANK(BB42,$BB$40:$BB$60))) -> 6 | BD42: =IF(BB42="","",(RANK(BB42,$BB$6:$BB$535))) -> 55 | BE42: =AVERAGE(M42,AI42,AT42) -> 8.8556505 | BF42: =AVERAGE(N42,AJ42,AU42) -> 8.959395 | BG42: =AVERAGE(O42,AK42,AV42) -> 12.348178 | BH42: 96 | BI42: 48.021978 | BJ42: 34.445055 | BK42: 36.718681 | BL42: 39.728571 | BM42: 119.18571 | BN42: 13 | BO42: 170 | BP42: 25.274725 | BQ42: 50.549451 | BR42: 53.846154 | BT42: 36
A43: 38 | B43: Nərimanov | C43: 37 | D43: tam orta məktəb | F43: 37.666667 | G43: 52 | H43: 41.333333 | I43: =IF(F43="","",AVERAGE(F43:H43)) -> 43.666667 | J43: =IF(F43="","",SUM(F43:H43)) -> 131 | K43: =IF(J43="","",(RANK(J43,$J$40:$J$60))) -> 13 | L43: =IF(J43="","",(RANK(J43,$J$6:$J$535))) -> 156 | P43: 59 | Q43: 40.677966 | R43: 39.389831 | S43: 48.813559 | T43: 42.960452 | U43: 128.88136 | V43: 18 | W43: 241 | X43: 32.20339 | Y43: 27.118644 | Z43: 28.813559 | AA43: 66 | AB43: 34.077079 | AC43: 41.517241 | AD43: 32.549634 | AE43: 36.047985 | AF43: 108.14395 | AG43: 18 | AH43: 258 | AI43: 46.551724 | AJ43: 39.655172 | AK43: 50 | AL43: 71 | AM43: 51.515152 | AN43: 33.230769 | AO43: 50.316742 | AP43: 45.40107 | AQ43: 135.06266 | AR43: 15 | AS43: 212 | AT43: 19.69697 | AU43: 43.076923 | AV43: 21.538462 | AW43: =AVERAGE(P43,AA43,AL43) -> 65.333333 | AX43: =AVERAGE(Q43,AB43,AM43) -> 42.090066 | AY43: =AVERAGE(R43,AC43,AN43) -> 38.045947 | AZ43: =AVERAGE(S43,AD43,AO43) -> 43.893312 | BA43: =AVERAGE(T43,AE43,AP43) -> 41.469835 | BB43: =AVERAGE(U43,AF43,AQ43) -> 124.02932 | BC43: =IF(BB43="","",(RANK(BB43,$BB$40:$BB$60))) -> 17 | BD43: =IF(BB43="","",(RANK(BB43,$BB$6:$BB$535))) -> 243 | BE43: =AVERAGE(M43,AI43,AT43) -> 33.124347 | BF43: =AVERAGE(N43,AJ43,AU43) -> 41.366048 | BG43: =AVERAGE(O43,AK43,AV43) -> 35.769231 | BH43: 72 | BI43: 43.073611 | BJ43: 29.140278 | BK43: 33.984722 | BL43: 35.399537 | BM43: 106.19861 | BN43: 18 | BO43: 246 | BP43: 27.777778 | BQ43: 59.722222 | BR43: 58.333333 | BT43: 37
A44: 39 | B44: Nərimanov | C44: 39 | D44: tam orta məktəb | F44: 50 | G44: 58.4 | H44: 47.333333 | I44: =IF(F44="","",AVERAGE(F44:H44)) -> 51.911111 | J44: =IF(F44="","",SUM(F44:H44)) -> 155.73333 | K44: =IF(J44="","",(RANK(J44,$J$40:$J$60))) -> 4 | L44: =IF(J44="","",(RANK(J44,$J$6:$J$535))) -> 62 | P44: 58 | Q44: 63.850575 | R44: 62.344828 | S44: 73.505747 | T44: 66.56705 | U44: 199.70115 | V44: 4 | W44: 15 | X44: 5.1724138 | Y44: 13.793103 | Z44: 8.6206897 | AA44: 70 | AB44: 56.705882 | AC44: 49.469388 | AD44: 60.482375 | AE44: 54.937184 | AF44: 166.65764 | AG44: 6 | AH44: 49 | AI44: 22 | AJ44: 28.571429 | AK44: 14.583333 | AL44: 70 | AM44: 61.054767 | AN44: 38.546366 | AO44: 61.004057 | AP44: 53.55863 | AQ44: 160.60519 | AR44: 8 | AS44: 100 | AT44: 6.8965517 | AU44: 50.877193 | AV44: 18.965517 | AW44: =AVERAGE(P44,AA44,AL44) -> 66 | AX44: =AVERAGE(Q44,AB44,AM44) -> 60.537075 | AY44: =AVERAGE(R44,AC44,AN44) -> 50.120194 | AZ44: =AVERAGE(S44,AD44,AO44) -> 64.997393 | BA44: =AVERAGE(T44,AE44,AP44) -> 58.354288 | BB44: =AVERAGE(U44,AF44,AQ44) -> 175.65466 | BC44: =IF(BB44="","",(RANK(BB44,$BB$40:$BB$60))) -> 4 | BD44: =IF(BB44="","",(RANK(BB44,$BB$6:$BB$535))) -> 38 | BE44: =AVERAGE(M44,AI44,AT44) -> 14.448276 | BF44: =AVERAGE(N44,AJ44,AU44) -> 39.724311 | BG44: =AVERAGE(O44,AK44,AV44) -> 16.774425 | BH44: 70 | BI44: 56.519118 | BJ44: 38.723529 | BK44: 46.316176 | BL44: 47.186275 | BM44: 141.55882 | BN44: 5 | BO44: 61 | BP44: 19.117647 | BQ44: 45.588235 | BR44: 33.823529 | BT44: 39
A45: 40 | B45: Nərimanov | C45: 45 | D45: tam orta məktəb | F45: 58.333333 | G45: 51.2 | H45: 42.666667 | I45: =IF(F45="","",AVERAGE(F45:H45)) -> 50.733333 | J45: =IF(F45="","",SUM(F45:H45)) -> 152.2 | K45: =IF(J45="","",(RANK(J45,$J$40:$J$60))) -> 6 | L45: =IF(J45="","",(RANK(J45,$J$6:$J$535))) -> 71 | P45: 129 | Q45: 57.571059 | R45: 55.59375 | S45: 69.265092 | T45: 60.779514 | U45: 182.4299 | V45: 7 | W45: 51 | X45: 7.751938 | Y45: 12.5 | Z45: 8.6614173 | AA45: 141 | AB45: 48.473282 | AC45: 60.030303 | AD45: 76.304397 | AE45: 61.64973 | AF45: 184.80798 | AG45: 3 | AH45: 20 | AI45: 11.450382 | AJ45: 6.0606061 | AK45: 2.6548673 | AL45: 139 | AM45: 57.518975 | AN45: 30.345622 | AO45: 61.860354 | AP45: 49.827867 | AQ45: 149.72495 | AR45: 10 | AS45: 142 | AT45: 6.4516129 | AU45: 55.645161 | AV45: 18.852459 | AW45: =AVERAGE(P45,AA45,AL45) -> 136.33333 | AX45: =AVERAGE(Q45,AB45,AM45) -> 54.521106 | AY45: =AVERAGE(R45,AC45,AN45) -> 48.656558 | AZ45: =AVERAGE(S45,AD45,AO45) -> 69.143281 | BA45: =AVERAGE(T45,AE45,AP45) -> 57.419037 | BB45: =AVERAGE(U45,AF45,AQ45) -> 172.32095 | BC45: =IF(BB45="","",(RANK(BB45,$BB$40:$BB$60))) -> 5 | BD45: =IF(BB45="","",(RANK(BB45,$BB$6:$BB$535))) -> 51 | BE45: =AVERAGE(M45,AI45,AT45) -> 8.9509973 | BF45: =AVERAGE(N45,AJ45,AU45) -> 30.852884 | BG45: =AVERAGE(O45,AK45,AV45) -> 10.753663 | BH45: 139 | BI45: 52.353957 | BJ45: 37.386331 | BK45: 40.860432 | BL45: 43.533573 | BM45: 130.60072 | BN45: 8 | BO45: 107 | BP45: 15.827338 | BQ45: 41.007194 | BR45: 42.446043 | BT45: 45
A46: 41 | B46: Nərimanov | C46: 47 | D46: tam orta məktəb | F46: 48.333333 | G46: 54.8 | H46: 50.333333 | I46: =IF(F46="","",AVERAGE(F46:H46)) -> 51.155556 | J46: =IF(F46="","",SUM(F46:H46)) -> 153.46667 | K46: =IF(J46="","",(RANK(J46,$J$40:$J$60))) -> 5 | L46: =IF(J46="","",(RANK(J46,$J$6:$J$535))) -> 68 | P46: 128 | Q46: 59.21875 | R46: 50.125 | S46: 64.140625 | T46: 57.828125 | U46: 173.48438 | V46: 10 | W46: 74 | X46: 5.46875 | Y46: 14.0625 | Z46: 11.71875 | AA46: 129 | AB46: 40.834473 | AC46: 38.697674 | AD46: 50.293634 | AE46: 43.275261 | AF46: 129.82578 | AG46: 15 | AH46: 174 | AI46: 34.883721 | AJ46: 38.75969 | AK46: 26.356589 | AL46: 128 | AM46: 51.5625 | AN46: 30.758929 | AO46: 50.78125 | AP46: 44.36756 | AQ46: 133.10268 | AR46: 16 | AS46: 221 | AT46: 21.875 | AU46: 54.6875 | AV46: 31.25 | AW46: =AVERAGE(P46,AA46,AL46) -> 128.33333 | AX46: =AVERAGE(Q46,AB46,AM46) -> 50.538574 | AY46: =AVERAGE(R46,AC46,AN46) -> 39.860534 | AZ46: =AVERAGE(S46,AD46,AO46) -> 55.071836 | BA46: =AVERAGE(T46,AE46,AP46) -> 48.490315 | BB46: =AVERAGE(U46,AF46,AQ46) -> 145.47095 | BC46: =IF(BB46="","",(RANK(BB46,$BB$40:$BB$60))) -> 14 | BD46: =IF(BB46="","",(RANK(BB46,$BB$6:$BB$535))) -> 142 | BE46: =AVERAGE(M46,AI46,AT46) -> 28.37936 | BF46: =AVERAGE(N46,AJ46,AU46) -> 46.723595 | BG46: =AVERAGE(O46,AK46,AV46) -> 28.803295 | BH46: 142 | BI46: 56.888732 | BJ46: 34.553521 | BK46: 47.203521 | BL46: 46.215258 | BM46: 138.64577 | BN46: 6 | BO46: 76 | BP46: 15.492958 | BQ46: 45.070423 | BR46: 31.690141 | BT46: 47
A47: 42 | B47: Nərimanov | C47: 57 | D47: tam orta məktəb | F47: 46.666667 | G47: 35.6 | H47: 26.666667 | I47: =IF(F47="","",AVERAGE(F47:H47)) -> 36.311111 | J47: =IF(F47="","",SUM(F47:H47)) -> 108.93333 | K47: =IF(J47="","",(RANK(J47,$J$40:$J$60))) -> 19 | L47: =IF(J47="","",(RANK(J47,$J$6:$J$535))) -> 232 | P47: 70 | Q47: 56.333333 | R47: 49.2 | S47: 58.809524 | T47: 54.780952 | U47: 164.34286 | V47: 13 | W47: 95 | X47: 4.2857143 | Y47: 18.571429 | Z47: 1.4285714 | AA47: 75 | AB47: 42.130366 | AC47: 47.567568 | AD47: 46.437346 | AE47: 45.378427 | AF47: 136.13528 | AG47: 13 | AH47: 150 | AI47: 36.486486 | AJ47: 20.27027 | AK47: 33.783784 | AL47: 75 | AM47: 63.888889 | AN47: 45.198413 | AO47: 60.212418 | AP47: 56.43324 | AQ47: 169.29972 | AR47: 5 | AS47: 69 | AT47: 5.5555556 | AU47: 26.760563 | AV47: 11.111111 | AW47: =AVERAGE(P47,AA47,AL47) -> 73.333333 | AX47: =AVERAGE(Q47,AB47,AM47) -> 54.117529 | AY47: =AVERAGE(R47,AC47,AN47) -> 47.321993 | AZ47: =AVERAGE(S47,AD47,AO47) -> 55.153096 | BA47: =AVERAGE(T47,AE47,AP47) -> 52.19754 | BB47: =AVERAGE(U47,AF47,AQ47) -> 156.59262 | BC47: =IF(BB47="","",(RANK(BB47,$BB$40:$BB$60))) -> 11 | BD47: =IF(BB47="","",(RANK(BB47,$BB$6:$BB$535))) -> 99 | BE47: =AVERAGE(M47,AI47,AT47) -> 21.021021 | BF47: =AVERAGE(N47,AJ47,AU47) -> 23.515417 | BG47: =AVERAGE(O47,AK47,AV47) -> 22.447447 | BH47: 75 | BI47: 44.138667 | BJ47: 37.986667 | BK47: 32.046667 | BL47: 38.057333 | BM47: 114.172 | BN47: 17 | BO47: 212 | BP47: 29.333333 | BQ47: 36 | BR47: 60 | BT47: 57
A48: 43 | B48: Nərimanov | C48: 73 | D48: tam orta məktəb | F48: 38.666667 | G48: 56 | H48: 49.666667 | I48: =IF(F48="","",AVERAGE(F48:H48)) -> 48.111111 | J48: =IF(F48="","",SUM(F48:H48)) -> 144.33333 | K48: =IF(J48="","",(RANK(J48,$J$40:$J$60))) -> 10 | L48: =IF(J48="","",(RANK(J48,$J$6:$J$535))) -> 110 | P48: 73 | Q48: 63.607306 | R48: 51.945205 | S48: 58.310502 | T48: 57.954338 | U48: 173.86301 | V48: 9 | W48: 72 | X48: 2.739726 | Y48: 19.178082 | Z48: 16.438356 | AA48: 75 | AB48: 51.007252 | AC48: 59.945205 | AD48: 58.987132 | AE48: 56.64653 | AF48: 169.93959 | AG48: 5 | AH48: 42 | AI48: 12.328767 | AJ48: 8.2191781 | AK48: 18.571429 | AL48: 76 | AM48: 64.141821 | AN48: 57.02544 | AO48: 71.112006 | AP48: 64.093089 | AQ48: 192.27927 | AR48: 3 | AS48: 23 | AT48: 0 | AU48: 2.739726 | AV48: 0 | AW48: =AVERAGE(P48,AA48,AL48) -> 74.666667 | AX48: =AVERAGE(Q48,AB48,AM48) -> 59.58546 | AY48: =AVERAGE(R48,AC48,AN48) -> 56.305284 | AZ48: =AVERAGE(S48,AD48,AO48) -> 62.803213 | BA48: =AVERAGE(T48,AE48,AP48) -> 59.564652 | BB48: =AVERAGE(U48,AF48,AQ48) -> 178.69396 | BC48: =IF(BB48="","",(RANK(BB48,$BB$40:$BB$60))) -> 3 | BD48: =IF(BB48="","",(RANK(BB48,$BB$6:$BB$535))) -> 34 | BE48: =AVERAGE(M48,AI48,AT48) -> 6.1643836 | BF48: =AVERAGE(N48,AJ48,AU48) -> 5.4794521 | BG48: =AVERAGE(O48,AK48,AV48) -> 9.2857143 | BH48: 72 | BI48: 46.843056 | BJ48: 32.9875 | BK48: 34.759722 | BL48: 38.196759 | BM48: 114.59028 | BN48: 15 | BO48: 205 | BP48: 27.777778 | BQ48: 52.777778 | BR48: 58.333333 | BT48: 73
A49: 44 | B49: Nərimanov | C49: 82 | D49: tam orta məktəb | F49: 50.666667 | G49: 44 | H49: 40.666667 | I49: =IF(F49="","",AVERAGE(F49:H49)) -> 45.111111 | J49: =IF(F49="","",SUM(F49:H49)) -> 135.33333 | K49: =IF(J49="","",(RANK(J49,$J$40:$J$60))) -> 12 | L49: =IF(J49="","",(RANK(J49,$J$6:$J$535))) -> 141 | P49: 118 | Q49: 67.146893 | R49: 61.118644 | S49: 74.322034 | T49: 67.52919 | U49: 202.58757 | V49: 2 | W49: 10 | X49: 2.5423729 | Y49: 8.6206897 | Z49: 3.3898305 | AA49: 124 | AB49: 54.621849 | AC49: 45.107143 | AD49: 51.16342 | AE49: 50.297471 | AF49: 150.89241 | AG49: 9 | AH49: 95 | AI49: 3.5714286 | AJ49: 8.0357143 | AK49: 2.6785714 | AL49: 124 | AM49: 56.279809 | AN49: 33.539254 | AO49: 57.472178 | AP49: 49.09708 | AQ49: 147.29124 | AR49: 11 | AS49: 158 | AT49: 3.6036036 | AU49: 41.441441 | AV49: 12.612613 | AW49: =AVERAGE(P49,AA49,AL49) -> 122 | AX49: =AVERAGE(Q49,AB49,AM49) -> 59.349517 | AY49: =AVERAGE(R49,AC49,AN49) -> 46.588347 | AZ49: =AVERAGE(S49,AD49,AO49) -> 60.985877 | BA49: =AVERAGE(T49,AE49,AP49) -> 55.641247 | BB49: =AVERAGE(U49,AF49,AQ49) -> 166.92374 | BC49: =IF(BB49="","",(RANK(BB49,$BB$40:$BB$60))) -> 8 | BD49: =IF(BB49="","",(RANK(BB49,$BB$6:$BB$535))) -> 68 | BE49: =AVERAGE(M49,AI49,AT49) -> 3.5875161 | BF49: =AVERAGE(N49,AJ49,AU49) -> 24.738578 | BG49: =AVERAGE(O49,AK49,AV49) -> 7.645592 | BH49: 124 | BI49: 65.127642 | BJ49: 42.534959 | BK49: 52.101626 | BL49: 53.254743 | BM49: 159.76423 | BN49: 2 | BO49: 17 | BP49: 6.504065 | BQ49: 33.333333 | BR49: 22.764228 | BT49: 82
A50: 45 | B50: Nərimanov | C50: 82x | D50: XTM | I50: =IF(F50="","",AVERAGE(F50:H50)) | J50: =IF(F50="","",SUM(F50:H50)) | K50: =IF(J50="","",(RANK(J50,$J$40:$J$60))) | L50: =IF(J50="","",(RANK(J50,$J$6:$J$535))) | BC50: =IF(BB50="","",(RANK(BB50,$BB$40:$BB$60))) | BD50: =IF(BB50="","",(RANK(BB50,$BB$6:$BB$535))) | BH50: 20 | BI50: 16.327778 | BJ50: 20.483333 | BK50: 15.511111 | BL50: 17.440741 | BM50: 52.322222 | BN50: 20 | BO50: 314 | BP50: 100 | BQ50: 83.333333 | BR50: 88.888889 | BT50: 82
A51: 46 | B51: Nərimanov | C51: 93 | D51: tam orta məktəb | F51: 60 | G51: 44 | H51: 41.666667 | I51: =IF(F51="","",AVERAGE(F51:H51)) -> 48.555556 | J51: =IF(F51="","",SUM(F51:H51)) -> 145.66667 | K51: =IF(J51="","",(RANK(J51,$J$40:$J$60))) -> 8 | L51: =IF(J51="","",(RANK(J51,$J$6:$J$535))) -> 97 | P51: 82 | Q51: 61.747967 | R51: 54.829268 | S51: 60.081301 | T51: 58.886179 | U51: 176.65854 | V51: 8 | W51: 63 | X51: 6.097561 | Y51: 11.25 | Z51: 6.097561 | AA51: 85 | AB51: 47.857662 | AC51: 56 | AD51: 53.385709 | AE51: 52.414457 | AF51: 157.24337 | AG51: 7 | AH51: 75 | AI51: 14.814815 | AJ51: 7.4074074 | AK51: 12.345679 | AL51: 85 | AM51: 60.914245 | AN51: 43.13253 | AO51: 49.007796 | AP51: 51.01819 | AQ51: 153.05457 | AR51: 9 | AS51: 131 | AT51: 14.457831 | AU51: 27.710843 | AV51: 27.710843 | AW51: =AVERAGE(P51,AA51,AL51) -> 84 | AX51: =AVERAGE(Q51,AB51,AM51) -> 56.839958 | AY51: =AVERAGE(R51,AC51,AN51) -> 51.320599 | AZ51: =AVERAGE(S51,AD51,AO51) -> 54.158269 | BA51: =AVERAGE(T51,AE51,AP51) -> 54.106275 | BB51: =AVERAGE(U51,AF51,AQ51) -> 162.31883 | BC51: =IF(BB51="","",(RANK(BB51,$BB$40:$BB$60))) -> 10 | BD51: =IF(BB51="","",(RANK(BB51,$BB$6:$BB$535))) -> 82 | BE51: =AVERAGE(M51,AI51,AT51) -> 14.636323 | BF51: =AVERAGE(N51,AJ51,AU51) -> 17.559125 | BG51: =AVERAGE(O51,AK51,AV51) -> 20.028261 | BH51: 84 | BI51: 48.296429 | BJ51: 35.584524 | BK51: 35.292857 | BL51: 39.724603 | BM51: 119.17381 | BN51: 14 | BO51: 171 | BP51: 23.809524 | BQ51: 45.238095 | BR51: 54.761905 | BT51: 93
