Workbook

Sheet Təlimat
A1: Dəyərli sinif rəhbərləri, bildiyiniz kimi müəllimlərin təhsil müəssisələrində şagird nailiyyətlərinin artırılması üzrə fəaliyyəti üç funksiya üzərində təşkil olunur. Təhsilləndirici, tərbiyəedici və inkişafetdirici funksiyalar kompleks icra olunmaqla şagirdin tam formalaşması prosesi baş verir. Bir çox hallarda təhsil müəssisələrində təhsilləndirici və tərbiyəedici funksiyaların yerinə yetirməsində o qədər də ciddi problemlər olmur. İnkişafetdirici funksiyanın həyata keçirilməsi digərləri ilə müqayisədə olduqca çətin və peşəkar inkişafı şərtləndirən fəaliyyətləri özündə əks etdirir. Eyni zamanda bu funksiyanın icrası digər iki funksiyanın daha səmərəli həyata keçirilməsinə də geniş şərait yaradır. İnkişafetdiricilik üçün hesabatlılıq və nailiyyətlərin müntəzəm izlənilməsi vacib olduğundan Bakı Şəhəri üzrə Təhsil İdarəsinin Təhsilin keyfiyyətinə nəzarət sektoru bu hesabat modelini sizin üçün hazırlamışdır. Hesabat modelinin yaradılmasında əsas məqsədlər müəllimlərin İKT biliklərinin səmərəli tətbiqini təşviq etmək, informasiyalar üzərində təhliletmə və pedaqoji fəaliyyətlərin rəqəmsal və qrafik-vizual görüntülərini yaratmaq səriştələrini formalaşdırmaqdır. Hesabat modeli sizə aşağıdakı imkanları təqdim edir: 1. Şagirdlərin nailiyyətlərini (uğurlarının və uğursuzluqlarının səbəblərini) ümümi şəkildə təhlil etmək; 2. Qiymətləndirmə səviyyələri üzrə dəqiq statistik məlumatlar əldə etmək bu məlumatlar əsasında qiymətləndirmələr arasındakı fərqləri, güclü və zəif tərəfləri aşkara çıxarmaq; 3. Sinfin orta bal göstəriciləri üzrə dinamikasını müəyyən etmək; 4. Şagirdlərin inkişafı üzrə dinamikanı və inkişafa təsir edən amillər arasında əlaqələri müəyyən etmək; 5. Fənn müəllimi, məktəb rəhbərliyi və təhsil idarəetmə orqanları tərəfindən aparılmış qiymətləndirmə və ya monitorinqlər arasındakı fərqləri müəyyən etmək; 6. Riskləri qabaqcadan müəyyən etməklə inkişafa dəstək olmaq üçün kompleks fəaliyyətləri tənzimləmək. 7. Bəzi xanaların mexaniki doldurulması ilə iş yükünü və hesablama işini azaltmaq.
A2: Sütunlarda və sətirlərdə verilən məlumatların doldurulması üçün qaydalar
A3: № | B3: Səhifə | C3: Sütun və ya sətirlərin adı | D3: Doldurulma qaydası | E3: Məlumatı daxil edən şəxs
A4: 1 | B4: Baza | C4: Tədris ili | D4: Sarı xanaya tədris ili qeyd edilir: 2022-2023 | E4: Sinif rəhbəri
A5: 2 | B5: Baza | C5: Şəhər | D5: Sarı xanaya yalnız Bakı qeyd edilir. | E5: Sinif rəhbəri
A6: 3 | B6: Baza | C6: Rayon | D6: Sarı xanaya təhsil müəssisəsinin yerləşdiyi rayon qeyd edilir: Binəqədi, Nəsimi və s. | E6: Sinif rəhbəri
A7: 4 | B7: Baza | C7: Məktəb indeksi | D7: Sarı xanaya təhsil müəssisəsinin indeksi (nömrə və ya abreviatura) yazılır: 1, 120, MLK, THL və s. | E7: Sinif rəhbəri
A8: 5 | B8: Baza | C8: Şagirdin UTİS kodu | D8: Şagirdin UTİS kodu qeyd edilir. UTİS kodu daxil etmək önəmlidir. Akademik nailiyyətlər UTİS kod üzrə təhlil olunur. UTİS kodların rəqəm formatında yazılması vacibdir. | E8: Sinif rəhbəri
A9: 6 | B9: Baza | C9: Sinif | D9: Sarı xanaya siniflər rəqəmlərlə qeyd edilir: 1, 2, 3, 4, 5, ..... 11 və s. | E9: Sinif rəhbəri
A10: 7 | B10: Baza | C10: İndeks | D10: Sarı xanaya siniflərin indeksi qeyd edilir: A,B,C,D,E və s. Tək siniflərə A qeyd olunur. | E10: Sinif rəhbəri
A11: 8 | B11: Baza | C11: Şagird (Soyad, ad, ata adı) | D11: Soyad, ad və ata adı ayrı-ayrı xanalara daxil edilir. | E11: Sinif rəhbəri
A12: 9 | B12: Baza | C12: Bölmə | D12: Sarı xanaya sinfin təhsil aldığı bölmə qeyd edilir: Azərbaycan bölməsi-A, Rus bölməsi-R | E12: Sinif rəhbəri
A13: 10 | B13: Baza | C13: Cins | D13: Şagirdin cinsi qeyd edilir: Qadın-Q, Kişi-K | E13: Sinif rəhbəri
A14: 11 | B14: Baza | C14: Doğum tarixi | D14: Şagirdin doğum tarixi qeyd edilir: 01.01.2010 formatında | E14: Sinif rəhbəri
A15: 12 | B15: Baza | C15: Mobil əlaqə nömrəsi | D15: Həm şagirdin, həm də valideynin mövcud olan və istifadə olunan mobil nömrələri qeyd edilir: 000 0000000 formatında | E15: Sinif rəhbəri
... A18: 15 | B18: Akademik nailiyyətlər | C18: Kod | D18: Qırmızı xanaya şagirdin UTİS kodu daxil edildikdə şagird haqqında bütün məlumatlar, "Sinif" yazdıqda ümumi sinif haqqında ətraflı məlumatlar əldə etmək mümkündür. Şagirdlərin UTİS kodlarının rəqəm formatında yazılması vacibdir. | E18: Sinif rəhbəri
A19: DİQQƏT! - Sətirləri və sütunları silmək olmaz. - Sinif rəhbəri yalnız sarı xanaları doldurur. - Fənn müəllimi yalnız ağ xanaları doldurur. - Yaşıl xanalar mexaniki doldurulur. - Şifrəyə müdaxilə etmək olmaz. - Şagirdlərin siyahısı yalnız sinif rəhbərinin verdiyi ardıcıllıqda olmalıdır. Siyahını dəyişdirmək qətiyyən olmaz. - Bəzi xanaların funksiyaları bir-biri ilə əlaqələndirildiyindən məlumatlar tam daxil edildikdən sonra digər məlumatlar görünür. Bu baxımdan əgər xanada mexaniki olaraq görülməli olan məlumat görünməzsə, hansısa əlaqəli məlumatın daxil edilməsinə diqqət etmək lazımdır.
A20: Fənnlərin kodları
A21: 101 | B21: Azərbaycan dili
A22: 102 | B22: Ədəbiyyat
A23: 104 | B23: Rus dili
A24: 106 | B24: İngilis dili
A25: 110 | B25: Riyaziyyat
A26: 114 | B26: İnformatika
A27: 115 | B27: Ümumi tarix
A28: 117 | B28: Azərbaycan tarixi
A29: 120 | B29: Coğrafiya
A30: 125 | B30: Fizika
A31: 127 | B31: Kimya
A32: 128 | B32: Həyat bilgisi
A33: 129 | B33: Biologiya
A34: 130 | B34: Çağırışaqədərki hazırlıq
A35: 131 | B35: Fiziki tərbiyə
A36: 132 | B36: Təsviri incəsənət
A37: 133 | B37: Musiqi
A38: 135 | B38: Texnologiya
A39: 181 | B39: Alman dili
... A44: 927 | B44: Təbiət

Sheet Baza
C1: Sinif haqqında ümumi məlumatlar | Q1: 101 | R1: Azərbaycan dili | BC1: 102 | BD1: Ədəbiyyat | CO1: 104 | CP1: Rus dili | EA1: 106 | EB1: İngilis dili | FM1: 110 | FN1: Riyaziyyat | GY1: 114 | GZ1: İnformatika | IK1: 115 | IL1: Ümumi tarix | JW1: 117 | JX1: Azərbaycan tarixi | LI1: 120 | LJ1: Coğrafiya | MU1: 125 | MV1: Fizika | OG1: 127 | OH1: Kimya | PS1: 128 | PT1: Həyat bilgisi | RE1: 129 | RF1: Biologiya | SQ1: 130 | SR1: Çağırışaqədərki hazırlıq | UC1: 131 | UD1: Fiziki tərbiyə | VO1: 132 | VP1: Təsviri incəsənət | XA1: 133 | XB1: Musiqi | YM1: 135 | YN1: Texnologiya | ZY1: 181 | ZZ1: Alman dili | ABK1: 182 | ABL1: Fransız dili | ACW1: 281 | ACX1: Rəqəmsal bacarıqlar | AEI1: 771 | AEJ1: STEAM | AFU1: 926 | AFV1: Zəfər tarixi | AHG1: 927 | AHH1: Təbiət
A2: =IF(A9="","",A9) -> 2023-2024 | B2: =IF(B9="","",B9) -> Bakı | C2: =IF(C9="","",C9) -> Binəqədi | D2: =IF(D9="","",D9) -> 99 | E2: Sinif | H2: =IF(F9="","",F9&G9) -> 8C | I2: =IF(K9="R","Rus",IF(K9="A","Azərbaycan","")) -> Azərbaycan | K2: =IF(K9="","",K9) -> A | L2: =SUM(L4,L6) -> 21 | P2: =IF(P9="","",P9) -> Ələkbərova Bahar Elimxan | R2: =IF(Q1="","",Q1) -> 101 | S2: =IF(S10="","",S10) | T2: =IFERROR(AVERAGE(T10:T59),"") | U2: =IFERROR(AVERAGE(U10:U59),"") | V2: =IFERROR(AVERAGE(V10:V59),"") | W2: =IFERROR(AVERAGE(W10:W59),"") | X2: =IFERROR(AVERAGE(X10:X59),"") | Y2: =IFERROR(AVERAGE(Y10:Y59),"") | Z2: =IFERROR(AVERAGE(Z10:Z59),"") | AA2: =IFERROR(AVERAGE(AA10:AA59),"") | ... AE2: =IFERROR(AVERAGE(AE10:AE59),"") | AF2: =IFERROR(SUM(AF10:AF59),"") -> 0 | AG2: =IFERROR(AVERAGE(AG10:AG59),"") | AH2: =IFERROR(AVERAGE(AH10:AH59),"") | AI2: =IFERROR(AVERAGE(AI10:AI59),"") | AJ2: =IFERROR(AVERAGE(AJ10:AJ59),"") | AK2: =IFERROR(AVERAGE(AK10:AK59),"") | AL2: =IFERROR(AVERAGE(AL10:AL59),"") | AM2: =IFERROR(AVERAGE(AM10:AM59),"") | AN2: =IFERROR(AVERAGE(AN10:AN59),"") | ... AR2: =IFERROR(AVERAGE(AR10:AR59),"") | AS2: =IFERROR(SUM(AS10:AS59),"") -> 0 | AT2: =IFERROR(AVERAGE(AT10:AT59),"") | AU2: =IFERROR(AVERAGE(AU10:AU59),"") | AV2: =IFERROR(AVERAGE(AV10:AV59),"") | AW2: =IFERROR(AVERAGE(AW10:AW59),"") | AX2: =IFERROR(AVERAGE(AX10:AX59),"") | AY2: =IFERROR(AVERAGE(AY10:AY59),"") | AZ2: =IFERROR(AVERAGE(AZ10:AZ59),"") | BA2: =IFERROR(SUM(BA10:BA59),"") -> 0 | BB2: =IFERROR(AVERAGE(BB10:BB59),"") | BD2: =IF(BC1="","",BC1) -> 102 | BE2: =IF(BE10="","",BE10) | BF2: =IFERROR(AVERAGE(BF10:BF59),"") | BG2: =IFERROR(AVERAGE(BG10:BG59),"") | BH2: =IFERROR(AVERAGE(BH10:BH59),"") | BI2: =IFERROR(AVERAGE(BI10:BI59),"") | BJ2: =IFERROR(AVERAGE(BJ10:BJ59),"") | BK2: =IFERROR(AVERAGE(BK10:BK59),"") | BL2: =IFERROR(AVERAGE(BL10:BL59),"") | BM2: =IFERROR(AVERAGE(BM10:BM59),"") | ... BQ2: =IFERROR(AVERAGE(BQ10:BQ59),"") | BR2: =IFERROR(SUM(BR10:BR59),"") -> 0 | BS2: =IFERROR(AVERAGE(BS10:BS59),"") | BT2: =IFERROR(AVERAGE(BT10:BT59),"") | BU2: =IFERROR(AVERAGE(BU10:BU59),"") | BV2: =IFERROR(AVERAGE(BV10:BV59),"") | BW2: =IFERROR(AVERAGE(BW10:BW59),"") | BX2: =IFERROR(AVERAGE(BX10:BX59),"") | BY2: =IFERROR(AVERAGE(BY10:BY59),"") | BZ2: =IFERROR(AVERAGE(BZ10:BZ59),"") | ... CD2: =IFERROR(AVERAGE(CD10:CD59),"") | CE2: =IFERROR(SUM(CE10:CE59),"") -> 0 | CF2: =IFERROR(AVERAGE(CF10:CF59),"") | CG2: =IFERROR(AVERAGE(CG10:CG59),"") | CH2: =IFERROR(AVERAGE(CH10:CH59),"") | CI2: =IFERROR(AVERAGE(CI10:CI59),"") | CJ2: =IFERROR(AVERAGE(CJ10:CJ59),"") | CK2: =IFERROR(AVERAGE(CK10:CK59),"") | CL2: =IFERROR(AVERAGE(CL10:CL59),"") | CM2: =IFERROR(SUM(CM10:CM59),"") -> 0 | CN2: =IFERROR(AVERAGE(CN10:CN59),"") | CP2: =IF(CO1="","",CO1) -> 104 | CQ2: =IF(CQ10="","",CQ10) | CR2: =IFERROR(AVERAGE(CR10:CR59),"") | CS2: =IFERROR(AVERAGE(CS10:CS59),"") | CT2: =IFERROR(AVERAGE(CT10:CT59),"") | CU2: =IFERROR(AVERAGE(CU10:CU59),"") | CV2: =IFERROR(AVERAGE(CV10:CV59),"") | CW2: =IFERROR(AVERAGE(CW10:CW59),"") | CX2: =IFERROR(AVERAGE(CX10:CX59),"") | CY2: =IFERROR(AVERAGE(CY10:CY59),"") | ... DC2: =IFERROR(AVERAGE(DC10:DC59),"") | DD2: =IFERROR(SUM(DD10:DD59),"") -> 0 | DE2: =IFERROR(AVERAGE(DE10:DE59),"") | DF2: =IFERROR(AVERAGE(DF10:DF59),"") | DG2: =IFERROR(AVERAGE(DG10:DG59),"") | DH2: =IFERROR(AVERAGE(DH10:DH59),"") | DI2: =IFERROR(AVERAGE(DI10:DI59),"") | DJ2: =IFERROR(AVERAGE(DJ10:DJ59),"") | DK2: =IFERROR(AVERAGE(DK10:DK59),"") | DL2: =IFERROR(AVERAGE(DL10:DL59),"") | ... DP2: =IFERROR(AVERAGE(DP10:DP59),"") | DQ2: =IFERROR(SUM(DQ10:DQ59),"") -> 0 | DR2: =IFERROR(AVERAGE(DR10:DR59),"") | DS2: =IFERROR(AVERAGE(DS10:DS59),"") | DT2: =IFERROR(AVERAGE(DT10:DT59),"") | DU2: =IFERROR(AVERAGE(DU10:DU59),"") | DV2: =IFERROR(AVERAGE(DV10:DV59),"") | DW2: =IFERROR(AVERAGE(DW10:DW59),"") | DX2: =IFERROR(AVERAGE(DX10:DX59),"") | DY2: =IFERROR(SUM(DY10:DY59),"") -> 0 | DZ2: =IFERROR(AVERAGE(DZ10:DZ59),"") | EB2: =IF(EA1="","",EA1) -> 106 | EC2: =IF(EC10="","",EC10) | ED2: =IFERROR(AVERAGE(ED10:ED59),"") | EE2: =IFERROR(AVERAGE(EE10:EE59),"") | EF2: =IFERROR(AVERAGE(EF10:EF59),"") | EG2: =IFERROR(AVERAGE(EG10:EG59),"") | EH2: =IFERROR(AVERAGE(EH10:EH59),"") | EI2: =IFERROR(AVERAGE(EI10:EI59),"") | EJ2: =IFERROR(AVERAGE(EJ10:EJ59),"") | EK2: =IFERROR(AVERAGE(EK10:EK59),"") | ... EO2: =IFERROR(AVERAGE(EO10:EO59),"") | EP2: =IFERROR(SUM(EP10:EP59),"") -> 0 | EQ2: =IFERROR(AVERAGE(EQ10:EQ59),"") | ER2: =IFERROR(AVERAGE(ER10:ER59),"") | ES2: =IFERROR(AVERAGE(ES10:ES59),"") | ET2: =IFERROR(AVERAGE(ET10:ET59),"") | EU2: =IFERROR(AVERAGE(EU10:EU59),"") | EV2: =IFERROR(AVERAGE(EV10:EV59),"") | EW2: =IFERROR(AVERAGE(EW10:EW59),"") | EX2: =IFERROR(AVERAGE(EX10:EX59),"") | ... FB2: =IFERROR(AVERAGE(FB10:FB59),"") | FC2: =IFERROR(SUM(FC10:FC59),"") -> 0 | FD2: =IFERROR(AVERAGE(FD10:FD59),"") | FE2: =IFERROR(AVERAGE(FE10:FE59),"") | FF2: =IFERROR(AVERAGE(FF10:FF59),"") | FG2: =IFERROR(AVERAGE(FG10:FG59),"") | FH2: =IFERROR(AVERAGE(FH10:FH59),"") | FI2: =IFERROR(AVERAGE(FI10:FI59),"") | FJ2: =IFERROR(AVERAGE(FJ10:FJ59),"") | FK2: =IFERROR(SUM(FK10:FK59),"") -> 0 | FL2: =IFERROR(AVERAGE(FL10:FL59),"") | FN2: =IF(FM1="","",FM1) -> 110 | FO2: =IF(FO10="","",FO10) | FP2: =IFERROR(AVERAGE(FP10:FP59),"") | FQ2: =IFERROR(AVERAGE(FQ10:FQ59),"") | FR2: =IFERROR(AVERAGE(FR10:FR59),"") | FS2: =IFERROR(AVERAGE(FS10:FS59),"") | FT2: =IFERROR(AVERAGE(FT10:FT59),"") | FU2: =IFERROR(AVERAGE(FU10:FU59),"") | FV2: =IFERROR(AVERAGE(FV10:FV59),"") | FW2: =IFERROR(AVERAGE(FW10:FW59),"") | ... GA2: =IFERROR(AVERAGE(GA10:GA59),"") | GB2: =IFERROR(SUM(GB10:GB59),"") -> 0 | GC2: =IFERROR(AVERAGE(GC10:GC59),"") | GD2: =IFERROR(AVERAGE(GD10:GD59),"") | GE2: =IFERROR(AVERAGE(GE10:GE59),"") | GF2: =IFERROR(AVERAGE(GF10:GF59),"") | GG2: =IFERROR(AVERAGE(GG10:GG59),"") | GH2: =IFERROR(AVERAGE(GH10:GH59),"") | GI2: =IFERROR(AVERAGE(GI10:GI59),"") | GJ2: =IFERROR(AVERAGE(GJ10:GJ59),"") | ... GN2: =IFERROR(AVERAGE(GN10:GN59),"") | GO2: =IFERROR(SUM(GO10:GO59),"") -> 0 | GP2: =IFERROR(AVERAGE(GP10:GP59),"") | GQ2: =IFERROR(AVERAGE(GQ10:GQ59),"") | GR2: =IFERROR(AVERAGE(GR10:GR59),"") | GS2: =IFERROR(AVERAGE(GS10:GS59),"") | GT2: =IFERROR(AVERAGE(GT10:GT59),"") | GU2: =IFERROR(AVERAGE(GU10:GU59),"") | GV2: =IFERROR(AVERAGE(GV10:GV59),"") | GW2: =IFERROR(SUM(GW10:GW59),"") -> 0 | GX2: =IFERROR(AVERAGE(GX10:GX59),"") | GZ2: =IF(GY1="","",GY1) -> 114 | HA2: =IF(HA10="","",HA10) | HB2: =IFERROR(AVERAGE(HB10:HB59),"") | HC2: =IFERROR(AVERAGE(HC10:HC59),"") | HD2: =IFERROR(AVERAGE(HD10:HD59),"") | HE2: =IFERROR(AVERAGE(HE10:HE59),"") | HF2: =IFERROR(AVERAGE(HF10:HF59),"") | HG2: =IFERROR(AVERAGE(HG10:HG59),"") | HH2: =IFERROR(AVERAGE(HH10:HH59),"") | HI2: =IFERROR(AVERAGE(HI10:HI59),"") | ... HM2: =IFERROR(AVERAGE(HM10:HM59),"") | HN2: =IFERROR(SUM(HN10:HN59),"") -> 0 | HO2: =IFERROR(AVERAGE(HO10:HO59),"") | HP2: =IFERROR(AVERAGE(HP10:HP59),"") | HQ2: =IFERROR(AVERAGE(HQ10:HQ59),"") | HR2: =IFERROR(AVERAGE(HR10:HR59),"") | HS2: =IFERROR(AVERAGE(HS10:HS59),"") | HT2: =IFERROR(AVERAGE(HT10:HT59),"") | HU2: =IFERROR(AVERAGE(HU10:HU59),"") | HV2: =IFERROR(AVERAGE(HV10:HV59),"") | ... HZ2: =IFERROR(AVERAGE(HZ10:HZ59),"") | IA2: =IFERROR(SUM(IA10:IA59),"") -> 0 | IB2: =IFERROR(AVERAGE(IB10:IB59),"") | IC2: =IFERROR(AVERAGE(IC10:IC59),"") | ID2: =IFERROR(AVERAGE(ID10:ID59),"") | IE2: =IFERROR(AVERAGE(IE10:IE59),"") | IF2: =IFERROR(AVERAGE(IF10:IF59),"") | IG2: =IFERROR(AVERAGE(IG10:IG59),"") | IH2: =IFERROR(AVERAGE(IH10:IH59),"") | II2: =IFERROR(SUM(II10:II59),"") -> 0 | IJ2: =IFERROR(AVERAGE(IJ10:IJ59),"") | IL2: =IF(IK1="","",IK1) -> 115 | IM2: =IF(IM10="","",IM10) | IN2: =IFERROR(AVERAGE(IN10:IN59),"") | IO2: =IFERROR(AVERAGE(IO10:IO59),"") | IP2: =IFERROR(AVERAGE(IP10:IP59),"") | IQ2: =IFERROR(AVERAGE(IQ10:IQ59),"") | IR2: =IFERROR(AVERAGE(IR10:IR59),"") | IS2: =IFERROR(AVERAGE(IS10:IS59),"") | IT2: =IFERROR(AVERAGE(IT10:IT59),"") | IU2: =IFERROR(AVERAGE(IU10:IU59),"") | ... IY2: =IFERROR(AVERAGE(IY10:IY59),"") | IZ2: =IFERROR(SUM(IZ10:IZ59),"") -> 0 | JA2: =IFERROR(AVERAGE(JA10:JA59),"") | JB2: =IFERROR(AVERAGE(JB10:JB59),"") | JC2: =IFERROR(AVERAGE(JC10:JC59),"") | JD2: =IFERROR(AVERAGE(JD10:JD59),"") | JE2: =IFERROR(AVERAGE(JE10:JE59),"") | JF2: =IFERROR(AVERAGE(JF10:JF59),"") | JG2: =IFERROR(AVERAGE(JG10:JG59),"") | JH2: =IFERROR(AVERAGE(JH10:JH59),"") | ... JL2: =IFERROR(AVERAGE(JL10:JL59),"") | JM2: =IFERROR(SUM(JM10:JM59),"") -> 0 | JN2: =IFERROR(AVERAGE(JN10:JN59),"") | JO2: =IFERROR(AVERAGE(JO10:JO59),"") | JP2: =IFERROR(AVERAGE(JP10:JP59),"") | JQ2: =IFERROR(AVERAGE(JQ10:JQ59),"") | JR2: =IFERROR(AVERAGE(JR10:JR59),"") | JS2: =IFERROR(AVERAGE(JS10:JS59),"") | JT2: =IFERROR(AVERAGE(JT10:JT59),"") | JU2: =IFERROR(SUM(JU10:JU59),"") -> 0 | JV2: =IFERROR(AVERAGE(JV10:JV59),"") | JX2: =IF(JW1="","",JW1) -> 117 | JY2: =IF(JY10="","",JY10) | JZ2: =IFERROR(AVERAGE(JZ10:JZ59),"") | KA2: =IFERROR(AVERAGE(KA10:KA59),"") | KB2: =IFERROR(AVERAGE(KB10:KB59),"") | KC2: =IFERROR(AVERAGE(KC10:KC59),"") | KD2: =IFERROR(AVERAGE(KD10:KD59),"") | KE2: =IFERROR(AVERAGE(KE10:KE59),"") | KF2: =IFERROR(AVERAGE(KF10:KF59),"") | KG2: =IFERROR(AVERAGE(KG10:KG59),"") | ... KK2: =IFERROR(AVERAGE(KK10:KK59),"") | KL2: =IFERROR(SUM(KL10:KL59),"") -> 0 | KM2: =IFERROR(AVERAGE(KM10:KM59),"") | KN2: =IFERROR(AVERAGE(KN10:KN59),"") | KO2: =IFERROR(AVERAGE(KO10:KO59),"") | KP2: =IFERROR(AVERAGE(KP10:KP59),"") | KQ2: =IFERROR(AVERAGE(KQ10:KQ59),"") | KR2: =IFERROR(AVERAGE(KR10:KR59),"") | KS2: =IFERROR(AVERAGE(KS10:KS59),"") | KT2: =IFERROR(AVERAGE(KT10:KT59),"") | ... KX2: =IFERROR(AVERAGE(KX10:KX59),"") | KY2: =IFERROR(SUM(KY10:KY59),"") -> 0 | KZ2: =IFERROR(AVERAGE(KZ10:KZ59),"") | LA2: =IFERROR(AVERAGE(LA10:LA59),"") | LB2: =IFERROR(AVERAGE(LB10:LB59),"") | LC2: =IFERROR(AVERAGE(LC10:LC59),"") | LD2: =IFERROR(AVERAGE(LD10:LD59),"") | LE2: =IFERROR(AVERAGE(LE10:LE59),"") | LF2: =IFERROR(AVERAGE(LF10:LF59),"") | LG2: =IFERROR(SUM(LG10:LG59),"") -> 0 | LH2: =IFERROR(AVERAGE(LH10:LH59),"") | LJ2: =IF(LI1="","",LI1) -> 120 | LK2: =IF(LK10="","",LK10) | LL2: =IFERROR(AVERAGE(LL10:LL59),"") | LM2: =IFERROR(AVERAGE(LM10:LM59),"") | LN2: =IFERROR(AVERAGE(LN10:LN59),"") | LO2: =IFERROR(AVERAGE(LO10:LO59),"") | LP2: =IFERROR(AVERAGE(LP10:LP59),"") | LQ2: =IFERROR(AVERAGE(LQ10:LQ59),"") | LR2: =IFERROR(AVERAGE(LR10:LR59),"") | LS2: =IFERROR(AVERAGE(LS10:LS59),"") | ... LW2: =IFERROR(AVERAGE(LW10:LW59),"") | LX2: =IFERROR(SUM(LX10:LX59),"") -> 0 | LY2: =IFERROR(AVERAGE(LY10:LY59),"") | LZ2: =IFERROR(AVERAGE(LZ10:LZ59),"") | MA2: =IFERROR(AVERAGE(MA10:MA59),"") | MB2: =IFERROR(AVERAGE(MB10:MB59),"") | MC2: =IFERROR(AVERAGE(MC10:MC59),"") | MD2: =IFERROR(AVERAGE(MD10:MD59),"") | ME2: =IFERROR(AVERAGE(ME10:ME59),"") | MF2: =IFERROR(AVERAGE(MF10:MF59),"") | ... MJ2: =IFERROR(AVERAGE(MJ10:MJ59),"") | MK2: =IFERROR(SUM(MK10:MK59),"") -> 0 | ML2: =IFERROR(AVERAGE(ML10:ML59),"") | MM2: =IFERROR(AVERAGE(MM10:MM59),"") | MN2: =IFERROR(AVERAGE(MN10:MN59),"") | MO2: =IFERROR(AVERAGE(MO10:MO59),"") | MP2: =IFERROR(AVERAGE(MP10:MP59),"") | MQ2: =IFERROR(AVERAGE(MQ10:MQ59),"") | MR2: =IFERROR(AVERAGE(MR10:MR59),"") | MS2: =IFERROR(SUM(MS10:MS59),"") -> 0 | MT2: =IFERROR(AVERAGE(MT10:MT59),"") | MV2: =IF(MU1="","",MU1) -> 125 | MW2: =IF(MW10="","",MW10) | MX2: =IFERROR(AVERAGE(MX10:MX59),"") | MY2: =IFERROR(AVERAGE(MY10:MY59),"") | MZ2: =IFERROR(AVERAGE(MZ10:MZ59),"") | NA2: =IFERROR(AVERAGE(NA10:NA59),"") | NB2: =IFERROR(AVERAGE(NB10:NB59),"") | NC2: =IFERROR(AVERAGE(NC10:NC59),"") | ND2: =IFERROR(AVERAGE(ND10:ND59),"") | NE2: =IFERROR(AVERAGE(NE10:NE59),"") | ... NI2: =IFERROR(AVERAGE(NI10:NI59),"") | NJ2: =IFERROR(SUM(NJ10:NJ59),"") -> 0 | NK2: =IFERROR(AVERAGE(NK10:NK59),"") | NL2: =IFERROR(AVERAGE(NL10:NL59),"") | NM2: =IFERROR(AVERAGE(NM10:NM59),"") | NN2: =IFERROR(AVERAGE(NN10:NN59),"") | NO2: =IFERROR(AVERAGE(NO10:NO59),"") | NP2: =IFERROR(AVERAGE(NP10:NP59),"") | NQ2: =IFERROR(AVERAGE(NQ10:NQ59),"") | NR2: =IFERROR(AVERAGE(NR10:NR59),"") | ... NV2: =IFERROR(AVERAGE(NV10:NV59),"") | NW2: =IFERROR(SUM(NW10:NW59),"") -> 0 | NX2: =IFERROR(AVERAGE(NX10:NX59),"") | NY2: =IFERROR(AVERAGE(NY10:NY59),"") | NZ2: =IFERROR(AVERAGE(NZ10:NZ59),"") | OA2: =IFERROR(AVERAGE(OA10:OA59),"") | OB2: =IFERROR(AVERAGE(OB10:OB59),"") | OC2: =IFERROR(AVERAGE(OC10:OC59),"") | OD2: =IFERROR(AVERAGE(OD10:OD59),"") | OE2: =IFERROR(SUM(OE10:OE59),"") -> 0 | OF2: =IFERROR(AVERAGE(OF10:OF59),"") | OH2: =IF(OG1="","",OG1) -> 127 | OI2: =IF(OI10="","",OI10) | OJ2: =IFERROR(AVERAGE(OJ10:OJ59),"") | OK2: =IFERROR(AVERAGE(OK10:OK59),"") | OL2: =IFERROR(AVERAGE(OL10:OL59),"") | OM2: =IFERROR(AVERAGE(OM10:OM59),"") | ON2: =IFERROR(AVERAGE(ON10:ON59),"") | OO2: =IFERROR(AVERAGE(OO10:OO59),"") | OP2: =IFERROR(AVERAGE(OP10:OP59),"") | OQ2: =IFERROR(AVERAGE(OQ10:OQ59),"") | ... OU2: =IFERROR(AVERAGE(OU10:OU59),"") | OV2: =IFERROR(SUM(OV10:OV59),"") -> 0 | OW2: =IFERROR(AVERAGE(OW10:OW59),"") | OX2: =IFERROR(AVERAGE(OX10:OX59),"") | OY2: =IFERROR(AVERAGE(OY10:OY59),"") | OZ2: =IFERROR(AVERAGE(OZ10:OZ59),"") | PA2: =IFERROR(AVERAGE(PA10:PA59),"") | PB2: =IFERROR(AVERAGE(PB10:PB59),"") | PC2: =IFERROR(AVERAGE(PC10:PC59),"") | PD2: =IFERROR(AVERAGE(PD10:PD59),"") | ... PH2: =IFERROR(AVERAGE(PH10:PH59),"") | PI2: =IFERROR(SUM(PI10:PI59),"") -> 0 | PJ2: =IFERROR(AVERAGE(PJ10:PJ59),"") | PK2: =IFERROR(AVERAGE(PK10:PK59),"") | PL2: =IFERROR(AVERAGE(PL10:PL59),"") | PM2: =IFERROR(AVERAGE(PM10:PM59),"") | PN2: =IFERROR(AVERAGE(PN10:PN59),"") | PO2: =IFERROR(AVERAGE(PO10:PO59),"") | PP2: =IFERROR(AVERAGE(PP10:PP59),"") | PQ2: =IFERROR(SUM(PQ10:PQ59),"") -> 0 | PR2: =IFERROR(AVERAGE(PR10:PR59),"") | PT2: =IF(PS1="","",PS1) -> 128 | PU2: =IF(PU10="","",PU10) | PV2: =IFERROR(AVERAGE(PV10:PV59),"") | PW2: =IFERROR(AVERAGE(PW10:PW59),"") | PX2: =IFERROR(AVERAGE(PX10:PX59),"") | PY2: =IFERROR(AVERAGE(PY10:PY59),"") | PZ2: =IFERROR(AVERAGE(PZ10:PZ59),"") | QA2: =IFERROR(AVERAGE(QA10:QA59),"") | QB2: =IFERROR(AVERAGE(QB10:QB59),"") | QC2: =IFERROR(AVERAGE(QC10:QC59),"") | ... QG2: =IFERROR(AVERAGE(QG10:QG59),"") | QH2: =IFERROR(SUM(QH10:QH59),"") -> 0 | QI2: =IFERROR(AVERAGE(QI10:QI59),"") | QJ2: =IFERROR(AVERAGE(QJ10:QJ59),"") | QK2: =IFERROR(AVERAGE(QK10:QK59),"") | QL2: =IFERROR(AVERAGE(QL10:QL59),"") | QM2: =IFERROR(AVERAGE(QM10:QM59),"") | QN2: =IFERROR(AVERAGE(QN10:QN59),"") | QO2: =IFERROR(AVERAGE(QO10:QO59),"") | QP2: =IFERROR(AVERAGE(QP10:QP59),"") | ... QT2: =IFERROR(AVERAGE(QT10:QT59),"") | QU2: =IFERROR(SUM(QU10:QU59),"") -> 0 | QV2: =IFERROR(AVERAGE(QV10:QV59),"") | QW2: =IFERROR(AVERAGE(QW10:QW59),"") | QX2: =IFERROR(AVERAGE(QX10:QX59),"") | QY2: =IFERROR(AVERAGE(QY10:QY59),"") | QZ2: =IFERROR(AVERAGE(QZ10:QZ59),"") | RA2: =IFERROR(AVERAGE(RA10:RA59),"") | RB2: =IFERROR(AVERAGE(RB10:RB59),"") | RC2: =IFERROR(SUM(RC10:RC59),"") -> 0 | RD2: =IFERROR(AVERAGE(RD10:RD59),"") | RF2: =IF(RE1="","",RE1) -> 129 | RG2: =IF(RG10="","",RG10) | RH2: =IFERROR(AVERAGE(RH10:RH59),"") | RI2: =IFERROR(AVERAGE(RI10:RI59),"") | RJ2: =IFERROR(AVERAGE(RJ10:RJ59),"") | RK2: =IFERROR(AVERAGE(RK10:RK59),"") | RL2: =IFERROR(AVERAGE(RL10:RL59),"") | RM2: =IFERROR(AVERAGE(RM10:RM59),"") | RN2: =IFERROR(AVERAGE(RN10:RN59),"") | RO2: =IFERROR(AVERAGE(RO10:RO59),"") | ... RS2: =IFERROR(AVERAGE(RS10:RS59),"") | RT2: =IFERROR(SUM(RT10:RT59),"") -> 0 | RU2: =IFERROR(AVERAGE(RU10:RU59),"") | RV2: =IFERROR(AVERAGE(RV10:RV59),"") | RW2: =IFERROR(AVERAGE(RW10:RW59),"") | RX2: =IFERROR(AVERAGE(RX10:RX59),"") | RY2: =IFERROR(AVERAGE(RY10:RY59),"") | RZ2: =IFERROR(AVERAGE(RZ10:RZ59),"") | SA2: =IFERROR(AVERAGE(SA10:SA59),"") | SB2: =IFERROR(AVERAGE(SB10:SB59),"") | ... SF2: =IFERROR(AVERAGE(SF10:SF59),"") | SG2: =IFERROR(SUM(SG10:SG59),"") -> 0 | SH2: =IFERROR(AVERAGE(SH10:SH59),"") | SI2: =IFERROR(AVERAGE(SI10:SI59),"") | SJ2: =IFERROR(AVERAGE(SJ10:SJ59),"") | SK2: =IFERROR(AVERAGE(SK10:SK59),"") | SL2: =IFERROR(AVERAGE(SL10:SL59),"") | SM2: =IFERROR(AVERAGE(SM10:SM59),"") | SN2: =IFERROR(AVERAGE(SN10:SN59),"") | SO2: =IFERROR(SUM(SO10:SO59),"") -> 0 | SP2: =IFERROR(AVERAGE(SP10:SP59),"") | SR2: =IF(SQ1="","",SQ1) -> 130 | SS2: =IF(SS10="","",SS10) | ST2: =IFERROR(AVERAGE(ST10:ST59),"") | SU2: =IFERROR(AVERAGE(SU10:SU59),"") | SV2: =IFERROR(AVERAGE(SV10:SV59),"") | SW2: =IFERROR(AVERAGE(SW10:SW59),"") | SX2: =IFERROR(AVERAGE(SX10:SX59),"") | SY2: =IFERROR(AVERAGE(SY10:SY59),"") | SZ2: =IFERROR(AVERAGE(SZ10:SZ59),"") | TA2: =IFERROR(AVERAGE(TA10:TA59),"") | ... TE2: =IFERROR(AVERAGE(TE10:TE59),"") | TF2: =IFERROR(SUM(TF10:TF59),"") -> 0 | TG2: =IFERROR(AVERAGE(TG10:TG59),"") | TH2: =IFERROR(AVERAGE(TH10:TH59),"") | TI2: =IFERROR(AVERAGE(TI10:TI59),"") | TJ2: =IFERROR(AVERAGE(TJ10:TJ59),"") | TK2: =IFERROR(AVERAGE(TK10:TK59),"") | TL2: =IFERROR(AVERAGE(TL10:TL59),"") | TM2: =IFERROR(AVERAGE(TM10:TM59),"") | TN2: =IFERROR(AVERAGE(TN10:TN59),"") | ... TR2: =IFERROR(AVERAGE(TR10:TR59),"") | TS2: =IFERROR(SUM(TS10:TS59),"") -> 0 | TT2: =IFERROR(AVERAGE(TT10:TT59),"") | TU2: =IFERROR(AVERAGE(TU10:TU59),"") | TV2: =IFERROR(AVERAGE(TV10:TV59),"") | TW2: =IFERROR(AVERAGE(TW10:TW59),"") | TX2: =IFERROR(AVERAGE(TX10:TX59),"") | TY2: =IFERROR(AVERAGE(TY10:TY59),"") | TZ2: =IFERROR(AVERAGE(TZ10:TZ59),"") | UA2: =IFERROR(SUM(UA10:UA59),"") -> 0 | UB2: =IFERROR(AVERAGE(UB10:UB59),"") | UD2: =IF(UC1="","",UC1) -> 131 | UE2: =IF(UE10="","",UE10) | UF2: =IFERROR(AVERAGE(UF10:UF59),"") | UG2: =IFERROR(AVERAGE(UG10:UG59),"") | UH2: =IFERROR(AVERAGE(UH10:UH59),"") | UI2: =IFERROR(AVERAGE(UI10:UI59),"") | UJ2: =IFERROR(AVERAGE(UJ10:UJ59),"") | UK2: =IFERROR(AVERAGE(UK10:UK59),"") | UL2: =IFERROR(AVERAGE(UL10:UL59),"") | UM2: =IFERROR(AVERAGE(UM10:UM59),"") | ... UQ2: =IFERROR(AVERAGE(UQ10:UQ59),"") | UR2: =IFERROR(SUM(UR10:UR59),"") -> 0 | US2: =IFERROR(AVERAGE(US10:US59),"") | UT2: =IFERROR(AVERAGE(UT10:UT59),"") | UU2: =IFERROR(AVERAGE(UU10:UU59),"") | UV2: =IFERROR(AVERAGE(UV10:UV59),"") | UW2: =IFERROR(AVERAGE(UW10:UW59),"") | UX2: =IFERROR(AVERAGE(UX10:UX59),"") | UY2: =IFERROR(AVERAGE(UY10:UY59),"") | UZ2: =IFERROR(AVERAGE(UZ10:UZ59),"") | ... VD2: =IFERROR(AVERAGE(VD10:VD59),"") | VE2: =IFERROR(SUM(VE10:VE59),"") -> 0 | VF2: =IFERROR(AVERAGE(VF10:VF59),"") | VG2: =IFERROR(AVERAGE(VG10:VG59),"") | VH2: =IFERROR(AVERAGE(VH10:VH59),"") | VI2: =IFERROR(AVERAGE(VI10:VI59),"") | VJ2: =IFERROR(AVERAGE(VJ10:VJ59),"") | VK2: =IFERROR(AVERAGE(VK10:VK59),"") | VL2: =IFERROR(AVERAGE(VL10:VL59),"") | VM2: =IFERROR(SUM(VM10:VM59),"") -> 0 | VN2: =IFERROR(AVERAGE(VN10:VN59),"") | VP2: =IF(VO1="","",VO1) -> 132 | VQ2: =IF(VQ10="","",VQ10) | VR2: =IFERROR(AVERAGE(VR10:VR59),"") | VS2: =IFERROR(AVERAGE(VS10:VS59),"") | VT2: =IFERROR(AVERAGE(VT10:VT59),"") | VU2: =IFERROR(AVERAGE(VU10:VU59),"") | VV2: =IFERROR(AVERAGE(VV10:VV59),"") | VW2: =IFERROR(AVERAGE(VW10:VW59),"") | VX2: =IFERROR(AVERAGE(VX10:VX59),"") | VY2: =IFERROR(AVERAGE(VY10:VY59),"") | ... WC2: =IFERROR(AVERAGE(WC10:WC59),"") | WD2: =IFERROR(SUM(WD10:WD59),"") -> 0 | WE2: =IFERROR(AVERAGE(WE10:WE59),"") | WF2: =IFERROR(AVERAGE(WF10:WF59),"") | WG2: =IFERROR(AVERAGE(WG10:WG59),"") | WH2: =IFERROR(AVERAGE(WH10:WH59),"") | WI2: =IFERROR(AVERAGE(WI10:WI59),"") | WJ2: =IFERROR(AVERAGE(WJ10:WJ59),"") | WK2: =IFERROR(AVERAGE(WK10:WK59),"") | WL2: =IFERROR(AVERAGE(WL10:WL59),"") | ... WP2: =IFERROR(AVERAGE(WP10:WP59),"") | WQ2: =IFERROR(SUM(WQ10:WQ59),"") -> 0 | WR2: =IFERROR(AVERAGE(WR10:WR59),"") | WS2: =IFERROR(AVERAGE(WS10:WS59),"") | WT2: =IFERROR(AVERAGE(WT10:WT59),"") | WU2: =IFERROR(AVERAGE(WU10:WU59),"") | WV2: =IFERROR(AVERAGE(WV10:WV59),"") | WW2: =IFERROR(AVERAGE(WW10:WW59),"") | WX2: =IFERROR(AVERAGE(WX10:WX59),"") | WY2: =IFERROR(SUM(WY10:WY59),"") -> 0 | WZ2: =IFERROR(AVERAGE(WZ10:WZ59),"") | XB2: =IF(XA1="","",XA1) -> 133 | XC2: =IF(XC10="","",XC10) | XD2: =IFERROR(AVERAGE(XD10:XD59),"") | XE2: =IFERROR(AVERAGE(XE10:XE59),"") | XF2: =IFERROR(AVERAGE(XF10:XF59),"") | XG2: =IFERROR(AVERAGE(XG10:XG59),"") | XH2: =IFERROR(AVERAGE(XH10:XH59),"") | XI2: =IFERROR(AVERAGE(XI10:XI59),"") | XJ2: =IFERROR(AVERAGE(XJ10:XJ59),"") | XK2: =IFERROR(AVERAGE(XK10:XK59),"") | ... XO2: =IFERROR(AVERAGE(XO10:XO59),"") | XP2: =IFERROR(SUM(XP10:XP59),"") -> 0 | XQ2: =IFERROR(AVERAGE(XQ10:XQ59),"") | XR2: =IFERROR(AVERAGE(XR10:XR59),"") | XS2: =IFERROR(AVERAGE(XS10:XS59),"") | XT2: =IFERROR(AVERAGE(XT10:XT59),"") | XU2: =IFERROR(AVERAGE(XU10:XU59),"") | XV2: =IFERROR(AVERAGE(XV10:XV59),"") | XW2: =IFERROR(AVERAGE(XW10:XW59),"") | XX2: =IFERROR(AVERAGE(XX10:XX59),"") | ... YB2: =IFERROR(AVERAGE(YB10:YB59),"") | YC2: =IFERROR(SUM(YC10:YC59),"") -> 0 | YD2: =IFERROR(AVERAGE(YD10:YD59),"") | YE2: =IFERROR(AVERAGE(YE10:YE59),"") | YF2: =IFERROR(AVERAGE(YF10:YF59),"") | YG2: =IFERROR(AVERAGE(YG10:YG59),"") | YH2: =IFERROR(AVERAGE(YH10:YH59),"") | YI2: =IFERROR(AVERAGE(YI10:YI59),"") | YJ2: =IFERROR(AVERAGE(YJ10:YJ59),"") | YK2: =IFERROR(SUM(YK10:YK59),"") -> 0 | YL2: =IFERROR(AVERAGE(YL10:YL59),"") | YN2: =IF(YM1="","",YM1) -> 135 | YO2: =IF(YO10="","",YO10) | YP2: =IFERROR(AVERAGE(YP10:YP59),"") | YQ2: =IFERROR(AVERAGE(YQ10:YQ59),"") | YR2: =IFERROR(AVERAGE(YR10:YR59),"") | YS2: =IFERROR(AVERAGE(YS10:YS59),"") | YT2: =IFERROR(AVERAGE(YT10:YT59),"") | YU2: =IFERROR(AVERAGE(YU10:YU59),"") | YV2: =IFERROR(AVERAGE(YV10:YV59),"") | YW2: =IFERROR(AVERAGE(YW10:YW59),"") | ... ZA2: =IFERROR(AVERAGE(ZA10:ZA59),"") | ZB2: =IFERROR(SUM(ZB10:ZB59),"") -> 0 | ZC2: =IFERROR(AVERAGE(ZC10:ZC59),"") | ZD2: =IFERROR(AVERAGE(ZD10:ZD59),"") | ZE2: =IFERROR(AVERAGE(ZE10:ZE59),"") | ZF2: =IFERROR(AVERAGE(ZF10:ZF59),"") | ZG2: =IFERROR(AVERAGE(ZG10:ZG59),"") | ZH2: =IFERROR(AVERAGE(ZH10:ZH59),"") | ZI2: =IFERROR(AVERAGE(ZI10:ZI59),"") | ZJ2: =IFERROR(AVERAGE(ZJ10:ZJ59),"") | ... ZN2: =IFERROR(AVERAGE(ZN10:ZN59),"") | ZO2: =IFERROR(SUM(ZO10:ZO59),"") -> 0 | ZP2: =IFERROR(AVERAGE(ZP10:ZP59),"") | ZQ2: =IFERROR(AVERAGE(ZQ10:ZQ59),"") | ZR2: =IFERROR(AVERAGE(ZR10:ZR59),"") | ZS2: =IFERROR(AVERAGE(ZS10:ZS59),"") | ZT2: =IFERROR(AVERAGE(ZT10:ZT59),"") | ZU2: =IFERROR(AVERAGE(ZU10:ZU59),"") | ZV2: =IFERROR(AVERAGE(ZV10:ZV59),"") | ZW2: =IFERROR(SUM(ZW10:ZW59),"") -> 0 | ZX2: =IFERROR(AVERAGE(ZX10:ZX59),"") | ZZ2: =IF(ZY1="","",ZY1) -> 181 | AAA2: =IF(AAA10="","",AAA10) | AAB2: =IFERROR(AVERAGE(AAB10:AAB59),"") | AAC2: =IFERROR(AVERAGE(AAC10:AAC59),"") | AAD2: =IFERROR(AVERAGE(AAD10:AAD59),"") | AAE2: =IFERROR(AVERAGE(AAE10:AAE59),"") | AAF2: =IFERROR(AVERAGE(AAF10:AAF59),"") | AAG2: =IFERROR(AVERAGE(AAG10:AAG59),"") | AAH2: =IFERROR(AVERAGE(AAH10:AAH59),"") | AAI2: =IFERROR(AVERAGE(AAI10:AAI59),"") | ... AAM2: =IFERROR(AVERAGE(AAM10:AAM59),"") | AAN2: =IFERROR(SUM(AAN10:AAN59),"") -> 0 | AAO2: =IFERROR(AVERAGE(AAO10:AAO59),"") | AAP2: =IFERROR(AVERAGE(AAP10:AAP59),"") | AAQ2: =IFERROR(AVERAGE(AAQ10:AAQ59),"") | AAR2: =IFERROR(AVERAGE(AAR10:AAR59),"") | AAS2: =IFERROR(AVERAGE(AAS10:AAS59),"") | AAT2: =IFERROR(AVERAGE(AAT10:AAT59),"") | AAU2: =IFERROR(AVERAGE(AAU10:AAU59),"") | AAV2: =IFERROR(AVERAGE(AAV10:AAV59),"") | ... AAZ2: =IFERROR(AVERAGE(AAZ10:AAZ59),"") | ABA2: =IFERROR(SUM(ABA10:ABA59),"") -> 0 | ABB2: =IFERROR(AVERAGE(ABB10:ABB59),"") | ABC2: =IFERROR(AVERAGE(ABC10:ABC59),"") | ABD2: =IFERROR(AVERAGE(ABD10:ABD59),"") | ABE2: =IFERROR(AVERAGE(ABE10:ABE59),"") | ABF2: =IFERROR(AVERAGE(ABF10:ABF59),"") | ABG2: =IFERROR(AVERAGE(ABG10:ABG59),"") | ABH2: =IFERROR(AVERAGE(ABH10:ABH59),"") | ABI2: =IFERROR(SUM(ABI10:ABI59),"") -> 0 | ABJ2: =IFERROR(AVERAGE(ABJ10:ABJ59),"") | ABL2: =IF(ABK1="","",ABK1) -> 182 | ABM2: =IF(ABM10="","",ABM10) | ABN2: =IFERROR(AVERAGE(ABN10:ABN59),"") | ABO2: =IFERROR(AVERAGE(ABO10:ABO59),"") | ABP2: =IFERROR(AVERAGE(ABP10:ABP59),"") | ABQ2: =IFERROR(AVERAGE(ABQ10:ABQ59),"") | ABR2: =IFERROR(AVERAGE(ABR10:ABR59),"") | ABS2: =IFERROR(AVERAGE(ABS10:ABS59),"") | ABT2: =IFERROR(AVERAGE(ABT10:ABT59),"") | ABU2: =IFERROR(AVERAGE(ABU10:ABU59),"") | ... ABY2: =IFERROR(AVERAGE(ABY10:ABY59),"") | ABZ2: =IFERROR(SUM(ABZ10:ABZ59),"") -> 0 | ACA2: =IFERROR(AVERAGE(ACA10:ACA59),"") | ACB2: =IFERROR(AVERAGE(ACB10:ACB59),"") | ACC2: =IFERROR(AVERAGE(ACC10:ACC59),"") | ACD2: =IFERROR(AVERAGE(ACD10:ACD59),"") | ACE2: =IFERROR(AVERAGE(ACE10:ACE59),"") | ACF2: =IFERROR(AVERAGE(ACF10:ACF59),"") | ACG2: =IFERROR(AVERAGE(ACG10:ACG59),"") | ACH2: =IFERROR(AVERAGE(ACH10:ACH59),"") | ... ACL2: =IFERROR(AVERAGE(ACL10:ACL59),"") | ACM2: =IFERROR(SUM(ACM10:ACM59),"") -> 0 | ACN2: =IFERROR(AVERAGE(ACN10:ACN59),"") | ACO2: =IFERROR(AVERAGE(ACO10:ACO59),"") | ACP2: =IFERROR(AVERAGE(ACP10:ACP59),"") | ACQ2: =IFERROR(AVERAGE(ACQ10:ACQ59),"") | ACR2: =IFERROR(AVERAGE(ACR10:ACR59),"") | ACS2: =IFERROR(AVERAGE(ACS10:ACS59),"") | ACT2: =IFERROR(AVERAGE(ACT10:ACT59),"") | ACU2: =IFERROR(SUM(ACU10:ACU59),"") -> 0 | ACV2: =IFERROR(AVERAGE(ACV10:ACV59),"") | ACX2: =IF(ACW1="","",ACW1) -> 281 | ACY2: =IF(ACY10="","",ACY10) | ACZ2: =IFERROR(AVERAGE(ACZ10:ACZ59),"") | ADA2: =IFERROR(AVERAGE(ADA10:ADA59),"") | ADB2: =IFERROR(AVERAGE(ADB10:ADB59),"") | ADC2: =IFERROR(AVERAGE(ADC10:ADC59),"") | ADD2: =IFERROR(AVERAGE(ADD10:ADD59),"") | ADE2: =IFERROR(AVERAGE(ADE10:ADE59),"") | ADF2: =IFERROR(AVERAGE(ADF10:ADF59),"") | ADG2: =IFERROR(AVERAGE(ADG10:ADG59),"") | ... ADK2: =IFERROR(AVERAGE(ADK10:ADK59),"") | ADL2: =IFERROR(SUM(ADL10:ADL59),"") -> 0 | ADM2: =IFERROR(AVERAGE(ADM10:ADM59),"") | ADN2: =IFERROR(AVERAGE(ADN10:ADN59),"") | ADO2: =IFERROR(AVERAGE(ADO10:ADO59),"") | ADP2: =IFERROR(AVERAGE(ADP10:ADP59),"") | ADQ2: =IFERROR(AVERAGE(ADQ10:ADQ59),"") | ADR2: =IFERROR(AVERAGE(ADR10:ADR59),"") | ADS2: =IFERROR(AVERAGE(ADS10:ADS59),"") | ADT2: =IFERROR(AVERAGE(ADT10:ADT59),"") | ... ADX2: =IFERROR(AVERAGE(ADX10:ADX59),"") | ADY2: =IFERROR(SUM(ADY10:ADY59),"") -> 0 | ADZ2: =IFERROR(AVERAGE(ADZ10:ADZ59),"") | AEA2: =IFERROR(AVERAGE(AEA10:AEA59),"") | AEB2: =IFERROR(AVERAGE(AEB10:AEB59),"") | AEC2: =IFERROR(AVERAGE(AEC10:AEC59),"") | AED2: =IFERROR(AVERAGE(AED10:AED59),"") | AEE2: =IFERROR(AVERAGE(AEE10:AEE59),"") | AEF2: =IFERROR(AVERAGE(AEF10:AEF59),"") | AEG2: =IFERROR(SUM(AEG10:AEG59),"") -> 0 | AEH2: =IFERROR(AVERAGE(AEH10:AEH59),"") | AEJ2: =IF(AEI1="","",AEI1) -> 771 | AEK2: =IF(AEK10="","",AEK10) | AEL2: =IFERROR(AVERAGE(AEL10:AEL59),"") | AEM2: =IFERROR(AVERAGE(AEM10:AEM59),"") | AEN2: =IFERROR(AVERAGE(AEN10:AEN59),"") | AEO2: =IFERROR(AVERAGE(AEO10:AEO59),"") | AEP2: =IFERROR(AVERAGE(AEP10:AEP59),"") | AEQ2: =IFERROR(AVERAGE(AEQ10:AEQ59),"") | AER2: =IFERROR(AVERAGE(AER10:AER59),"") | AES2: =IFERROR(AVERAGE(AES10:AES59),"") | ... AEW2: =IFERROR(AVERAGE(AEW10:AEW59),"") | AEX2: =IFERROR(SUM(AEX10:AEX59),"") -> 0 | AEY2: =IFERROR(AVERAGE(AEY10:AEY59),"") | AEZ2: =IFERROR(AVERAGE(AEZ10:AEZ59),"") | AFA2: =IFERROR(AVERAGE(AFA10:AFA59),"") | AFB2: =IFERROR(AVERAGE(AFB10:AFB59),"") | AFC2: =IFERROR(AVERAGE(AFC10:AFC59),"") | AFD2: =IFERROR(AVERAGE(AFD10:AFD59),"") | AFE2: =IFERROR(AVERAGE(AFE10:AFE59),"") | AFF2: =IFERROR(AVERAGE(AFF10:AFF59),"") | ... AFJ2: =IFERROR(AVERAGE(AFJ10:AFJ59),"") | AFK2: =IFERROR(SUM(AFK10:AFK59),"") -> 0 | AFL2: =IFERROR(AVERAGE(AFL10:AFL59),"") | AFM2: =IFERROR(AVERAGE(AFM10:AFM59),"") | AFN2: =IFERROR(AVERAGE(AFN10:AFN59),"") | AFO2: =IFERROR(AVERAGE(AFO10:AFO59),"") | AFP2: =IFERROR(AVERAGE(AFP10:AFP59),"") | AFQ2: =IFERROR(AVERAGE(AFQ10:AFQ59),"") | AFR2: =IFERROR(AVERAGE(AFR10:AFR59),"") | AFS2: =IFERROR(SUM(AFS10:AFS59),"") -> 0 | AFT2: =IFERROR(AVERAGE(AFT10:AFT59),"") | AFV2: =IF(AFU1="","",AFU1) -> 926 | AFW2: =IF(AFW10="","",AFW10) | AFX2: =IFERROR(AVERAGE(AFX10:AFX59),"") | AFY2: =IFERROR(AVERAGE(AFY10:AFY59),"") | AFZ2: =IFERROR(AVERAGE(AFZ10:AFZ59),"") | AGA2: =IFERROR(AVERAGE(AGA10:AGA59),"") | AGB2: =IFERROR(AVERAGE(AGB10:AGB59),"") | AGC2: =IFERROR(AVERAGE(AGC10:AGC59),"") | AGD2: =IFERROR(AVERAGE(AGD10:AGD59),"") | AGE2: =IFERROR(AVERAGE(AGE10:AGE59),"") | ... AGI2: =IFERROR(AVERAGE(AGI10:AGI59),"") | AGJ2: =IFERROR(SUM(AGJ10:AGJ59),"") -> 0 | AGK2: =IFERROR(AVERAGE(AGK10:AGK59),"") | AGL2: =IFERROR(AVERAGE(AGL10:AGL59),"") | AGM2: =IFERROR(AVERAGE(AGM10:AGM59),"") | AGN2: =IFERROR(AVERAGE(AGN10:AGN59),"") | AGO2: =IFERROR(AVERAGE(AGO10:AGO59),"") | AGP2: =IFERROR(AVERAGE(AGP10:AGP59),"") | AGQ2: =IFERROR(AVERAGE(AGQ10:AGQ59),"") | AGR2: =IFERROR(AVERAGE(AGR10:AGR59),"") | ... AGV2: =IFERROR(AVERAGE(AGV10:AGV59),"") | AGW2: =IFERROR(SUM(AGW10:AGW59),"") -> 0 | AGX2: =IFERROR(AVERAGE(AGX10:AGX59),"") | AGY2: =IFERROR(AVERAGE(AGY10:AGY59),"") | AGZ2: =IFERROR(AVERAGE(AGZ10:AGZ59),"") | AHA2: =IFERROR(AVERAGE(AHA10:AHA59),"") | AHB2: =IFERROR(AVERAGE(AHB10:AHB59),"") | AHC2: =IFERROR(AVERAGE(AHC10:AHC59),"") | AHD2: =IFERROR(AVERAGE(AHD10:AHD59),"") | AHE2: =IFERROR(SUM(AHE10:AHE59),"") -> 0 | AHF2: =IFERROR(AVERAGE(AHF10:AHF59),"") | AHH2: =IF(AHG1="","",AHG1) -> 927 | AHI2: =IF(AHI10="","",AHI10) | AHJ2: =IFERROR(AVERAGE(AHJ10:AHJ59),"") | AHK2: =IFERROR(AVERAGE(AHK10:AHK59),"") | AHL2: =IFERROR(AVERAGE(AHL10:AHL59),"") | AHM2: =IFERROR(AVERAGE(AHM10:AHM59),"") | AHN2: =IFERROR(AVERAGE(AHN10:AHN59),"") | AHO2: =IFERROR(AVERAGE(AHO10:AHO59),"") | AHP2: =IFERROR(AVERAGE(AHP10:AHP59),"") | AHQ2: =IFERROR(AVERAGE(AHQ10:AHQ59),"") | ... AHU2: =IFERROR(AVERAGE(AHU10:AHU59),"") | AHV2: =IFERROR(SUM(AHV10:AHV59),"") -> 0 | AHW2: =IFERROR(AVERAGE(AHW10:AHW59),"") | AHX2: =IFERROR(AVERAGE(AHX10:AHX59),"") | AHY2: =IFERROR(AVERAGE(AHY10:AHY59),"") | AHZ2: =IFERROR(AVERAGE(AHZ10:AHZ59),"") | AIA2: =IFERROR(AVERAGE(AIA10:AIA59),"") | AIB2: =IFERROR(AVERAGE(AIB10:AIB59),"") | AIC2: =IFERROR(AVERAGE(AIC10:AIC59),"") | AID2: =IFERROR(AVERAGE(AID10:AID59),"") | ... AIH2: =IFERROR(AVERAGE(AIH10:AIH59),"") | AII2: =IFERROR(SUM(AII10:AII59),"") -> 0 | AIJ2: =IFERROR(AVERAGE(AIJ10:AIJ59),"") | AIK2: =IFERROR(AVERAGE(AIK10:AIK59),"") | AIL2: =IFERROR(AVERAGE(AIL10:AIL59),"") | AIM2: =IFERROR(AVERAGE(AIM10:AIM59),"") | AIN2: =IFERROR(AVERAGE(AIN10:AIN59),"") | AIO2: =IFERROR(AVERAGE(AIO10:AIO59),"") | AIP2: =IFERROR(AVERAGE(AIP10:AIP59),"") | AIQ2: =IFERROR(SUM(AIQ10:AIQ59),"") -> 0 | AIR2: =IFERROR(AVERAGE(AIR10:AIR59),"")
